Workbook

Sheet Synthèse agents
A1: Synthèse d'assiduité par agent
A2: Du | B2: =MIN(Données!$Q$2:$Q$5000) -> 45982 | C2: ← Période modifiable : saisir une date pour filtrer toutes les colonnes (par défaut : tout l'historique).
A3: Au | B3: =MAX(Données!$Q$2:$Q$5000) -> 46327
A5: Agent | B5: Jours planifiés | C5: Jours d'absence | D5: Taux d'absentéisme (jours) | E5: Nb retards | F5: Total retards | G5: Nb départs anticipés | H5: Total départs anticipés | I5: Hr planifiées | J5: Hr adhérées | K5: Taux d'adhérence | L5: Hr absence totales | M5: Taux d'absentéisme (heures) | N5: Heures sup | O5: Jours congé payé | P5: Jours congé sans solde | Q5: Jours congé spécial | R5: Jours fériés
A6: =Agents!A2 -> BENCHRIF HAFSSA | B6: =COUNTIFS(Données!$B$2:$B$5000,$A6,Données!$Q$2:$Q$5000,">="&$B$2,Données!$Q$2:$Q$5000,"<="&$B$3,Données!$O$2:$O$5000,">0") -> 102 | C6: =COUNTIFS(Données!$B$2:$B$5000,$A6,Données!$Q$2:$Q$5000,">="&$B$2,Données!$Q$2:$Q$5000,"<="&$B$3,Données!$M$2:$M$5000,"Abs") -> 1 | D6: =IFERROR(C6/B6,0) -> 0.0098039216 | E6: =COUNTIFS(Données!$B$2:$B$5000,$A6,Données!$Q$2:$Q$5000,">="&$B$2,Données!$Q$2:$Q$5000,"<="&$B$3,Données!$I$2:$I$5000,">0") -> 2 | F6: =SUMIFS(Données!$I$2:$I$5000,Données!$B$2:$B$5000,$A6,Données!$Q$2:$Q$5000,">="&$B$2,Données!$Q$2:$Q$5000,"<="&$B$3) -> 0.019444444 | G6: =COUNTIFS(Données!$B$2:$B$5000,$A6,Données!$Q$2:$Q$5000,">="&$B$2,Données!$Q$2:$Q$5000,"<="&$B$3,Données!$L$2:$L$5000,">0") -> 0 | H6: =SUMIFS(Données!$L$2:$L$5000,Données!$B$2:$B$5000,$A6,Données!$Q$2:$Q$5000,">="&$B$2,Données!$Q$2:$Q$5000,"<="&$B$3) -> 0 | I6: =SUMIFS(Données!$O$2:$O$5000,Données!$B$2:$B$5000,$A6,Données!$Q$2:$Q$5000,">="&$B$2,Données!$Q$2:$Q$5000,"<="&$B$3) -> 37.291667 | J6: =SUMIFS(Données!$N$2:$N$5000,Données!$B$2:$B$5000,$A6,Données!$Q$2:$Q$5000,">="&$B$2,Données!$Q$2:$Q$5000,"<="&$B$3) -> 36.897222 | K6: =IFERROR(J6/I6,0) -> 0.98942272 | L6: =SUMIFS(Données!$S$2:$S$5000,Données!$B$2:$B$5000,$A6,Données!$Q$2:$Q$5000,">="&$B$2,Données!$Q$2:$Q$5000,"<="&$B$3) -> 0.39444444 | M6: =IFERROR(L6/I6,0) -> 0.010577281 | N6: =SUMIFS(Données!$X$2:$X$5000,Données!$B$2:$B$5000,$A6,Données!$Q$2:$Q$5000,">="&$B$2,Données!$Q$2:$Q$5000,"<="&$B$3) -> 0.010416667 | O6: =ROUND(SUMIFS(Données!$AB$2:$AB$5000,Données!$B$2:$B$5000,$A6,Données!$Q$2:$Q$5000,">="&$B$2,Données!$Q$2:$Q$5000,"<="&$B$3)*3,2) -> 3 | P6: =ROUND(SUMIFS(Données!$AC$2:$AC$5000,Données!$B$2:$B$5000,$A6,Données!$Q$2:$Q$5000,">="&$B$2,Données!$Q$2:$Q$5000,"<="&$B$3)*3,2) -> 0 | Q6: =ROUND(SUMIFS(Données!$AD$2:$AD$5000,Données!$B$2:$B$5000,$A6,Données!$Q$2:$Q$5000,">="&$B$2,Données!$Q$2:$Q$5000,"<="&$B$3)*3,2) -> 0 | R6: =ROUND(SUMIFS(Données!$AE$2:$AE$5000,Données!$B$2:$B$5000,$A6,Données!$Q$2:$Q$5000,">="&$B$2,Données!$Q$2:$Q$5000,"<="&$B$3)*3,2) -> 1
A7: =Agents!A3 -> HAMDANI MOHAMED | B7: =COUNTIFS(Données!$B$2:$B$5000,$A7,Données!$Q$2:$Q$5000,">="&$B$2,Données!$Q$2:$Q$5000,"<="&$B$3,Données!$O$2:$O$5000,">0") -> 233 | C7: =COUNTIFS(Données!$B$2:$B$5000,$A7,Données!$Q$2:$Q$5000,">="&$B$2,Données!$Q$2:$Q$5000,"<="&$B$3,Données!$M$2:$M$5000,"Abs") -> 6 | D7: =IFERROR(C7/B7,0) -> 0.025751073 | E7: =COUNTIFS(Données!$B$2:$B$5000,$A7,Données!$Q$2:$Q$5000,">="&$B$2,Données!$Q$2:$Q$5000,"<="&$B$3,Données!$I$2:$I$5000,">0") -> 9 | F7: =SUMIFS(Données!$I$2:$I$5000,Données!$B$2:$B$5000,$A7,Données!$Q$2:$Q$5000,">="&$B$2,Données!$Q$2:$Q$5000,"<="&$B$3) -> 0.10902778 | G7: =COUNTIFS(Données!$B$2:$B$5000,$A7,Données!$Q$2:$Q$5000,">="&$B$2,Données!$Q$2:$Q$5000,"<="&$B$3,Données!$L$2:$L$5000,">0") -> 0 | H7: =SUMIFS(Données!$L$2:$L$5000,Données!$B$2:$B$5000,$A7,Données!$Q$2:$Q$5000,">="&$B$2,Données!$Q$2:$Q$5000,"<="&$B$3) -> 0 | I7: =SUMIFS(Données!$O$2:$O$5000,Données!$B$2:$B$5000,$A7,Données!$Q$2:$Q$5000,">="&$B$2,Données!$Q$2:$Q$5000,"<="&$B$3) -> 85.416667 | J7: =SUMIFS(Données!$N$2:$N$5000,Données!$B$2:$B$5000,$A7,Données!$Q$2:$Q$5000,">="&$B$2,Données!$Q$2:$Q$5000,"<="&$B$3) -> 83.140972 | K7: =IFERROR(J7/I7,0) -> 0.97335772 | L7: =SUMIFS(Données!$S$2:$S$5000,Données!$B$2:$B$5000,$A7,Données!$Q$2:$Q$5000,">="&$B$2,Données!$Q$2:$Q$5000,"<="&$B$3) -> 2.2756944 | M7: =IFERROR(L7/I7,0) -> 0.026642276 | N7: =SUMIFS(Données!$X$2:$X$5000,Données!$B$2:$B$5000,$A7,Données!$Q$2:$Q$5000,">="&$B$2,Données!$Q$2:$Q$5000,"<="&$B$3) -> 0.14652778 | O7: =ROUND(SUMIFS(Données!$AB$2:$AB$5000,Données!$B$2:$B$5000,$A7,Données!$Q$2:$Q$5000,">="&$B$2,Données!$Q$2:$Q$5000,"<="&$B$3)*3,2) -> 4 | P7: =ROUND(SUMIFS(Données!$AC$2:$AC$5000,Données!$B$2:$B$5000,$A7,Données!$Q$2:$Q$5000,">="&$B$2,Données!$Q$2:$Q$5000,"<="&$B$3)*3,2) -> 0 | Q7: =ROUND(SUMIFS(Données!$AD$2:$AD$5000,Données!$B$2:$B$5000,$A7,Données!$Q$2:$Q$5000,">="&$B$2,Données!$Q$2:$Q$5000,"<="&$B$3)*3,2) -> 0 | R7: =ROUND(SUMIFS(Données!$AE$2:$AE$5000,Données!$B$2:$B$5000,$A7,Données!$Q$2:$Q$5000,">="&$B$2,Données!$Q$2:$Q$5000,"<="&$B$3)*3,2) -> 4
A8: =Agents!A4 -> JEBBALI YOUSSEF | B8: =COUNTIFS(Données!$B$2:$B$5000,$A8,Données!$Q$2:$Q$5000,">="&$B$2,Données!$Q$2:$Q$5000,"<="&$B$3,Données!$O$2:$O$5000,">0") -> 20 | C8: =COUNTIFS(Données!$B$2:$B$5000,$A8,Données!$Q$2:$Q$5000,">="&$B$2,Données!$Q$2:$Q$5000,"<="&$B$3,Données!$M$2:$M$5000,"Abs") -> 1 | D8: =IFERROR(C8/B8,0) -> 0.05 | E8: =COUNTIFS(Données!$B$2:$B$5000,$A8,Données!$Q$2:$Q$5000,">="&$B$2,Données!$Q$2:$Q$5000,"<="&$B$3,Données!$I$2:$I$5000,">0") -> 0 | F8: =SUMIFS(Données!$I$2:$I$5000,Données!$B$2:$B$5000,$A8,Données!$Q$2:$Q$5000,">="&$B$2,Données!$Q$2:$Q$5000,"<="&$B$3) -> 0 | G8: =COUNTIFS(Données!$B$2:$B$5000,$A8,Données!$Q$2:$Q$5000,">="&$B$2,Données!$Q$2:$Q$5000,"<="&$B$3,Données!$L$2:$L$5000,">0") -> 0 | H8: =SUMIFS(Données!$L$2:$L$5000,Données!$B$2:$B$5000,$A8,Données!$Q$2:$Q$5000,">="&$B$2,Données!$Q$2:$Q$5000,"<="&$B$3) -> 0 | I8: =SUMIFS(Données!$O$2:$O$5000,Données!$B$2:$B$5000,$A8,Données!$Q$2:$Q$5000,">="&$B$2,Données!$Q$2:$Q$5000,"<="&$B$3) -> 7.3333333 | J8: =SUMIFS(Données!$N$2:$N$5000,Données!$B$2:$B$5000,$A8,Données!$Q$2:$Q$5000,">="&$B$2,Données!$Q$2:$Q$5000,"<="&$B$3) -> 7 | K8: =IFERROR(J8/I8,0) -> 0.95454545 | L8: =SUMIFS(Données!$S$2:$S$5000,Données!$B$2:$B$5000,$A8,Données!$Q$2:$Q$5000,">="&$B$2,Données!$Q$2:$Q$5000,"<="&$B$3) -> 0.33333333 | M8: =IFERROR(L8/I8,0) -> 0.045454545 | N8: =SUMIFS(Données!$X$2:$X$5000,Données!$B$2:$B$5000,$A8,Données!$Q$2:$Q$5000,">="&$B$2,Données!$Q$2:$Q$5000,"<="&$B$3) -> 0.020833333 | O8: =ROUND(SUMIFS(Données!$AB$2:$AB$5000,Données!$B$2:$B$5000,$A8,Données!$Q$2:$Q$5000,">="&$B$2,Données!$Q$2:$Q$5000,"<="&$B$3)*3,2) -> 0 | P8: =ROUND(SUMIFS(Données!$AC$2:$AC$5000,Données!$B$2:$B$5000,$A8,Données!$Q$2:$Q$5000,">="&$B$2,Données!$Q$2:$Q$5000,"<="&$B$3)*3,2) -> 0 | Q8: =ROUND(SUMIFS(Données!$AD$2:$AD$5000,Données!$B$2:$B$5000,$A8,Données!$Q$2:$Q$5000,">="&$B$2,Données!$Q$2:$Q$5000,"<="&$B$3)*3,2) -> 0 | R8: =ROUND(SUMIFS(Données!$AE$2:$AE$5000,Données!$B$2:$B$5000,$A8,Données!$Q$2:$Q$5000,">="&$B$2,Données!$Q$2:$Q$5000,"<="&$B$3)*3,2) -> 0
A9: =Agents!A5 -> LISSAOUI HIBA | B9: =COUNTIFS(Données!$B$2:$B$5000,$A9,Données!$Q$2:$Q$5000,">="&$B$2,Données!$Q$2:$Q$5000,"<="&$B$3,Données!$O$2:$O$5000,">0") -> 228 | C9: =COUNTIFS(Données!$B$2:$B$5000,$A9,Données!$Q$2:$Q$5000,">="&$B$2,Données!$Q$2:$Q$5000,"<="&$B$3,Données!$M$2:$M$5000,"Abs") -> 7 | D9: =IFERROR(C9/B9,0) -> 0.030701754 | E9: =COUNTIFS(Données!$B$2:$B$5000,$A9,Données!$Q$2:$Q$5000,">="&$B$2,Données!$Q$2:$Q$5000,"<="&$B$3,Données!$I$2:$I$5000,">0") -> 1 | F9: =SUMIFS(Données!$I$2:$I$5000,Données!$B$2:$B$5000,$A9,Données!$Q$2:$Q$5000,">="&$B$2,Données!$Q$2:$Q$5000,"<="&$B$3) -> 0.057638889 | G9: =COUNTIFS(Données!$B$2:$B$5000,$A9,Données!$Q$2:$Q$5000,">="&$B$2,Données!$Q$2:$Q$5000,"<="&$B$3,Données!$L$2:$L$5000,">0") -> 0 | H9: =SUMIFS(Données!$L$2:$L$5000,Données!$B$2:$B$5000,$A9,Données!$Q$2:$Q$5000,">="&$B$2,Données!$Q$2:$Q$5000,"<="&$B$3) -> 0 | I9: =SUMIFS(Données!$O$2:$O$5000,Données!$B$2:$B$5000,$A9,Données!$Q$2:$Q$5000,">="&$B$2,Données!$Q$2:$Q$5000,"<="&$B$3) -> 83.541667 | J9: =SUMIFS(Données!$N$2:$N$5000,Données!$B$2:$B$5000,$A9,Données!$Q$2:$Q$5000,">="&$B$2,Données!$Q$2:$Q$5000,"<="&$B$3) -> 80.942361 | K9: =IFERROR(J9/I9,0) -> 0.96888612 | L9: =SUMIFS(Données!$S$2:$S$5000,Données!$B$2:$B$5000,$A9,Données!$Q$2:$Q$5000,">="&$B$2,Données!$Q$2:$Q$5000,"<="&$B$3) -> 2.5993056 | M9: =IFERROR(L9/I9,0) -> 0.031113882 | N9: =SUMIFS(Données!$X$2:$X$5000,Données!$B$2:$B$5000,$A9,Données!$Q$2:$Q$5000,">="&$B$2,Données!$Q$2:$Q$5000,"<="&$B$3) -> 0.19097222 | O9: =ROUND(SUMIFS(Données!$AB$2:$AB$5000,Données!$B$2:$B$5000,$A9,Données!$Q$2:$Q$5000,">="&$B$2,Données!$Q$2:$Q$5000,"<="&$B$3)*3,2) -> 8 | P9: =ROUND(SUMIFS(Données!$AC$2:$AC$5000,Données!$B$2:$B$5000,$A9,Données!$Q$2:$Q$5000,">="&$B$2,Données!$Q$2:$Q$5000,"<="&$B$3)*3,2) -> 0 | Q9: =ROUND(SUMIFS(Données!$AD$2:$AD$5000,Données!$B$2:$B$5000,$A9,Données!$Q$2:$Q$5000,">="&$B$2,Données!$Q$2:$Q$5000,"<="&$B$3)*3,2) -> 0 | R9: =ROUND(SUMIFS(Données!$AE$2:$AE$5000,Données!$B$2:$B$5000,$A9,Données!$Q$2:$Q$5000,">="&$B$2,Données!$Q$2:$Q$5000,"<="&$B$3)*3,2) -> 5
A10: =Agents!A6 -> RMAIDI IMAD | B10: =COUNTIFS(Données!$B$2:$B$5000,$A10,Données!$Q$2:$Q$5000,">="&$B$2,Données!$Q$2:$Q$5000,"<="&$B$3,Données!$O$2:$O$5000,">0") -> 228 | C10: =COUNTIFS(Données!$B$2:$B$5000,$A10,Données!$Q$2:$Q$5000,">="&$B$2,Données!$Q$2:$Q$5000,"<="&$B$3,Données!$M$2:$M$5000,"Abs") -> 6 | D10: =IFERROR(C10/B10,0) -> 0.026315789 | E10: =COUNTIFS(Données!$B$2:$B$5000,$A10,Données!$Q$2:$Q$5000,">="&$B$2,Données!$Q$2:$Q$5000,"<="&$B$3,Données!$I$2:$I$5000,">0") -> 4 | F10: =SUMIFS(Données!$I$2:$I$5000,Données!$B$2:$B$5000,$A10,Données!$Q$2:$Q$5000,">="&$B$2,Données!$Q$2:$Q$5000,"<="&$B$3) -> 0.024305556 | G10: =COUNTIFS(Données!$B$2:$B$5000,$A10,Données!$Q$2:$Q$5000,">="&$B$2,Données!$Q$2:$Q$5000,"<="&$B$3,Données!$L$2:$L$5000,">0") -> 0 | H10: =SUMIFS(Données!$L$2:$L$5000,Données!$B$2:$B$5000,$A10,Données!$Q$2:$Q$5000,">="&$B$2,Données!$Q$2:$Q$5000,"<="&$B$3) -> 0 | I10: =SUMIFS(Données!$O$2:$O$5000,Données!$B$2:$B$5000,$A10,Données!$Q$2:$Q$5000,">="&$B$2,Données!$Q$2:$Q$5000,"<="&$B$3) -> 83.541667 | J10: =SUMIFS(Données!$N$2:$N$5000,Données!$B$2:$B$5000,$A10,Données!$Q$2:$Q$5000,">="&$B$2,Données!$Q$2:$Q$5000,"<="&$B$3) -> 81.350694 | K10: =IFERROR(J10/I10,0) -> 0.9737739 | L10: =SUMIFS(Données!$S$2:$S$5000,Données!$B$2:$B$5000,$A10,Données!$Q$2:$Q$5000,">="&$B$2,Données!$Q$2:$Q$5000,"<="&$B$3) -> 2.1909722 | M10: =IFERROR(L10/I10,0) -> 0.026226101 | N10: =SUMIFS(Données!$X$2:$X$5000,Données!$B$2:$B$5000,$A10,Données!$Q$2:$Q$5000,">="&$B$2,Données!$Q$2:$Q$5000,"<="&$B$3) -> 0.17777778 | O10: =ROUND(SUMIFS(Données!$AB$2:$AB$5000,Données!$B$2:$B$5000,$A10,Données!$Q$2:$Q$5000,">="&$B$2,Données!$Q$2:$Q$5000,"<="&$B$3)*3,2) -> 10 | P10: =ROUND(SUMIFS(Données!$AC$2:$AC$5000,Données!$B$2:$B$5000,$A10,Données!$Q$2:$Q$5000,">="&$B$2,Données!$Q$2:$Q$5000,"<="&$B$3)*3,2) -> 0 | Q10: =ROUND(SUMIFS(Données!$AD$2:$AD$5000,Données!$B$2:$B$5000,$A10,Données!$Q$2:$Q$5000,">="&$B$2,Données!$Q$2:$Q$5000,"<="&$B$3)*3,2) -> 0 | R10: =ROUND(SUMIFS(Données!$AE$2:$AE$5000,Données!$B$2:$B$5000,$A10,Données!$Q$2:$Q$5000,">="&$B$2,Données!$Q$2:$Q$5000,"<="&$B$3)*3,2) -> 3
A11: TOTAL | B11: =SUM(B6:B10) -> 811 | C11: =SUM(C6:C10) -> 21 | D11: =IFERROR(C11/B11,0) -> 0.025893958 | E11: =SUM(E6:E10) -> 16 | F11: =SUM(F6:F10) -> 0.21041667 | G11: =SUM(G6:G10) -> 0 | H11: =SUM(H6:H10) -> 0 | I11: =SUM(I6:I10) -> 297.125 | J11: =SUM(J6:J10) -> 289.33125 | K11: =IFERROR(J11/I11,0) -> 0.97376946 | L11: =SUM(L6:L10) -> 7.79375 | M11: =IFERROR(L11/I11,0) -> 0.026230543 | N11: =SUM(N6:N10) -> 0.54652778 | O11: =SUM(O6:O10) -> 25 | P11: =SUM(P6:P10) -> 0 | Q11: =SUM(Q6:Q10) -> 0 | R11: =SUM(R6:R10) -> 13
A13: Notes
A14: • Absence = jour planifié (Hr planifiée > 0) sans heure de début réalisée. Adhérence = Hr adhérées / Hr planifiées.
A15: • Congés : valeurs d'origine 1/3 de jour = 8 h ; les colonnes « Jours » = somme × 3 (1 = journée complète, 0,5 = demi-journée).
A16: • Les durées sont au format [h]:mm (heures cumulées, pas limitées à 24 h).
A17: • Feuille Données : cellules bleues = saisies issues des fichiers hebdomadaires ; cellules noires = formules (reprises à l'identique de vos fichiers).
A18: • Ajouter une semaine : coller les lignes à la suite dans Données (colonnes bleues), recopier les formules vers le bas ; les synthèses se mettent à jour.

Sheet Par semaine
A1: Assiduité par semaine
A2: Agent | B2: Tous | C2: ← Choisir « Tous » ou un agent dans la liste.
A3: Critère | B3: =IF($B$2="Tous","*",$B$2) -> *
A5: Semaine | B5: Début | C5: Fin | D5: Jours planifiés | E5: Jours d'absence | F5: Taux d'absentéisme (jours) | G5: Nb retards | H5: Total retards | I5: Total départs anticipés | J5: Hr planifiées | K5: Hr adhérées | L5: Taux d'adhérence | M5: Hr absence totales | N5: Taux d'absentéisme (heures) | O5: Heures sup
A6: =IF(B6="","",YEAR(B6+3)&"-S"&TEXT(WEEKNUM(B6,21),"00")) -> 2025-S47 | B6: =MIN(Données!$Q$2:$Q$5000)-WEEKDAY(MIN(Données!$Q$2:$Q$5000),2)+1 -> 45978 | C6: =IF(B6="","",B6+6) -> 45984 | D6: =IF($B6="","",COUNTIFS(Données!$A$2:$A$5000,$A6,Données!$B$2:$B$5000,$B$3,Données!$O$2:$O$5000,">0")) -> 4 | E6: =IF($B6="","",COUNTIFS(Données!$A$2:$A$5000,$A6,Données!$B$2:$B$5000,$B$3,Données!$M$2:$M$5000,"Abs")) -> 0 | F6: =IF($B6="","",IFERROR(E6/D6,0)) -> 0 | G6: =IF($B6="","",COUNTIFS(Données!$A$2:$A$5000,$A6,Données!$B$2:$B$5000,$B$3,Données!$I$2:$I$5000,">0")) -> 0 | H6: =IF($B6="","",SUMIFS(Données!$I$2:$I$5000,Données!$A$2:$A$5000,$A6,Données!$B$2:$B$5000,$B$3)) -> 0 | I6: =IF($B6="","",SUMIFS(Données!$L$2:$L$5000,Données!$A$2:$A$5000,$A6,Données!$B$2:$B$5000,$B$3)) -> 0 | J6: =IF($B6="","",SUMIFS(Données!$O$2:$O$5000,Données!$A$2:$A$5000,$A6,Données!$B$2:$B$5000,$B$3)) -> 1.5 | K6: =IF($B6="","",SUMIFS(Données!$N$2:$N$5000,Données!$A$2:$A$5000,$A6,Données!$B$2:$B$5000,$B$3)) -> 1.5 | L6: =IF($B6="","",IFERROR(K6/J6,0)) -> 1 | M6: =IF($B6="","",SUMIFS(Données!$S$2:$S$5000,Données!$A$2:$A$5000,$A6,Données!$B$2:$B$5000,$B$3)) -> 0 | N6: =IF($B6="","",IFERROR(M6/J6,0)) -> 0 | O6: =IF($B6="","",SUMIFS(Données!$X$2:$X$5000,Données!$A$2:$A$5000,$A6,Données!$B$2:$B$5000,$B$3)) -> 0
A7: =IF(B7="","",YEAR(B7+3)&"-S"&TEXT(WEEKNUM(B7,21),"00")) -> 2025-S48 | B7: =IF(B6="","",IF(B6+7>MAX(Données!$Q$2:$Q$5000),"",B6+7)) -> 45985 | C7: =IF(B7="","",B7+6) -> 45991 | D7: =IF($B7="","",COUNTIFS(Données!$A$2:$A$5000,$A7,Données!$B$2:$B$5000,$B$3,Données!$O$2:$O$5000,">0")) -> 20 | E7: =IF($B7="","",COUNTIFS(Données!$A$2:$A$5000,$A7,Données!$B$2:$B$5000,$B$3,Données!$M$2:$M$5000,"Abs")) -> 0 | F7: =IF($B7="","",IFERROR(E7/D7,0)) -> 0 | G7: =IF($B7="","",COUNTIFS(Données!$A$2:$A$5000,$A7,Données!$B$2:$B$5000,$B$3,Données!$I$2:$I$5000,">0")) -> 1 | H7: =IF($B7="","",SUMIFS(Données!$I$2:$I$5000,Données!$A$2:$A$5000,$A7,Données!$B$2:$B$5000,$B$3)) -> 0.0027777778 | I7: =IF($B7="","",SUMIFS(Données!$L$2:$L$5000,Données!$A$2:$A$5000,$A7,Données!$B$2:$B$5000,$B$3)) -> 0 | J7: =IF($B7="","",SUMIFS(Données!$O$2:$O$5000,Données!$A$2:$A$5000,$A7,Données!$B$2:$B$5000,$B$3)) -> 7.3333333 | K7: =IF($B7="","",SUMIFS(Données!$N$2:$N$5000,Données!$A$2:$A$5000,$A7,Données!$B$2:$B$5000,$B$3)) -> 7.3305556 | L7: =IF($B7="","",IFERROR(K7/J7,0)) -> 0.99962121 | M7: =IF($B7="","",SUMIFS(Données!$S$2:$S$5000,Données!$A$2:$A$5000,$A7,Données!$B$2:$B$5000,$B$3)) -> 0.0027777778 | N7: =IF($B7="","",IFERROR(M7/J7,0)) -> 0.00037878788 | O7: =IF($B7="","",SUMIFS(Données!$X$2:$X$5000,Données!$A$2:$A$5000,$A7,Données!$B$2:$B$5000,$B$3)) -> 0.0069444444
A8: =IF(B8="","",YEAR(B8+3)&"-S"&TEXT(WEEKNUM(B8,21),"00")) -> 2025-S49 | B8: =IF(B7="","",IF(B7+7>MAX(Données!$Q$2:$Q$5000),"",B7+7)) -> 45992 | C8: =IF(B8="","",B8+6) -> 45998 | D8: =IF($B8="","",COUNTIFS(Données!$A$2:$A$5000,$A8,Données!$B$2:$B$5000,$B$3,Données!$O$2:$O$5000,">0")) -> 20 | E8: =IF($B8="","",COUNTIFS(Données!$A$2:$A$5000,$A8,Données!$B$2:$B$5000,$B$3,Données!$M$2:$M$5000,"Abs")) -> 0 | F8: =IF($B8="","",IFERROR(E8/D8,0)) -> 0 | G8: =IF($B8="","",COUNTIFS(Données!$A$2:$A$5000,$A8,Données!$B$2:$B$5000,$B$3,Données!$I$2:$I$5000,">0")) -> 1 | H8: =IF($B8="","",SUMIFS(Données!$I$2:$I$5000,Données!$A$2:$A$5000,$A8,Données!$B$2:$B$5000,$B$3)) -> 0.0034722222 | I8: =IF($B8="","",SUMIFS(Données!$L$2:$L$5000,Données!$A$2:$A$5000,$A8,Données!$B$2:$B$5000,$B$3)) -> 0 | J8: =IF($B8="","",SUMIFS(Données!$O$2:$O$5000,Données!$A$2:$A$5000,$A8,Données!$B$2:$B$5000,$B$3)) -> 7.3333333 | K8: =IF($B8="","",SUMIFS(Données!$N$2:$N$5000,Données!$A$2:$A$5000,$A8,Données!$B$2:$B$5000,$B$3)) -> 7.3298611 | L8: =IF($B8="","",IFERROR(K8/J8,0)) -> 0.99952652 | M8: =IF($B8="","",SUMIFS(Données!$S$2:$S$5000,Données!$A$2:$A$5000,$A8,Données!$B$2:$B$5000,$B$3)) -> 0.0034722222 | N8: =IF($B8="","",IFERROR(M8/J8,0)) -> 0.00047348485 | O8: =IF($B8="","",SUMIFS(Données!$X$2:$X$5000,Données!$A$2:$A$5000,$A8,Données!$B$2:$B$5000,$B$3)) -> 0.0041666667
A9: =IF(B9="","",YEAR(B9+3)&"-S"&TEXT(WEEKNUM(B9,21),"00")) -> 2025-S50 | B9: =IF(B8="","",IF(B8+7>MAX(Données!$Q$2:$Q$5000),"",B8+7)) -> 45999 | C9: =IF(B9="","",B9+6) -> 46005 | D9: =IF($B9="","",COUNTIFS(Données!$A$2:$A$5000,$A9,Données!$B$2:$B$5000,$B$3,Données!$O$2:$O$5000,">0")) -> 20 | E9: =IF($B9="","",COUNTIFS(Données!$A$2:$A$5000,$A9,Données!$B$2:$B$5000,$B$3,Données!$M$2:$M$5000,"Abs")) -> 0 | F9: =IF($B9="","",IFERROR(E9/D9,0)) -> 0 | G9: =IF($B9="","",COUNTIFS(Données!$A$2:$A$5000,$A9,Données!$B$2:$B$5000,$B$3,Données!$I$2:$I$5000,">0")) -> 0 | H9: =IF($B9="","",SUMIFS(Données!$I$2:$I$5000,Données!$A$2:$A$5000,$A9,Données!$B$2:$B$5000,$B$3)) -> 0 | I9: =IF($B9="","",SUMIFS(Données!$L$2:$L$5000,Données!$A$2:$A$5000,$A9,Données!$B$2:$B$5000,$B$3)) -> 0 | J9: =IF($B9="","",SUMIFS(Données!$O$2:$O$5000,Données!$A$2:$A$5000,$A9,Données!$B$2:$B$5000,$B$3)) -> 7.3333333 | K9: =IF($B9="","",SUMIFS(Données!$N$2:$N$5000,Données!$A$2:$A$5000,$A9,Données!$B$2:$B$5000,$B$3)) -> 7.3333333 | L9: =IF($B9="","",IFERROR(K9/J9,0)) -> 1 | M9: =IF($B9="","",SUMIFS(Données!$S$2:$S$5000,Données!$A$2:$A$5000,$A9,Données!$B$2:$B$5000,$B$3)) -> 0 | N9: =IF($B9="","",IFERROR(M9/J9,0)) -> 0 | O9: =IF($B9="","",SUMIFS(Données!$X$2:$X$5000,Données!$A$2:$A$5000,$A9,Données!$B$2:$B$5000,$B$3)) -> 0.0125
A10: =IF(B10="","",YEAR(B10+3)&"-S"&TEXT(WEEKNUM(B10,21),"00")) -> 2025-S51 | B10: =IF(B9="","",IF(B9+7>MAX(Données!$Q$2:$Q$5000),"",B9+7)) -> 46006 | C10: =IF(B10="","",B10+6) -> 46012 | D10: =IF($B10="","",COUNTIFS(Données!$A$2:$A$5000,$A10,Données!$B$2:$B$5000,$B$3,Données!$O$2:$O$5000,">0")) -> 20 | E10: =IF($B10="","",COUNTIFS(Données!$A$2:$A$5000,$A10,Données!$B$2:$B$5000,$B$3,Données!$M$2:$M$5000,"Abs")) -> 0 | F10: =IF($B10="","",IFERROR(E10/D10,0)) -> 0 | G10: =IF($B10="","",COUNTIFS(Données!$A$2:$A$5000,$A10,Données!$B$2:$B$5000,$B$3,Données!$I$2:$I$5000,">0")) -> 0 | H10: =IF($B10="","",SUMIFS(Données!$I$2:$I$5000,Données!$A$2:$A$5000,$A10,Données!$B$2:$B$5000,$B$3)) -> 0 | I10: =IF($B10="","",SUMIFS(Données!$L$2:$L$5000,Données!$A$2:$A$5000,$A10,Données!$B$2:$B$5000,$B$3)) -> 0 | J10: =IF($B10="","",SUMIFS(Données!$O$2:$O$5000,Données!$A$2:$A$5000,$A10,Données!$B$2:$B$5000,$B$3)) -> 7.3333333 | K10: =IF($B10="","",SUMIFS(Données!$N$2:$N$5000,Données!$A$2:$A$5000,$A10,Données!$B$2:$B$5000,$B$3)) -> 7.3333333 | L10: =IF($B10="","",IFERROR(K10/J10,0)) -> 1 | M10: =IF($B10="","",SUMIFS(Données!$S$2:$S$5000,Données!$A$2:$A$5000,$A10,Données!$B$2:$B$5000,$B$3)) -> 0 | N10: =IF($B10="","",IFERROR(M10/J10,0)) -> 0 | O10: =IF($B10="","",SUMIFS(Données!$X$2:$X$5000,Données!$A$2:$A$5000,$A10,Données!$B$2:$B$5000,$B$3)) -> 0.0055555556
A11: =IF(B11="","",YEAR(B11+3)&"-S"&TEXT(WEEKNUM(B11,21),"00")) -> 2025-S52 | B11: =IF(B10="","",IF(B10+7>MAX(Données!$Q$2:$Q$5000),"",B10+7)) -> 46013 | C11: =IF(B11="","",B11+6) -> 46019 | D11: =IF($B11="","",COUNTIFS(Données!$A$2:$A$5000,$A11,Données!$B$2:$B$5000,$B$3,Données!$O$2:$O$5000,">0")) -> 16 | E11: =IF($B11="","",COUNTIFS(Données!$A$2:$A$5000,$A11,Données!$B$2:$B$5000,$B$3,Données!$M$2:$M$5000,"Abs")) -> 0 | F11: =IF($B11="","",IFERROR(E11/D11,0)) -> 0 | G11: =IF($B11="","",COUNTIFS(Données!$A$2:$A$5000,$A11,Données!$B$2:$B$5000,$B$3,Données!$I$2:$I$5000,">0")) -> 0 | H11: =IF($B11="","",SUMIFS(Données!$I$2:$I$5000,Données!$A$2:$A$5000,$A11,Données!$B$2:$B$5000,$B$3)) -> 0 | I11: =IF($B11="","",SUMIFS(Données!$L$2:$L$5000,Données!$A$2:$A$5000,$A11,Données!$B$2:$B$5000,$B$3)) -> 0 | J11: =IF($B11="","",SUMIFS(Données!$O$2:$O$5000,Données!$A$2:$A$5000,$A11,Données!$B$2:$B$5000,$B$3)) -> 5.8333333 | K11: =IF($B11="","",SUMIFS(Données!$N$2:$N$5000,Données!$A$2:$A$5000,$A11,Données!$B$2:$B$5000,$B$3)) -> 5.8333333 | L11: =IF($B11="","",IFERROR(K11/J11,0)) -> 1 | M11: =IF($B11="","",SUMIFS(Données!$S$2:$S$5000,Données!$A$2:$A$5000,$A11,Données!$B$2:$B$5000,$B$3)) -> 0 | N11: =IF($B11="","",IFERROR(M11/J11,0)) -> 0 | O11: =IF($B11="","",SUMIFS(Données!$X$2:$X$5000,Données!$A$2:$A$5000,$A11,Données!$B$2:$B$5000,$B$3)) -> 0.0048611111
A12: =IF(B12="","",YEAR(B12+3)&"-S"&TEXT(WEEKNUM(B12,21),"00")) -> 2026-S01 | B12: =IF(B11="","",IF(B11+7>MAX(Données!$Q$2:$Q$5000),"",B11+7)) -> 46020 | C12: =IF(B12="","",B12+6) -> 46026 | D12: =IF($B12="","",COUNTIFS(Données!$A$2:$A$5000,$A12,Données!$B$2:$B$5000,$B$3,Données!$O$2:$O$5000,">0")) -> 16 | E12: =IF($B12="","",COUNTIFS(Données!$A$2:$A$5000,$A12,Données!$B$2:$B$5000,$B$3,Données!$M$2:$M$5000,"Abs")) -> 0 | F12: =IF($B12="","",IFERROR(E12/D12,0)) -> 0 | G12: =IF($B12="","",COUNTIFS(Données!$A$2:$A$5000,$A12,Données!$B$2:$B$5000,$B$3,Données!$I$2:$I$5000,">0")) -> 0 | H12: =IF($B12="","",SUMIFS(Données!$I$2:$I$5000,Données!$A$2:$A$5000,$A12,Données!$B$2:$B$5000,$B$3)) -> 0 | I12: =IF($B12="","",SUMIFS(Données!$L$2:$L$5000,Données!$A$2:$A$5000,$A12,Données!$B$2:$B$5000,$B$3)) -> 0 | J12: =IF($B12="","",SUMIFS(Données!$O$2:$O$5000,Données!$A$2:$A$5000,$A12,Données!$B$2:$B$5000,$B$3)) -> 5.8333333 | K12: =IF($B12="","",SUMIFS(Données!$N$2:$N$5000,Données!$A$2:$A$5000,$A12,Données!$B$2:$B$5000,$B$3)) -> 5.8333333 | L12: =IF($B12="","",IFERROR(K12/J12,0)) -> 1 | M12: =IF($B12="","",SUMIFS(Données!$S$2:$S$5000,Données!$A$2:$A$5000,$A12,Données!$B$2:$B$5000,$B$3)) -> 0 | N12: =IF($B12="","",IFERROR(M12/J12,0)) -> 0 | O12: =IF($B12="","",SUMIFS(Données!$X$2:$X$5000,Données!$A$2:$A$5000,$A12,Données!$B$2:$B$5000,$B$3)) -> 0.0048611111
A13: =IF(B13="","",YEAR(B13+3)&"-S"&TEXT(WEEKNUM(B13,21),"00")) -> 2026-S02 | B13: =IF(B12="","",IF(B12+7>MAX(Données!$Q$2:$Q$5000),"",B12+7)) -> 46027 | C13: =IF(B13="","",B13+6) -> 46033 | D13: =IF($B13="","",COUNTIFS(Données!$A$2:$A$5000,$A13,Données!$B$2:$B$5000,$B$3,Données!$O$2:$O$5000,">0")) -> 19 | E13: =IF($B13="","",COUNTIFS(Données!$A$2:$A$5000,$A13,Données!$B$2:$B$5000,$B$3,Données!$M$2:$M$5000,"Abs")) -> 0 | F13: =IF($B13="","",IFERROR(E13/D13,0)) -> 0 | G13: =IF($B13="","",COUNTIFS(Données!$A$2:$A$5000,$A13,Données!$B$2:$B$5000,$B$3,Données!$I$2:$I$5000,">0")) -> 1 | H13: =IF($B13="","",SUMIFS(Données!$I$2:$I$5000,Données!$A$2:$A$5000,$A13,Données!$B$2:$B$5000,$B$3)) -> 0.0034722222 | I13: =IF($B13="","",SUMIFS(Données!$L$2:$L$5000,Données!$A$2:$A$5000,$A13,Données!$B$2:$B$5000,$B$3)) -> 0 | J13: =IF($B13="","",SUMIFS(Données!$O$2:$O$5000,Données!$A$2:$A$5000,$A13,Données!$B$2:$B$5000,$B$3)) -> 7 | K13: =IF($B13="","",SUMIFS(Données!$N$2:$N$5000,Données!$A$2:$A$5000,$A13,Données!$B$2:$B$5000,$B$3)) -> 6.9965278 | L13: =IF($B13="","",IFERROR(K13/J13,0)) -> 0.99950397 | M13: =IF($B13="","",SUMIFS(Données!$S$2:$S$5000,Données!$A$2:$A$5000,$A13,Données!$B$2:$B$5000,$B$3)) -> 0.0034722222 | N13: =IF($B13="","",IFERROR(M13/J13,0)) -> 0.00049603175 | O13: =IF($B13="","",SUMIFS(Données!$X$2:$X$5000,Données!$A$2:$A$5000,$A13,Données!$B$2:$B$5000,$B$3)) -> 0.010416667
A14: =IF(B14="","",YEAR(B14+3)&"-S"&TEXT(WEEKNUM(B14,21),"00")) -> 2026-S03 | B14: =IF(B13="","",IF(B13+7>MAX(Données!$Q$2:$Q$5000),"",B13+7)) -> 46034 | C14: =IF(B14="","",B14+6) -> 46040 | D14: =IF($B14="","",COUNTIFS(Données!$A$2:$A$5000,$A14,Données!$B$2:$B$5000,$B$3,Données!$O$2:$O$5000,">0")) -> 20 | E14: =IF($B14="","",COUNTIFS(Données!$A$2:$A$5000,$A14,Données!$B$2:$B$5000,$B$3,Données!$M$2:$M$5000,"Abs")) -> 0 | F14: =IF($B14="","",IFERROR(E14/D14,0)) -> 0 | G14: =IF($B14="","",COUNTIFS(Données!$A$2:$A$5000,$A14,Données!$B$2:$B$5000,$B$3,Données!$I$2:$I$5000,">0")) -> 1 | H14: =IF($B14="","",SUMIFS(Données!$I$2:$I$5000,Données!$A$2:$A$5000,$A14,Données!$B$2:$B$5000,$B$3)) -> 0.057638889 | I14: =IF($B14="","",SUMIFS(Données!$L$2:$L$5000,Données!$A$2:$A$5000,$A14,Données!$B$2:$B$5000,$B$3)) -> 0 | J14: =IF($B14="","",SUMIFS(Données!$O$2:$O$5000,Données!$A$2:$A$5000,$A14,Données!$B$2:$B$5000,$B$3)) -> 7.3333333 | K14: =IF($B14="","",SUMIFS(Données!$N$2:$N$5000,Données!$A$2:$A$5000,$A14,Données!$B$2:$B$5000,$B$3)) -> 7.2756944 | L14: =IF($B14="","",IFERROR(K14/J14,0)) -> 0.99214015 | M14: =IF($B14="","",SUMIFS(Données!$S$2:$S$5000,Données!$A$2:$A$5000,$A14,Données!$B$2:$B$5000,$B$3)) -> 0.057638889 | N14: =IF($B14="","",IFERROR(M14/J14,0)) -> 0.0078598485 | O14: =IF($B14="","",SUMIFS(Données!$X$2:$X$5000,Données!$A$2:$A$5000,$A14,Données!$B$2:$B$5000,$B$3)) -> 0.015972222
A15: =IF(B15="","",YEAR(B15+3)&"-S"&TEXT(WEEKNUM(B15,21),"00")) -> 2026-S04 | B15: =IF(B14="","",IF(B14+7>MAX(Données!$Q$2:$Q$5000),"",B14+7)) -> 46041 | C15: =IF(B15="","",B15+6) -> 46047 | D15: =IF($B15="","",COUNTIFS(Données!$A$2:$A$5000,$A15,Données!$B$2:$B$5000,$B$3,Données!$O$2:$O$5000,">0")) -> 20 | E15: =IF($B15="","",COUNTIFS(Données!$A$2:$A$5000,$A15,Données!$B$2:$B$5000,$B$3,Données!$M$2:$M$5000,"Abs")) -> 1 | F15: =IF($B15="","",IFERROR(E15/D15,0)) -> 0.05 | G15: =IF($B15="","",COUNTIFS(Données!$A$2:$A$5000,$A15,Données!$B$2:$B$5000,$B$3,Données!$I$2:$I$5000,">0")) -> 1 | H15: =IF($B15="","",SUMIFS(Données!$I$2:$I$5000,Données!$A$2:$A$5000,$A15,Données!$B$2:$B$5000,$B$3)) -> 0.0083333333 | I15: =IF($B15="","",SUMIFS(Données!$L$2:$L$5000,Données!$A$2:$A$5000,$A15,Données!$B$2:$B$5000,$B$3)) -> 0 | J15: =IF($B15="","",SUMIFS(Données!$O$2:$O$5000,Données!$A$2:$A$5000,$A15,Données!$B$2:$B$5000,$B$3)) -> 7.3333333 | K15: =IF($B15="","",SUMIFS(Données!$N$2:$N$5000,Données!$A$2:$A$5000,$A15,Données!$B$2:$B$5000,$B$3)) -> 6.95 | L15: =IF($B15="","",IFERROR(K15/J15,0)) -> 0.94772727 | M15: =IF($B15="","",SUMIFS(Données!$S$2:$S$5000,Données!$A$2:$A$5000,$A15,Données!$B$2:$B$5000,$B$3)) -> 0.38333333 | N15: =IF($B15="","",IFERROR(M15/J15,0)) -> 0.052272727 | O15: =IF($B15="","",SUMIFS(Données!$X$2:$X$5000,Données!$A$2:$A$5000,$A15,Données!$B$2:$B$5000,$B$3)) -> 0.015277778
A16: =IF(B16="","",YEAR(B16+3)&"-S"&TEXT(WEEKNUM(B16,21),"00")) -> 2026-S05 | B16: =IF(B15="","",IF(B15+7>MAX(Données!$Q$2:$Q$5000),"",B15+7)) -> 46048 | C16: =IF(B16="","",B16+6) -> 46054 | D16: =IF($B16="","",COUNTIFS(Données!$A$2:$A$5000,$A16,Données!$B$2:$B$5000,$B$3,Données!$O$2:$O$5000,">0")) -> 19 | E16: =IF($B16="","",COUNTIFS(Données!$A$2:$A$5000,$A16,Données!$B$2:$B$5000,$B$3,Données!$M$2:$M$5000,"Abs")) -> 0 | F16: =IF($B16="","",IFERROR(E16/D16,0)) -> 0 | G16: =IF($B16="","",COUNTIFS(Données!$A$2:$A$5000,$A16,Données!$B$2:$B$5000,$B$3,Données!$I$2:$I$5000,">0")) -> 0 | H16: =IF($B16="","",SUMIFS(Données!$I$2:$I$5000,Données!$A$2:$A$5000,$A16,Données!$B$2:$B$5000,$B$3)) -> 0 | I16: =IF($B16="","",SUMIFS(Données!$L$2:$L$5000,Données!$A$2:$A$5000,$A16,Données!$B$2:$B$5000,$B$3)) -> 0 | J16: =IF($B16="","",SUMIFS(Données!$O$2:$O$5000,Données!$A$2:$A$5000,$A16,Données!$B$2:$B$5000,$B$3)) -> 6.9583333 | K16: =IF($B16="","",SUMIFS(Données!$N$2:$N$5000,Données!$A$2:$A$5000,$A16,Données!$B$2:$B$5000,$B$3)) -> 6.9583333 | L16: =IF($B16="","",IFERROR(K16/J16,0)) -> 1 | M16: =IF($B16="","",SUMIFS(Données!$S$2:$S$5000,Données!$A$2:$A$5000,$A16,Données!$B$2:$B$5000,$B$3)) -> 0 | N16: =IF($B16="","",IFERROR(M16/J16,0)) -> 0 | O16: =IF($B16="","",SUMIFS(Données!$X$2:$X$5000,Données!$A$2:$A$5000,$A16,Données!$B$2:$B$5000,$B$3)) -> 0.0076388889
A17: =IF(B17="","",YEAR(B17+3)&"-S"&TEXT(WEEKNUM(B17,21),"00")) -> 2026-S06 | B17: =IF(B16="","",IF(B16+7>MAX(Données!$Q$2:$Q$5000),"",B16+7)) -> 46055 | C17: =IF(B17="","",B17+6) -> 46061 | D17: =IF($B17="","",COUNTIFS(Données!$A$2:$A$5000,$A17,Données!$B$2:$B$5000,$B$3,Données!$O$2:$O$5000,">0")) -> 20 | E17: =IF($B17="","",COUNTIFS(Données!$A$2:$A$5000,$A17,Données!$B$2:$B$5000,$B$3,Données!$M$2:$M$5000,"Abs")) -> 0 | F17: =IF($B17="","",IFERROR(E17/D17,0)) -> 0 | G17: =IF($B17="","",COUNTIFS(Données!$A$2:$A$5000,$A17,Données!$B$2:$B$5000,$B$3,Données!$I$2:$I$5000,">0")) -> 3 | H17: =IF($B17="","",SUMIFS(Données!$I$2:$I$5000,Données!$A$2:$A$5000,$A17,Données!$B$2:$B$5000,$B$3)) -> 0.039583333 | I17: =IF($B17="","",SUMIFS(Données!$L$2:$L$5000,Données!$A$2:$A$5000,$A17,Données!$B$2:$B$5000,$B$3)) -> 0 | J17: =IF($B17="","",SUMIFS(Données!$O$2:$O$5000,Données!$A$2:$A$5000,$A17,Données!$B$2:$B$5000,$B$3)) -> 7.3333333 | K17: =IF($B17="","",SUMIFS(Données!$N$2:$N$5000,Données!$A$2:$A$5000,$A17,Données!$B$2:$B$5000,$B$3)) -> 7.29375 | L17: =IF($B17="","",IFERROR(K17/J17,0)) -> 0.99460227 | M17: =IF($B17="","",SUMIFS(Données!$S$2:$S$5000,Données!$A$2:$A$5000,$A17,Données!$B$2:$B$5000,$B$3)) -> 0.039583333 | N17: =IF($B17="","",IFERROR(M17/J17,0)) -> 0.0053977273 | O17: =IF($B17="","",SUMIFS(Données!$X$2:$X$5000,Données!$A$2:$A$5000,$A17,Données!$B$2:$B$5000,$B$3)) -> 0.010416667
A18: =IF(B18="","",YEAR(B18+3)&"-S"&TEXT(WEEKNUM(B18,21),"00")) -> 2026-S07 | B18: =IF(B17="","",IF(B17+7>MAX(Données!$Q$2:$Q$5000),"",B17+7)) -> 46062 | C18: =IF(B18="","",B18+6) -> 46068 | D18: =IF($B18="","",COUNTIFS(Données!$A$2:$A$5000,$A18,Données!$B$2:$B$5000,$B$3,Données!$O$2:$O$5000,">0")) -> 20 | E18: =IF($B18="","",COUNTIFS(Données!$A$2:$A$5000,$A18,Données!$B$2:$B$5000,$B$3,Données!$M$2:$M$5000,"Abs")) -> 0 | F18: =IF($B18="","",IFERROR(E18/D18,0)) -> 0 | G18: =IF($B18="","",COUNTIFS(Données!$A$2:$A$5000,$A18,Données!$B$2:$B$5000,$B$3,Données!$I$2:$I$5000,">0")) -> 0 | H18: =IF($B18="","",SUMIFS(Données!$I$2:$I$5000,Données!$A$2:$A$5000,$A18,Données!$B$2:$B$5000,$B$3)) -> 0 | I18: =IF($B18="","",SUMIFS(Données!$L$2:$L$5000,Données!$A$2:$A$5000,$A18,Données!$B$2:$B$5000,$B$3)) -> 0 | J18: =IF($B18="","",SUMIFS(Données!$O$2:$O$5000,Données!$A$2:$A$5000,$A18,Données!$B$2:$B$5000,$B$3)) -> 7.3333333 | K18: =IF($B18="","",SUMIFS(Données!$N$2:$N$5000,Données!$A$2:$A$5000,$A18,Données!$B$2:$B$5000,$B$3)) -> 7.3333333 | L18: =IF($B18="","",IFERROR(K18/J18,0)) -> 1 | M18: =IF($B18="","",SUMIFS(Données!$S$2:$S$5000,Données!$A$2:$A$5000,$A18,Données!$B$2:$B$5000,$B$3)) -> 0 | N18: =IF($B18="","",IFERROR(M18/J18,0)) -> 0 | O18: =IF($B18="","",SUMIFS(Données!$X$2:$X$5000,Données!$A$2:$A$5000,$A18,Données!$B$2:$B$5000,$B$3)) -> 0.00625
... A65: =IF(B65="","",YEAR(B65+3)&"-S"&TEXT(WEEKNUM(B65,21),"00")) | B65: =IF(B64="","",IF(B64+7>MAX(Données!$Q$2:$Q$5000),"",B64+7)) | C65: =IF(B65="","",B65+6) | D65: =IF($B65="","",COUNTIFS(Données!$A$2:$A$5000,$A65,Données!$B$2:$B$5000,$B$3,Données!$O$2:$O$5000,">0")) | E65: =IF($B65="","",COUNTIFS(Données!$A$2:$A$5000,$A65,Données!$B$2:$B$5000,$B$3,Données!$M$2:$M$5000,"Abs")) | F65: =IF($B65="","",IFERROR(E65/D65,0)) | G65: =IF($B65="","",COUNTIFS(Données!$A$2:$A$5000,$A65,Données!$B$2:$B$5000,$B$3,Données!$I$2:$I$5000,">0")) | H65: =IF($B65="","",SUMIFS(Données!$I$2:$I$5000,Données!$A$2:$A$5000,$A65,Données!$B$2:$B$5000,$B$3)) | I65: =IF($B65="","",SUMIFS(Données!$L$2:$L$5000,Données!$A$2:$A$5000,$A65,Données!$B$2:$B$5000,$B$3)) | J65: =IF($B65="","",SUMIFS(Données!$O$2:$O$5000,Données!$A$2:$A$5000,$A65,Données!$B$2:$B$5000,$B$3)) | K65: =IF($B65="","",SUMIFS(Données!$N$2:$N$5000,Données!$A$2:$A$5000,$A65,Données!$B$2:$B$5000,$B$3)) | L65: =IF($B65="","",IFERROR(K65/J65,0)) | M65: =IF($B65="","",SUMIFS(Données!$S$2:$S$5000,Données!$A$2:$A$5000,$A65,Données!$B$2:$B$5000,$B$3)) | N65: =IF($B65="","",IFERROR(M65/J65,0)) | O65: =IF($B65="","",SUMIFS(Données!$X$2:$X$5000,Données!$A$2:$A$5000,$A65,Données!$B$2:$B$5000,$B$3))

Sheet Par mois
A1: Assiduité par mois
A2: Agent | B2: Tous | C2: ← Choisir « Tous » ou un agent dans la liste.
A3: Critère | B3: =IF($B$2="Tous","*",$B$2) -> *
A5: Mois | B5: Début | C5: Fin | D5: Jours planifiés | E5: Jours d'absence | F5: Taux d'absentéisme (jours) | G5: Nb retards | H5: Total retards | I5: Total départs anticipés | J5: Hr planifiées | K5: Hr adhérées | L5: Taux d'adhérence | M5: Hr absence totales | N5: Taux d'absentéisme (heures) | O5: Heures sup
A6: =IF(B6="","",CHOOSE(MONTH(B6),"Janvier","Février","Mars","Avril","Mai","Juin","Juillet","Août","Septembre","Octobre","Novembre","Décembre")&" "&YEAR(B6)) -> Novembre 2025 | B6: =DATE(YEAR(MIN(Données!$Q$2:$Q$5000)),MONTH(MIN(Données!$Q$2:$Q$5000)),1) -> 45962 | C6: =IF(B6="","",EDATE(B6,1)-1) -> 45991 | D6: =IF($B6="","",COUNTIFS(Données!$Q$2:$Q$5000,">="&$B6,Données!$Q$2:$Q$5000,"<="&$C6,Données!$B$2:$B$5000,$B$3,Données!$O$2:$O$5000,">0")) -> 24 | E6: =IF($B6="","",COUNTIFS(Données!$Q$2:$Q$5000,">="&$B6,Données!$Q$2:$Q$5000,"<="&$C6,Données!$B$2:$B$5000,$B$3,Données!$M$2:$M$5000,"Abs")) -> 0 | F6: =IF($B6="","",IFERROR(E6/D6,0)) -> 0 | G6: =IF($B6="","",COUNTIFS(Données!$Q$2:$Q$5000,">="&$B6,Données!$Q$2:$Q$5000,"<="&$C6,Données!$B$2:$B$5000,$B$3,Données!$I$2:$I$5000,">0")) -> 1 | H6: =IF($B6="","",SUMIFS(Données!$I$2:$I$5000,Données!$Q$2:$Q$5000,">="&$B6,Données!$Q$2:$Q$5000,"<="&$C6,Données!$B$2:$B$5000,$B$3)) -> 0.0027777778 | I6: =IF($B6="","",SUMIFS(Données!$L$2:$L$5000,Données!$Q$2:$Q$5000,">="&$B6,Données!$Q$2:$Q$5000,"<="&$C6,Données!$B$2:$B$5000,$B$3)) -> 0 | J6: =IF($B6="","",SUMIFS(Données!$O$2:$O$5000,Données!$Q$2:$Q$5000,">="&$B6,Données!$Q$2:$Q$5000,"<="&$C6,Données!$B$2:$B$5000,$B$3)) -> 8.8333333 | K6: =IF($B6="","",SUMIFS(Données!$N$2:$N$5000,Données!$Q$2:$Q$5000,">="&$B6,Données!$Q$2:$Q$5000,"<="&$C6,Données!$B$2:$B$5000,$B$3)) -> 8.8305556 | L6: =IF($B6="","",IFERROR(K6/J6,0)) -> 0.99968553 | M6: =IF($B6="","",SUMIFS(Données!$S$2:$S$5000,Données!$Q$2:$Q$5000,">="&$B6,Données!$Q$2:$Q$5000,"<="&$C6,Données!$B$2:$B$5000,$B$3)) -> 0.0027777778 | N6: =IF($B6="","",IFERROR(M6/J6,0)) -> 0.00031446541 | O6: =IF($B6="","",SUMIFS(Données!$X$2:$X$5000,Données!$Q$2:$Q$5000,">="&$B6,Données!$Q$2:$Q$5000,"<="&$C6,Données!$B$2:$B$5000,$B$3)) -> 0.0069444444
A7: =IF(B7="","",CHOOSE(MONTH(B7),"Janvier","Février","Mars","Avril","Mai","Juin","Juillet","Août","Septembre","Octobre","Novembre","Décembre")&" "&YEAR(B7)) -> Décembre 2025 | B7: =IF(B6="","",IF(EDATE(B6,1)>MAX(Données!$Q$2:$Q$5000),"",EDATE(B6,1))) -> 45992 | C7: =IF(B7="","",EDATE(B7,1)-1) -> 46022 | D7: =IF($B7="","",COUNTIFS(Données!$Q$2:$Q$5000,">="&$B7,Données!$Q$2:$Q$5000,"<="&$C7,Données!$B$2:$B$5000,$B$3,Données!$O$2:$O$5000,">0")) -> 88 | E7: =IF($B7="","",COUNTIFS(Données!$Q$2:$Q$5000,">="&$B7,Données!$Q$2:$Q$5000,"<="&$C7,Données!$B$2:$B$5000,$B$3,Données!$M$2:$M$5000,"Abs")) -> 0 | F7: =IF($B7="","",IFERROR(E7/D7,0)) -> 0 | G7: =IF($B7="","",COUNTIFS(Données!$Q$2:$Q$5000,">="&$B7,Données!$Q$2:$Q$5000,"<="&$C7,Données!$B$2:$B$5000,$B$3,Données!$I$2:$I$5000,">0")) -> 1 | H7: =IF($B7="","",SUMIFS(Données!$I$2:$I$5000,Données!$Q$2:$Q$5000,">="&$B7,Données!$Q$2:$Q$5000,"<="&$C7,Données!$B$2:$B$5000,$B$3)) -> 0.0034722222 | I7: =IF($B7="","",SUMIFS(Données!$L$2:$L$5000,Données!$Q$2:$Q$5000,">="&$B7,Données!$Q$2:$Q$5000,"<="&$C7,Données!$B$2:$B$5000,$B$3)) -> 0 | J7: =IF($B7="","",SUMIFS(Données!$O$2:$O$5000,Données!$Q$2:$Q$5000,">="&$B7,Données!$Q$2:$Q$5000,"<="&$C7,Données!$B$2:$B$5000,$B$3)) -> 32.333333 | K7: =IF($B7="","",SUMIFS(Données!$N$2:$N$5000,Données!$Q$2:$Q$5000,">="&$B7,Données!$Q$2:$Q$5000,"<="&$C7,Données!$B$2:$B$5000,$B$3)) -> 32.329861 | L7: =IF($B7="","",IFERROR(K7/J7,0)) -> 0.99989261 | M7: =IF($B7="","",SUMIFS(Données!$S$2:$S$5000,Données!$Q$2:$Q$5000,">="&$B7,Données!$Q$2:$Q$5000,"<="&$C7,Données!$B$2:$B$5000,$B$3)) -> 0.0034722222 | N7: =IF($B7="","",IFERROR(M7/J7,0)) -> 0.00010738832 | O7: =IF($B7="","",SUMIFS(Données!$X$2:$X$5000,Données!$Q$2:$Q$5000,">="&$B7,Données!$Q$2:$Q$5000,"<="&$C7,Données!$B$2:$B$5000,$B$3)) -> 0.031944444
A8: =IF(B8="","",CHOOSE(MONTH(B8),"Janvier","Février","Mars","Avril","Mai","Juin","Juillet","Août","Septembre","Octobre","Novembre","Décembre")&" "&YEAR(B8)) -> Janvier 2026 | B8: =IF(B7="","",IF(EDATE(B7,1)>MAX(Données!$Q$2:$Q$5000),"",EDATE(B7,1))) -> 46023 | C8: =IF(B8="","",EDATE(B8,1)-1) -> 46053 | D8: =IF($B8="","",COUNTIFS(Données!$Q$2:$Q$5000,">="&$B8,Données!$Q$2:$Q$5000,"<="&$C8,Données!$B$2:$B$5000,$B$3,Données!$O$2:$O$5000,">0")) -> 82 | E8: =IF($B8="","",COUNTIFS(Données!$Q$2:$Q$5000,">="&$B8,Données!$Q$2:$Q$5000,"<="&$C8,Données!$B$2:$B$5000,$B$3,Données!$M$2:$M$5000,"Abs")) -> 1 | F8: =IF($B8="","",IFERROR(E8/D8,0)) -> 0.012195122 | G8: =IF($B8="","",COUNTIFS(Données!$Q$2:$Q$5000,">="&$B8,Données!$Q$2:$Q$5000,"<="&$C8,Données!$B$2:$B$5000,$B$3,Données!$I$2:$I$5000,">0")) -> 3 | H8: =IF($B8="","",SUMIFS(Données!$I$2:$I$5000,Données!$Q$2:$Q$5000,">="&$B8,Données!$Q$2:$Q$5000,"<="&$C8,Données!$B$2:$B$5000,$B$3)) -> 0.069444444 | I8: =IF($B8="","",SUMIFS(Données!$L$2:$L$5000,Données!$Q$2:$Q$5000,">="&$B8,Données!$Q$2:$Q$5000,"<="&$C8,Données!$B$2:$B$5000,$B$3)) -> 0 | J8: =IF($B8="","",SUMIFS(Données!$O$2:$O$5000,Données!$Q$2:$Q$5000,">="&$B8,Données!$Q$2:$Q$5000,"<="&$C8,Données!$B$2:$B$5000,$B$3)) -> 29.958333 | K8: =IF($B8="","",SUMIFS(Données!$N$2:$N$5000,Données!$Q$2:$Q$5000,">="&$B8,Données!$Q$2:$Q$5000,"<="&$C8,Données!$B$2:$B$5000,$B$3)) -> 29.513889 | L8: =IF($B8="","",IFERROR(K8/J8,0)) -> 0.98516458 | M8: =IF($B8="","",SUMIFS(Données!$S$2:$S$5000,Données!$Q$2:$Q$5000,">="&$B8,Données!$Q$2:$Q$5000,"<="&$C8,Données!$B$2:$B$5000,$B$3)) -> 0.44444444 | N8: =IF($B8="","",IFERROR(M8/J8,0)) -> 0.01483542 | O8: =IF($B8="","",SUMIFS(Données!$X$2:$X$5000,Données!$Q$2:$Q$5000,">="&$B8,Données!$Q$2:$Q$5000,"<="&$C8,Données!$B$2:$B$5000,$B$3)) -> 0.049305556
A9: =IF(B9="","",CHOOSE(MONTH(B9),"Janvier","Février","Mars","Avril","Mai","Juin","Juillet","Août","Septembre","Octobre","Novembre","Décembre")&" "&YEAR(B9)) -> Février 2026 | B9: =IF(B8="","",IF(EDATE(B8,1)>MAX(Données!$Q$2:$Q$5000),"",EDATE(B8,1))) -> 46054 | C9: =IF(B9="","",EDATE(B9,1)-1) -> 46081 | D9: =IF($B9="","",COUNTIFS(Données!$Q$2:$Q$5000,">="&$B9,Données!$Q$2:$Q$5000,"<="&$C9,Données!$B$2:$B$5000,$B$3,Données!$O$2:$O$5000,">0")) -> 80 | E9: =IF($B9="","",COUNTIFS(Données!$Q$2:$Q$5000,">="&$B9,Données!$Q$2:$Q$5000,"<="&$C9,Données!$B$2:$B$5000,$B$3,Données!$M$2:$M$5000,"Abs")) -> 0 | F9: =IF($B9="","",IFERROR(E9/D9,0)) -> 0 | G9: =IF($B9="","",COUNTIFS(Données!$Q$2:$Q$5000,">="&$B9,Données!$Q$2:$Q$5000,"<="&$C9,Données!$B$2:$B$5000,$B$3,Données!$I$2:$I$5000,">0")) -> 3 | H9: =IF($B9="","",SUMIFS(Données!$I$2:$I$5000,Données!$Q$2:$Q$5000,">="&$B9,Données!$Q$2:$Q$5000,"<="&$C9,Données!$B$2:$B$5000,$B$3)) -> 0.039583333 | I9: =IF($B9="","",SUMIFS(Données!$L$2:$L$5000,Données!$Q$2:$Q$5000,">="&$B9,Données!$Q$2:$Q$5000,"<="&$C9,Données!$B$2:$B$5000,$B$3)) -> 0 | J9: =IF($B9="","",SUMIFS(Données!$O$2:$O$5000,Données!$Q$2:$Q$5000,">="&$B9,Données!$Q$2:$Q$5000,"<="&$C9,Données!$B$2:$B$5000,$B$3)) -> 28.833333 | K9: =IF($B9="","",SUMIFS(Données!$N$2:$N$5000,Données!$Q$2:$Q$5000,">="&$B9,Données!$Q$2:$Q$5000,"<="&$C9,Données!$B$2:$B$5000,$B$3)) -> 28.79375 | L9: =IF($B9="","",IFERROR(K9/J9,0)) -> 0.99862717 | M9: =IF($B9="","",SUMIFS(Données!$S$2:$S$5000,Données!$Q$2:$Q$5000,">="&$B9,Données!$Q$2:$Q$5000,"<="&$C9,Données!$B$2:$B$5000,$B$3)) -> 0.039583333 | N9: =IF($B9="","",IFERROR(M9/J9,0)) -> 0.0013728324 | O9: =IF($B9="","",SUMIFS(Données!$X$2:$X$5000,Données!$Q$2:$Q$5000,">="&$B9,Données!$Q$2:$Q$5000,"<="&$C9,Données!$B$2:$B$5000,$B$3)) -> 0.025
A10: =IF(B10="","",CHOOSE(MONTH(B10),"Janvier","Février","Mars","Avril","Mai","Juin","Juillet","Août","Septembre","Octobre","Novembre","Décembre")&" "&YEAR(B10)) -> Mars 2026 | B10: =IF(B9="","",IF(EDATE(B9,1)>MAX(Données!$Q$2:$Q$5000),"",EDATE(B9,1))) -> 46082 | C10: =IF(B10="","",EDATE(B10,1)-1) -> 46112 | D10: =IF($B10="","",COUNTIFS(Données!$Q$2:$Q$5000,">="&$B10,Données!$Q$2:$Q$5000,"<="&$C10,Données!$B$2:$B$5000,$B$3,Données!$O$2:$O$5000,">0")) -> 86 | E10: =IF($B10="","",COUNTIFS(Données!$Q$2:$Q$5000,">="&$B10,Données!$Q$2:$Q$5000,"<="&$C10,Données!$B$2:$B$5000,$B$3,Données!$M$2:$M$5000,"Abs")) -> 0 | F10: =IF($B10="","",IFERROR(E10/D10,0)) -> 0 | G10: =IF($B10="","",COUNTIFS(Données!$Q$2:$Q$5000,">="&$B10,Données!$Q$2:$Q$5000,"<="&$C10,Données!$B$2:$B$5000,$B$3,Données!$I$2:$I$5000,">0")) -> 0 | H10: =IF($B10="","",SUMIFS(Données!$I$2:$I$5000,Données!$Q$2:$Q$5000,">="&$B10,Données!$Q$2:$Q$5000,"<="&$C10,Données!$B$2:$B$5000,$B$3)) -> 0 | I10: =IF($B10="","",SUMIFS(Données!$L$2:$L$5000,Données!$Q$2:$Q$5000,">="&$B10,Données!$Q$2:$Q$5000,"<="&$C10,Données!$B$2:$B$5000,$B$3)) -> 0 | J10: =IF($B10="","",SUMIFS(Données!$O$2:$O$5000,Données!$Q$2:$Q$5000,">="&$B10,Données!$Q$2:$Q$5000,"<="&$C10,Données!$B$2:$B$5000,$B$3)) -> 31.666667 | K10: =IF($B10="","",SUMIFS(Données!$N$2:$N$5000,Données!$Q$2:$Q$5000,">="&$B10,Données!$Q$2:$Q$5000,"<="&$C10,Données!$B$2:$B$5000,$B$3)) -> 31.666667 | L10: =IF($B10="","",IFERROR(K10/J10,0)) -> 1 | M10: =IF($B10="","",SUMIFS(Données!$S$2:$S$5000,Données!$Q$2:$Q$5000,">="&$B10,Données!$Q$2:$Q$5000,"<="&$C10,Données!$B$2:$B$5000,$B$3)) -> 0 | N10: =IF($B10="","",IFERROR(M10/J10,0)) -> 0 | O10: =IF($B10="","",SUMIFS(Données!$X$2:$X$5000,Données!$Q$2:$Q$5000,">="&$B10,Données!$Q$2:$Q$5000,"<="&$C10,Données!$B$2:$B$5000,$B$3)) -> 0.031944444
A11: =IF(B11="","",CHOOSE(MONTH(B11),"Janvier","Février","Mars","Avril","Mai","Juin","Juillet","Août","Septembre","Octobre","Novembre","Décembre")&" "&YEAR(B11)) -> Avril 2026 | B11: =IF(B10="","",IF(EDATE(B10,1)>MAX(Données!$Q$2:$Q$5000),"",EDATE(B10,1))) -> 46113 | C11: =IF(B11="","",EDATE(B11,1)-1) -> 46142 | D11: =IF($B11="","",COUNTIFS(Données!$Q$2:$Q$5000,">="&$B11,Données!$Q$2:$Q$5000,"<="&$C11,Données!$B$2:$B$5000,$B$3,Données!$O$2:$O$5000,">0")) -> 74 | E11: =IF($B11="","",COUNTIFS(Données!$Q$2:$Q$5000,">="&$B11,Données!$Q$2:$Q$5000,"<="&$C11,Données!$B$2:$B$5000,$B$3,Données!$M$2:$M$5000,"Abs")) -> 5 | F11: =IF($B11="","",IFERROR(E11/D11,0)) -> 0.067567568 | G11: =IF($B11="","",COUNTIFS(Données!$Q$2:$Q$5000,">="&$B11,Données!$Q$2:$Q$5000,"<="&$C11,Données!$B$2:$B$5000,$B$3,Données!$I$2:$I$5000,">0")) -> 0 | H11: =IF($B11="","",SUMIFS(Données!$I$2:$I$5000,Données!$Q$2:$Q$5000,">="&$B11,Données!$Q$2:$Q$5000,"<="&$C11,Données!$B$2:$B$5000,$B$3)) -> 0 | I11: =IF($B11="","",SUMIFS(Données!$L$2:$L$5000,Données!$Q$2:$Q$5000,">="&$B11,Données!$Q$2:$Q$5000,"<="&$C11,Données!$B$2:$B$5000,$B$3)) -> 0 | J11: =IF($B11="","",SUMIFS(Données!$O$2:$O$5000,Données!$Q$2:$Q$5000,">="&$B11,Données!$Q$2:$Q$5000,"<="&$C11,Données!$B$2:$B$5000,$B$3)) -> 27.125 | K11: =IF($B11="","",SUMIFS(Données!$N$2:$N$5000,Données!$Q$2:$Q$5000,">="&$B11,Données!$Q$2:$Q$5000,"<="&$C11,Données!$B$2:$B$5000,$B$3)) -> 25.291667 | L11: =IF($B11="","",IFERROR(K11/J11,0)) -> 0.93241167 | M11: =IF($B11="","",SUMIFS(Données!$S$2:$S$5000,Données!$Q$2:$Q$5000,">="&$B11,Données!$Q$2:$Q$5000,"<="&$C11,Données!$B$2:$B$5000,$B$3)) -> 1.8333333 | N11: =IF($B11="","",IFERROR(M11/J11,0)) -> 0.067588326 | O11: =IF($B11="","",SUMIFS(Données!$X$2:$X$5000,Données!$Q$2:$Q$5000,">="&$B11,Données!$Q$2:$Q$5000,"<="&$C11,Données!$B$2:$B$5000,$B$3)) -> 0.040277778
A12: =IF(B12="","",CHOOSE(MONTH(B12),"Janvier","Février","Mars","Avril","Mai","Juin","Juillet","Août","Septembre","Octobre","Novembre","Décembre")&" "&YEAR(B12)) -> Mai 2026 | B12: =IF(B11="","",IF(EDATE(B11,1)>MAX(Données!$Q$2:$Q$5000),"",EDATE(B11,1))) -> 46143 | C12: =IF(B12="","",EDATE(B12,1)-1) -> 46173 | D12: =IF($B12="","",COUNTIFS(Données!$Q$2:$Q$5000,">="&$B12,Données!$Q$2:$Q$5000,"<="&$C12,Données!$B$2:$B$5000,$B$3,Données!$O$2:$O$5000,">0")) -> 45 | E12: =IF($B12="","",COUNTIFS(Données!$Q$2:$Q$5000,">="&$B12,Données!$Q$2:$Q$5000,"<="&$C12,Données!$B$2:$B$5000,$B$3,Données!$M$2:$M$5000,"Abs")) -> 1 | F12: =IF($B12="","",IFERROR(E12/D12,0)) -> 0.022222222 | G12: =IF($B12="","",COUNTIFS(Données!$Q$2:$Q$5000,">="&$B12,Données!$Q$2:$Q$5000,"<="&$C12,Données!$B$2:$B$5000,$B$3,Données!$I$2:$I$5000,">0")) -> 2 | H12: =IF($B12="","",SUMIFS(Données!$I$2:$I$5000,Données!$Q$2:$Q$5000,">="&$B12,Données!$Q$2:$Q$5000,"<="&$C12,Données!$B$2:$B$5000,$B$3)) -> 0.0069444444 | I12: =IF($B12="","",SUMIFS(Données!$L$2:$L$5000,Données!$Q$2:$Q$5000,">="&$B12,Données!$Q$2:$Q$5000,"<="&$C12,Données!$B$2:$B$5000,$B$3)) -> 0 | J12: =IF($B12="","",SUMIFS(Données!$O$2:$O$5000,Données!$Q$2:$Q$5000,">="&$B12,Données!$Q$2:$Q$5000,"<="&$C12,Données!$B$2:$B$5000,$B$3)) -> 16.625 | K12: =IF($B12="","",SUMIFS(Données!$N$2:$N$5000,Données!$Q$2:$Q$5000,">="&$B12,Données!$Q$2:$Q$5000,"<="&$C12,Données!$B$2:$B$5000,$B$3)) -> 16.243056 | L12: =IF($B12="","",IFERROR(K12/J12,0)) -> 0.9770259 | M12: =IF($B12="","",SUMIFS(Données!$S$2:$S$5000,Données!$Q$2:$Q$5000,">="&$B12,Données!$Q$2:$Q$5000,"<="&$C12,Données!$B$2:$B$5000,$B$3)) -> 0.38194444 | N12: =IF($B12="","",IFERROR(M12/J12,0)) -> 0.022974102 | O12: =IF($B12="","",SUMIFS(Données!$X$2:$X$5000,Données!$Q$2:$Q$5000,">="&$B12,Données!$Q$2:$Q$5000,"<="&$C12,Données!$B$2:$B$5000,$B$3)) -> 0.024305556
A13: =IF(B13="","",CHOOSE(MONTH(B13),"Janvier","Février","Mars","Avril","Mai","Juin","Juillet","Août","Septembre","Octobre","Novembre","Décembre")&" "&YEAR(B13)) -> Juin 2026 | B13: =IF(B12="","",IF(EDATE(B12,1)>MAX(Données!$Q$2:$Q$5000),"",EDATE(B12,1))) -> 46174 | C13: =IF(B13="","",EDATE(B13,1)-1) -> 46203 | D13: =IF($B13="","",COUNTIFS(Données!$Q$2:$Q$5000,">="&$B13,Données!$Q$2:$Q$5000,"<="&$C13,Données!$B$2:$B$5000,$B$3,Données!$O$2:$O$5000,">0")) -> 65 | E13: =IF($B13="","",COUNTIFS(Données!$Q$2:$Q$5000,">="&$B13,Données!$Q$2:$Q$5000,"<="&$C13,Données!$B$2:$B$5000,$B$3,Données!$M$2:$M$5000,"Abs")) -> 0 | F13: =IF($B13="","",IFERROR(E13/D13,0)) -> 0 | G13: =IF($B13="","",COUNTIFS(Données!$Q$2:$Q$5000,">="&$B13,Données!$Q$2:$Q$5000,"<="&$C13,Données!$B$2:$B$5000,$B$3,Données!$I$2:$I$5000,">0")) -> 3 | H13: =IF($B13="","",SUMIFS(Données!$I$2:$I$5000,Données!$Q$2:$Q$5000,">="&$B13,Données!$Q$2:$Q$5000,"<="&$C13,Données!$B$2:$B$5000,$B$3)) -> 0.043055556 | I13: =IF($B13="","",SUMIFS(Données!$L$2:$L$5000,Données!$Q$2:$Q$5000,">="&$B13,Données!$Q$2:$Q$5000,"<="&$C13,Données!$B$2:$B$5000,$B$3)) -> 0 | J13: =IF($B13="","",SUMIFS(Données!$O$2:$O$5000,Données!$Q$2:$Q$5000,">="&$B13,Données!$Q$2:$Q$5000,"<="&$C13,Données!$B$2:$B$5000,$B$3)) -> 23.916667 | K13: =IF($B13="","",SUMIFS(Données!$N$2:$N$5000,Données!$Q$2:$Q$5000,">="&$B13,Données!$Q$2:$Q$5000,"<="&$C13,Données!$B$2:$B$5000,$B$3)) -> 23.873611 | L13: =IF($B13="","",IFERROR(K13/J13,0)) -> 0.99819977 | M13: =IF($B13="","",SUMIFS(Données!$S$2:$S$5000,Données!$Q$2:$Q$5000,">="&$B13,Données!$Q$2:$Q$5000,"<="&$C13,Données!$B$2:$B$5000,$B$3)) -> 0.043055556 | N13: =IF($B13="","",IFERROR(M13/J13,0)) -> 0.0018002323 | O13: =IF($B13="","",SUMIFS(Données!$X$2:$X$5000,Données!$Q$2:$Q$5000,">="&$B13,Données!$Q$2:$Q$5000,"<="&$C13,Données!$B$2:$B$5000,$B$3)) -> 0.043055556
A14: =IF(B14="","",CHOOSE(MONTH(B14),"Janvier","Février","Mars","Avril","Mai","Juin","Juillet","Août","Septembre","Octobre","Novembre","Décembre")&" "&YEAR(B14)) -> Juillet 2026 | B14: =IF(B13="","",IF(EDATE(B13,1)>MAX(Données!$Q$2:$Q$5000),"",EDATE(B13,1))) -> 46204 | C14: =IF(B14="","",EDATE(B14,1)-1) -> 46234 | D14: =IF($B14="","",COUNTIFS(Données!$Q$2:$Q$5000,">="&$B14,Données!$Q$2:$Q$5000,"<="&$C14,Données!$B$2:$B$5000,$B$3,Données!$O$2:$O$5000,">0")) -> 64 | E14: =IF($B14="","",COUNTIFS(Données!$Q$2:$Q$5000,">="&$B14,Données!$Q$2:$Q$5000,"<="&$C14,Données!$B$2:$B$5000,$B$3,Données!$M$2:$M$5000,"Abs")) -> 0 | F14: =IF($B14="","",IFERROR(E14/D14,0)) -> 0 | G14: =IF($B14="","",COUNTIFS(Données!$Q$2:$Q$5000,">="&$B14,Données!$Q$2:$Q$5000,"<="&$C14,Données!$B$2:$B$5000,$B$3,Données!$I$2:$I$5000,">0")) -> 0 | H14: =IF($B14="","",SUMIFS(Données!$I$2:$I$5000,Données!$Q$2:$Q$5000,">="&$B14,Données!$Q$2:$Q$5000,"<="&$C14,Données!$B$2:$B$5000,$B$3)) -> 0 | I14: =IF($B14="","",SUMIFS(Données!$L$2:$L$5000,Données!$Q$2:$Q$5000,">="&$B14,Données!$Q$2:$Q$5000,"<="&$C14,Données!$B$2:$B$5000,$B$3)) -> 0 | J14: =IF($B14="","",SUMIFS(Données!$O$2:$O$5000,Données!$Q$2:$Q$5000,">="&$B14,Données!$Q$2:$Q$5000,"<="&$C14,Données!$B$2:$B$5000,$B$3)) -> 23.416667 | K14: =IF($B14="","",SUMIFS(Données!$N$2:$N$5000,Données!$Q$2:$Q$5000,">="&$B14,Données!$Q$2:$Q$5000,"<="&$C14,Données!$B$2:$B$5000,$B$3)) -> 23.416667 | L14: =IF($B14="","",IFERROR(K14/J14,0)) -> 1 | M14: =IF($B14="","",SUMIFS(Données!$S$2:$S$5000,Données!$Q$2:$Q$5000,">="&$B14,Données!$Q$2:$Q$5000,"<="&$C14,Données!$B$2:$B$5000,$B$3)) -> 0 | N14: =IF($B14="","",IFERROR(M14/J14,0)) -> 0 | O14: =IF($B14="","",SUMIFS(Données!$X$2:$X$5000,Données!$Q$2:$Q$5000,">="&$B14,Données!$Q$2:$Q$5000,"<="&$C14,Données!$B$2:$B$5000,$B$3)) -> 0.10763889
A15: =IF(B15="","",CHOOSE(MONTH(B15),"Janvier","Février","Mars","Avril","Mai","Juin","Juillet","Août","Septembre","Octobre","Novembre","Décembre")&" "&YEAR(B15)) -> Août 2026 | B15: =IF(B14="","",IF(EDATE(B14,1)>MAX(Données!$Q$2:$Q$5000),"",EDATE(B14,1))) -> 46235 | C15: =IF(B15="","",EDATE(B15,1)-1) -> 46265 | D15: =IF($B15="","",COUNTIFS(Données!$Q$2:$Q$5000,">="&$B15,Données!$Q$2:$Q$5000,"<="&$C15,Données!$B$2:$B$5000,$B$3,Données!$O$2:$O$5000,">0")) -> 57 | E15: =IF($B15="","",COUNTIFS(Données!$Q$2:$Q$5000,">="&$B15,Données!$Q$2:$Q$5000,"<="&$C15,Données!$B$2:$B$5000,$B$3,Données!$M$2:$M$5000,"Abs")) -> 2 | F15: =IF($B15="","",IFERROR(E15/D15,0)) -> 0.035087719 | G15: =IF($B15="","",COUNTIFS(Données!$Q$2:$Q$5000,">="&$B15,Données!$Q$2:$Q$5000,"<="&$C15,Données!$B$2:$B$5000,$B$3,Données!$I$2:$I$5000,">0")) -> 1 | H15: =IF($B15="","",SUMIFS(Données!$I$2:$I$5000,Données!$Q$2:$Q$5000,">="&$B15,Données!$Q$2:$Q$5000,"<="&$C15,Données!$B$2:$B$5000,$B$3)) -> 0.014583333 | I15: =IF($B15="","",SUMIFS(Données!$L$2:$L$5000,Données!$Q$2:$Q$5000,">="&$B15,Données!$Q$2:$Q$5000,"<="&$C15,Données!$B$2:$B$5000,$B$3)) -> 0 | J15: =IF($B15="","",SUMIFS(Données!$O$2:$O$5000,Données!$Q$2:$Q$5000,">="&$B15,Données!$Q$2:$Q$5000,"<="&$C15,Données!$B$2:$B$5000,$B$3)) -> 20.916667 | K15: =IF($B15="","",SUMIFS(Données!$N$2:$N$5000,Données!$Q$2:$Q$5000,">="&$B15,Données!$Q$2:$Q$5000,"<="&$C15,Données!$B$2:$B$5000,$B$3)) -> 20.152083 | L15: =IF($B15="","",IFERROR(K15/J15,0)) -> 0.96344622 | M15: =IF($B15="","",SUMIFS(Données!$S$2:$S$5000,Données!$Q$2:$Q$5000,">="&$B15,Données!$Q$2:$Q$5000,"<="&$C15,Données!$B$2:$B$5000,$B$3)) -> 0.76458333 | N15: =IF($B15="","",IFERROR(M15/J15,0)) -> 0.036553785 | O15: =IF($B15="","",SUMIFS(Données!$X$2:$X$5000,Données!$Q$2:$Q$5000,">="&$B15,Données!$Q$2:$Q$5000,"<="&$C15,Données!$B$2:$B$5000,$B$3)) -> 0.059027778
A16: =IF(B16="","",CHOOSE(MONTH(B16),"Janvier","Février","Mars","Avril","Mai","Juin","Juillet","Août","Septembre","Octobre","Novembre","Décembre")&" "&YEAR(B16)) -> Septembre 2026 | B16: =IF(B15="","",IF(EDATE(B15,1)>MAX(Données!$Q$2:$Q$5000),"",EDATE(B15,1))) -> 46266 | C16: =IF(B16="","",EDATE(B16,1)-1) -> 46295 | D16: =IF($B16="","",COUNTIFS(Données!$Q$2:$Q$5000,">="&$B16,Données!$Q$2:$Q$5000,"<="&$C16,Données!$B$2:$B$5000,$B$3,Données!$O$2:$O$5000,">0")) -> 61 | E16: =IF($B16="","",COUNTIFS(Données!$Q$2:$Q$5000,">="&$B16,Données!$Q$2:$Q$5000,"<="&$C16,Données!$B$2:$B$5000,$B$3,Données!$M$2:$M$5000,"Abs")) -> 8 | F16: =IF($B16="","",IFERROR(E16/D16,0)) -> 0.13114754 | G16: =IF($B16="","",COUNTIFS(Données!$Q$2:$Q$5000,">="&$B16,Données!$Q$2:$Q$5000,"<="&$C16,Données!$B$2:$B$5000,$B$3,Données!$I$2:$I$5000,">0")) -> 2 | H16: =IF($B16="","",SUMIFS(Données!$I$2:$I$5000,Données!$Q$2:$Q$5000,">="&$B16,Données!$Q$2:$Q$5000,"<="&$C16,Données!$B$2:$B$5000,$B$3)) -> 0.030555556 | I16: =IF($B16="","",SUMIFS(Données!$L$2:$L$5000,Données!$Q$2:$Q$5000,">="&$B16,Données!$Q$2:$Q$5000,"<="&$C16,Données!$B$2:$B$5000,$B$3)) -> 0 | J16: =IF($B16="","",SUMIFS(Données!$O$2:$O$5000,Données!$Q$2:$Q$5000,">="&$B16,Données!$Q$2:$Q$5000,"<="&$C16,Données!$B$2:$B$5000,$B$3)) -> 22.416667 | K16: =IF($B16="","",SUMIFS(Données!$N$2:$N$5000,Données!$Q$2:$Q$5000,">="&$B16,Données!$Q$2:$Q$5000,"<="&$C16,Données!$B$2:$B$5000,$B$3)) -> 19.469444 | L16: =IF($B16="","",IFERROR(K16/J16,0)) -> 0.8685254 | M16: =IF($B16="","",SUMIFS(Données!$S$2:$S$5000,Données!$Q$2:$Q$5000,">="&$B16,Données!$Q$2:$Q$5000,"<="&$C16,Données!$B$2:$B$5000,$B$3)) -> 2.9472222 | N16: =IF($B16="","",IFERROR(M16/J16,0)) -> 0.1314746 | O16: =IF($B16="","",SUMIFS(Données!$X$2:$X$5000,Données!$Q$2:$Q$5000,">="&$B16,Données!$Q$2:$Q$5000,"<="&$C16,Données!$B$2:$B$5000,$B$3)) -> 0.056944444
A17: =IF(B17="","",CHOOSE(MONTH(B17),"Janvier","Février","Mars","Avril","Mai","Juin","Juillet","Août","Septembre","Octobre","Novembre","Décembre")&" "&YEAR(B17)) -> Octobre 2026 | B17: =IF(B16="","",IF(EDATE(B16,1)>MAX(Données!$Q$2:$Q$5000),"",EDATE(B16,1))) -> 46296 | C17: =IF(B17="","",EDATE(B17,1)-1) -> 46326 | D17: =IF($B17="","",COUNTIFS(Données!$Q$2:$Q$5000,">="&$B17,Données!$Q$2:$Q$5000,"<="&$C17,Données!$B$2:$B$5000,$B$3,Données!$O$2:$O$5000,">0")) -> 85 | E17: =IF($B17="","",COUNTIFS(Données!$Q$2:$Q$5000,">="&$B17,Données!$Q$2:$Q$5000,"<="&$C17,Données!$B$2:$B$5000,$B$3,Données!$M$2:$M$5000,"Abs")) -> 4 | F17: =IF($B17="","",IFERROR(E17/D17,0)) -> 0.047058824 | G17: =IF($B17="","",COUNTIFS(Données!$Q$2:$Q$5000,">="&$B17,Données!$Q$2:$Q$5000,"<="&$C17,Données!$B$2:$B$5000,$B$3,Données!$I$2:$I$5000,">0")) -> 0 | H17: =IF($B17="","",SUMIFS(Données!$I$2:$I$5000,Données!$Q$2:$Q$5000,">="&$B17,Données!$Q$2:$Q$5000,"<="&$C17,Données!$B$2:$B$5000,$B$3)) -> 0 | I17: =IF($B17="","",SUMIFS(Données!$L$2:$L$5000,Données!$Q$2:$Q$5000,">="&$B17,Données!$Q$2:$Q$5000,"<="&$C17,Données!$B$2:$B$5000,$B$3)) -> 0 | J17: =IF($B17="","",SUMIFS(Données!$O$2:$O$5000,Données!$Q$2:$Q$5000,">="&$B17,Données!$Q$2:$Q$5000,"<="&$C17,Données!$B$2:$B$5000,$B$3)) -> 31.083333 | K17: =IF($B17="","",SUMIFS(Données!$N$2:$N$5000,Données!$Q$2:$Q$5000,">="&$B17,Données!$Q$2:$Q$5000,"<="&$C17,Données!$B$2:$B$5000,$B$3)) -> 29.75 | L17: =IF($B17="","",IFERROR(K17/J17,0)) -> 0.95710456 | M17: =IF($B17="","",SUMIFS(Données!$S$2:$S$5000,Données!$Q$2:$Q$5000,">="&$B17,Données!$Q$2:$Q$5000,"<="&$C17,Données!$B$2:$B$5000,$B$3)) -> 1.3333333 | N17: =IF($B17="","",IFERROR(M17/J17,0)) -> 0.042895442 | O17: =IF($B17="","",SUMIFS(Données!$X$2:$X$5000,Données!$Q$2:$Q$5000,">="&$B17,Données!$Q$2:$Q$5000,"<="&$C17,Données!$B$2:$B$5000,$B$3)) -> 0.070138889
A18: =IF(B18="","",CHOOSE(MONTH(B18),"Janvier","Février","Mars","Avril","Mai","Juin","Juillet","Août","Septembre","Octobre","Novembre","Décembre")&" "&YEAR(B18)) -> Novembre 2026 | B18: =IF(B17="","",IF(EDATE(B17,1)>MAX(Données!$Q$2:$Q$5000),"",EDATE(B17,1))) -> 46327 | C18: =IF(B18="","",EDATE(B18,1)-1) -> 46356 | D18: =IF($B18="","",COUNTIFS(Données!$Q$2:$Q$5000,">="&$B18,Données!$Q$2:$Q$5000,"<="&$C18,Données!$B$2:$B$5000,$B$3,Données!$O$2:$O$5000,">0")) -> 0 | E18: =IF($B18="","",COUNTIFS(Données!$Q$2:$Q$5000,">="&$B18,Données!$Q$2:$Q$5000,"<="&$C18,Données!$B$2:$B$5000,$B$3,Données!$M$2:$M$5000,"Abs")) -> 0 | F18: =IF($B18="","",IFERROR(E18/D18,0)) -> 0 | G18: =IF($B18="","",COUNTIFS(Données!$Q$2:$Q$5000,">="&$B18,Données!$Q$2:$Q$5000,"<="&$C18,Données!$B$2:$B$5000,$B$3,Données!$I$2:$I$5000,">0")) -> 0 | H18: =IF($B18="","",SUMIFS(Données!$I$2:$I$5000,Données!$Q$2:$Q$5000,">="&$B18,Données!$Q$2:$Q$5000,"<="&$C18,Données!$B$2:$B$5000,$B$3)) -> 0 | I18: =IF($B18="","",SUMIFS(Données!$L$2:$L$5000,Données!$Q$2:$Q$5000,">="&$B18,Données!$Q$2:$Q$5000,"<="&$C18,Données!$B$2:$B$5000,$B$3)) -> 0 | J18: =IF($B18="","",SUMIFS(Données!$O$2:$O$5000,Données!$Q$2:$Q$5000,">="&$B18,Données!$Q$2:$Q$5000,"<="&$C18,Données!$B$2:$B$5000,$B$3)) -> 0 | K18: =IF($B18="","",SUMIFS(Données!$N$2:$N$5000,Données!$Q$2:$Q$5000,">="&$B18,Données!$Q$2:$Q$5000,"<="&$C18,Données!$B$2:$B$5000,$B$3)) -> 0 | L18: =IF($B18="","",IFERROR(K18/J18,0)) -> 0 | M18: =IF($B18="","",SUMIFS(Données!$S$2:$S$5000,Données!$Q$2:$Q$5000,">="&$B18,Données!$Q$2:$Q$5000,"<="&$C18,Données!$B$2:$B$5000,$B$3)) -> 0 | N18: =IF($B18="","",IFERROR(M18/J18,0)) -> 0 | O18: =IF($B18="","",SUMIFS(Données!$X$2:$X$5000,Données!$Q$2:$Q$5000,">="&$B18,Données!$Q$2:$Q$5000,"<="&$C18,Données!$B$2:$B$5000,$B$3)) -> 0
... A29: =IF(B29="","",CHOOSE(MONTH(B29),"Janvier","Février","Mars","Avril","Mai","Juin","Juillet","Août","Septembre","Octobre","Novembre","Décembre")&" "&YEAR(B29)) | B29: =IF(B28="","",IF(EDATE(B28,1)>MAX(Données!$Q$2:$Q$5000),"",EDATE(B28,1))) | C29: =IF(B29="","",EDATE(B29,1)-1) | D29: =IF($B29="","",COUNTIFS(Données!$Q$2:$Q$5000,">="&$B29,Données!$Q$2:$Q$5000,"<="&$C29,Données!$B$2:$B$5000,$B$3,Données!$O$2:$O$5000,">0")) | E29: =IF($B29="","",COUNTIFS(Données!$Q$2:$Q$5000,">="&$B29,Données!$Q$2:$Q$5000,"<="&$C29,Données!$B$2:$B$5000,$B$3,Données!$M$2:$M$5000,"Abs")) | F29: =IF($B29="","",IFERROR(E29/D29,0)) | G29: =IF($B29="","",COUNTIFS(Données!$Q$2:$Q$5000,">="&$B29,Données!$Q$2:$Q$5000,"<="&$C29,Données!$B$2:$B$5000,$B$3,Données!$I$2:$I$5000,">0")) | H29: =IF($B29="","",SUMIFS(Données!$I$2:$I$5000,Données!$Q$2:$Q$5000,">="&$B29,Données!$Q$2:$Q$5000,"<="&$C29,Données!$B$2:$B$5000,$B$3)) | I29: =IF($B29="","",SUMIFS(Données!$L$2:$L$5000,Données!$Q$2:$Q$5000,">="&$B29,Données!$Q$2:$Q$5000,"<="&$C29,Données!$B$2:$B$5000,$B$3)) | J29: =IF($B29="","",SUMIFS(Données!$O$2:$O$5000,Données!$Q$2:$Q$5000,">="&$B29,Données!$Q$2:$Q$5000,"<="&$C29,Données!$B$2:$B$5000,$B$3)) | K29: =IF($B29="","",SUMIFS(Données!$N$2:$N$5000,Données!$Q$2:$Q$5000,">="&$B29,Données!$Q$2:$Q$5000,"<="&$C29,Données!$B$2:$B$5000,$B$3)) | L29: =IF($B29="","",IFERROR(K29/J29,0)) | M29: =IF($B29="","",SUMIFS(Données!$S$2:$S$5000,Données!$Q$2:$Q$5000,">="&$B29,Données!$Q$2:$Q$5000,"<="&$C29,Données!$B$2:$B$5000,$B$3)) | N29: =IF($B29="","",IFERROR(M29/J29,0)) | O29: =IF($B29="","",SUMIFS(Données!$X$2:$X$5000,Données!$Q$2:$Q$5000,">="&$B29,Données!$Q$2:$Q$5000,"<="&$C29,Données!$B$2:$B$5000,$B$3))

Sheet Données
A1: Clé semaine (ISO) | B1: Nom De l'agent | C1: Hr début shift Réalisée | D1: Hr début shift Planifiée | E1: Hr fin shift Réalisée | F1: Hr Fin shift Planifiée | G1: Durée de la Pause Dej | H1: Dépassement des pauses | I1: Retard Debut de shift | J1: Retard Dej | K1: Somme des retards | L1: Départs Anticipés | M1: Absences | N1: Hr Adhérée | O1: Hr Planifiée | P1: Segment | Q1: Date | R1: Hr Abs Pure | S1: Hr Abs Totales | T1: Semaine | U1: Mois | V1: Année | W1: VTO | X1: Heures SUP | Y1: Team | Z1: Business | AA1: Fichier source | AB1: Congé payé | AC1: Congé sans solde | AD1: Congé spécial | AE1: Jour férié | AF1: Commentaire | AG1: Plannif spécial
