Workbook

Sheet Mensuel
B2: BO | D2: AE | F2: Formation initiale BO | H2: Formation continue BO | J2: Formation initiale FO | L2: Formation continue FO | N2: Total CC | P2: Manager | R2: Relation Clients
B3: ETP | C3: Heures | D3: ETP | E3: Heures | F3: ETP | G3: Heures | H3: ETP | I3: Heures | J3: ETP | K3: Heures | L3: ETP | M3: Heures
A4: 45809 | B4: =C4/8 -> 0 | C4: 0 | D4: =E4/8 -> 0 | E4: 0 | F4: =G4/8 -> 0 | H4: =I4/8 -> 0 | J4: =K4/8 -> 0 | L4: =M4/8 -> 0
A5: 45810 | B5: =C5/8 -> 0 | C5: 0 | D5: =E5/8 -> 0 | E5: 0 | F5: =G5/8 -> 0 | H5: =I5/8 -> 0 | J5: =K5/8 -> 0 | L5: =M5/8 -> 0
A6: 45811 | B6: =C6/8 -> 0 | C6: 0 | D6: =E6/8 -> 0 | E6: 0 | F6: =G6/8 -> 0 | H6: =I6/8 -> 0 | J6: =K6/8 -> 0 | L6: =M6/8 -> 0
A7: 45812 | B7: =C7/8 -> 0 | D7: =E7/8 -> 0 | F7: =G7/8 -> 0 | H7: =I7/8 -> 0 | J7: =K7/8 -> 0 | L7: =M7/8 -> 0
A8: 45813 | B8: =C8/8 -> 0 | C8: 0 | D8: =E8/8 -> 0 | E8: 0 | F8: =G8/8 -> 0 | H8: =I8/8 -> 0 | J8: 0 | L8: 0
A9: 45814 | B9: =C9/8 -> 0 | C9: 0 | D9: =E9/8 -> 0 | E9: 0 | F9: =G9/8 -> 0 | H9: =I9/8 -> 0 | J9: =K9/8 -> 0 | L9: =M9/8 -> 0
A10: 45815 | B10: =C10/8 -> 0 | C10: 0 | D10: =E10/8 -> 0 | E10: 0 | F10: =G10/8 -> 0 | H10: =I10/8 -> 0 | J10: =K10/8 -> 0 | L10: =M10/8 -> 0
A11: 45816 | B11: =C11/8 -> 0 | C11: 0 | D11: =E11/8 -> 0 | E11: 0 | F11: =G11/8 -> 0 | H11: =I11/8 -> 0 | J11: =K11/8 -> 0 | L11: =M11/8 -> 0
A12: 45817 | B12: =C12/8 -> 0 | C12: 0 | D12: =E12/8 -> 0 | E12: 0 | F12: =G12/8 -> 0 | H12: =I12/8 -> 0 | J12: =K12/8 -> 0 | L12: =M12/8 -> 0
A13: 45818 | B13: =C13/8 -> 0 | C13: 0 | D13: =E13/8 -> 0 | E13: 0 | F13: =G13/8 -> 0 | H13: =I13/8 -> 0 | J13: =K13/8 -> 0 | L13: =M13/8 -> 0
A14: 45819 | B14: =C14/8 -> 0 | D14: =E14/8 -> 0 | F14: =G14/8 -> 0 | H14: =I14/8 -> 0 | J14: =K14/8 -> 0 | L14: =M14/8 -> 0
A15: 45820 | B15: =C15/8 -> 0 | C15: 0 | D15: =E15/8 -> 0 | E15: 0 | F15: =G15/8 -> 0 | H15: =I15/8 -> 0 | J15: =K15/8 -> 0 | L15: =M15/8 -> 0
A16: 45821 | B16: =C16/8 -> 0 | C16: 0 | D16: =E16/8 -> 0 | E16: 0 | F16: =G16/8 -> 0 | H16: =I16/8 -> 0 | J16: =K16/8 -> 0 | L16: =M16/8 -> 0
A17: 45822 | B17: =C17/8 -> 0 | C17: 0 | D17: =E17/8 -> 0 | E17: 0 | F17: =G17/8 -> 0 | H17: =I17/8 -> 0 | J17: =K17/8 -> 0 | L17: =M17/8 -> 0
A18: 45823 | B18: =C18/8 -> 0 | C18: 0 | D18: =E18/8 -> 0 | E18: 0 | F18: =G18/8 -> 0 | H18: =I18/8 -> 0 | J18: =K18/8 -> 0 | L18: =M18/8 -> 0
A19: 45824 | B19: =C19/8 -> 0 | C19: 0 | D19: =E19/8 -> 0 | E19: 0 | F19: =G19/8 -> 0 | H19: =I19/8 -> 0 | J19: =K19/8 -> 0 | L19: =M19/8 -> 0
A20: 45825 | B20: =C20/8 -> 0 | C20: 0 | D20: =E20/8 -> 0 | E20: 0 | F20: =G20/8 -> 0 | H20: =I20/8 -> 0 | J20: =K20/8 -> 0 | L20: =M20/8 -> 0
A21: 45826 | B21: =C21/8 -> 0 | D21: =E21/8 -> 0 | F21: =G21/8 -> 0 | H21: =I21/8 -> 0 | J21: =K21/8 -> 0 | L21: =M21/8 -> 0
A22: 45827 | B22: =C22/8 -> 0 | C22: 0 | D22: =E22/8 -> 0 | E22: 0 | F22: =G22/8 -> 0 | H22: =I22/8 -> 0 | J22: =K22/8 -> 0 | L22: =M22/8 -> 0
A23: 45828 | B23: =C23/8 -> 0 | C23: 0 | D23: =E23/8 -> 0 | E23: 0 | F23: =G23/8 -> 0 | H23: =I23/8 -> 0 | J23: =K23/8 -> 0 | L23: =M23/8 -> 0
A24: 45829 | B24: =C24/8 -> 0 | C24: 0 | D24: =E24/8 -> 0 | E24: 0 | F24: =G24/8 -> 0 | H24: =I24/8 -> 0 | J24: =K24/8 -> 0 | L24: =M24/8 -> 0
A25: 45830 | B25: =C25/8 -> 0 | C25: 0 | D25: =E25/8 -> 0 | E25: 0 | F25: =G25/8 -> 0 | H25: =I25/8 -> 0 | J25: =K25/8 -> 0 | L25: =M25/8 -> 0
A26: 45831 | B26: =C26/8 -> 0 | C26: 0 | D26: =E26/8 -> 0 | E26: 0 | F26: =G26/8 -> 0 | H26: =I26/8 -> 0 | J26: =K26/8 -> 0 | L26: =M26/8 -> 0
A27: 45832 | B27: =C27/8 -> 0 | D27: =E27/8 -> 0 | E27: 0 | F27: =G27/8 -> 0 | H27: =I27/8 -> 0 | J27: =K27/8 -> 0 | L27: =M27/8 -> 0
A28: 45833 | B28: =C28/8 -> 0 | D28: =E28/8 -> 0 | F28: =G28/8 -> 0 | H28: =I28/8 -> 0 | J28: =K28/8 -> 0 | L28: =M28/8 -> 0
A29: 45834 | B29: =C29/8 -> 0 | C29: 0 | D29: =E29/8 -> 0 | E29: 0 | F29: =G29/8 -> 0 | H29: =I29/8 -> 0 | J29: =K29/8 -> 0 | L29: =M29/8 -> 0
A30: 45835 | B30: =C30/8 -> 0 | C30: 0 | D30: =E30/8 -> 0 | E30: 0 | F30: =G30/8 -> 0 | H30: =I30/8 -> 0 | J30: =K30/8 -> 0 | L30: =M30/8 -> 0
A31: 45836 | B31: =C31/8 -> 0 | C31: 0 | D31: =E31/8 -> 0 | E31: 0 | F31: =G31/8 -> 0 | H31: =I31/8 -> 0 | J31: =K31/8 -> 0 | L31: =M31/8 -> 0
A32: 45837 | B32: =C32/8 -> 0 | C32: 0 | D32: =E32/8 -> 0 | E32: 0 | F32: =G32/8 -> 0 | H32: =I32/8 -> 0 | J32: =K32/8 -> 0 | L32: =M32/8 -> 0
A33: 45838 | B33: =C33/8 -> 0 | C33: 0 | D33: =E33/8 -> 0 | E33: 0 | F33: =G33/8 -> 0 | H33: =I33/8 -> 0 | J33: =K33/8 -> 0 | L33: =M33/8 -> 0
A34: Total | B34: =IFERROR(AVERAGE(B4:B33),0) -> 0 | C34: =SUM(C4:C33) -> 0 | D34: =AVERAGE(D6:D32) -> 0 | E34: =SUM(E4:E33) -> 0 | F34: =AVERAGE(F4:F33) -> 0 | G34: =SUM(G4:G33) -> 0 | H34: =AVERAGE(H4:H33) -> 0 | I34: =SUM(I4:I33) -> 0 | J34: =AVERAGE(J4:J33) -> 0 | K34: =SUM(K4:K33) -> 0 | L34: =AVERAGE(L4:L33) -> 0 | M34: =SUM(M4:M33) -> 0 | N34: =IFERROR(AVERAGE(N4:N33),0) -> 0 | O34: =#REF!+C34+I34+E34+G34+K34+M34 -> #REF! | P34: =IFERROR(AVERAGE(P4:P33),0) -> 0 | Q34: =SUM(Q4:Q33) -> 0 | R34: =IFERROR(AVERAGE(R4:R33),0) -> 0 | S34: =SUM(S4:S33) -> 0

Sheet GLF
A1: GLF
B3: 45809 | C3: 45839 | D3: 45870 | E3: 45901 | F3: 45931 | G3: 45962 | H3: 45992 | I3: Cumul 2025 | J3: 46023 | K3: 46054 | L3: 46082 | M3: 46113 | N3: 46143 | O3: 46174 | P3: 46204 | Q3: 46235 | R3: 46266 | S3: 46296 | T3: 46327 | U3: 46357 | V3: Cumul 2026
A4: Cumul des heures | B4: =B13+B17+B20+B23 -> 1664 | C4: =C13+C17+C20+C23 -> 1557.24 | D4: =D13+D17+D20+D23 -> 1867.5 | E4: =E13+E17+E20+E23 -> 2618.07 | F4: =F13+F17+F20+F23 -> 2542.02 | G4: =G13+G17+G20+G23 -> 2554.35 | H4: =H13+H17+H20+H23 -> 2731.32 | I4: =SUM(B4:H4) -> 15534.5 | J4: =J13+J17+J20+J23 -> 3116 | K4: =K13+K17+K20+K23 -> 4855.97 | L4: =L13+L17+L20+L23 -> 6907.76 | M4: =M13+M17+M20+M23 -> 6084.43 | N4: =N13+N17+N20+N23 -> 4521.3 | O4: =O13+O17+O20+O23 -> 4443.5 | P4: =P13+P17+P20+P23 -> 2761.9 | Q4: =Q13+Q17+Q20+Q23 -> 2471.85 | ... U4: =U13+U17+U20+U23 -> 0 | V4: =SUM(J4:U4) -> 37554.667
A5: Cumul des actes | C5: =C11+C16+C12 -> 1448 | D5: =D11+D16+D12 -> 2951 | E5: =E11+E16+E12 -> 8373 | F5: =F11+F16+F12 -> 9505 | G5: =G11+G16+G12 -> 10006 | H5: =H11+H16+H12 -> 7540 | I5: =SUM(C5:H5) -> 39823 | J5: =J11+J16+J12 -> 6996 | K5: =K11+K16+K12 -> 8634 | L5: =L11+L16+L12 -> 9200 | M5: =M11+M16+M12 -> 18013 | N5: =N11+N16+N12 -> 16538 | O5: =O11+O16+O12 -> 11343 | P5: =P11+P16+P12 -> 8068 | Q5: =Q11+Q16+Q12 -> 7893 | ... U5: =U11+U16+U12 -> 0 | V5: =SUM(J5:U5) -> 93598
A7: Données réalisées
B9: 45809 | C9: 45839 | D9: 45870 | E9: 45901 | F9: 45931 | G9: 45962 | H9: 45992 | I9: Cumul 2025 | J9: 46023 | K9: 46054 | L9: 46082 | M9: 46113 | N9: 46143 | O9: 46174 | P9: 46204 | Q9: 46235 | R9: 46266 | S9: 46296 | T9: 46327 | U9: 46357 | V9: Cumul 2026
A10: ACT00075A – Back office
A11: Nb d'actes traités | C11: 647 | D11: 1003 | E11: 2068 | F11: 1574 | G11: 1659 | H11: 1147 | I11: =SUM(C11:H11) -> 8098 | J11: 1151 | K11: 1611 | L11: 1770 | M11: 4269 | N11: 4381 | O11: 2097 | P11: 1028 | Q11: 1360 | R11: 1115 | V11: =SUM(J11:U11) -> 18782
A12: Nb de qualifications | D12: 834 | E12: 4832 | F12: 5887 | G12: 6418 | H12: 4956 | I12: =SUM(C12:H12) -> 22927 | J12: 4277 | K12: 5026 | L12: 5296 | M12: 7153 | N12: 6907 | O12: 6266 | P12: 5200 | Q12: 4770 | R12: 4219 | V12: =SUM(J12:U12) -> 49114
A13: Nb d'heures | C13: =Juillet!C35+(Juillet!Q35/2) -> 858.41 | D13: =Aout!C35+(Aout!Q35/2) -> 658.5 | E13: =Septembre!C34+(Septembre!Q34/2) -> 1524.942 | F13: =Octobre!C35+(Octobre!Q35/2) -> 1345.91 | G13: =Novembre!C34+(Novembre!Q34/2) -> 1254.93 | H13: =Décembre!C35+(Décembre!Q35/2) -> 1336.72 | I13: =SUM(C13:H13) -> 6979.412 | J13: 1134 | K13: =Fevrier26!C32+(Fevrier26!Q32/2) -> 1977 | L13: =Mars26!C35+(Mars26!Q35/2) -> 2981.45 | M13: =Avril26!C34+(Avril26!Q34/2) -> 3181.21 | N13: ='Mai26'!C33+('Mai26'!Q33/2) -> 2379.2 | O13: =Juin26!C34+(Juin26!Q34/2) -> 2686.105 | P13: =Juillet26!C35+(Juillet26!Q35/2) -> 1298.04 | Q13: =Aout26!C35+(Aout26!Q35/2) -> 1137.87 | R13: =Septembre26!C34+(Septembre26!Q34/2) -> 1086.8537 | V13: =SUM(J13:U13) -> 17861.729
A14: EFFECTIFS RABAT | C14: 8 | D14: 9 | E14: 14 | F14: 13 | G14: 15 | H14: 14 | I14: =AVERAGE(B14:H14) -> 12.166667 | J14: 14 | K14: 30 | L14: 37 | M14: 35 | N14: 31 | O14: 25 | P14: 14 | Q14: 14 | R14: 14 | V14: =AVERAGE(J14:U14) -> 23.777778
A15: ACT00075B – Appels
A16: Nb d'appels traités | C16: 801 | D16: 1114 | E16: 1473 | F16: 2044 | G16: 1929 | H16: 1437 | I16: =SUM(C16:H16) -> 8798 | J16: 1568 | K16: 1997 | L16: 2134 | M16: 6591 | N16: 5250 | O16: 2980 | P16: 1840 | Q16: 1763 | R16: 1579 | V16: =SUM(J16:U16) -> 25702
A17: Nb d'heures | C17: =Juillet!E35+(Juillet!Q35/2) -> 419.5 | D17: =Aout!E35+(Aout!Q35/2) -> 701 | E17: =Septembre!E34+(Septembre!Q34/2) -> 1066.628 | F17: =Octobre!E35+(Octobre!Q35/2) -> 1190.11 | G17: =Novembre!E34+(Novembre!Q34/2) -> 1147.67 | H17: =Décembre!E35+(Décembre!Q35/2) -> 1380.6 | I17: =SUM(C17:H17) -> 5905.508 | J17: 1330 | K17: =Fevrier26!E32+(Fevrier26!Q32/2) -> 2226.97 | L17: =Mars26!E35+(Mars26!Q35/2) -> 2933.31 | M17: =Avril26!E34+(Avril26!Q34/2) -> 2890.22 | N17: ='Mai26'!E33+('Mai26'!Q33/2) -> 2142.1 | O17: =Juin26!E34+(Juin26!Q34/2) -> 1723.395 | P17: =Juillet26!E35+(Juillet26!Q35/2) -> 1463.86 | Q17: =Aout26!E35+(Aout26!Q35/2) -> 1333.98 | R17: =Septembre26!E34+(Septembre26!Q34/2) -> 1305.1032 | V17: =SUM(J17:U17) -> 17348.938
A18: EFFECTIFS RABAT | C18: 8 | D18: 9 | E18: 14 | F18: 13 | G18: 15 | H18: 14 | I18: =AVERAGE(B18:H18) -> 12.166667 | J18: 14 | K18: 30 | L18: 37 | M18: 35 | N18: 31 | O18: 25 | P18: 14 | Q18: 14 | R18: 14 | V18: =AVERAGE(J18:U18) -> 23.777778
A19: ACT00075C – Formations*
A20: Nb d'heures | B20: 1664 | C20: =Juillet!G35+Juillet!I35+Juillet!K35+Juillet!M35 -> 279.33 | D20: =Aout!G35+Aout!I35+Aout!K35+Aout!M35 -> 508 | E20: =Septembre!G35+Septembre!I34+Septembre!K34+Septembre!M34 -> 26.5 | F20: =Octobre!G35+Octobre!I35+Octobre!K35+Octobre!M35 -> 6 | G20: =Novembre!G34+Novembre!I34+Novembre!K34+Novembre!M34 -> 151.75 | H20: =Décembre!G35+Décembre!I35+Décembre!K35+Décembre!M35 -> 14 | I20: =SUM(C20:H20) -> 985.58 | J20: 652 | K20: =Fevrier26!G32+Fevrier26!I32+Fevrier26!K32+Fevrier26!M32 -> 652 | L20: =Mars26!G35+Mars26!I35+Mars26!K35+Mars26!M35 -> 993 | M20: =Avril26!G34+Avril26!I34+Avril26!K34+Avril26!M34 -> 13 | N20: ='Mai26'!G33+'Mai26'!I33+'Mai26'!K33+'Mai26'!M33 -> 0 | O20: =Juin26!G34+Juin26!I34+Juin26!K34+Juin26!M34 -> 34 | P20: =Juillet26!G35+Juillet26!I35+Juillet26!K35+Juillet26!M35 -> 0 | Q20: =Aout26!H35+Aout26!J35+Aout26!L35+Aout26!N35 -> 0 | R20: =Aout26!H34+Aout26!J34+Aout26!L34+Aout26!N34 -> 0 | V20: =SUM(J20:U20) -> 2344
A21: EFFECTIFS RABAT | B21: 9 | C21: 9 | D21: 9 | E21: 14 | F21: 13 | G21: 2 | H21: 14 | I21: =AVERAGE(B21:H21) -> 10 | J21: 8 | K21: 8 | L21: 12 | M21: 17 | N21: 0 | O21: 25 | P21: 14 | Q21: 14 | R21: 14 | V21: =AVERAGE(J21:U21) -> 12.444444
A22: ACT00075D – Relation clients
A23: Nb d'heures
A28: * heures de formations des nouveaux collaborateurs prévus pour renforcer l’équipe (pas de facturation pour les collaborateurs arrivés en remplacement des collaborateurs qui sont partis (= turn over))
A29: Les heures de management sont divisées par moitié égale sur les activité BO et FO

Sheet Juin
B2: BO | D2: AE | F2: Formation initiale BO | H2: Formation continue BO | J2: Formation initiale FO | L2: Formation continue FO | N2: Total CC | P2: Manager | R2: Relation Clients
B3: ETP | C3: Heures | D3: ETP | E3: Heures | F3: ETP | G3: Heures | H3: ETP | I3: Heures | J3: ETP | K3: Heures | L3: ETP | M3: Heures
A4: 45809 | B4: =C4/8 -> 0 | C4: 0 | D4: =E4/8 -> 0 | E4: 0 | F4: =G4/8 -> 0 | H4: =I4/8 -> 0 | J4: =K4/8 -> 0 | L4: =M4/8 -> 0
A5: 45810 | B5: =C5/8 -> 0 | C5: 0 | D5: =E5/8 -> 0 | E5: 0 | F5: =G5/8 -> 0 | H5: =I5/8 -> 0 | J5: =K5/8 -> 0 | L5: =M5/8 -> 0
A6: 45811 | B6: =C6/8 -> 0 | C6: 0 | D6: =E6/8 -> 0 | E6: 0 | F6: =G6/8 -> 0 | H6: =I6/8 -> 0 | J6: =K6/8 -> 0 | L6: =M6/8 -> 0
A7: 45812 | B7: =C7/8 -> 0 | D7: =E7/8 -> 0 | F7: =G7/8 -> 0 | H7: =I7/8 -> 0 | J7: =K7/8 -> 0 | L7: =M7/8 -> 0
A8: 45813 | B8: =C8/8 -> 0 | C8: 0 | D8: =E8/8 -> 0 | E8: 0 | F8: =G8/8 -> 0 | H8: =I8/8 -> 0 | J8: 0 | L8: 0
A9: 45814 | B9: =C9/8 -> 0 | C9: 0 | D9: =E9/8 -> 0 | E9: 0 | F9: =G9/8 -> 0 | H9: =I9/8 -> 0 | J9: =K9/8 -> 0 | L9: =M9/8 -> 0
A10: 45815 | B10: =C10/8 -> 0 | C10: 0 | D10: =E10/8 -> 0 | E10: 0 | F10: =G10/8 -> 0 | H10: =I10/8 -> 0 | J10: =K10/8 -> 0 | L10: =M10/8 -> 0
A11: 45816 | B11: =C11/8 -> 0 | C11: 0 | D11: =E11/8 -> 0 | E11: 0 | F11: =G11/8 -> 0 | H11: =I11/8 -> 0 | J11: =K11/8 -> 0 | L11: =M11/8 -> 0
A12: 45817 | B12: =C12/8 -> 0 | C12: 0 | D12: =E12/8 -> 0 | E12: 0 | F12: =G12/8 -> 0 | H12: =I12/8 -> 0 | J12: =K12/8 -> 0 | L12: =M12/8 -> 0
A13: 45818 | B13: =C13/8 -> 0 | C13: 0 | D13: =E13/8 -> 0 | E13: 0 | F13: =G13/8 -> 0 | H13: =I13/8 -> 0 | J13: =K13/8 -> 0 | L13: =M13/8 -> 0
A14: 45819 | B14: =C14/8 -> 0 | D14: =E14/8 -> 0 | F14: =G14/8 -> 0 | H14: =I14/8 -> 0 | J14: =K14/8 -> 0 | L14: =M14/8 -> 0
A15: 45820 | B15: =C15/8 -> 0 | C15: 0 | D15: =E15/8 -> 0 | E15: 0 | F15: =G15/8 -> 0 | H15: =I15/8 -> 0 | J15: =K15/8 -> 0 | L15: =M15/8 -> 0
A16: 45821 | B16: =C16/8 -> 0 | C16: 0 | D16: =E16/8 -> 0 | E16: 0 | F16: =G16/8 -> 0 | H16: =I16/8 -> 0 | J16: =K16/8 -> 0 | L16: =M16/8 -> 0
A17: 45822 | B17: =C17/8 -> 0 | C17: 0 | D17: =E17/8 -> 0 | E17: 0 | F17: =G17/8 -> 0 | H17: =I17/8 -> 0 | J17: =K17/8 -> 0 | L17: =M17/8 -> 0
A18: 45823 | B18: =C18/8 -> 0 | C18: 0 | D18: =E18/8 -> 0 | E18: 0 | F18: =G18/8 -> 0 | H18: =I18/8 -> 0 | J18: =K18/8 -> 0 | L18: =M18/8 -> 0
A19: 45824 | B19: =C19/8 -> 0 | C19: 0 | D19: =E19/8 -> 0 | E19: 0 | F19: =G19/8 -> 0 | H19: =I19/8 -> 0 | J19: =K19/8 -> 0 | L19: =M19/8 -> 0
A20: 45825 | B20: =C20/8 -> 0 | C20: 0 | D20: =E20/8 -> 0 | E20: 0 | F20: =G20/8 -> 0 | H20: =I20/8 -> 0 | J20: =K20/8 -> 0 | L20: =M20/8 -> 0
A21: 45826 | B21: =C21/8 -> 0 | D21: =E21/8 -> 0 | F21: =G21/8 -> 0 | H21: =I21/8 -> 0 | J21: =K21/8 -> 0 | L21: =M21/8 -> 0
A22: 45827 | B22: =C22/8 -> 0 | C22: 0 | D22: =E22/8 -> 0 | E22: 0 | F22: =G22/8 -> 0 | H22: =I22/8 -> 0 | J22: =K22/8 -> 0 | L22: =M22/8 -> 0
A23: 45828 | B23: =C23/8 -> 0 | C23: 0 | D23: =E23/8 -> 0 | E23: 0 | F23: =G23/8 -> 0 | H23: =I23/8 -> 0 | J23: =K23/8 -> 0 | L23: =M23/8 -> 0
A24: 45829 | B24: =C24/8 -> 0 | C24: 0 | D24: =E24/8 -> 0 | E24: 0 | F24: =G24/8 -> 0 | H24: =I24/8 -> 0 | J24: =K24/8 -> 0 | L24: =M24/8 -> 0
A25: 45830 | B25: =C25/8 -> 0 | C25: 0 | D25: =E25/8 -> 0 | E25: 0 | F25: =G25/8 -> 0 | H25: =I25/8 -> 0 | J25: =K25/8 -> 0 | L25: =M25/8 -> 0
A26: 45831 | B26: =C26/8 -> 0 | C26: 0 | D26: =E26/8 -> 0 | E26: 0 | F26: =G26/8 -> 0 | H26: =I26/8 -> 0 | J26: =K26/8 -> 0 | L26: =M26/8 -> 0
A27: 45832 | B27: =C27/8 -> 0 | D27: =E27/8 -> 0 | E27: 0 | F27: =G27/8 -> 0 | H27: =I27/8 -> 0 | J27: =K27/8 -> 0 | L27: =M27/8 -> 0
A28: 45833 | B28: =C28/8 -> 0 | D28: =E28/8 -> 0 | F28: =G28/8 -> 0 | H28: =I28/8 -> 0 | J28: =K28/8 -> 0 | L28: =M28/8 -> 0
A29: 45834 | B29: =C29/8 -> 0 | C29: 0 | D29: =E29/8 -> 0 | E29: 0 | F29: =G29/8 -> 0 | H29: =I29/8 -> 0 | J29: =K29/8 -> 0 | L29: =M29/8 -> 0
A30: 45835 | B30: =C30/8 -> 0 | C30: 0 | D30: =E30/8 -> 0 | E30: 0 | F30: =G30/8 -> 0 | H30: =I30/8 -> 0 | J30: =K30/8 -> 0 | L30: =M30/8 -> 0
A31: 45836 | B31: =C31/8 -> 0 | C31: 0 | D31: =E31/8 -> 0 | E31: 0 | F31: =G31/8 -> 0 | H31: =I31/8 -> 0 | J31: =K31/8 -> 0 | L31: =M31/8 -> 0
A32: 45837 | B32: =C32/8 -> 0 | C32: 0 | D32: =E32/8 -> 0 | E32: 0 | F32: =G32/8 -> 0 | H32: =I32/8 -> 0 | J32: =K32/8 -> 0 | L32: =M32/8 -> 0
A33: 45838 | B33: =C33/8 -> 0 | C33: 0 | D33: =E33/8 -> 0 | E33: 0 | F33: =G33/8 -> 0 | H33: =I33/8 -> 0 | J33: =K33/8 -> 0 | L33: =M33/8 -> 0
A34: Total | B34: =IFERROR(AVERAGE(B4:B33),0) -> 0 | C34: =SUM(C4:C33) -> 0 | D34: =AVERAGE(D6:D32) -> 0 | E34: =SUM(E4:E33) -> 0 | F34: =AVERAGE(F4:F33) -> 0 | G34: =SUM(G4:G33) -> 0 | H34: =AVERAGE(H4:H33) -> 0 | I34: =SUM(I4:I33) -> 0 | J34: =AVERAGE(J4:J33) -> 0 | K34: =SUM(K4:K33) -> 0 | L34: =AVERAGE(L4:L33) -> 0 | M34: =SUM(M4:M33) -> 0 | N34: =IFERROR(AVERAGE(N4:N33),0) -> 0 | O34: =#REF!+C34+I34+E34+G34+K34+M34 -> #REF! | P34: =IFERROR(AVERAGE(P4:P33),0) -> 0 | Q34: =SUM(Q4:Q33) -> 0 | R34: =IFERROR(AVERAGE(R4:R33),0) -> 0 | S34: =SUM(S4:S33) -> 0

Sheet Juillet
A2: 2025 | B2: BO | D2: AE | F2: Formation initiale BO | H2: Formation continue BO | J2: Formation initiale FO | L2: Formation continue FO | N2: Total CC | P2: Manager | R2: Relation Clients
B3: ETP | C3: Heures | D3: ETP | E3: Heures | F3: ETP | G3: Heures | H3: ETP | I3: Heures | J3: ETP | K3: Heures | L3: ETP | M3: Heures | N3: ETP | O3: Heures
A4: 45839 | B4: =C4/8 -> 0 | C4: 0 | D4: =E4/8 -> 0 | E4: 0 | F4: =G4/8 -> 9.5 | G4: 76 | H4: =I4/8 -> 0 | I4: 0 | J4: =K4/8 -> 0 | K4: 0 | L4: =M4/8 -> 0 | M4: 0 | N4: =O4/8 -> 0 | O4: 0 | P4: 1 | Q4: 8
A5: 45840 | B5: =C5/8 -> 0 | C5: 0 | D5: =E5/8 -> 0 | E5: 0 | F5: =G5/8 -> 8.91625 | G5: 71.33 | H5: =I5/8 -> 0 | I5: 0 | J5: =K5/8 -> 0 | K5: 0 | L5: =M5/8 -> 0 | M5: 0 | N5: =O5/8 -> 0 | O5: 0 | P5: 1 | Q5: 8
A6: 45841 | B6: =C6/8 -> 0 | C6: 0 | D6: =E6/8 -> 0 | E6: 0 | F6: =G6/8 -> 9 | G6: 72 | H6: =I6/8 -> 0 | I6: 0 | J6: =K6/8 -> 0 | K6: 0 | L6: =M6/8 -> 0 | M6: 0 | N6: =O6/8 -> 0 | O6: 0 | P6: 1 | Q6: 8
A7: 45842 | B7: =C7/8 -> 0 | C7: 0 | D7: =E7/8 -> 0 | E7: 0 | F7: =G7/8 -> 7.5 | G7: 60 | H7: =I7/8 -> 0 | I7: 0 | J7: =K7/8 -> 0 | K7: 0 | L7: =M7/8 -> 0 | M7: 0 | N7: =O7/8 -> 0 | O7: 0 | P7: 1 | Q7: 8
A8: 45843 | B8: =C8/8 -> 0 | C8: 0 | D8: =E8/8 -> 0 | E8: 0 | F8: =G8/8 -> 0 | G8: 0 | H8: =I8/8 -> 0 | I8: 0 | J8: 0 | K8: 0 | L8: 0 | M8: 0 | N8: =O8/8 -> 0 | O8: 0 | P8: 0 | Q8: 0
A9: 45844 | B9: =C9/8 -> 0 | C9: 0 | D9: =E9/8 -> 0 | E9: 0 | F9: =G9/8 -> 0 | G9: 0 | H9: =I9/8 -> 0 | I9: 0 | J9: =K9/8 -> 0 | K9: 0 | L9: =M9/8 -> 0 | M9: 0 | N9: =O9/8 -> 0 | O9: 0 | P9: 0 | Q9: 0
A10: 45845 | B10: =C10/8 -> 9 | C10: 72 | D10: =E10/8 -> 0 | E10: 0 | F10: =G10/8 -> 0 | G10: 0 | H10: =I10/8 -> 0 | I10: 0 | J10: =K10/8 -> 0 | K10: 0 | L10: =M10/8 -> 0 | M10: 0 | N10: =O10/8 -> 0 | O10: 0 | P10: 1 | Q10: 9
A11: 45846 | B11: =C11/8 -> 9 | C11: 72 | D11: =E11/8 -> 0 | E11: 0 | F11: =G11/8 -> 0 | G11: 0 | H11: =I11/8 -> 0 | I11: 0 | J11: =K11/8 -> 0 | K11: 0 | L11: =M11/8 -> 0 | M11: 0 | N11: =O11/8 -> 0 | O11: 0 | P11: 1 | Q11: 9
A12: 45847 | B12: =C12/8 -> 9 | C12: 72 | D12: =E12/8 -> 0 | E12: 0 | F12: =G12/8 -> 0 | G12: 0 | H12: =I12/8 -> 0 | I12: 0 | J12: =K12/8 -> 0 | K12: 0 | L12: =M12/8 -> 0 | M12: 0 | N12: =O12/8 -> 0 | O12: 0 | P12: 1 | Q12: 9
A13: 45848 | B13: =C13/8 -> 9 | C13: 72 | D13: =E13/8 -> 0 | E13: 0 | F13: =G13/8 -> 0 | G13: 0 | H13: =I13/8 -> 0 | I13: 0 | J13: =K13/8 -> 0 | K13: 0 | L13: =M13/8 -> 0 | M13: 0 | N13: =O13/8 -> 0 | O13: 0 | P13: 1 | Q13: 9
A14: 45849 | B14: =C14/8 -> 8 | C14: 64 | D14: =E14/8 -> 0 | E14: 0 | F14: =G14/8 -> 0 | G14: 0 | H14: =I14/8 -> 0 | I14: 0 | J14: =K14/8 -> 0 | K14: 0 | L14: =M14/8 -> 0 | M14: 0 | N14: =O14/8 -> 0 | O14: 0 | P14: 1 | Q14: 8
A15: 45850 | B15: =C15/8 -> 0 | C15: 0 | D15: =E15/8 -> 0 | E15: 0 | F15: =G15/8 -> 0 | G15: 0 | H15: =I15/8 -> 0 | I15: 0 | J15: =K15/8 -> 0 | K15: 0 | L15: =M15/8 -> 0 | M15: 0 | N15: =O15/8 -> 0 | O15: 0 | P15: 0 | Q15: 0
A16: 45851 | B16: =C16/8 -> 0 | C16: 0 | D16: =E16/8 -> 0 | E16: 0 | F16: =G16/8 -> 0 | G16: 0 | H16: =I16/8 -> 0 | I16: 0 | J16: =K16/8 -> 0 | K16: 0 | L16: =M16/8 -> 0 | M16: 0 | N16: =O16/8 -> 0 | O16: 0 | P16: 0 | Q16: 0
A17: 45852 | B17: =C17/8 -> 0 | C17: 0 | D17: =E17/8 -> 0 | E17: 0 | F17: =G17/8 -> 0 | G17: 0 | H17: =I17/8 -> 0 | I17: 0 | J17: =K17/8 -> 0 | K17: 0 | L17: =M17/8 -> 0 | M17: 0 | N17: =O17/8 -> 0 | O17: 0 | P17: 0 | Q17: 0
A18: 45853 | B18: =C18/8 -> 7.875 | C18: 63 | D18: =E18/8 -> 0 | E18: 0 | F18: =G18/8 -> 0 | G18: 0 | H18: =I18/8 -> 0 | I18: 0 | J18: =K18/8 -> 0 | K18: 0 | L18: =M18/8 -> 0 | M18: 0 | N18: =O18/8 -> 0 | O18: 0 | P18: 1 | Q18: 9
A19: 45854 | B19: =C19/8 -> 7.875 | C19: 63 | D19: =E19/8 -> 0 | E19: 0 | F19: =G19/8 -> 0 | G19: 0 | H19: =I19/8 -> 0 | I19: 0 | J19: =K19/8 -> 0 | K19: 0 | L19: =M19/8 -> 0 | M19: 0 | N19: =O19/8 -> 0 | O19: 0 | P19: 1 | Q19: 9
A20: 45855 | B20: =C20/8 -> 7.71875 | C20: 61.75 | D20: =E20/8 -> 0 | E20: 0 | F20: =G20/8 -> 0 | G20: 0 | H20: =I20/8 -> 0 | I20: 0 | J20: =K20/8 -> 0 | K20: 0 | L20: =M20/8 -> 0 | M20: 0 | N20: =O20/8 -> 0 | O20: 0 | P20: 1 | Q20: 9
... A28: 45863 | B28: =C28/8 -> 2.25 | C28: 18 | D28: =E28/8 -> 3.75 | E28: 30 | F28: =G28/8 -> 0 | G28: 0 | H28: =I28/8 -> 0 | I28: 0 | J28: =K28/8 -> 0 | K28: 0 | L28: =M28/8 -> 0 | M28: 0 | N28: =O28/8 -> 0 | O28: 0 | P28: 1 | Q28: 8
A29: 45864 | B29: =C29/8 -> 0 | C29: 0 | D29: =E29/8 -> 0 | E29: 0 | F29: =G29/8 -> 0 | G29: 0 | H29: =I29/8 -> 0 | I29: 0 | J29: =K29/8 -> 0 | K29: 0 | L29: =M29/8 -> 0 | M29: 0 | N29: =O29/8 -> 0 | O29: =+C29+I29+E29+G29+K29+M29 -> 0 | P29: 0 | Q29: 0
A30: 45865 | B30: =C30/8 -> 0 | C30: 0 | D30: =E30/8 -> 0 | E30: 0 | F30: =G30/8 -> 0 | G30: 0 | H30: =I30/8 -> 0 | I30: 0 | J30: =K30/8 -> 0 | K30: 0 | L30: =M30/8 -> 0 | M30: 0 | N30: =O30/8 -> 0 | O30: =+C30+I30+E30+G30+K30+M30 -> 0 | P30: 0 | Q30: 0
A31: 45866 | B31: =C31/8 -> 2.25 | C31: 18 | D31: =E31/8 -> 4.5 | E31: 36 | F31: =G31/8 -> 0 | G31: 0 | H31: =I31/8 -> 0 | I31: 0 | J31: =K31/8 -> 0 | K31: 0 | L31: =M31/8 -> 0 | M31: 0 | N31: =O31/8 -> 6.75 | O31: =+C31+I31+E31+G31+K31+M31 -> 54 | P31: 1 | Q31: 9
A32: 45867 | B32: =C32/8 -> 2.25 | C32: 18 | D32: =E32/8 -> 4.5 | E32: 36 | F32: =G32/8 -> 0 | G32: 0 | H32: =I32/8 -> 0 | I32: 0 | J32: =K32/8 -> 0 | K32: 0 | L32: =M32/8 -> 0 | M32: 0 | N32: =O32/8 -> 6.75 | O32: =+C32+I32+E32+G32+K32+M32 -> 54 | P32: 1 | Q32: 9
A33: 45868 | B33: =C33/8 -> 2.02 | C33: 16.16 | D33: =E33/8 -> 3.75 | E33: 30 | F33: =G33/8 -> 0 | G33: 0 | H33: =I33/8 -> 0 | I33: 0 | J33: =K33/8 -> 0 | K33: 0 | L33: =M33/8 -> 0 | M33: 0 | N33: =O33/8 -> 5.77 | O33: =+C33+I33+E33+G33+K33+M33 -> 46.16 | P33: 1 | Q33: 9
A34: 45869 | B34: =C34/8 -> 1.875 | C34: 15 | D34: =E34/8 -> 3.75 | E34: 30 | F34: =G34/8 -> 0 | G34: 0 | H34: =I34/8 -> 0 | I34: 0 | J34: =K34/8 -> 0 | K34: 0 | L34: =M34/8 -> 0 | M34: 0 | N34: =O34/8 -> 5.625 | O34: =+C34+I34+E34+G34+K34+M34 -> 45 | P34: 1 | Q34: 9
A35: Total | B35: =IFERROR(AVERAGE(B4:B34),0) -> 3.07625 | C35: =SUM(C4:C34) -> 762.91 | D35: =IFERROR(AVERAGE(D4:D34),0) -> 1.3064516 | E35: =SUM(E4:E34) -> 324 | F35: =IFERROR(AVERAGE(F4:F34),0) -> 1.1263306 | G35: =SUM(G4:G34) -> 279.33 | H35: =AVERAGE(H4:H33) -> 0 | I35: =SUM(I4:I34) -> 0 | J35: =AVERAGE(J4:J33) -> 0 | K35: =SUM(K4:K34) -> 0 | L35: =AVERAGE(L4:L33) -> 0 | M35: =SUM(M4:M33) -> 0 | N35: =IFERROR(AVERAGE(N4:N33),0) -> 0.64233333 | O35: =+C35+I35+E35+G35+K35+M35 -> 1366.24 | P35: =IFERROR(AVERAGE(P4:P34),0) -> 0.70967742 | Q35: =SUM(Q4:Q34) -> 191 | R35: =IFERROR(AVERAGE(R4:R33),0) -> 0 | S35: =SUM(S4:S33) -> 0

Sheet Aout
A1: 2025
B2: BO | D2: AE | F2: Formation initiale BO | H2: Formation continue BO | J2: Formation initiale FO | L2: Formation continue FO | N2: Total CC | P2: Manager | R2: Relation Clients
B3: ETP | C3: Heures | D3: ETP | E3: Heures | F3: ETP | G3: Heures | H3: ETP | I3: Heures | J3: ETP | K3: Heures | L3: ETP | M3: Heures
A4: 45870 | B4: =C4/8 -> 1.25 | C4: 10 | D4: =E4/8 -> 4.125 | E4: 33 | F4: =G4/8 -> 0 | G4: 0 | H4: =I4/8 -> 0 | I4: 0 | J4: =K4/8 -> 0 | K4: 0 | L4: =M4/8 -> 0 | M4: 0 | P4: 1 | Q4: 8
A5: 45871 | B5: =C5/8 -> 0 | C5: 0 | D5: =E5/8 -> 0 | E5: 0 | F5: =G5/8 -> 0 | H5: =I5/8 -> 0 | J5: =K5/8 -> 0 | L5: =M5/8 -> 0
A6: 45872 | B6: =C6/8 -> 0 | C6: 0 | D6: =E6/8 -> 0 | E6: 0 | F6: =G6/8 -> 0 | H6: =I6/8 -> 0 | J6: =K6/8 -> 0 | L6: =M6/8 -> 0
A7: 45873 | B7: =C7/8 -> 1.875 | C7: 15 | D7: =E7/8 -> 3.75 | E7: 30 | F7: =G7/8 -> 0 | G7: 0 | H7: =I7/8 -> 0 | I7: 0 | J7: =K7/8 -> 0 | K7: 0 | L7: =M7/8 -> 0 | M7: 0 | P7: 1 | Q7: 9
A8: 45874 | B8: =C8/8 -> 1.625 | C8: 13 | D8: =E8/8 -> 3.375 | E8: 27 | F8: =G8/8 -> 0 | G8: 0 | H8: =I8/8 -> 0 | I8: 0 | J8: 0 | K8: 0 | L8: 0 | M8: 5 | P8: 1 | Q8: 9
A9: 45875 | B9: =C9/8 -> 2.5 | C9: 20 | D9: =E9/8 -> 3.125 | E9: 25 | F9: =G9/8 -> 0 | G9: 0 | H9: =I9/8 -> 0 | I9: 0 | J9: =K9/8 -> 0 | K9: 0 | L9: =M9/8 -> 0 | M9: 0 | P9: 1 | Q9: 9
A10: 45876 | B10: =C10/8 -> 2 | C10: 16 | D10: =E10/8 -> 3.75 | E10: 30 | F10: =G10/8 -> 0 | G10: 0 | H10: =I10/8 -> 0 | I10: 0 | J10: =K10/8 -> 0 | K10: 0 | L10: =M10/8 -> 0 | M10: 0 | P10: 1 | Q10: 9
A11: 45877 | B11: =C11/8 -> 1.625 | C11: 13 | D11: =E11/8 -> 3.375 | E11: 27 | F11: =G11/8 -> 0 | G11: 0 | H11: =I11/8 -> 0 | I11: 0 | J11: =K11/8 -> 0 | K11: 0 | L11: =M11/8 -> 0 | M11: 0 | P11: 1 | Q11: 8
A12: 45878 | B12: =C12/8 -> 0 | C12: 0 | D12: =E12/8 -> 0 | E12: 0 | F12: =G12/8 -> 0 | G12: 0 | H12: =I12/8 -> 0 | I12: 0 | J12: =K12/8 -> 0 | K12: 0 | L12: =M12/8 -> 0 | M12: 0 | Q12: 0
A13: 45879 | B13: =C13/8 -> 0 | C13: 0 | D13: =E13/8 -> 0 | E13: 0 | F13: =G13/8 -> 0 | G13: 0 | H13: =I13/8 -> 0 | I13: 0 | J13: =K13/8 -> 0 | K13: 0 | L13: =M13/8 -> 0 | M13: 0 | Q13: 0
A14: 45880 | B14: =C14/8 -> 1.875 | C14: 15 | D14: =E14/8 -> 3.75 | E14: 30 | F14: =G14/8 -> 0 | G14: 0 | H14: =I14/8 -> 0 | I14: 0 | J14: =K14/8 -> 0 | K14: 0 | L14: =M14/8 -> 0 | M14: 0 | P14: 1 | Q14: 9
A15: 45881 | B15: =C15/8 -> 1.875 | C15: 15 | D15: =E15/8 -> 3.75 | E15: 30 | F15: =G15/8 -> 0 | G15: 0 | H15: =I15/8 -> 0 | I15: 0 | J15: =K15/8 -> 0 | K15: 0 | L15: =M15/8 -> 0 | M15: 0 | P15: 1 | Q15: 9
A16: 45882 | B16: =C16/8 -> 1.25 | C16: 10 | D16: =E16/8 -> 4.375 | E16: 35 | F16: =G16/8 -> 0 | G16: 0 | H16: =I16/8 -> 0 | I16: 0 | J16: =K16/8 -> 0 | K16: 0 | L16: =M16/8 -> 0 | M16: 0 | P16: 1 | Q16: 9
A17: 45883 | B17: =C17/8 -> 1.25 | C17: 10 | D17: =E17/8 -> 3.75 | E17: 30 | F17: =G17/8 -> 0 | G17: 0 | H17: =I17/8 -> 0 | I17: 0 | J17: =K17/8 -> 0 | K17: 0 | L17: =M17/8 -> 0.625 | M17: 5 | P17: 1 | Q17: 9
A18: 45884 | B18: =C18/8 -> 0 | C18: 0 | D18: =E18/8 -> 0 | E18: 0 | F18: =G18/8 -> 0 | G18: 0 | H18: =I18/8 -> 0 | I18: 0 | J18: =K18/8 -> 0 | K18: 0 | L18: =M18/8 -> 0 | M18: 0 | Q18: 0
A19: 45885 | B19: =C19/8 -> 0 | C19: 0 | D19: =E19/8 -> 0 | E19: 0 | F19: =G19/8 -> 0 | G19: 0 | H19: =I19/8 -> 0 | I19: 0 | J19: =K19/8 -> 0 | K19: 0 | L19: =M19/8 -> 0 | M19: 0 | Q19: 0
A20: 45886 | B20: =C20/8 -> 0 | C20: 0 | D20: =E20/8 -> 0 | E20: 0 | F20: =G20/8 -> 0 | G20: 0 | H20: =I20/8 -> 0 | I20: 0 | J20: =K20/8 -> 0 | K20: 0 | L20: =M20/8 -> 0 | M20: 0 | Q20: 0
A21: 45887 | B21: =C21/8 -> 6.5 | C21: 52 | D21: =E21/8 -> 3.25 | E21: 26 | F21: =G21/8 -> 7 | G21: 56 | H21: =I21/8 -> 0.375 | I21: 3 | J21: =K21/8 -> 0 | K21: =L21/8 -> 0 | L21: =M21/8 -> 0 | M21: 0 | P21: 1 | Q21: 9
A22: 45888 | B22: =C22/8 -> 6.5 | C22: 52 | D22: =E22/8 -> 3.25 | E22: 26 | F22: =G22/8 -> 7 | G22: 56 | H22: =I22/8 -> 0.375 | I22: 3 | J22: =K22/8 -> 0 | K22: =L22/8 -> 0 | L22: =M22/8 -> 0 | M22: 0 | P22: 1 | Q22: 9
A23: 45889 | B23: =C23/8 -> 6.5 | C23: 52 | D23: =E23/8 -> 3.25 | E23: 26 | F23: =G23/8 -> 7 | G23: 56 | H23: =I23/8 -> 0.375 | I23: 3 | J23: =K23/8 -> 0 | K23: =L23/8 -> 0 | L23: =M23/8 -> 0 | M23: 0 | P23: 1 | Q23: 9
A24: 45890 | B24: =C24/8 -> 6.5 | C24: 52 | D24: =E24/8 -> 3.25 | E24: 26 | F24: =G24/8 -> 7 | G24: 56 | H24: =I24/8 -> 0.375 | I24: 3 | J24: =K24/8 -> 0 | K24: =L24/8 -> 0 | L24: =M24/8 -> 0 | M24: 0 | P24: 1 | Q24: 9
A25: 45891 | B25: =C25/8 -> 7 | C25: 56 | D25: =E25/8 -> 1.625 | E25: 13 | F25: =G25/8 -> 7 | G25: 56 | H25: =I25/8 -> 0.375 | I25: 3 | J25: =K25/8 -> 0 | K25: =L25/8 -> 0 | L25: =M25/8 -> 0 | M25: 0 | P25: 1 | Q25: 8
A26: 45892 | B26: =C26/8 -> 0 | C26: 0 | D26: =E26/8 -> 0 | E26: 0 | F26: =G26/8 -> 0 | G26: 0 | H26: =I26/8 -> 0 | I26: 0 | J26: =K26/8 -> 0 | K26: 0 | L26: =M26/8 -> 0 | M26: 0 | Q26: 0
A27: 45893 | B27: =C27/8 -> 0 | C27: 0 | D27: =E27/8 -> 0 | E27: 0 | F27: =G27/8 -> 0 | G27: 0 | H27: =I27/8 -> 0 | I27: 0 | J27: =K27/8 -> 0 | K27: 0 | L27: =M27/8 -> 0 | M27: 0 | Q27: 0
A28: 45894 | B28: =C28/8 -> 4.4375 | C28: 35.5 | D28: =E28/8 -> 5.25 | E28: 42 | F28: =G28/8 -> 4.5 | G28: 36 | H28: =I28/8 -> 0.5 | I28: 4 | J28: =K28/8 -> 1.25 | K28: 10 | L28: =M28/8 -> 0 | M28: 0 | P28: 1 | Q28: 9
A29: 45895 | B29: =C29/8 -> 4.5 | C29: 36 | D29: =E29/8 -> 4.125 | E29: 33 | F29: =G29/8 -> 2 | G29: 16 | H29: =I29/8 -> 0.5 | I29: 4 | J29: =K29/8 -> 0 | K29: 0 | L29: =M29/8 -> 1.125 | M29: 9 | P29: 1 | Q29: 9
A30: 45896 | B30: =C30/8 -> 4.375 | C30: 35 | D30: =E30/8 -> 5.25 | E30: 42 | F30: =G30/8 -> 4 | G30: 32 | H30: =I30/8 -> 0.5 | I30: 4 | J30: =K30/8 -> 0 | K30: =L30/8 -> 0 | L30: =M30/8 -> 0 | M30: 0 | P30: 1 | Q30: 9
A31: 45897 | B31: =C31/8 -> 4.375 | C31: 35 | D31: =E31/8 -> 5.25 | E31: 42 | F31: =G31/8 -> 4 | G31: 32 | H31: =I31/8 -> 0.5 | I31: 4 | J31: =K31/8 -> 1 | K31: 8 | L31: =M31/8 -> 0 | M31: 0 | P31: 1 | Q31: 9
A32: 45898 | B32: =C32/8 -> 3.5 | C32: 28 | D32: =E32/8 -> 5 | E32: 40 | F32: =G32/8 -> 4 | G32: 32 | H32: =I32/8 -> 0.5 | I32: 4 | J32: =K32/8 -> 1 | K32: 8 | L32: =M32/8 -> 0 | M32: 0 | P32: 1 | Q32: 8
A33: 45899 | B33: =C33/8 -> 0 | C33: 0 | D33: =E33/8 -> 0 | E33: 0 | F33: =G33/8 -> 0 | G33: 0 | H33: =I33/8 -> 0 | I33: 0 | J33: =K33/8 -> 0 | K33: 0 | L33: =M33/8 -> 0 | M33: =N33/8 -> 0 | Q33: 0
A34: 45900 | B34: =C34/8 -> 0 | C34: 0 | D34: =E34/8 -> 0 | E34: 0 | F34: =G34/8 -> 0 | G34: 0 | H34: =I34/8 -> 0 | I34: 0 | J34: =K34/8 -> 0 | K34: 0 | L34: =M34/8 -> 0 | M34: =N34/8 -> 0 | Q34: 0
A35: Total | B35: =IFERROR(AVERAGE(B4:B34),0) -> 2.3004032 | C35: =SUM(C4:C34) -> 570.5 | D35: =IFERROR(AVERAGE(D4:D34),0) -> 2.4717742 | E35: =SUM(E4:E34) -> 613 | F35: =IFERROR(AVERAGE(F4:F34),0) -> 1.7258065 | G35: =SUM(G4:G34) -> 428 | H35: =IFERROR(AVERAGE(H4:H34),0) -> 0.14112903 | I35: =SUM(I4:I34) -> 35 | J35: =IFERROR(AVERAGE(J4:J34),0) -> 0.10483871 | K35: =SUM(K4:K34) -> 26 | L35: =IFERROR(AVERAGE(L4:L34),0) -> 0.056451613 | M35: =SUM(M4:M34) -> 19 | N35: =IFERROR(AVERAGE(N4:N33),0) -> 0 | O35: =C35+I35+E35+G35+K35+M35 -> 1691.5 | P35: =IFERROR(AVERAGE(P4:P34),0) -> 1 | Q35: =SUM(Q4:Q34) -> 176 | R35: =IFERROR(AVERAGE(R4:R33),0) -> 0 | S35: =SUM(S4:S33) -> 0

Sheet Septembre
A1: 2025
B2: BO | D2: AE | F2: Formation initiale BO | H2: Formation continue BO | J2: Formation initiale FO | L2: Formation continue FO | N2: Total CC | P2: Manager | R2: Relation Clients
B3: ETP | C3: Heures | D3: ETP | E3: Heures | F3: ETP | G3: Heures | H3: ETP | I3: Heures | J3: ETP | K3: Heures | L3: ETP | M3: Heures
A4: 45901 | B4: =C4/8 -> 9.4875 | C4: 75.9 | D4: =E4/8 -> 6.325 | E4: 50.6 | F4: =G4/8 -> 0 | G4: 0 | H4: =I4/8 -> 0 | I4: 0 | J4: 0 | K4: 0 | L4: 0 | M4: 0 | P4: 1 | Q4: 9
A5: 45902 | B5: =C5/8 -> 8.6125 | C5: 68.9 | D5: =E5/8 -> 6.325 | E5: 50.6 | F5: =G5/8 -> 0 | G5: 0 | H5: =I5/8 -> 0.875 | I5: 7 | J5: =K5/8 -> 0 | K5: 0 | L5: =M5/8 -> 0 | M5: 0 | P5: 1 | Q5: 9
A6: 45903 | B6: =C6/8 -> 9.45 | C6: 75.6 | D6: =E6/8 -> 6.3 | E6: 50.4 | F6: =G6/8 -> 0 | G6: 0 | H6: =I6/8 -> 0 | I6: 0 | J6: =K6/8 -> 0 | K6: 0 | L6: =M6/8 -> 0 | M6: 0 | P6: 1 | Q6: 9
A7: 45904 | B7: =C7/8 -> 9.5625 | C7: 76.5 | D7: =E7/8 -> 6.375 | E7: 51 | F7: =G7/8 -> 0 | G7: 0 | H7: =I7/8 -> 0 | I7: 0 | J7: =K7/8 -> 0 | K7: 0 | L7: =M7/8 -> 0 | M7: 0 | P7: 1 | Q7: 9
A8: 45905 | B8: =C8/8 -> 7.9125 | C8: 63.3 | D8: =E8/8 -> 5.275 | E8: 42.2 | F8: =G8/8 -> 0 | G8: 0 | H8: =I8/8 -> 0 | I8: 0 | J8: =K8/8 -> 0 | K8: 0 | L8: =M8/8 -> 0 | M8: 0 | P8: 1 | Q8: 8
A9: 45906 | B9: =C9/8 -> 0 | C9: 0 | D9: =E9/8 -> 0 | E9: 0 | F9: =G9/8 -> 0 | G9: 0 | H9: =I9/8 -> 0 | I9: 0 | J9: =K9/8 -> 0 | K9: 0 | L9: =M9/8 -> 0 | M9: 0
A10: 45907 | B10: =C10/8 -> 0 | D10: =E10/8 -> 0 | F10: =G10/8 -> 0 | H10: =I10/8 -> 0 | J10: =K10/8 -> 0 | L10: =M10/8 -> 0
A11: 45908 | B11: =C11/8 -> 7.1875 | C11: 57.5 | D11: =E11/8 -> 5.875 | E11: 47 | F11: =G11/8 -> 0 | G11: 0 | H11: =I11/8 -> 1.625 | I11: 13 | J11: =K11/8 -> 0 | K11: 0 | L11: =M11/8 -> 0 | M11: 0 | P11: 1 | Q11: 9
A12: 45909 | B12: =C12/8 -> 8.60025 | C12: 68.802 | D12: =E12/8 -> 5.7335 | E12: 45.868 | F12: =G12/8 -> 0 | G12: 0 | H12: =I12/8 -> 0 | I12: 0 | J12: =K12/8 -> 0 | K12: 0 | L12: =M12/8 -> 0 | M12: 0 | P12: 1 | Q12: 9
A13: 45910 | B13: =C13/8 -> 8.1 | C13: 64.8 | D13: =E13/8 -> 5.4 | E13: 43.2 | F13: =G13/8 -> 0 | G13: 0 | H13: =I13/8 -> 0 | I13: 0 | J13: =K13/8 -> 0 | K13: 0 | L13: =M13/8 -> 0 | M13: 0 | P13: 1 | Q13: 9
A14: 45911 | B14: =C14/8 -> 8.175 | C14: 65.4 | D14: =E14/8 -> 5.45 | E14: 43.6 | F14: =G14/8 -> 0 | G14: 0 | H14: =I14/8 -> 0 | I14: 0 | J14: =K14/8 -> 0 | K14: 0 | L14: =M14/8 -> 0 | M14: 0 | P14: 1 | Q14: 9
A15: 45912 | B15: =C15/8 -> 7.2 | C15: 57.6 | D15: =E15/8 -> 4.8 | E15: 38.4 | F15: =G15/8 -> 0 | G15: 0 | H15: =I15/8 -> 0 | I15: 0 | J15: =K15/8 -> 0 | K15: 0 | L15: =M15/8 -> 0 | M15: 0 | P15: 1 | Q15: 8
A16: 45913 | B16: =C16/8 -> 0 | C16: 0 | D16: =E16/8 -> 0 | E16: 0 | F16: =G16/8 -> 0 | G16: 0 | H16: =I16/8 -> 0 | I16: 0 | J16: =K16/8 -> 0 | K16: 0 | L16: =M16/8 -> 0 | M16: 0
A17: 45914 | B17: =C17/8 -> 0 | D17: =E17/8 -> 0 | F17: =G17/8 -> 0 | H17: =I17/8 -> 0 | J17: =K17/8 -> 0 | L17: =M17/8 -> 0
A18: 45915 | B18: =C18/8 -> 7.5375 | C18: 60.3 | D18: =E18/8 -> 5.025 | E18: 40.2 | F18: =G18/8 -> 0 | G18: 0 | H18: =I18/8 -> 0 | I18: 0 | J18: =K18/8 -> 0 | K18: 0 | L18: =M18/8 -> 0 | M18: 0 | P18: 1 | Q18: 9
A19: 45916 | B19: =C19/8 -> 8.0625 | C19: 64.5 | D19: =E19/8 -> 5.375 | E19: 43 | F19: =G19/8 -> 0 | G19: 0 | H19: =I19/8 -> 0 | I19: 0 | J19: =K19/8 -> 0 | K19: 0 | L19: =M19/8 -> 0 | M19: 0 | P19: 1 | Q19: 9
A20: 45917 | B20: =C20/8 -> 7.5 | C20: 60 | D20: =E20/8 -> 5 | E20: 40 | F20: =G20/8 -> 0 | G20: 0 | H20: =I20/8 -> 0 | I20: 0 | J20: =K20/8 -> 0 | K20: 0 | L20: =M20/8 -> 0 | M20: 0 | P20: 1 | Q20: 9
A21: 45918 | B21: =C21/8 -> 8.1 | C21: 64.8 | D21: =E21/8 -> 5.4 | E21: 43.2 | F21: =G21/8 -> 0 | G21: 0 | H21: =I21/8 -> 0 | I21: 0 | J21: =K21/8 -> 0 | K21: 0 | L21: =M21/8 -> 0 | M21: 0 | P21: 1 | Q21: 9
A22: 45919 | B22: =C22/8 -> 7.275 | C22: 58.2 | D22: =E22/8 -> 4.85 | E22: 38.8 | F22: =G22/8 -> 0 | G22: 0 | H22: =I22/8 -> 0 | I22: 0 | J22: =K22/8 -> 0 | K22: 0 | L22: =M22/8 -> 0 | M22: 0 | P22: 1 | Q22: 8
A23: 45920 | B23: =C23/8 -> 0 | C23: 0 | D23: =E23/8 -> 0 | E23: 0 | F23: =G23/8 -> 0 | G23: 0 | H23: =I23/8 -> 0 | I23: 0 | J23: =K23/8 -> 0 | K23: 0 | L23: =M23/8 -> 0 | M23: 0
A24: 45921 | B24: =C24/8 -> 0 | D24: =E24/8 -> 0 | F24: =G24/8 -> 0 | H24: =I24/8 -> 0 | J24: =K24/8 -> 0 | L24: =M24/8 -> 0
A25: 45922 | B25: =C25/8 -> 8.1 | C25: 64.8 | D25: =E25/8 -> 5.4 | E25: 43.2 | F25: =G25/8 -> 0 | G25: 0 | H25: =I25/8 -> 0 | I25: 0 | J25: =K25/8 -> 0 | K25: 0 | L25: =M25/8 -> 0 | M25: 0 | P25: 1 | Q25: 9
A26: 45923 | B26: =C26/8 -> 7.425 | C26: 59.4 | D26: =E26/8 -> 4.95 | E26: 39.6 | F26: =G26/8 -> 0 | G26: 0 | H26: =I26/8 -> 0 | I26: 0 | J26: =K26/8 -> 0 | K26: 0 | L26: =M26/8 -> 0 | M26: 0 | P26: 1 | Q26: 9
A27: 45924 | B27: =C27/8 -> 8.1 | C27: 64.8 | D27: =E27/8 -> 5.4 | E27: 43.2 | F27: =G27/8 -> 0 | G27: 0 | H27: =I27/8 -> 0 | I27: 0 | J27: =K27/8 -> 0 | K27: 0 | L27: =M27/8 -> 0 | M27: 0 | P27: 1 | Q27: 9
A28: 45925 | B28: =C28/8 -> 8.1 | C28: 64.8 | D28: =E28/8 -> 5.4 | E28: 43.2 | F28: =G28/8 -> 0 | G28: 0 | H28: =I28/8 -> 0 | I28: 0 | J28: =K28/8 -> 0 | K28: 0 | L28: =M28/8 -> 0 | M28: 0 | P28: 1 | Q28: 9
A29: 45926 | B29: =C29/8 -> 7.275 | C29: 58.2 | D29: =E29/8 -> 4.85 | E29: 38.8 | F29: =G29/8 -> 0 | G29: 0 | H29: =I29/8 -> 0 | I29: 0 | J29: =K29/8 -> 0 | K29: 0 | L29: =M29/8 -> 0 | M29: 0 | P29: 1 | Q29: 8
A30: 45927 | B30: =C30/8 -> 0 | C30: 0 | D30: =E30/8 -> 0 | E30: 0 | F30: =G30/8 -> 0 | G30: 0 | H30: =I30/8 -> 0 | I30: 0 | J30: =K30/8 -> 0 | K30: 0 | L30: =M30/8 -> 0 | M30: 0
A31: 45928 | B31: =C31/8 -> 0 | D31: =E31/8 -> 0 | F31: =G31/8 -> 0 | H31: =I31/8 -> 0 | J31: =K31/8 -> 0 | L31: =M31/8 -> 0
A32: 45929 | B32: =C32/8 -> 8.73 | C32: 69.84 | D32: =E32/8 -> 5.82 | E32: 46.56 | F32: =G32/8 -> 0 | G32: 0 | H32: =I32/8 -> 0 | I32: 0 | J32: =K32/8 -> 0 | K32: 0 | L32: =M32/8 -> 0 | M32: 0 | P32: 1 | Q32: 9
A33: 45930 | B33: =C33/8 -> 8 | C33: 64 | D33: =E33/8 -> 5.875 | E33: 47 | F33: =G33/8 -> 0 | G33: 0 | H33: =I33/8 -> 0.8125 | I33: 6.5 | J33: =K33/8 -> 0 | K33: 0 | L33: =M33/8 -> 0 | M33: 0 | P33: 1 | Q33: 9
A34: Total | B34: =IFERROR(AVERAGE(B4:B33),0) -> 5.9497583 | C34: =SUM(C4:C33) -> 1427.942 | D34: =AVERAGE(D4:D33) -> 4.0401167 | E34: =SUM(E4:E33) -> 969.628 | F34: =AVERAGE(F4:F33) -> 0 | G34: =SUM(G4:G33) -> 0 | H34: =AVERAGE(H4:H33) -> 0.11041667 | I34: =SUM(I4:I33) -> 26.5 | J34: =AVERAGE(J4:J33) -> 0 | K34: =SUM(K4:K33) -> 0 | L34: =AVERAGE(L4:L33) -> 0 | M34: =SUM(M4:M33) -> 0 | N34: =IFERROR(AVERAGE(N4:N33),0) -> 0 | O34: =C34+I34+E34+G34+K34+M34 -> 2424.07 | P34: =IFERROR(AVERAGE(P4:P33),0) -> 1 | Q34: =SUM(Q4:Q33) -> 194 | R34: =IFERROR(AVERAGE(R4:R33),0) -> 0 | S34: =SUM(S4:S33) -> 0

Sheet Octobre
A1: 2025
B2: BO | D2: AE | F2: Formation initiale BO | H2: Formation continue BO | J2: Formation initiale FO | L2: Formation continue FO | N2: Total CC | P2: Manager | R2: Relation Clients
B3: ETP | C3: Heures | D3: ETP | E3: Heures | F3: ETP | G3: Heures | H3: ETP | I3: Heures | J3: ETP | K3: Heures | L3: ETP | M3: Heures
A4: 45931 | B4: =C4/8 -> 6.15 | C4: 49.2 | D4: =E4/8 -> 6.15 | E4: 49.2 | F4: =G4/8 -> 0 | G4: 0 | H4: =I4/8 -> 0 | I4: 0 | J4: =K4/8 -> 0 | K4: 0 | L4: =M4/8 -> 0 | M4: 0 | P4: 1 | Q4: 9
A5: 45932 | B5: =C5/8 -> 8.625 | C5: 69 | D5: =E5/8 -> 3.75 | E5: 30 | F5: =G5/8 -> 0 | G5: 0 | H5: =I5/8 -> 0 | I5: 0 | J5: =K5/8 -> 0 | K5: 0 | L5: =M5/8 -> 0 | M5: 0 | P5: 1 | Q5: 9
A6: 45933 | B6: =C6/8 -> 7.8 | C6: 62.4 | D6: =E6/8 -> 5.2 | E6: 41.6 | F6: =G6/8 -> 0 | G6: 0 | H6: =I6/8 -> 0 | I6: 0 | J6: =K6/8 -> 0 | K6: 0 | L6: =M6/8 -> 0 | M6: 0 | P6: 1 | Q6: 8
A7: 45934 | B7: =C7/8 -> 0 | D7: =E7/8 -> 0 | F7: =G7/8 -> 0 | H7: =I7/8 -> 0 | J7: =K7/8 -> 0 | L7: =M7/8 -> 0
A8: 45935 | B8: =C8/8 -> 0 | D8: =E8/8 -> 0 | F8: =G8/8 -> 0 | H8: =I8/8 -> 0 | J8: =K8/8 -> 0 | L8: =M8/8 -> 0
A9: 45936 | B9: =C9/8 -> 6.1875 | C9: 49.5 | D9: =E9/8 -> 6.1875 | E9: 49.5 | F9: =G9/8 -> 0 | G9: 0 | H9: =I9/8 -> 0 | I9: 0 | J9: =K9/8 -> 0 | K9: 0 | L9: =M9/8 -> 0 | M9: 0 | P9: 1 | Q9: 9
A10: 45937 | B10: =C10/8 -> 8.1 | C10: 64.8 | D10: =E10/8 -> 5.4 | E10: 43.2 | F10: =G10/8 -> 0 | G10: 0 | H10: =I10/8 -> 0 | I10: 0 | J10: =K10/8 -> 0 | K10: 0 | L10: =M10/8 -> 0 | M10: 0 | P10: 1 | Q10: 9
A11: 45938 | B11: =C11/8 -> 7.3125 | C11: 58.5 | D11: =E11/8 -> 7.3125 | E11: 58.5 | F11: =G11/8 -> 0 | G11: 0 | H11: =I11/8 -> 0 | I11: 0 | J11: =K11/8 -> 0 | K11: 0 | L11: =M11/8 -> 0 | M11: 0 | P11: 1 | Q11: 9
A12: 45939 | B12: =C12/8 -> 7.25 | C12: 58 | D12: =E12/8 -> 7.2875 | E12: 58.3 | F12: =G12/8 -> 0 | G12: 0 | H12: =I12/8 -> 0 | I12: 0 | J12: =K12/8 -> 0 | K12: 0 | L12: =M12/8 -> 0 | M12: 0 | P12: 1 | Q12: 9
A13: 45940 | B13: =C13/8 -> 6.5 | C13: 52 | D13: =E13/8 -> 6.5 | E13: 52 | F13: =G13/8 -> 0 | G13: 0 | H13: =I13/8 -> 0 | I13: 0 | J13: =K13/8 -> 0 | K13: 0 | L13: =M13/8 -> 0 | M13: 0 | P13: 1 | Q13: 8
A14: 45941 | B14: =C14/8 -> 0 | D14: =E14/8 -> 0 | F14: =G14/8 -> 0 | H14: =I14/8 -> 0 | J14: =K14/8 -> 0 | L14: =M14/8 -> 0
A15: 45942 | B15: =C15/8 -> 0 | D15: =E15/8 -> 0 | F15: =G15/8 -> 0 | H15: =I15/8 -> 0 | J15: =K15/8 -> 0 | L15: =M15/8 -> 0
A16: 45943 | B16: =C16/8 -> 6.75 | C16: 54 | D16: =E16/8 -> 4.5 | E16: 36 | F16: =G16/8 -> 0 | G16: 0 | H16: =I16/8 -> 0 | I16: 0 | J16: =K16/8 -> 0 | K16: 0 | L16: =M16/8 -> 0 | M16: 0 | P16: 1 | Q16: 9
A17: 45944 | B17: =C17/8 -> 6.9 | C17: 55.2 | D17: =E17/8 -> 4.6 | E17: 36.8 | F17: =G17/8 -> 0 | G17: 0 | H17: =I17/8 -> 0 | I17: 0 | J17: =K17/8 -> 0 | K17: 0 | L17: =M17/8 -> 0 | M17: 0 | P17: 1 | Q17: 9
A18: 45945 | B18: =C18/8 -> 6.75 | C18: 54 | D18: =E18/8 -> 4.5 | E18: 36 | F18: =G18/8 -> 0 | G18: 0 | H18: =I18/8 -> 0 | I18: 0 | J18: =K18/8 -> 0 | K18: 0 | L18: =M18/8 -> 0 | M18: 0 | P18: 1 | Q18: 9
A19: 45946 | B19: =C19/8 -> 7.425 | C19: 59.4 | D19: =E19/8 -> 4.95 | E19: 39.6 | F19: =G19/8 -> 0 | G19: 0 | H19: =I19/8 -> 0 | I19: 0 | J19: =K19/8 -> 0 | K19: 0 | L19: =M19/8 -> 0 | M19: 0 | P19: 1 | Q19: 9
A20: 45947 | B20: =C20/8 -> 6.6 | C20: 52.8 | D20: =E20/8 -> 4.4 | E20: 35.2 | F20: =G20/8 -> 0 | G20: 0 | H20: =I20/8 -> 0 | I20: 0 | J20: =K20/8 -> 0 | K20: 0 | L20: =M20/8 -> 0 | M20: 0 | P20: 1 | Q20: 8
A21: 45948 | B21: =C21/8 -> 0 | D21: =E21/8 -> 0 | F21: =G21/8 -> 0 | H21: =I21/8 -> 0 | J21: =K21/8 -> 0 | L21: =M21/8 -> 0
A22: 45949 | B22: =C22/8 -> 0 | D22: =E22/8 -> 0 | F22: =G22/8 -> 0 | H22: =I22/8 -> 0 | J22: =K22/8 -> 0 | L22: =M22/8 -> 0
A23: 45950 | B23: =C23/8 -> 7.30125 | C23: 58.41 | D23: =E23/8 -> 7.30125 | E23: 58.41 | F23: =G23/8 -> 0 | G23: 0 | H23: =I23/8 -> 0 | I23: 0 | J23: =K23/8 -> 0 | K23: 0 | L23: =M23/8 -> 0 | M23: 0 | P23: 1 | Q23: 9
A24: 45951 | B24: =C24/8 -> 8.7 | C24: 69.6 | D24: =E24/8 -> 5.8 | E24: 46.4 | F24: =G24/8 -> 0 | G24: 0 | H24: =I24/8 -> 0 | I24: 0 | J24: =K24/8 -> 0 | K24: 0 | L24: =M24/8 -> 0 | M24: 0 | P24: 1 | Q24: 9
A25: 45952 | B25: =C25/8 -> 8.2875 | C25: 66.3 | D25: =E25/8 -> 4.4625 | E25: 35.7 | F25: =G25/8 -> 0 | G25: 0 | H25: =I25/8 -> 0.75 | I25: 6 | J25: =K25/8 -> 0 | K25: 0 | L25: =M25/8 -> 0 | M25: 0 | P25: 1 | Q25: 9
A26: 45953 | B26: =C26/8 -> 4.05 | C26: 32.4 | D26: =E26/8 -> 9.45 | E26: 75.6 | F26: =G26/8 -> 0 | G26: 0 | H26: =I26/8 -> 0 | I26: 0 | J26: =K26/8 -> 0 | K26: 0 | L26: =M26/8 -> 0 | M26: 0 | P26: 1 | Q26: 9
A27: 45954 | B27: =C27/8 -> 4.4 | C27: 35.2 | D27: =E27/8 -> 6.6 | E27: 52.8 | F27: =G27/8 -> 0 | G27: 0 | H27: =I27/8 -> 0 | I27: 0 | J27: =K27/8 -> 0 | K27: 0 | L27: =M27/8 -> 0 | M27: 0 | P27: 1 | Q27: 8
A28: 45955 | B28: =C28/8 -> 0 | D28: =E28/8 -> 0 | F28: =G28/8 -> 0 | H28: =I28/8 -> 0 | J28: =K28/8 -> 0 | L28: =M28/8 -> 0
A29: 45956 | B29: =C29/8 -> 0 | D29: =E29/8 -> 0 | F29: =G29/8 -> 0 | H29: =I29/8 -> 0 | J29: =K29/8 -> 0 | L29: =M29/8 -> 0
A30: 45957 | B30: =C30/8 -> 4.95 | C30: 39.6 | D30: =E30/8 -> 7.425 | E30: 59.4 | F30: =G30/8 -> 0 | G30: 0 | H30: =I30/8 -> 0 | I30: 0 | J30: =K30/8 -> 0 | K30: 0 | L30: =M30/8 -> 0 | M30: 0 | P30: 1 | Q30: 9
A31: 45958 | B31: =C31/8 -> 5.625 | C31: 45 | D31: =E31/8 -> 5.625 | E31: 45 | F31: =G31/8 -> 0 | G31: 0 | H31: =I31/8 -> 0 | I31: 0 | J31: =K31/8 -> 0 | K31: 0 | L31: =M31/8 -> 0 | M31: 0 | P31: 1 | Q31: 9
A32: 45959 | B32: =C32/8 -> 6.53125 | C32: 52.25 | D32: =E32/8 -> 6.53125 | E32: 52.25 | F32: =G32/8 -> 0 | G32: 0 | H32: =I32/8 -> 0 | I32: 0 | J32: =K32/8 -> 0 | K32: 0 | L32: =M32/8 -> 0 | M32: 0 | P32: 1 | Q32: 9
A33: 45960 | B33: =C33/8 -> 6.75 | C33: 54 | D33: =E33/8 -> 6.75 | E33: 54 | F33: =G33/8 -> 0 | G33: 0 | H33: =I33/8 -> 0 | I33: 0 | J33: =K33/8 -> 0 | K33: 0 | L33: =M33/8 -> 0 | M33: 0 | P33: 1 | Q33: 9
A34: 45961 | B34: =C34/8 -> 6.66875 | C34: 53.35 | D34: =E34/8 -> 5.45625 | E34: 43.65 | F34: =G34/8 -> 0 | G34: 0 | H34: =I34/8 -> 0 | I34: 0 | J34: =K34/8 -> 0 | K34: 0 | L34: =M34/8 -> 0 | M34: 0 | P34: 1 | Q34: 8
A35: Total | B35: =IFERROR(AVERAGE(B4:B34),0) -> 5.0197984 | C35: =SUM(C4:C34) -> 1244.91 | D35: =AVERAGE(D4:D34) -> 4.3915726 | E35: =SUM(E4:E34) -> 1089.11 | F35: =AVERAGE(F4:F34) -> 0 | G35: =SUM(G4:G34) -> 0 | H35: =AVERAGE(H4:H34) -> 0.024193548 | I35: =SUM(I4:I34) -> 6 | J35: =AVERAGE(J4:J34) -> 0 | K35: =SUM(K4:K34) -> 0 | L35: =AVERAGE(L4:L34) -> 0 | M35: =SUM(M4:M34) -> 0 | N35: =IFERROR(AVERAGE(N4:N34),0) -> 0 | O35: =C35+I35+E35+G35+K35+M35 -> 2340.02 | P35: =IFERROR(AVERAGE(P4:P34),0) -> 1 | Q35: =SUM(Q4:Q34) -> 202 | R35: =IFERROR(AVERAGE(R4:R34),0) -> 0 | S35: =SUM(S4:S34) -> 0

Sheet Novembre
A1: 2025
B2: BO | D2: AE | F2: Formation initiale BO | H2: Formation continue BO | J2: Formation initiale FO | L2: Formation continue FO | N2: Total CC | P2: Manager | R2: Relation Clients
B3: ETP | C3: Heures | D3: ETP | E3: Heures | F3: ETP | G3: Heures | H3: ETP | I3: Heures | J3: ETP | K3: Heures | L3: ETP | M3: Heures
A4: 45962
A5: 45963
A6: 45964 | B6: =C6/8 -> 5.61875 | C6: 44.95 | D6: =E6/8 -> 5.61875 | E6: 44.95 | F6: =G6/8 -> 0 | G6: 0 | H6: =I6/8 -> 0 | I6: 0 | J6: =K6/8 -> 0 | K6: 0 | L6: =M6/8 -> 0 | M6: 0 | P6: 1 | Q6: 9
A7: 45965 | B7: =C7/8 -> 6.1875 | C7: 49.5 | D7: =E7/8 -> 5.67125 | E7: 45.37 | F7: =G7/8 -> 0 | G7: 0 | H7: =I7/8 -> 0 | I7: 0 | J7: =K7/8 -> 0 | K7: 0 | L7: =M7/8 -> 0 | M7: 0 | P7: 1 | Q7: 9
A8: 45966 | B8: =C8/8 -> 9.45 | C8: 75.6 | D8: =E8/8 -> 6.3 | E8: 50.4 | F8: =G8/8 -> 0 | G8: 0 | H8: =I8/8 -> 0 | I8: 0 | J8: =K8/8 -> 0 | K8: 0 | L8: =M8/8 -> 0 | M8: 0 | P8: 1 | Q8: 9
A9: 45967 | B9: =C9/8 -> 8.9625 | C9: 71.7 | D9: =E9/8 -> 5.975 | E9: 47.8 | F9: =G9/8 -> 0 | G9: 0 | H9: =I9/8 -> 0 | I9: 0 | J9: =K9/8 -> 0 | K9: 0 | L9: =M9/8 -> 0 | M9: 0 | P9: 1 | Q9: 9
A10: 45968 | B10: =C10/8 -> 5.6 | C10: 44.8 | D10: =E10/8 -> 8.4 | E10: 67.2 | F10: =G10/8 -> 0 | G10: 0 | H10: =I10/8 -> 0 | I10: 0 | J10: =K10/8 -> 0 | K10: 0 | L10: =M10/8 -> 0 | M10: 0 | P10: 1 | Q10: 8
A11: 45969
A12: 45970
A13: 45971 | B13: =C13/8 -> 8.775 | C13: 70.2 | D13: =E13/8 -> 5.85 | E13: 46.8 | F13: =G13/8 -> 0 | G13: 0 | H13: =I13/8 -> 0 | I13: 0 | J13: =K13/8 -> 0 | K13: 0 | L13: =M13/8 -> 0 | M13: 0 | P13: 1 | Q13: 9
A14: 45972
A15: 45973 | B15: =C15/8 -> 7.3125 | C15: 58.5 | D15: =E15/8 -> 7.3125 | E15: 58.5 | F15: =G15/8 -> 3 | G15: 24 | H15: =I15/8 -> 0 | I15: 0 | J15: =K15/8 -> 0 | K15: 0 | L15: =M15/8 -> 0 | M15: 0 | P15: 1 | Q15: 9
A16: 45974 | B16: =C16/8 -> 8.775 | C16: 70.2 | D16: =E16/8 -> 5.85 | E16: 46.8 | F16: =G16/8 -> 2.96875 | G16: 23.75 | H16: =I16/8 -> 0 | I16: 0 | J16: =K16/8 -> 0 | K16: 0 | L16: =M16/8 -> 0 | M16: 0 | P16: 1 | Q16: 9
A17: 45975 | B17: =C17/8 -> 6.5 | C17: 52 | D17: =E17/8 -> 6.5 | E17: 52 | F17: =G17/8 -> 2 | G17: 16 | H17: =I17/8 -> 0 | I17: 0 | J17: =K17/8 -> 0 | K17: 0 | L17: =M17/8 -> 0 | M17: 0 | P17: 1 | Q17: 8
A18: 45976
A19: 45977
A20: 45978 | B20: =C20/8 -> 9.45 | C20: 75.6 | D20: =E20/8 -> 6.3 | E20: 50.4 | F20: =G20/8 -> 2 | G20: 16 | H20: =I20/8 -> 0 | I20: 0 | J20: =K20/8 -> 0 | K20: 0 | L20: =M20/8 -> 0 | M20: 0 | P20: 1 | Q20: 9
A21: 45979 | B21: =C21/8 -> 7.625 | C21: 61 | D21: =E21/8 -> 7.78125 | E21: 62.25 | F21: =G21/8 -> 2 | G21: 16 | H21: =I21/8 -> 0 | I21: 0 | J21: =K21/8 -> 0 | K21: 0 | L21: =M21/8 -> 0 | M21: 0 | P21: 1 | Q21: 9
A22: 45980 | B22: =C22/8 -> 7.875 | C22: 63 | D22: =E22/8 -> 7.875 | E22: 63 | F22: =G22/8 -> 2 | G22: 16 | H22: =I22/8 -> 0 | I22: 0 | J22: =K22/8 -> 0 | K22: 0 | L22: =M22/8 -> 0 | M22: 0 | P22: 1 | Q22: 9
A23: 45981 | B23: =C23/8 -> 9.45 | C23: 75.6 | D23: =E23/8 -> 6.3 | E23: 50.4 | F23: =G23/8 -> 1 | G23: 8 | H23: =I23/8 -> 0 | I23: 0 | J23: =K23/8 -> 0 | K23: 0 | L23: =M23/8 -> 0 | M23: 0 | P23: 1 | Q23: 9
A24: 45982 | B24: =C24/8 -> 7 | C24: 56 | D24: =E24/8 -> 7 | E24: 56 | F24: =G24/8 -> 1 | G24: 8 | H24: =I24/8 -> 0 | I24: 0 | J24: =K24/8 -> 0 | K24: 0 | L24: =M24/8 -> 0 | M24: 0 | P24: 1 | Q24: 8
A25: 45983
A26: 45984
A27: 45985 | B27: =C27/8 -> 6.075 | C27: 48.6 | D27: =E27/8 -> 9.1125 | E27: 72.9 | F27: =G27/8 -> 1 | G27: 8 | H27: =I27/8 -> 0 | I27: 0 | J27: =K27/8 -> 0 | K27: 0 | L27: =M27/8 -> 0 | M27: 0 | P27: 1 | Q27: 9
A28: 45986 | B28: =C28/8 -> 7.3125 | C28: 58.5 | D28: =E28/8 -> 7.3125 | E28: 58.5 | F28: =G28/8 -> 2 | G28: 16 | H28: =I28/8 -> 0 | I28: 0 | J28: =K28/8 -> 0 | K28: 0 | L28: =M28/8 -> 0 | M28: 0 | P28: 1 | Q28: 9
A29: 45987 | B29: =C29/8 -> 10.4875 | C29: 83.9 | D29: =E29/8 -> 6.98125 | E29: 55.85 | F29: =G29/8 -> 0 | G29: 0 | H29: =I29/8 -> 0 | I29: 0 | J29: =K29/8 -> 0 | K29: 0 | L29: =M29/8 -> 0 | M29: 0 | P29: 1 | Q29: 9
A30: 45988 | B30: =C30/8 -> 8.15625 | C30: 65.25 | D30: =E30/8 -> 8.15625 | E30: 65.25 | F30: =G30/8 -> 0 | G30: 0 | H30: =I30/8 -> 0 | I30: 0 | J30: =K30/8 -> 0 | K30: 0 | L30: =M30/8 -> 0 | M30: 0 | P30: 1 | Q30: 9
A31: 45989 | B31: =C31/8 -> 5.81625 | C31: 46.53 | D31: =E31/8 -> 8.725 | E31: 69.8 | F31: =G31/8 -> 0 | G31: 0 | H31: =I31/8 -> 0 | I31: 0 | J31: =K31/8 -> 0 | K31: 0 | L31: =M31/8 -> 0 | M31: 0 | P31: 1 | Q31: 8
A32: 45990
A33: 45991
A34: Total | B34: =IFERROR(AVERAGE(B4:B33),0) -> 7.7067763 | C34: =SUM(C4:C33) -> 1171.43 | D34: =AVERAGE(D4:D33) -> 7.0011184 | E34: =SUM(E4:E33) -> 1064.17 | F34: =AVERAGE(F4:F33) -> 0.99835526 | G34: =SUM(G4:G33) -> 151.75 | H34: =AVERAGE(H4:H33) -> 0 | I34: =SUM(I4:I33) -> 0 | J34: =AVERAGE(J4:J33) -> 0 | K34: =SUM(K4:K33) -> 0 | L34: =AVERAGE(L4:L33) -> 0 | M34: =SUM(M4:M33) -> 0 | N34: =IFERROR(AVERAGE(N4:N33),0) -> 0 | O34: =+C34+I34+E34+G34+K34+M34 -> 2387.35 | P34: =IFERROR(AVERAGE(P4:P33),0) -> 1 | Q34: =SUM(Q4:Q33) -> 167 | R34: =IFERROR(AVERAGE(R4:R33),0) -> 0 | S34: =SUM(S4:S33) -> 0

Sheet Décembre
A1: 2025
B2: BO | D2: AE | F2: Formation initiale BO | H2: Formation continue BO | J2: Formation initiale FO | L2: Formation continue FO | N2: Total CC | P2: Manager | R2: Relation Clients
B3: ETP | C3: Heures | D3: ETP | E3: Heures | F3: ETP | G3: Heures | H3: ETP | I3: Heures | J3: ETP | K3: Heures | L3: ETP | M3: Heures
A4: 45992 | B4: =C4/8 -> 9.3125 | C4: 74.5 | D4: =E4/8 -> 5.85 | E4: 46.8 | F4: =G4/8 -> 0 | G4: 0 | H4: =I4/8 -> 0 | I4: 0 | J4: =K4/8 -> 0 | K4: 0 | L4: =M4/8 -> 0 | M4: 0 | P4: 1 | Q4: 9
A5: 45993 | B5: =C5/8 -> 10.125 | C5: 81 | D5: =E5/8 -> 6.75 | E5: 54 | F5: =G5/8 -> 0 | G5: 0 | H5: =I5/8 -> 0 | I5: 0 | J5: =K5/8 -> 0 | K5: 0 | L5: =M5/8 -> 0 | M5: 0 | P5: 1 | Q5: 9
A6: 45994 | B6: =C6/8 -> 6.75 | C6: 54 | D6: =E6/8 -> 10.125 | E6: 81 | F6: =G6/8 -> 0 | G6: 0 | H6: =I6/8 -> 0 | I6: 0 | J6: =K6/8 -> 0 | K6: 0 | L6: =M6/8 -> 0 | M6: 0 | P6: 1 | Q6: 9
A7: 45995 | B7: =C7/8 -> 6.05 | C7: 48.4 | D7: =E7/8 -> 9.075 | E7: 72.6 | F7: =G7/8 -> 0 | G7: 0 | H7: =I7/8 -> 0 | I7: 0 | J7: =K7/8 -> 0 | K7: 0 | L7: =M7/8 -> 0 | M7: 0 | P7: 1 | Q7: 9
A8: 45996 | B8: =C8/8 -> 5.2 | C8: 41.6 | D8: =E8/8 -> 7.8 | E8: 62.4 | F8: =G8/8 -> 0 | G8: 0 | H8: =I8/8 -> 0 | I8: 0 | J8: =K8/8 -> 0 | K8: 0 | L8: =M8/8 -> 0 | M8: 0 | P8: 1 | Q8: 8
A9: 45997
A10: 45998
A11: 45999 | B11: =C11/8 -> 6.3 | C11: 50.4 | D11: =E11/8 -> 9.45 | E11: 75.6 | F11: =G11/8 -> 0 | G11: 0 | H11: =I11/8 -> 0 | I11: 0 | J11: =K11/8 -> 0 | K11: 0 | L11: =M11/8 -> 0 | M11: 0 | P11: 1 | Q11: 9
A12: 46000 | B12: =C12/8 -> 6.75 | C12: 54 | D12: =E12/8 -> 6.75 | E12: 54 | F12: =G12/8 -> 0 | G12: 0 | H12: =I12/8 -> 0 | I12: 0 | J12: =K12/8 -> 0 | K12: 0 | L12: =M12/8 -> 0 | M12: 0 | P12: 1 | Q12: 9
A13: 46001 | B13: =C13/8 -> 5.4 | C13: 43.2 | D13: =E13/8 -> 8.1 | E13: 64.8 | F13: =G13/8 -> 0 | G13: 0 | H13: =I13/8 -> 0 | I13: 0 | J13: =K13/8 -> 0 | K13: 0 | L13: =M13/8 -> 0 | M13: 0 | P13: 1 | Q13: 9
A14: 46002 | B14: =C14/8 -> 6.75 | C14: 54 | D14: =E14/8 -> 6.75 | E14: 54 | F14: =G14/8 -> 0 | G14: 0 | H14: =I14/8 -> 0 | I14: 0 | J14: =K14/8 -> 0 | K14: 0 | L14: =M14/8 -> 0 | M14: 0 | P14: 1 | Q14: 9
A15: 46003 | B15: =C15/8 -> 5.2 | C15: 41.6 | D15: =E15/8 -> 7.8 | E15: 62.4 | F15: =G15/8 -> 0 | G15: 0 | H15: =I15/8 -> 0 | I15: 0 | J15: =K15/8 -> 0 | K15: 0 | L15: =M15/8 -> 0 | M15: 0 | P15: 1 | Q15: 8
A16: 46004
A17: 46005
A18: 46006 | B18: =C18/8 -> 4.725 | C18: 37.8 | D18: =E18/8 -> 11.025 | E18: 88.2 | F18: =G18/8 -> 0 | G18: 0 | H18: =I18/8 -> 0 | I18: 0 | J18: =K18/8 -> 0 | K18: 0 | L18: =M18/8 -> 0 | M18: 0 | P18: 1 | Q18: 9
A19: 46007 | B19: =C19/8 -> 5.49 | C19: 43.92 | D19: =E19/8 -> 8.2375 | E19: 65.9 | F19: =G19/8 -> 0 | G19: 0 | H19: =I19/8 -> 0 | I19: 0 | J19: =K19/8 -> 0 | K19: 0 | L19: =M19/8 -> 0 | M19: 0 | P19: 1 | Q19: 9
A20: 46008 | B20: =C20/8 -> 5.85 | C20: 46.8 | D20: =E20/8 -> 8.775 | E20: 70.2 | F20: =G20/8 -> 0 | G20: 0 | H20: =I20/8 -> 0 | I20: 0 | J20: =K20/8 -> 0 | K20: 0 | L20: =M20/8 -> 0 | M20: 0 | P20: 1 | Q20: 9
A21: 46009 | B21: =C21/8 -> 6.75 | C21: 54 | D21: =E21/8 -> 5 | E21: 40 | F21: =G21/8 -> 0 | G21: 0 | H21: =I21/8 -> 1.75 | I21: 14 | J21: =K21/8 -> 0 | K21: 0 | L21: =M21/8 -> 0 | M21: 0 | P21: 1 | Q21: 9
A22: 46010 | B22: =C22/8 -> 6.5 | C22: 52 | D22: =E22/8 -> 6.5 | E22: 52 | F22: =G22/8 -> 0 | G22: 0 | H22: =I22/8 -> 0 | I22: 0 | J22: =K22/8 -> 0 | K22: 0 | L22: =M22/8 -> 0 | M22: 0 | P22: 1 | Q22: 8
A23: 46011
A24: 46012
A25: 46013 | B25: =C25/8 -> 10.71875 | C25: 85.75 | D25: =E25/8 -> 4.59375 | E25: 36.75 | F25: =G25/8 -> 0 | G25: 0 | H25: =I25/8 -> 0 | I25: 0 | J25: =K25/8 -> 0 | K25: 0 | L25: =M25/8 -> 0 | M25: 0 | P25: 1 | Q25: 9
A26: 46014 | B26: =C26/8 -> 11.025 | C26: 88.2 | D26: =E26/8 -> 4.725 | E26: 37.8 | F26: =G26/8 -> 0 | G26: 0 | H26: =I26/8 -> 0 | I26: 0 | J26: =K26/8 -> 0 | K26: 0 | L26: =M26/8 -> 0 | M26: 0 | P26: 1 | Q26: 9
A27: 46015 | B27: =C27/8 -> 8.775 | C27: 70.2 | D27: =E27/8 -> 5.85 | E27: 46.8 | F27: =G27/8 -> 0 | G27: 0 | H27: =I27/8 -> 0 | I27: 0 | J27: =K27/8 -> 0 | K27: 0 | L27: =M27/8 -> 0 | M27: 0 | P27: 1 | Q27: 9
A28: 46016
A29: 46017 | B29: =C29/8 -> 6.5 | C29: 52 | D29: =E29/8 -> 6.5 | E29: 52 | F29: =G29/8 -> 0 | G29: 0 | H29: =I29/8 -> 0 | I29: 0 | J29: =K29/8 -> 0 | K29: 0 | L29: =M29/8 -> 0 | M29: 0 | P29: 1 | Q29: 0
A30: 46018
A31: 46019
A32: 46020 | B32: =C32/8 -> 6.70625 | C32: 53.65 | D32: =E32/8 -> 6.70625 | E32: 53.65 | F32: =G32/8 -> 0 | G32: 0 | H32: =I32/8 -> 0 | I32: 0 | J32: =K32/8 -> 0 | K32: 0 | L32: =M32/8 -> 0 | M32: 0 | P32: 1 | Q32: 9
A33: 46021 | B33: =C33/8 -> 7.875 | C33: 63 | D33: =E33/8 -> 7.875 | E33: 63 | F33: =G33/8 -> 0 | G33: 0 | H33: =I33/8 -> 0 | I33: 0 | J33: =K33/8 -> 0 | K33: 0 | L33: =M33/8 -> 0 | M33: 0 | P33: 1 | Q33: 9
A34: 46022 | B34: =C34/8 -> 6.7125 | C34: 53.7 | D34: =E34/8 -> 6.7125 | E34: 53.7 | F34: =G34/8 -> 0 | G34: 0 | H34: =I34/8 -> 0 | I34: 0 | J34: =K34/8 -> 0 | K34: 0 | L34: =M34/8 -> 0 | M34: 0 | P34: 1 | Q34: 9
A35: Total | B35: =IFERROR(AVERAGE(B4:B31),0) -> 7.0616447 | C35: =SUM(C4:C34) -> 1243.72 | D35: =AVERAGE(D4:D31) -> 7.3503289 | E35: =SUM(E4:E34) -> 1287.6 | F35: =AVERAGE(F4:F31) -> 0 | G35: =SUM(G4:G34) -> 0 | H35: =AVERAGE(H4:H31) -> 0.092105263 | I35: =SUM(I4:I34) -> 14 | J35: =AVERAGE(J4:J31) -> 0 | K35: =SUM(K4:K34) -> 0 | L35: =AVERAGE(L4:L31) -> 0 | M35: =SUM(M4:M34) -> 0 | N35: =IFERROR(AVERAGE(N4:N31),0) -> 0 | O35: =C35+I35+E35+G35+K35+M35 -> 2545.32 | P35: =IFERROR(AVERAGE(P4:P31),0) -> 1 | Q35: =SUM(Q4:Q34) -> 186 | R35: =IFERROR(AVERAGE(R4:R31),0) -> 0 | S35: =SUM(S4:S31) -> 0

Sheet Janvier26
A1: 2026
B2: BO | D2: AE | F2: Formation initiale BO | H2: Formation continue BO | J2: Formation initiale FO | L2: Formation continue FO | N2: Total CC | P2: Manager | R2: Relation Clients
B3: ETP | C3: Heures | D3: ETP | E3: Heures | F3: ETP | G3: Heures | H3: ETP | I3: Heures | J3: ETP | K3: Heures | L3: ETP | M3: Heures
A4: 46023
A5: 46024 | B5: =C5/8 -> 5 | C5: 40 | D5: =E5/8 -> 7.5 | E5: 60 | F5: =G5/8 -> 0 | G5: 0 | H5: =I5/8 -> 0 | I5: 0 | J5: =K5/8 -> 0 | K5: 0 | L5: =M5/8 -> 0 | M5: 0 | P5: 1 | Q5: 8
A6: 46025
A7: 46026
A8: 46027 | B8: =C8/8 -> 4.75 | C8: 38 | D8: =E8/8 -> 7.125 | E8: 57 | F8: =G8/8 -> 0 | G8: 0 | H8: =I8/8 -> 0 | I8: 0 | J8: =K8/8 -> 0 | K8: 0 | L8: =M8/8 -> 0 | M8: 0 | P8: 1 | Q8: 9
A9: 46028 | B9: =C9/8 -> 5.875 | C9: 47 | D9: =E9/8 -> 8.75 | E9: 70 | F9: =G9/8 -> 0 | G9: 0 | H9: =I9/8 -> 0 | I9: 0 | J9: =K9/8 -> 0 | K9: 0 | L9: =M9/8 -> 0 | M9: 0 | P9: 1 | Q9: 9
A10: 46029 | B10: =C10/8 -> 5.875 | C10: 47 | D10: =E10/8 -> 8.75 | E10: 70 | F10: =G10/8 -> 0 | G10: 0 | H10: =I10/8 -> 0 | I10: 0 | J10: =K10/8 -> 0 | K10: 0 | L10: =M10/8 -> 0 | M10: 0 | P10: 1 | Q10: 9
A11: 46030 | B11: =C11/8 -> 5.5 | C11: 44 | D11: =E11/8 -> 8 | E11: 64 | F11: =G11/8 -> 0 | G11: 0 | H11: =I11/8 -> 0 | I11: 0 | J11: =K11/8 -> 0 | K11: 0 | L11: =M11/8 -> 0 | M11: 0 | P11: 1 | Q11: 9
A12: 46031 | B12: =C12/8 -> 5.5 | C12: 44 | D12: =E12/8 -> 5.5 | E12: 44 | F12: =G12/8 -> 0 | G12: 0 | H12: =I12/8 -> 0 | I12: 0 | J12: =K12/8 -> 0 | K12: 0 | L12: =M12/8 -> 0 | M12: 0 | P12: 1 | Q12: 8
A13: 46032
A14: 46033
A15: 46034 | B15: =C15/8 -> 4.375 | C15: 35 | D15: =E15/8 -> 10.25 | E15: 82 | F15: =G15/8 -> 0 | G15: 0 | H15: =I15/8 -> 0 | I15: 0 | J15: =K15/8 -> 0 | K15: 0 | L15: =M15/8 -> 0 | M15: 0 | P15: 1 | Q15: 9
A16: 46035 | B16: =C16/8 -> 8.75 | C16: 70 | D16: =E16/8 -> 5.875 | E16: 47 | F16: =G16/8 -> 0 | G16: 0 | H16: =I16/8 -> 0 | I16: 0 | J16: =K16/8 -> 0 | K16: 0 | L16: =M16/8 -> 0 | M16: 0 | P16: 1 | Q16: 9
A17: 46036 | B17: =C17/8 -> 7.25 | C17: 58 | D17: =E17/8 -> 7.375 | E17: 59 | F17: =G17/8 -> 0 | G17: 0 | H17: =I17/8 -> 0 | I17: 0 | J17: =K17/8 -> 0 | K17: 0 | L17: =M17/8 -> 0 | M17: 0 | P17: 1 | Q17: 9
A18: 46037 | B18: =C18/8 -> 7.25 | C18: 58 | D18: =E18/8 -> 7.375 | E18: 59 | F18: =G18/8 -> 0 | G18: 0 | H18: =I18/8 -> 0 | I18: 0 | J18: =K18/8 -> 0 | K18: 0 | L18: =M18/8 -> 0 | M18: 0 | P18: 1 | Q18: 9
A19: 46038 | B19: =C19/8 -> 6 | C19: 48 | D19: =E19/8 -> 6 | E19: 48 | F19: =G19/8 -> 0 | G19: 0 | H19: =I19/8 -> 0 | I19: 0 | J19: =K19/8 -> 0 | K19: 0 | L19: =M19/8 -> 0 | M19: 0 | P19: 1 | Q19: 8
A20: 46039
A21: 46040
A22: 46041 | B22: =C22/8 -> 6.07375 | C22: 48.59 | D22: =E22/8 -> 6.07375 | E22: 48.59 | F22: =G22/8 -> 8.875 | G22: 71 | H22: =I22/8 -> 0 | I22: 0 | J22: =K22/8 -> 0 | K22: 0 | L22: =M22/8 -> 0 | M22: 0 | P22: 1 | Q22: 9
A23: 46042 | B23: =C23/8 -> 8.125 | C23: 65 | D23: =E23/8 -> 5.375 | E23: 43 | F23: =G23/8 -> 9 | G23: 72 | H23: =I23/8 -> 0 | I23: 0 | J23: =K23/8 -> 0 | K23: 0 | L23: =M23/8 -> 0 | M23: 0 | P23: 1 | Q23: 9
A24: 46043 | B24: =C24/8 -> 8.75 | C24: 70 | D24: =E24/8 -> 5.875 | E24: 47 | F24: =G24/8 -> 9 | G24: 72 | H24: =I24/8 -> 0 | I24: 0 | J24: =K24/8 -> 0 | K24: 0 | L24: =M24/8 -> 0 | M24: 0 | P24: 1 | Q24: 9
A25: 46044 | B25: =C25/8 -> 7.25 | C25: 58 | D25: =E25/8 -> 7.375 | E25: 59 | F25: =G25/8 -> 8.375 | G25: 67 | H25: =I25/8 -> 0 | I25: 0 | J25: =K25/8 -> 0 | K25: 0 | L25: =M25/8 -> 0 | M25: 0 | P25: 1 | Q25: 9
A26: 46045 | B26: =C26/8 -> 6.5 | C26: 52 | D26: =E26/8 -> 6.5 | E26: 52 | F26: =G26/8 -> 8 | G26: 64 | H26: =I26/8 -> 0 | I26: 0 | J26: =K26/8 -> 0 | K26: 0 | L26: =M26/8 -> 0 | M26: 0 | P26: 1 | Q26: 8
A27: 46046
A28: 46047
A29: 46048 | B29: =C29/8 -> 5.875 | C29: 47 | D29: =E29/8 -> 8.75 | E29: 70 | F29: =G29/8 -> 8 | G29: 64 | H29: =I29/8 -> 0 | I29: 0 | J29: =K29/8 -> 0 | K29: 0 | L29: =M29/8 -> 0 | M29: 0 | P29: 1 | Q29: 9
A30: 46049 | B30: =C30/8 -> 5.375 | C30: 43 | D30: =E30/8 -> 8.125 | E30: 65 | F30: =G30/8 -> 7.375 | G30: 59 | H30: =I30/8 -> 0 | I30: 0 | J30: =K30/8 -> 0 | K30: 0 | L30: =M30/8 -> 0 | M30: 0 | P30: 1 | Q30: 9
A31: 46050 | B31: =C31/8 -> 5.875 | C31: 47 | D31: =E31/8 -> 8.75 | E31: 70 | F31: =G31/8 -> 8 | G31: 64 | H31: =I31/8 -> 0 | I31: 0 | J31: =K31/8 -> 0 | K31: 0 | L31: =M31/8 -> 0 | M31: 0 | P31: 1 | Q31: 9
A32: 46051 | B32: =C32/8 -> 5.875 | C32: 47 | D32: =E32/8 -> 8.75 | E32: 70 | F32: =G32/8 -> 0 | G32: 0 | H32: =I32/8 -> 0 | I32: 0 | J32: =K32/8 -> 8 | K32: 64 | L32: =M32/8 -> 0 | M32: 0 | P32: 1 | Q32: 9
A33: 46052 | B33: =C33/8 -> 4.375 | C33: 35 | D33: =E33/8 -> 6.625 | E33: 53 | F33: =G33/8 -> 3.375 | G33: 27 | H33: =I33/8 -> 0 | I33: 0 | J33: =K33/8 -> 3.4375 | K33: 27.5 | L33: =M33/8 -> 0 | M33: 0 | P33: 1 | Q33: 8
A34: 46053
A35: Total | B35: =IFERROR(AVERAGE(B4:B28),0) -> 6.4264844 | C35: =SUM(C4:C33) -> 1041.59 | D35: =AVERAGE(D4:D28) -> 7.1061719 | E35: =SUM(E4:E34) -> 1237.59 | F35: =AVERAGE(F4:F28) -> 2.703125 | G35: =SUM(G4:G34) -> 560 | H35: =AVERAGE(H4:H28) -> 0 | I35: =SUM(I4:I34) -> 0 | J35: =AVERAGE(J4:J28) -> 0 | K35: =SUM(K4:K34) -> 91.5 | L35: =AVERAGE(L4:L28) -> 0 | M35: =SUM(M4:M34) -> 0 | N35: =IFERROR(AVERAGE(N4:N28),0) -> 0 | O35: =C35+I35+E35+G35+K35+M35 -> 2930.68 | P35: =IFERROR(AVERAGE(P4:P28),0) -> 1 | Q35: =SUM(Q4:Q34) -> 184 | R35: =IFERROR(AVERAGE(R4:R28),0) -> 0 | S35: =SUM(S4:S28) -> 0

Sheet Fevrier26
A1: 2026
B2: BO | D2: AE | F2: Formation initiale BO | H2: Formation continue BO | J2: Formation initiale FO | L2: Formation continue FO | N2: Total CC | P2: Manager | R2: Relation Clients
B3: ETP | C3: Heures | D3: ETP | E3: Heures | F3: ETP | G3: Heures | H3: ETP | I3: Heures | J3: ETP | K3: Heures | L3: ETP | M3: Heures
A4: 46054
A5: 46055 | B5: =C5/8 -> 10.125 | C5: 81 | D5: =E5/8 -> 13.5 | E5: 108 | F5: =G5/8 -> 9 | G5: 72 | H5: =I5/8 -> 0 | I5: 0 | J5: =K5/8 -> 0 | K5: 0 | L5: =M5/8 -> 0 | M5: 0 | P5: 1 | Q5: 9
A6: 46056 | B6: =C6/8 -> 11.875 | C6: 95 | D6: =E6/8 -> 11.75 | E6: 94 | F6: =G6/8 -> 9 | G6: 72 | H6: =I6/8 -> 0 | I6: 0 | J6: =K6/8 -> 0 | K6: 0 | L6: =M6/8 -> 0 | M6: 0 | P6: 1 | Q6: 9
A7: 46057 | B7: =C7/8 -> 11.25 | C7: 90 | D7: =E7/8 -> 11.25 | E7: 90 | F7: =G7/8 -> 9 | G7: 72 | H7: =I7/8 -> 0 | I7: 0 | J7: =K7/8 -> 0 | K7: 0 | L7: =M7/8 -> 0 | M7: 0 | P7: 1 | Q7: 9
A8: 46058 | B8: =C8/8 -> 6.75 | C8: 54 | D8: =E8/8 -> 15.75 | E8: 126 | F8: =G8/8 -> 9 | G8: 72 | H8: =I8/8 -> 0 | I8: 0 | J8: =K8/8 -> 0 | K8: 0 | L8: =M8/8 -> 0 | M8: 0 | P8: 1 | Q8: 9
