Workbook

Sheet GUIDE
A1: Étape | B1: Consigne
A2: 1 | B2: Renseigner les référentiels et les barèmes.
A3: 2 | B3: FORMULAIRE : préparer une saisie, puis copier les valeurs dans TRAITEMENTS (sans macro).
A4: 3 | B4: TRAITEMENTS : une ligne par document/version ; saisir barème historique et heures ajustées.
A5: 4 | B5: CONNEXIONS : une ligne par agent/jour.
A6: 5 | B6: VENTILATION : prorata automatique par agent/mois ; contrôler les heures non ventilées.
A7: 6 | B7: AJUSTEMENTS : allocations manuelles si aucune production ou exception.
A8: 7 | B8: DASHBOARD : choisir année/mois ; renseigner heures théoriques mensuelles.
A9: 8 | B9: Historique : modifier les nouveaux barèmes sans toucher aux anciennes lignes.

Sheet ENTITES
A1: Entité | B1: Domaine | C1: Sous-domaine
A2: ACM | C2: ASS-BIENS
A3: ACM | C3: ASS-COMPTA-CONTENTIEUX
A4: ACM | C4: ASS-EMPRUNTEURS
A5: ACM | C5: ASS-ERE
A6: ACM | C6: ASS-INDEMN-BIENS-PERS
A7: ACM | C7: ASS-PERS-COLL
A8: ACM | C8: ASS-PERS-IND
A9: ACM | C9: ASS-PROTECTION-JUR
A10: ACM | C10: ASS-VIE-EPARGNE-RET
A11: COFIDIS France | B11: DMA | C11: DMA – Agence WEB
A12: COFIDIS France | B12: DMA | C12: DMA – Marque et Stratégie
A13: COFIDIS France | B13: DMA | C13: DMA – Performance Digitale
A14: COFIDIS France | B14: DPA | C14: DPA – Domaine Marketing
A15: COFIDIS France | B15: DPA | C15: DPA – Service Marketing
A16: COFIDIS France | B16: DPA | C16: DPA – Service Relation
A17: CONTRATHEQUE | B17: CONDITIONS GENERALES | C17: CIC
A18: CONTRATHEQUE | B18: CONDITIONS GENERALES | C18: CM
A19: CONTRATHEQUE | B19: CONDITIONS GENERALES | C19: Mixte
A20: CONTRATHEQUE | B20: DOCUMENT D'INFORMATION TARIFAIRE
A21: CONTRATHEQUE | B21: GARANTIES
A22: CONTRATHEQUE | B22: POLITIQUE DE PROTECTION
A23: CREATIS
A24: CMMABN
A25: MONABANQ
A26: Bouygues Telecom
A27: DIRCOM | C27: CIC
A28: DIRCOM | C28: CM
A29: DIRCO | C29: CIC
A30: DIRCO | C30: CM
A31: CIC CIB Asset Servicing | C31: Agence Clientèle Déposée
A32: CMO | C32: BAD
A33: CMO | C33: Cartes bancaires
A34: CMO | C34: Compte courant
A35: CMO | C35: Épargne bancaire
A36: CMO | C36: Épargne financière
A37: CMO | C37: Packages
A38: CMO | C38: Tarif

Sheet COLLABORATEURS
A1: Collaborateur | B1: Actif
A2: HAMDANI Mohamed | B2: Oui
A3: RMAIDI Imad | B3: Oui
A4: LISSAOUI Hiba | B4: Oui
A5: JEBBALI Youssef | B5: Non

Sheet TYPES
A1: Type de document
A2: Conditions générales
A3: Fiche Clarté
A4: Fiche Zoom
A5: Livre blanc
A6: Document commercial
A7: Autre

Sheet BAREMES
A1: Entité | B1: Type | C1: Version | D1: Date début | E1: Durée référence (h) | F1: Actif
A2: ACM | B2: Conditions générales | C2: V1 | D2: 46296 | E2: 9 | F2: Oui
A3: ACM | B3: Fiche Clarté | C3: V1 | D3: 46296 | E3: 4.5 | F3: Oui
A4: DIRCOM | B4: Document commercial | C4: V1 | D4: 46296 | E4: 9 | F4: Oui

Sheet FORMULAIRE
A1: Champ | B1: Valeur
A2: ID traitement
A3: ID document initial
A4: Version document
A5: Date fin
A6: Collaborateur
A7: Entité
A8: Domaine
A9: Sous-domaine
A10: Type document
A11: Nom document
A12: Barème historique (h)
A13: Version barème
... A15: Facturable Oui/Non

Sheet TRAITEMENTS
A1: ID traitement | B1: ID document initial | C1: Version document | D1: Date fin | E1: Collaborateur | F1: Entité | G1: Domaine | H1: Sous-domaine | I1: Type document | J1: Nom document | K1: Barème historique (h) | L1: Version barème | M1: Heures ajustées | N1: Facturable Oui/Non | O1: Heures facturables | P1: Heures non facturables | Q1: Mois clé | R1: Actes facturables
O2: =IF(OR(D2="",M2=""),0,IF(N2="Oui",M2,0)) | P2: =IF(OR(D2="",M2=""),0,IF(N2="Non",M2,0)) | Q2: =IF(D2="","",YEAR(D2)*100+MONTH(D2)) | R2: =IF(AND(D2<>"",N2="Oui"),1,0)
O3: =IF(OR(D3="",M3=""),0,IF(N3="Oui",M3,0)) | P3: =IF(OR(D3="",M3=""),0,IF(N3="Non",M3,0)) | Q3: =IF(D3="","",YEAR(D3)*100+MONTH(D3)) | R3: =IF(AND(D3<>"",N3="Oui"),1,0)
O4: =IF(OR(D4="",M4=""),0,IF(N4="Oui",M4,0)) | P4: =IF(OR(D4="",M4=""),0,IF(N4="Non",M4,0)) | Q4: =IF(D4="","",YEAR(D4)*100+MONTH(D4)) | R4: =IF(AND(D4<>"",N4="Oui"),1,0)
O5: =IF(OR(D5="",M5=""),0,IF(N5="Oui",M5,0)) | P5: =IF(OR(D5="",M5=""),0,IF(N5="Non",M5,0)) | Q5: =IF(D5="","",YEAR(D5)*100+MONTH(D5)) | R5: =IF(AND(D5<>"",N5="Oui"),1,0)
O6: =IF(OR(D6="",M6=""),0,IF(N6="Oui",M6,0)) | P6: =IF(OR(D6="",M6=""),0,IF(N6="Non",M6,0)) | Q6: =IF(D6="","",YEAR(D6)*100+MONTH(D6)) | R6: =IF(AND(D6<>"",N6="Oui"),1,0)
O7: =IF(OR(D7="",M7=""),0,IF(N7="Oui",M7,0)) | P7: =IF(OR(D7="",M7=""),0,IF(N7="Non",M7,0)) | Q7: =IF(D7="","",YEAR(D7)*100+MONTH(D7)) | R7: =IF(AND(D7<>"",N7="Oui"),1,0)
O8: =IF(OR(D8="",M8=""),0,IF(N8="Oui",M8,0)) | P8: =IF(OR(D8="",M8=""),0,IF(N8="Non",M8,0)) | Q8: =IF(D8="","",YEAR(D8)*100+MONTH(D8)) | R8: =IF(AND(D8<>"",N8="Oui"),1,0)
O9: =IF(OR(D9="",M9=""),0,IF(N9="Oui",M9,0)) | P9: =IF(OR(D9="",M9=""),0,IF(N9="Non",M9,0)) | Q9: =IF(D9="","",YEAR(D9)*100+MONTH(D9)) | R9: =IF(AND(D9<>"",N9="Oui"),1,0)
O10: =IF(OR(D10="",M10=""),0,IF(N10="Oui",M10,0)) | P10: =IF(OR(D10="",M10=""),0,IF(N10="Non",M10,0)) | Q10: =IF(D10="","",YEAR(D10)*100+MONTH(D10)) | R10: =IF(AND(D10<>"",N10="Oui"),1,0)
O11: =IF(OR(D11="",M11=""),0,IF(N11="Oui",M11,0)) | P11: =IF(OR(D11="",M11=""),0,IF(N11="Non",M11,0)) | Q11: =IF(D11="","",YEAR(D11)*100+MONTH(D11)) | R11: =IF(AND(D11<>"",N11="Oui"),1,0)
O12: =IF(OR(D12="",M12=""),0,IF(N12="Oui",M12,0)) | P12: =IF(OR(D12="",M12=""),0,IF(N12="Non",M12,0)) | Q12: =IF(D12="","",YEAR(D12)*100+MONTH(D12)) | R12: =IF(AND(D12<>"",N12="Oui"),1,0)
O13: =IF(OR(D13="",M13=""),0,IF(N13="Oui",M13,0)) | P13: =IF(OR(D13="",M13=""),0,IF(N13="Non",M13,0)) | Q13: =IF(D13="","",YEAR(D13)*100+MONTH(D13)) | R13: =IF(AND(D13<>"",N13="Oui"),1,0)
... O501: =IF(OR(D501="",M501=""),0,IF(N501="Oui",M501,0)) | P501: =IF(OR(D501="",M501=""),0,IF(N501="Non",M501,0)) | Q501: =IF(D501="","",YEAR(D501)*100+MONTH(D501)) | R501: =IF(AND(D501<>"",N501="Oui"),1,0)

Sheet CONNEXIONS
A1: Date | B1: Collaborateur | C1: Heures connectées | D1: Mois clé
D2: =IF(A2="","",YEAR(A2)*100+MONTH(A2))
D3: =IF(A3="","",YEAR(A3)*100+MONTH(A3))
D4: =IF(A4="","",YEAR(A4)*100+MONTH(A4))
D5: =IF(A5="","",YEAR(A5)*100+MONTH(A5))
D6: =IF(A6="","",YEAR(A6)*100+MONTH(A6))
D7: =IF(A7="","",YEAR(A7)*100+MONTH(A7))
D8: =IF(A8="","",YEAR(A8)*100+MONTH(A8))
D9: =IF(A9="","",YEAR(A9)*100+MONTH(A9))
D10: =IF(A10="","",YEAR(A10)*100+MONTH(A10))
D11: =IF(A11="","",YEAR(A11)*100+MONTH(A11))
D12: =IF(A12="","",YEAR(A12)*100+MONTH(A12))
D13: =IF(A13="","",YEAR(A13)*100+MONTH(A13))
... D501: =IF(A501="","",YEAR(A501)*100+MONTH(A501))

Sheet CALENDRIER
A1: Date | B1: Férié Oui/Non | C1: Travaillé Oui/Non | D1: Commentaire

Sheet ABSENCES
A1: Date | B1: Collaborateur | C1: Heures absence | D1: Motif

Sheet AJUSTEMENTS
A1: Mois clé | B1: Collaborateur | C1: Entité | D1: Domaine | E1: Sous-domaine | F1: Heures allouées manuelles | G1: Motif

Sheet VENTILATION
A1: Mois clé | B1: Collaborateur | C1: Entité | D1: Domaine | E1: Sous-domaine | F1: Facturables ligne | G1: Facturables agent/mois | H1: Connectées agent/mois | I1: Ventilation automatique | J1: Ventilation manuelle | K1: Ventilation retenue
A2: =IF(TRAITEMENTS!$Q2="","",TRAITEMENTS!Q2) | B2: =IF(TRAITEMENTS!$Q2="","",TRAITEMENTS!E2) | C2: =IF(TRAITEMENTS!$Q2="","",TRAITEMENTS!F2) | D2: =IF(TRAITEMENTS!$Q2="","",TRAITEMENTS!G2) | E2: =IF(TRAITEMENTS!$Q2="","",TRAITEMENTS!H2) | F2: =IF(TRAITEMENTS!$Q2="","",TRAITEMENTS!O2) | G2: =IF(A2="",0,SUMIFS(TRAITEMENTS!$O$2:$O$501,TRAITEMENTS!$Q$2:$Q$501,A2,TRAITEMENTS!$E$2:$E$501,B2)) | H2: =IF(A2="",0,SUMIFS(CONNEXIONS!$C$2:$C$501,CONNEXIONS!$D$2:$D$501,A2,CONNEXIONS!$B$2:$B$501,B2)) | I2: =IF(G2=0,0,F2/G2*H2) | J2: =IF(A2="",0,SUMIFS(AJUSTEMENTS!$F$2:$F$501,AJUSTEMENTS!$A$2:$A$501,A2,AJUSTEMENTS!$B$2:$B$501,B2,AJUSTEMENTS!$C$2:$C$501,C2,AJUSTEMENTS!$D$2:$D$501,D2,AJUSTEMENTS!$E$2:$E$501,E2)) | K2: =IF(A2="",0,IF(J2<>0,J2,I2))
A3: =IF(TRAITEMENTS!$Q3="","",TRAITEMENTS!Q3) | B3: =IF(TRAITEMENTS!$Q3="","",TRAITEMENTS!E3) | C3: =IF(TRAITEMENTS!$Q3="","",TRAITEMENTS!F3) | D3: =IF(TRAITEMENTS!$Q3="","",TRAITEMENTS!G3) | E3: =IF(TRAITEMENTS!$Q3="","",TRAITEMENTS!H3) | F3: =IF(TRAITEMENTS!$Q3="","",TRAITEMENTS!O3) | G3: =IF(A3="",0,SUMIFS(TRAITEMENTS!$O$2:$O$501,TRAITEMENTS!$Q$2:$Q$501,A3,TRAITEMENTS!$E$2:$E$501,B3)) | H3: =IF(A3="",0,SUMIFS(CONNEXIONS!$C$2:$C$501,CONNEXIONS!$D$2:$D$501,A3,CONNEXIONS!$B$2:$B$501,B3)) | I3: =IF(G3=0,0,F3/G3*H3) | J3: =IF(A3="",0,SUMIFS(AJUSTEMENTS!$F$2:$F$501,AJUSTEMENTS!$A$2:$A$501,A3,AJUSTEMENTS!$B$2:$B$501,B3,AJUSTEMENTS!$C$2:$C$501,C3,AJUSTEMENTS!$D$2:$D$501,D3,AJUSTEMENTS!$E$2:$E$501,E3)) | K3: =IF(A3="",0,IF(J3<>0,J3,I3))
A4: =IF(TRAITEMENTS!$Q4="","",TRAITEMENTS!Q4) | B4: =IF(TRAITEMENTS!$Q4="","",TRAITEMENTS!E4) | C4: =IF(TRAITEMENTS!$Q4="","",TRAITEMENTS!F4) | D4: =IF(TRAITEMENTS!$Q4="","",TRAITEMENTS!G4) | E4: =IF(TRAITEMENTS!$Q4="","",TRAITEMENTS!H4) | F4: =IF(TRAITEMENTS!$Q4="","",TRAITEMENTS!O4) | G4: =IF(A4="",0,SUMIFS(TRAITEMENTS!$O$2:$O$501,TRAITEMENTS!$Q$2:$Q$501,A4,TRAITEMENTS!$E$2:$E$501,B4)) | H4: =IF(A4="",0,SUMIFS(CONNEXIONS!$C$2:$C$501,CONNEXIONS!$D$2:$D$501,A4,CONNEXIONS!$B$2:$B$501,B4)) | I4: =IF(G4=0,0,F4/G4*H4) | J4: =IF(A4="",0,SUMIFS(AJUSTEMENTS!$F$2:$F$501,AJUSTEMENTS!$A$2:$A$501,A4,AJUSTEMENTS!$B$2:$B$501,B4,AJUSTEMENTS!$C$2:$C$501,C4,AJUSTEMENTS!$D$2:$D$501,D4,AJUSTEMENTS!$E$2:$E$501,E4)) | K4: =IF(A4="",0,IF(J4<>0,J4,I4))
A5: =IF(TRAITEMENTS!$Q5="","",TRAITEMENTS!Q5) | B5: =IF(TRAITEMENTS!$Q5="","",TRAITEMENTS!E5) | C5: =IF(TRAITEMENTS!$Q5="","",TRAITEMENTS!F5) | D5: =IF(TRAITEMENTS!$Q5="","",TRAITEMENTS!G5) | E5: =IF(TRAITEMENTS!$Q5="","",TRAITEMENTS!H5) | F5: =IF(TRAITEMENTS!$Q5="","",TRAITEMENTS!O5) | G5: =IF(A5="",0,SUMIFS(TRAITEMENTS!$O$2:$O$501,TRAITEMENTS!$Q$2:$Q$501,A5,TRAITEMENTS!$E$2:$E$501,B5)) | H5: =IF(A5="",0,SUMIFS(CONNEXIONS!$C$2:$C$501,CONNEXIONS!$D$2:$D$501,A5,CONNEXIONS!$B$2:$B$501,B5)) | I5: =IF(G5=0,0,F5/G5*H5) | J5: =IF(A5="",0,SUMIFS(AJUSTEMENTS!$F$2:$F$501,AJUSTEMENTS!$A$2:$A$501,A5,AJUSTEMENTS!$B$2:$B$501,B5,AJUSTEMENTS!$C$2:$C$501,C5,AJUSTEMENTS!$D$2:$D$501,D5,AJUSTEMENTS!$E$2:$E$501,E5)) | K5: =IF(A5="",0,IF(J5<>0,J5,I5))
A6: =IF(TRAITEMENTS!$Q6="","",TRAITEMENTS!Q6) | B6: =IF(TRAITEMENTS!$Q6="","",TRAITEMENTS!E6) | C6: =IF(TRAITEMENTS!$Q6="","",TRAITEMENTS!F6) | D6: =IF(TRAITEMENTS!$Q6="","",TRAITEMENTS!G6) | E6: =IF(TRAITEMENTS!$Q6="","",TRAITEMENTS!H6) | F6: =IF(TRAITEMENTS!$Q6="","",TRAITEMENTS!O6) | G6: =IF(A6="",0,SUMIFS(TRAITEMENTS!$O$2:$O$501,TRAITEMENTS!$Q$2:$Q$501,A6,TRAITEMENTS!$E$2:$E$501,B6)) | H6: =IF(A6="",0,SUMIFS(CONNEXIONS!$C$2:$C$501,CONNEXIONS!$D$2:$D$501,A6,CONNEXIONS!$B$2:$B$501,B6)) | I6: =IF(G6=0,0,F6/G6*H6) | J6: =IF(A6="",0,SUMIFS(AJUSTEMENTS!$F$2:$F$501,AJUSTEMENTS!$A$2:$A$501,A6,AJUSTEMENTS!$B$2:$B$501,B6,AJUSTEMENTS!$C$2:$C$501,C6,AJUSTEMENTS!$D$2:$D$501,D6,AJUSTEMENTS!$E$2:$E$501,E6)) | K6: =IF(A6="",0,IF(J6<>0,J6,I6))
A7: =IF(TRAITEMENTS!$Q7="","",TRAITEMENTS!Q7) | B7: =IF(TRAITEMENTS!$Q7="","",TRAITEMENTS!E7) | C7: =IF(TRAITEMENTS!$Q7="","",TRAITEMENTS!F7) | D7: =IF(TRAITEMENTS!$Q7="","",TRAITEMENTS!G7) | E7: =IF(TRAITEMENTS!$Q7="","",TRAITEMENTS!H7) | F7: =IF(TRAITEMENTS!$Q7="","",TRAITEMENTS!O7) | G7: =IF(A7="",0,SUMIFS(TRAITEMENTS!$O$2:$O$501,TRAITEMENTS!$Q$2:$Q$501,A7,TRAITEMENTS!$E$2:$E$501,B7)) | H7: =IF(A7="",0,SUMIFS(CONNEXIONS!$C$2:$C$501,CONNEXIONS!$D$2:$D$501,A7,CONNEXIONS!$B$2:$B$501,B7)) | I7: =IF(G7=0,0,F7/G7*H7) | J7: =IF(A7="",0,SUMIFS(AJUSTEMENTS!$F$2:$F$501,AJUSTEMENTS!$A$2:$A$501,A7,AJUSTEMENTS!$B$2:$B$501,B7,AJUSTEMENTS!$C$2:$C$501,C7,AJUSTEMENTS!$D$2:$D$501,D7,AJUSTEMENTS!$E$2:$E$501,E7)) | K7: =IF(A7="",0,IF(J7<>0,J7,I7))
A8: =IF(TRAITEMENTS!$Q8="","",TRAITEMENTS!Q8) | B8: =IF(TRAITEMENTS!$Q8="","",TRAITEMENTS!E8) | C8: =IF(TRAITEMENTS!$Q8="","",TRAITEMENTS!F8) | D8: =IF(TRAITEMENTS!$Q8="","",TRAITEMENTS!G8) | E8: =IF(TRAITEMENTS!$Q8="","",TRAITEMENTS!H8) | F8: =IF(TRAITEMENTS!$Q8="","",TRAITEMENTS!O8) | G8: =IF(A8="",0,SUMIFS(TRAITEMENTS!$O$2:$O$501,TRAITEMENTS!$Q$2:$Q$501,A8,TRAITEMENTS!$E$2:$E$501,B8)) | H8: =IF(A8="",0,SUMIFS(CONNEXIONS!$C$2:$C$501,CONNEXIONS!$D$2:$D$501,A8,CONNEXIONS!$B$2:$B$501,B8)) | I8: =IF(G8=0,0,F8/G8*H8) | J8: =IF(A8="",0,SUMIFS(AJUSTEMENTS!$F$2:$F$501,AJUSTEMENTS!$A$2:$A$501,A8,AJUSTEMENTS!$B$2:$B$501,B8,AJUSTEMENTS!$C$2:$C$501,C8,AJUSTEMENTS!$D$2:$D$501,D8,AJUSTEMENTS!$E$2:$E$501,E8)) | K8: =IF(A8="",0,IF(J8<>0,J8,I8))
A9: =IF(TRAITEMENTS!$Q9="","",TRAITEMENTS!Q9) | B9: =IF(TRAITEMENTS!$Q9="","",TRAITEMENTS!E9) | C9: =IF(TRAITEMENTS!$Q9="","",TRAITEMENTS!F9) | D9: =IF(TRAITEMENTS!$Q9="","",TRAITEMENTS!G9) | E9: =IF(TRAITEMENTS!$Q9="","",TRAITEMENTS!H9) | F9: =IF(TRAITEMENTS!$Q9="","",TRAITEMENTS!O9) | G9: =IF(A9="",0,SUMIFS(TRAITEMENTS!$O$2:$O$501,TRAITEMENTS!$Q$2:$Q$501,A9,TRAITEMENTS!$E$2:$E$501,B9)) | H9: =IF(A9="",0,SUMIFS(CONNEXIONS!$C$2:$C$501,CONNEXIONS!$D$2:$D$501,A9,CONNEXIONS!$B$2:$B$501,B9)) | I9: =IF(G9=0,0,F9/G9*H9) | J9: =IF(A9="",0,SUMIFS(AJUSTEMENTS!$F$2:$F$501,AJUSTEMENTS!$A$2:$A$501,A9,AJUSTEMENTS!$B$2:$B$501,B9,AJUSTEMENTS!$C$2:$C$501,C9,AJUSTEMENTS!$D$2:$D$501,D9,AJUSTEMENTS!$E$2:$E$501,E9)) | K9: =IF(A9="",0,IF(J9<>0,J9,I9))
A10: =IF(TRAITEMENTS!$Q10="","",TRAITEMENTS!Q10) | B10: =IF(TRAITEMENTS!$Q10="","",TRAITEMENTS!E10) | C10: =IF(TRAITEMENTS!$Q10="","",TRAITEMENTS!F10) | D10: =IF(TRAITEMENTS!$Q10="","",TRAITEMENTS!G10) | E10: =IF(TRAITEMENTS!$Q10="","",TRAITEMENTS!H10) | F10: =IF(TRAITEMENTS!$Q10="","",TRAITEMENTS!O10) | G10: =IF(A10="",0,SUMIFS(TRAITEMENTS!$O$2:$O$501,TRAITEMENTS!$Q$2:$Q$501,A10,TRAITEMENTS!$E$2:$E$501,B10)) | H10: =IF(A10="",0,SUMIFS(CONNEXIONS!$C$2:$C$501,CONNEXIONS!$D$2:$D$501,A10,CONNEXIONS!$B$2:$B$501,B10)) | I10: =IF(G10=0,0,F10/G10*H10) | J10: =IF(A10="",0,SUMIFS(AJUSTEMENTS!$F$2:$F$501,AJUSTEMENTS!$A$2:$A$501,A10,AJUSTEMENTS!$B$2:$B$501,B10,AJUSTEMENTS!$C$2:$C$501,C10,AJUSTEMENTS!$D$2:$D$501,D10,AJUSTEMENTS!$E$2:$E$501,E10)) | K10: =IF(A10="",0,IF(J10<>0,J10,I10))
A11: =IF(TRAITEMENTS!$Q11="","",TRAITEMENTS!Q11) | B11: =IF(TRAITEMENTS!$Q11="","",TRAITEMENTS!E11) | C11: =IF(TRAITEMENTS!$Q11="","",TRAITEMENTS!F11) | D11: =IF(TRAITEMENTS!$Q11="","",TRAITEMENTS!G11) | E11: =IF(TRAITEMENTS!$Q11="","",TRAITEMENTS!H11) | F11: =IF(TRAITEMENTS!$Q11="","",TRAITEMENTS!O11) | G11: =IF(A11="",0,SUMIFS(TRAITEMENTS!$O$2:$O$501,TRAITEMENTS!$Q$2:$Q$501,A11,TRAITEMENTS!$E$2:$E$501,B11)) | H11: =IF(A11="",0,SUMIFS(CONNEXIONS!$C$2:$C$501,CONNEXIONS!$D$2:$D$501,A11,CONNEXIONS!$B$2:$B$501,B11)) | I11: =IF(G11=0,0,F11/G11*H11) | J11: =IF(A11="",0,SUMIFS(AJUSTEMENTS!$F$2:$F$501,AJUSTEMENTS!$A$2:$A$501,A11,AJUSTEMENTS!$B$2:$B$501,B11,AJUSTEMENTS!$C$2:$C$501,C11,AJUSTEMENTS!$D$2:$D$501,D11,AJUSTEMENTS!$E$2:$E$501,E11)) | K11: =IF(A11="",0,IF(J11<>0,J11,I11))
A12: =IF(TRAITEMENTS!$Q12="","",TRAITEMENTS!Q12) | B12: =IF(TRAITEMENTS!$Q12="","",TRAITEMENTS!E12) | C12: =IF(TRAITEMENTS!$Q12="","",TRAITEMENTS!F12) | D12: =IF(TRAITEMENTS!$Q12="","",TRAITEMENTS!G12) | E12: =IF(TRAITEMENTS!$Q12="","",TRAITEMENTS!H12) | F12: =IF(TRAITEMENTS!$Q12="","",TRAITEMENTS!O12) | G12: =IF(A12="",0,SUMIFS(TRAITEMENTS!$O$2:$O$501,TRAITEMENTS!$Q$2:$Q$501,A12,TRAITEMENTS!$E$2:$E$501,B12)) | H12: =IF(A12="",0,SUMIFS(CONNEXIONS!$C$2:$C$501,CONNEXIONS!$D$2:$D$501,A12,CONNEXIONS!$B$2:$B$501,B12)) | I12: =IF(G12=0,0,F12/G12*H12) | J12: =IF(A12="",0,SUMIFS(AJUSTEMENTS!$F$2:$F$501,AJUSTEMENTS!$A$2:$A$501,A12,AJUSTEMENTS!$B$2:$B$501,B12,AJUSTEMENTS!$C$2:$C$501,C12,AJUSTEMENTS!$D$2:$D$501,D12,AJUSTEMENTS!$E$2:$E$501,E12)) | K12: =IF(A12="",0,IF(J12<>0,J12,I12))
A13: =IF(TRAITEMENTS!$Q13="","",TRAITEMENTS!Q13) | B13: =IF(TRAITEMENTS!$Q13="","",TRAITEMENTS!E13) | C13: =IF(TRAITEMENTS!$Q13="","",TRAITEMENTS!F13) | D13: =IF(TRAITEMENTS!$Q13="","",TRAITEMENTS!G13) | E13: =IF(TRAITEMENTS!$Q13="","",TRAITEMENTS!H13) | F13: =IF(TRAITEMENTS!$Q13="","",TRAITEMENTS!O13) | G13: =IF(A13="",0,SUMIFS(TRAITEMENTS!$O$2:$O$501,TRAITEMENTS!$Q$2:$Q$501,A13,TRAITEMENTS!$E$2:$E$501,B13)) | H13: =IF(A13="",0,SUMIFS(CONNEXIONS!$C$2:$C$501,CONNEXIONS!$D$2:$D$501,A13,CONNEXIONS!$B$2:$B$501,B13)) | I13: =IF(G13=0,0,F13/G13*H13) | J13: =IF(A13="",0,SUMIFS(AJUSTEMENTS!$F$2:$F$501,AJUSTEMENTS!$A$2:$A$501,A13,AJUSTEMENTS!$B$2:$B$501,B13,AJUSTEMENTS!$C$2:$C$501,C13,AJUSTEMENTS!$D$2:$D$501,D13,AJUSTEMENTS!$E$2:$E$501,E13)) | K13: =IF(A13="",0,IF(J13<>0,J13,I13))
... A501: =IF(TRAITEMENTS!$Q501="","",TRAITEMENTS!Q501) | B501: =IF(TRAITEMENTS!$Q501="","",TRAITEMENTS!E501) | C501: =IF(TRAITEMENTS!$Q501="","",TRAITEMENTS!F501) | D501: =IF(TRAITEMENTS!$Q501="","",TRAITEMENTS!G501) | E501: =IF(TRAITEMENTS!$Q501="","",TRAITEMENTS!H501) | F501: =IF(TRAITEMENTS!$Q501="","",TRAITEMENTS!O501) | G501: =IF(A501="",0,SUMIFS(TRAITEMENTS!$O$2:$O$501,TRAITEMENTS!$Q$2:$Q$501,A501,TRAITEMENTS!$E$2:$E$501,B501)) | H501: =IF(A501="",0,SUMIFS(CONNEXIONS!$C$2:$C$501,CONNEXIONS!$D$2:$D$501,A501,CONNEXIONS!$B$2:$B$501,B501)) | I501: =IF(G501=0,0,F501/G501*H501) | J501: =IF(A501="",0,SUMIFS(AJUSTEMENTS!$F$2:$F$501,AJUSTEMENTS!$A$2:$A$501,A501,AJUSTEMENTS!$B$2:$B$501,B501,AJUSTEMENTS!$C$2:$C$501,C501,AJUSTEMENTS!$D$2:$D$501,D501,AJUSTEMENTS!$E$2:$E$501,E501)) | K501: =IF(A501="",0,IF(J501<>0,J501,I501))

Sheet 2026_10
A1: Entité | B1: Domaine | C1: Sous-domaine | D1: Facturables (h) | E1: Actes | F1: Non facturables (h) | G1: Connectées ventilées (h) | H1: Écart (h) | J1: Année | K1: 2026
A2: ACM | C2: ASS-BIENS | D2: =SUMIFS(TRAITEMENTS!$O$2:$O$501,TRAITEMENTS!$Q$2:$Q$501,$K$3,TRAITEMENTS!$F$2:$F$501,A2,TRAITEMENTS!$G$2:$G$501,B2,TRAITEMENTS!$H$2:$H$501,C2) | E2: =SUMIFS(TRAITEMENTS!$R$2:$R$501,TRAITEMENTS!$Q$2:$Q$501,$K$3,TRAITEMENTS!$F$2:$F$501,A2,TRAITEMENTS!$G$2:$G$501,B2,TRAITEMENTS!$H$2:$H$501,C2) | F2: =SUMIFS(TRAITEMENTS!$P$2:$P$501,TRAITEMENTS!$Q$2:$Q$501,$K$3,TRAITEMENTS!$F$2:$F$501,A2,TRAITEMENTS!$G$2:$G$501,B2,TRAITEMENTS!$H$2:$H$501,C2) | G2: =SUMIFS(VENTILATION!$K$2:$K$501,VENTILATION!$A$2:$A$501,$K$3,VENTILATION!$C$2:$C$501,A2,VENTILATION!$D$2:$D$501,B2,VENTILATION!$E$2:$E$501,C2) | H2: =D2-G2 | J2: Mois | K2: 10
A3: ACM | C3: ASS-COMPTA-CONTENTIEUX | D3: =SUMIFS(TRAITEMENTS!$O$2:$O$501,TRAITEMENTS!$Q$2:$Q$501,$K$3,TRAITEMENTS!$F$2:$F$501,A3,TRAITEMENTS!$G$2:$G$501,B3,TRAITEMENTS!$H$2:$H$501,C3) | E3: =SUMIFS(TRAITEMENTS!$R$2:$R$501,TRAITEMENTS!$Q$2:$Q$501,$K$3,TRAITEMENTS!$F$2:$F$501,A3,TRAITEMENTS!$G$2:$G$501,B3,TRAITEMENTS!$H$2:$H$501,C3) | F3: =SUMIFS(TRAITEMENTS!$P$2:$P$501,TRAITEMENTS!$Q$2:$Q$501,$K$3,TRAITEMENTS!$F$2:$F$501,A3,TRAITEMENTS!$G$2:$G$501,B3,TRAITEMENTS!$H$2:$H$501,C3) | G3: =SUMIFS(VENTILATION!$K$2:$K$501,VENTILATION!$A$2:$A$501,$K$3,VENTILATION!$C$2:$C$501,A3,VENTILATION!$D$2:$D$501,B3,VENTILATION!$E$2:$E$501,C3) | H3: =D3-G3 | J3: Clé | K3: 202610
A4: ACM | C4: ASS-EMPRUNTEURS | D4: =SUMIFS(TRAITEMENTS!$O$2:$O$501,TRAITEMENTS!$Q$2:$Q$501,$K$3,TRAITEMENTS!$F$2:$F$501,A4,TRAITEMENTS!$G$2:$G$501,B4,TRAITEMENTS!$H$2:$H$501,C4) | E4: =SUMIFS(TRAITEMENTS!$R$2:$R$501,TRAITEMENTS!$Q$2:$Q$501,$K$3,TRAITEMENTS!$F$2:$F$501,A4,TRAITEMENTS!$G$2:$G$501,B4,TRAITEMENTS!$H$2:$H$501,C4) | F4: =SUMIFS(TRAITEMENTS!$P$2:$P$501,TRAITEMENTS!$Q$2:$Q$501,$K$3,TRAITEMENTS!$F$2:$F$501,A4,TRAITEMENTS!$G$2:$G$501,B4,TRAITEMENTS!$H$2:$H$501,C4) | G4: =SUMIFS(VENTILATION!$K$2:$K$501,VENTILATION!$A$2:$A$501,$K$3,VENTILATION!$C$2:$C$501,A4,VENTILATION!$D$2:$D$501,B4,VENTILATION!$E$2:$E$501,C4) | H4: =D4-G4
A5: ACM | C5: ASS-ERE | D5: =SUMIFS(TRAITEMENTS!$O$2:$O$501,TRAITEMENTS!$Q$2:$Q$501,$K$3,TRAITEMENTS!$F$2:$F$501,A5,TRAITEMENTS!$G$2:$G$501,B5,TRAITEMENTS!$H$2:$H$501,C5) | E5: =SUMIFS(TRAITEMENTS!$R$2:$R$501,TRAITEMENTS!$Q$2:$Q$501,$K$3,TRAITEMENTS!$F$2:$F$501,A5,TRAITEMENTS!$G$2:$G$501,B5,TRAITEMENTS!$H$2:$H$501,C5) | F5: =SUMIFS(TRAITEMENTS!$P$2:$P$501,TRAITEMENTS!$Q$2:$Q$501,$K$3,TRAITEMENTS!$F$2:$F$501,A5,TRAITEMENTS!$G$2:$G$501,B5,TRAITEMENTS!$H$2:$H$501,C5) | G5: =SUMIFS(VENTILATION!$K$2:$K$501,VENTILATION!$A$2:$A$501,$K$3,VENTILATION!$C$2:$C$501,A5,VENTILATION!$D$2:$D$501,B5,VENTILATION!$E$2:$E$501,C5) | H5: =D5-G5 | J5: Connectées | K5: =SUMIFS(CONNEXIONS!C2:C501,CONNEXIONS!D2:D501,K3)
A6: ACM | C6: ASS-INDEMN-BIENS-PERS | D6: =SUMIFS(TRAITEMENTS!$O$2:$O$501,TRAITEMENTS!$Q$2:$Q$501,$K$3,TRAITEMENTS!$F$2:$F$501,A6,TRAITEMENTS!$G$2:$G$501,B6,TRAITEMENTS!$H$2:$H$501,C6) | E6: =SUMIFS(TRAITEMENTS!$R$2:$R$501,TRAITEMENTS!$Q$2:$Q$501,$K$3,TRAITEMENTS!$F$2:$F$501,A6,TRAITEMENTS!$G$2:$G$501,B6,TRAITEMENTS!$H$2:$H$501,C6) | F6: =SUMIFS(TRAITEMENTS!$P$2:$P$501,TRAITEMENTS!$Q$2:$Q$501,$K$3,TRAITEMENTS!$F$2:$F$501,A6,TRAITEMENTS!$G$2:$G$501,B6,TRAITEMENTS!$H$2:$H$501,C6) | G6: =SUMIFS(VENTILATION!$K$2:$K$501,VENTILATION!$A$2:$A$501,$K$3,VENTILATION!$C$2:$C$501,A6,VENTILATION!$D$2:$D$501,B6,VENTILATION!$E$2:$E$501,C6) | H6: =D6-G6 | J6: Facturables | K6: =SUM(D2:D38)
A7: ACM | C7: ASS-PERS-COLL | D7: =SUMIFS(TRAITEMENTS!$O$2:$O$501,TRAITEMENTS!$Q$2:$Q$501,$K$3,TRAITEMENTS!$F$2:$F$501,A7,TRAITEMENTS!$G$2:$G$501,B7,TRAITEMENTS!$H$2:$H$501,C7) | E7: =SUMIFS(TRAITEMENTS!$R$2:$R$501,TRAITEMENTS!$Q$2:$Q$501,$K$3,TRAITEMENTS!$F$2:$F$501,A7,TRAITEMENTS!$G$2:$G$501,B7,TRAITEMENTS!$H$2:$H$501,C7) | F7: =SUMIFS(TRAITEMENTS!$P$2:$P$501,TRAITEMENTS!$Q$2:$Q$501,$K$3,TRAITEMENTS!$F$2:$F$501,A7,TRAITEMENTS!$G$2:$G$501,B7,TRAITEMENTS!$H$2:$H$501,C7) | G7: =SUMIFS(VENTILATION!$K$2:$K$501,VENTILATION!$A$2:$A$501,$K$3,VENTILATION!$C$2:$C$501,A7,VENTILATION!$D$2:$D$501,B7,VENTILATION!$E$2:$E$501,C7) | H7: =D7-G7 | J7: Actes | K7: =SUM(E2:E38)
A8: ACM | C8: ASS-PERS-IND | D8: =SUMIFS(TRAITEMENTS!$O$2:$O$501,TRAITEMENTS!$Q$2:$Q$501,$K$3,TRAITEMENTS!$F$2:$F$501,A8,TRAITEMENTS!$G$2:$G$501,B8,TRAITEMENTS!$H$2:$H$501,C8) | E8: =SUMIFS(TRAITEMENTS!$R$2:$R$501,TRAITEMENTS!$Q$2:$Q$501,$K$3,TRAITEMENTS!$F$2:$F$501,A8,TRAITEMENTS!$G$2:$G$501,B8,TRAITEMENTS!$H$2:$H$501,C8) | F8: =SUMIFS(TRAITEMENTS!$P$2:$P$501,TRAITEMENTS!$Q$2:$Q$501,$K$3,TRAITEMENTS!$F$2:$F$501,A8,TRAITEMENTS!$G$2:$G$501,B8,TRAITEMENTS!$H$2:$H$501,C8) | G8: =SUMIFS(VENTILATION!$K$2:$K$501,VENTILATION!$A$2:$A$501,$K$3,VENTILATION!$C$2:$C$501,A8,VENTILATION!$D$2:$D$501,B8,VENTILATION!$E$2:$E$501,C8) | H8: =D8-G8 | J8: Non facturables | K8: =SUM(F2:F38)
A9: ACM | C9: ASS-PROTECTION-JUR | D9: =SUMIFS(TRAITEMENTS!$O$2:$O$501,TRAITEMENTS!$Q$2:$Q$501,$K$3,TRAITEMENTS!$F$2:$F$501,A9,TRAITEMENTS!$G$2:$G$501,B9,TRAITEMENTS!$H$2:$H$501,C9) | E9: =SUMIFS(TRAITEMENTS!$R$2:$R$501,TRAITEMENTS!$Q$2:$Q$501,$K$3,TRAITEMENTS!$F$2:$F$501,A9,TRAITEMENTS!$G$2:$G$501,B9,TRAITEMENTS!$H$2:$H$501,C9) | F9: =SUMIFS(TRAITEMENTS!$P$2:$P$501,TRAITEMENTS!$Q$2:$Q$501,$K$3,TRAITEMENTS!$F$2:$F$501,A9,TRAITEMENTS!$G$2:$G$501,B9,TRAITEMENTS!$H$2:$H$501,C9) | G9: =SUMIFS(VENTILATION!$K$2:$K$501,VENTILATION!$A$2:$A$501,$K$3,VENTILATION!$C$2:$C$501,A9,VENTILATION!$D$2:$D$501,B9,VENTILATION!$E$2:$E$501,C9) | H9: =D9-G9 | J9: Écart | K9: =K6-K5
A10: ACM | C10: ASS-VIE-EPARGNE-RET | D10: =SUMIFS(TRAITEMENTS!$O$2:$O$501,TRAITEMENTS!$Q$2:$Q$501,$K$3,TRAITEMENTS!$F$2:$F$501,A10,TRAITEMENTS!$G$2:$G$501,B10,TRAITEMENTS!$H$2:$H$501,C10) | E10: =SUMIFS(TRAITEMENTS!$R$2:$R$501,TRAITEMENTS!$Q$2:$Q$501,$K$3,TRAITEMENTS!$F$2:$F$501,A10,TRAITEMENTS!$G$2:$G$501,B10,TRAITEMENTS!$H$2:$H$501,C10) | F10: =SUMIFS(TRAITEMENTS!$P$2:$P$501,TRAITEMENTS!$Q$2:$Q$501,$K$3,TRAITEMENTS!$F$2:$F$501,A10,TRAITEMENTS!$G$2:$G$501,B10,TRAITEMENTS!$H$2:$H$501,C10) | G10: =SUMIFS(VENTILATION!$K$2:$K$501,VENTILATION!$A$2:$A$501,$K$3,VENTILATION!$C$2:$C$501,A10,VENTILATION!$D$2:$D$501,B10,VENTILATION!$E$2:$E$501,C10) | H10: =D10-G10 | J10: Non ventilées | K10: =K5-SUM(G2:G38)
A11: COFIDIS France | B11: DMA | C11: DMA – Agence WEB | D11: =SUMIFS(TRAITEMENTS!$O$2:$O$501,TRAITEMENTS!$Q$2:$Q$501,$K$3,TRAITEMENTS!$F$2:$F$501,A11,TRAITEMENTS!$G$2:$G$501,B11,TRAITEMENTS!$H$2:$H$501,C11) | E11: =SUMIFS(TRAITEMENTS!$R$2:$R$501,TRAITEMENTS!$Q$2:$Q$501,$K$3,TRAITEMENTS!$F$2:$F$501,A11,TRAITEMENTS!$G$2:$G$501,B11,TRAITEMENTS!$H$2:$H$501,C11) | F11: =SUMIFS(TRAITEMENTS!$P$2:$P$501,TRAITEMENTS!$Q$2:$Q$501,$K$3,TRAITEMENTS!$F$2:$F$501,A11,TRAITEMENTS!$G$2:$G$501,B11,TRAITEMENTS!$H$2:$H$501,C11) | G11: =SUMIFS(VENTILATION!$K$2:$K$501,VENTILATION!$A$2:$A$501,$K$3,VENTILATION!$C$2:$C$501,A11,VENTILATION!$D$2:$D$501,B11,VENTILATION!$E$2:$E$501,C11) | H11: =D11-G11
A12: COFIDIS France | B12: DMA | C12: DMA – Marque et Stratégie | D12: =SUMIFS(TRAITEMENTS!$O$2:$O$501,TRAITEMENTS!$Q$2:$Q$501,$K$3,TRAITEMENTS!$F$2:$F$501,A12,TRAITEMENTS!$G$2:$G$501,B12,TRAITEMENTS!$H$2:$H$501,C12) | E12: =SUMIFS(TRAITEMENTS!$R$2:$R$501,TRAITEMENTS!$Q$2:$Q$501,$K$3,TRAITEMENTS!$F$2:$F$501,A12,TRAITEMENTS!$G$2:$G$501,B12,TRAITEMENTS!$H$2:$H$501,C12) | F12: =SUMIFS(TRAITEMENTS!$P$2:$P$501,TRAITEMENTS!$Q$2:$Q$501,$K$3,TRAITEMENTS!$F$2:$F$501,A12,TRAITEMENTS!$G$2:$G$501,B12,TRAITEMENTS!$H$2:$H$501,C12) | G12: =SUMIFS(VENTILATION!$K$2:$K$501,VENTILATION!$A$2:$A$501,$K$3,VENTILATION!$C$2:$C$501,A12,VENTILATION!$D$2:$D$501,B12,VENTILATION!$E$2:$E$501,C12) | H12: =D12-G12
A13: COFIDIS France | B13: DMA | C13: DMA – Performance Digitale | D13: =SUMIFS(TRAITEMENTS!$O$2:$O$501,TRAITEMENTS!$Q$2:$Q$501,$K$3,TRAITEMENTS!$F$2:$F$501,A13,TRAITEMENTS!$G$2:$G$501,B13,TRAITEMENTS!$H$2:$H$501,C13) | E13: =SUMIFS(TRAITEMENTS!$R$2:$R$501,TRAITEMENTS!$Q$2:$Q$501,$K$3,TRAITEMENTS!$F$2:$F$501,A13,TRAITEMENTS!$G$2:$G$501,B13,TRAITEMENTS!$H$2:$H$501,C13) | F13: =SUMIFS(TRAITEMENTS!$P$2:$P$501,TRAITEMENTS!$Q$2:$Q$501,$K$3,TRAITEMENTS!$F$2:$F$501,A13,TRAITEMENTS!$G$2:$G$501,B13,TRAITEMENTS!$H$2:$H$501,C13) | G13: =SUMIFS(VENTILATION!$K$2:$K$501,VENTILATION!$A$2:$A$501,$K$3,VENTILATION!$C$2:$C$501,A13,VENTILATION!$D$2:$D$501,B13,VENTILATION!$E$2:$E$501,C13) | H13: =D13-G13
A14: COFIDIS France | B14: DPA | C14: DPA – Domaine Marketing | D14: =SUMIFS(TRAITEMENTS!$O$2:$O$501,TRAITEMENTS!$Q$2:$Q$501,$K$3,TRAITEMENTS!$F$2:$F$501,A14,TRAITEMENTS!$G$2:$G$501,B14,TRAITEMENTS!$H$2:$H$501,C14) | E14: =SUMIFS(TRAITEMENTS!$R$2:$R$501,TRAITEMENTS!$Q$2:$Q$501,$K$3,TRAITEMENTS!$F$2:$F$501,A14,TRAITEMENTS!$G$2:$G$501,B14,TRAITEMENTS!$H$2:$H$501,C14) | F14: =SUMIFS(TRAITEMENTS!$P$2:$P$501,TRAITEMENTS!$Q$2:$Q$501,$K$3,TRAITEMENTS!$F$2:$F$501,A14,TRAITEMENTS!$G$2:$G$501,B14,TRAITEMENTS!$H$2:$H$501,C14) | G14: =SUMIFS(VENTILATION!$K$2:$K$501,VENTILATION!$A$2:$A$501,$K$3,VENTILATION!$C$2:$C$501,A14,VENTILATION!$D$2:$D$501,B14,VENTILATION!$E$2:$E$501,C14) | H14: =D14-G14
A15: COFIDIS France | B15: DPA | C15: DPA – Service Marketing | D15: =SUMIFS(TRAITEMENTS!$O$2:$O$501,TRAITEMENTS!$Q$2:$Q$501,$K$3,TRAITEMENTS!$F$2:$F$501,A15,TRAITEMENTS!$G$2:$G$501,B15,TRAITEMENTS!$H$2:$H$501,C15) | E15: =SUMIFS(TRAITEMENTS!$R$2:$R$501,TRAITEMENTS!$Q$2:$Q$501,$K$3,TRAITEMENTS!$F$2:$F$501,A15,TRAITEMENTS!$G$2:$G$501,B15,TRAITEMENTS!$H$2:$H$501,C15) | F15: =SUMIFS(TRAITEMENTS!$P$2:$P$501,TRAITEMENTS!$Q$2:$Q$501,$K$3,TRAITEMENTS!$F$2:$F$501,A15,TRAITEMENTS!$G$2:$G$501,B15,TRAITEMENTS!$H$2:$H$501,C15) | G15: =SUMIFS(VENTILATION!$K$2:$K$501,VENTILATION!$A$2:$A$501,$K$3,VENTILATION!$C$2:$C$501,A15,VENTILATION!$D$2:$D$501,B15,VENTILATION!$E$2:$E$501,C15) | H15: =D15-G15
A16: COFIDIS France | B16: DPA | C16: DPA – Service Relation | D16: =SUMIFS(TRAITEMENTS!$O$2:$O$501,TRAITEMENTS!$Q$2:$Q$501,$K$3,TRAITEMENTS!$F$2:$F$501,A16,TRAITEMENTS!$G$2:$G$501,B16,TRAITEMENTS!$H$2:$H$501,C16) | E16: =SUMIFS(TRAITEMENTS!$R$2:$R$501,TRAITEMENTS!$Q$2:$Q$501,$K$3,TRAITEMENTS!$F$2:$F$501,A16,TRAITEMENTS!$G$2:$G$501,B16,TRAITEMENTS!$H$2:$H$501,C16) | F16: =SUMIFS(TRAITEMENTS!$P$2:$P$501,TRAITEMENTS!$Q$2:$Q$501,$K$3,TRAITEMENTS!$F$2:$F$501,A16,TRAITEMENTS!$G$2:$G$501,B16,TRAITEMENTS!$H$2:$H$501,C16) | G16: =SUMIFS(VENTILATION!$K$2:$K$501,VENTILATION!$A$2:$A$501,$K$3,VENTILATION!$C$2:$C$501,A16,VENTILATION!$D$2:$D$501,B16,VENTILATION!$E$2:$E$501,C16) | H16: =D16-G16
A17: CONTRATHEQUE | B17: CONDITIONS GENERALES | C17: CIC | D17: =SUMIFS(TRAITEMENTS!$O$2:$O$501,TRAITEMENTS!$Q$2:$Q$501,$K$3,TRAITEMENTS!$F$2:$F$501,A17,TRAITEMENTS!$G$2:$G$501,B17,TRAITEMENTS!$H$2:$H$501,C17) | E17: =SUMIFS(TRAITEMENTS!$R$2:$R$501,TRAITEMENTS!$Q$2:$Q$501,$K$3,TRAITEMENTS!$F$2:$F$501,A17,TRAITEMENTS!$G$2:$G$501,B17,TRAITEMENTS!$H$2:$H$501,C17) | F17: =SUMIFS(TRAITEMENTS!$P$2:$P$501,TRAITEMENTS!$Q$2:$Q$501,$K$3,TRAITEMENTS!$F$2:$F$501,A17,TRAITEMENTS!$G$2:$G$501,B17,TRAITEMENTS!$H$2:$H$501,C17) | G17: =SUMIFS(VENTILATION!$K$2:$K$501,VENTILATION!$A$2:$A$501,$K$3,VENTILATION!$C$2:$C$501,A17,VENTILATION!$D$2:$D$501,B17,VENTILATION!$E$2:$E$501,C17) | H17: =D17-G17
A18: CONTRATHEQUE | B18: CONDITIONS GENERALES | C18: CM | D18: =SUMIFS(TRAITEMENTS!$O$2:$O$501,TRAITEMENTS!$Q$2:$Q$501,$K$3,TRAITEMENTS!$F$2:$F$501,A18,TRAITEMENTS!$G$2:$G$501,B18,TRAITEMENTS!$H$2:$H$501,C18) | E18: =SUMIFS(TRAITEMENTS!$R$2:$R$501,TRAITEMENTS!$Q$2:$Q$501,$K$3,TRAITEMENTS!$F$2:$F$501,A18,TRAITEMENTS!$G$2:$G$501,B18,TRAITEMENTS!$H$2:$H$501,C18) | F18: =SUMIFS(TRAITEMENTS!$P$2:$P$501,TRAITEMENTS!$Q$2:$Q$501,$K$3,TRAITEMENTS!$F$2:$F$501,A18,TRAITEMENTS!$G$2:$G$501,B18,TRAITEMENTS!$H$2:$H$501,C18) | G18: =SUMIFS(VENTILATION!$K$2:$K$501,VENTILATION!$A$2:$A$501,$K$3,VENTILATION!$C$2:$C$501,A18,VENTILATION!$D$2:$D$501,B18,VENTILATION!$E$2:$E$501,C18) | H18: =D18-G18
A19: CONTRATHEQUE | B19: CONDITIONS GENERALES | C19: Mixte | D19: =SUMIFS(TRAITEMENTS!$O$2:$O$501,TRAITEMENTS!$Q$2:$Q$501,$K$3,TRAITEMENTS!$F$2:$F$501,A19,TRAITEMENTS!$G$2:$G$501,B19,TRAITEMENTS!$H$2:$H$501,C19) | E19: =SUMIFS(TRAITEMENTS!$R$2:$R$501,TRAITEMENTS!$Q$2:$Q$501,$K$3,TRAITEMENTS!$F$2:$F$501,A19,TRAITEMENTS!$G$2:$G$501,B19,TRAITEMENTS!$H$2:$H$501,C19) | F19: =SUMIFS(TRAITEMENTS!$P$2:$P$501,TRAITEMENTS!$Q$2:$Q$501,$K$3,TRAITEMENTS!$F$2:$F$501,A19,TRAITEMENTS!$G$2:$G$501,B19,TRAITEMENTS!$H$2:$H$501,C19) | G19: =SUMIFS(VENTILATION!$K$2:$K$501,VENTILATION!$A$2:$A$501,$K$3,VENTILATION!$C$2:$C$501,A19,VENTILATION!$D$2:$D$501,B19,VENTILATION!$E$2:$E$501,C19) | H19: =D19-G19
A20: CONTRATHEQUE | B20: DOCUMENT D'INFORMATION TARIFAIRE | D20: =SUMIFS(TRAITEMENTS!$O$2:$O$501,TRAITEMENTS!$Q$2:$Q$501,$K$3,TRAITEMENTS!$F$2:$F$501,A20,TRAITEMENTS!$G$2:$G$501,B20,TRAITEMENTS!$H$2:$H$501,C20) | E20: =SUMIFS(TRAITEMENTS!$R$2:$R$501,TRAITEMENTS!$Q$2:$Q$501,$K$3,TRAITEMENTS!$F$2:$F$501,A20,TRAITEMENTS!$G$2:$G$501,B20,TRAITEMENTS!$H$2:$H$501,C20) | F20: =SUMIFS(TRAITEMENTS!$P$2:$P$501,TRAITEMENTS!$Q$2:$Q$501,$K$3,TRAITEMENTS!$F$2:$F$501,A20,TRAITEMENTS!$G$2:$G$501,B20,TRAITEMENTS!$H$2:$H$501,C20) | G20: =SUMIFS(VENTILATION!$K$2:$K$501,VENTILATION!$A$2:$A$501,$K$3,VENTILATION!$C$2:$C$501,A20,VENTILATION!$D$2:$D$501,B20,VENTILATION!$E$2:$E$501,C20) | H20: =D20-G20
A21: CONTRATHEQUE | B21: GARANTIES | D21: =SUMIFS(TRAITEMENTS!$O$2:$O$501,TRAITEMENTS!$Q$2:$Q$501,$K$3,TRAITEMENTS!$F$2:$F$501,A21,TRAITEMENTS!$G$2:$G$501,B21,TRAITEMENTS!$H$2:$H$501,C21) | E21: =SUMIFS(TRAITEMENTS!$R$2:$R$501,TRAITEMENTS!$Q$2:$Q$501,$K$3,TRAITEMENTS!$F$2:$F$501,A21,TRAITEMENTS!$G$2:$G$501,B21,TRAITEMENTS!$H$2:$H$501,C21) | F21: =SUMIFS(TRAITEMENTS!$P$2:$P$501,TRAITEMENTS!$Q$2:$Q$501,$K$3,TRAITEMENTS!$F$2:$F$501,A21,TRAITEMENTS!$G$2:$G$501,B21,TRAITEMENTS!$H$2:$H$501,C21) | G21: =SUMIFS(VENTILATION!$K$2:$K$501,VENTILATION!$A$2:$A$501,$K$3,VENTILATION!$C$2:$C$501,A21,VENTILATION!$D$2:$D$501,B21,VENTILATION!$E$2:$E$501,C21) | H21: =D21-G21
A22: CONTRATHEQUE | B22: POLITIQUE DE PROTECTION | D22: =SUMIFS(TRAITEMENTS!$O$2:$O$501,TRAITEMENTS!$Q$2:$Q$501,$K$3,TRAITEMENTS!$F$2:$F$501,A22,TRAITEMENTS!$G$2:$G$501,B22,TRAITEMENTS!$H$2:$H$501,C22) | E22: =SUMIFS(TRAITEMENTS!$R$2:$R$501,TRAITEMENTS!$Q$2:$Q$501,$K$3,TRAITEMENTS!$F$2:$F$501,A22,TRAITEMENTS!$G$2:$G$501,B22,TRAITEMENTS!$H$2:$H$501,C22) | F22: =SUMIFS(TRAITEMENTS!$P$2:$P$501,TRAITEMENTS!$Q$2:$Q$501,$K$3,TRAITEMENTS!$F$2:$F$501,A22,TRAITEMENTS!$G$2:$G$501,B22,TRAITEMENTS!$H$2:$H$501,C22) | G22: =SUMIFS(VENTILATION!$K$2:$K$501,VENTILATION!$A$2:$A$501,$K$3,VENTILATION!$C$2:$C$501,A22,VENTILATION!$D$2:$D$501,B22,VENTILATION!$E$2:$E$501,C22) | H22: =D22-G22
A23: CREATIS | D23: =SUMIFS(TRAITEMENTS!$O$2:$O$501,TRAITEMENTS!$Q$2:$Q$501,$K$3,TRAITEMENTS!$F$2:$F$501,A23,TRAITEMENTS!$G$2:$G$501,B23,TRAITEMENTS!$H$2:$H$501,C23) | E23: =SUMIFS(TRAITEMENTS!$R$2:$R$501,TRAITEMENTS!$Q$2:$Q$501,$K$3,TRAITEMENTS!$F$2:$F$501,A23,TRAITEMENTS!$G$2:$G$501,B23,TRAITEMENTS!$H$2:$H$501,C23) | F23: =SUMIFS(TRAITEMENTS!$P$2:$P$501,TRAITEMENTS!$Q$2:$Q$501,$K$3,TRAITEMENTS!$F$2:$F$501,A23,TRAITEMENTS!$G$2:$G$501,B23,TRAITEMENTS!$H$2:$H$501,C23) | G23: =SUMIFS(VENTILATION!$K$2:$K$501,VENTILATION!$A$2:$A$501,$K$3,VENTILATION!$C$2:$C$501,A23,VENTILATION!$D$2:$D$501,B23,VENTILATION!$E$2:$E$501,C23) | H23: =D23-G23
A24: CMMABN | D24: =SUMIFS(TRAITEMENTS!$O$2:$O$501,TRAITEMENTS!$Q$2:$Q$501,$K$3,TRAITEMENTS!$F$2:$F$501,A24,TRAITEMENTS!$G$2:$G$501,B24,TRAITEMENTS!$H$2:$H$501,C24) | E24: =SUMIFS(TRAITEMENTS!$R$2:$R$501,TRAITEMENTS!$Q$2:$Q$501,$K$3,TRAITEMENTS!$F$2:$F$501,A24,TRAITEMENTS!$G$2:$G$501,B24,TRAITEMENTS!$H$2:$H$501,C24) | F24: =SUMIFS(TRAITEMENTS!$P$2:$P$501,TRAITEMENTS!$Q$2:$Q$501,$K$3,TRAITEMENTS!$F$2:$F$501,A24,TRAITEMENTS!$G$2:$G$501,B24,TRAITEMENTS!$H$2:$H$501,C24) | G24: =SUMIFS(VENTILATION!$K$2:$K$501,VENTILATION!$A$2:$A$501,$K$3,VENTILATION!$C$2:$C$501,A24,VENTILATION!$D$2:$D$501,B24,VENTILATION!$E$2:$E$501,C24) | H24: =D24-G24
A25: MONABANQ | D25: =SUMIFS(TRAITEMENTS!$O$2:$O$501,TRAITEMENTS!$Q$2:$Q$501,$K$3,TRAITEMENTS!$F$2:$F$501,A25,TRAITEMENTS!$G$2:$G$501,B25,TRAITEMENTS!$H$2:$H$501,C25) | E25: =SUMIFS(TRAITEMENTS!$R$2:$R$501,TRAITEMENTS!$Q$2:$Q$501,$K$3,TRAITEMENTS!$F$2:$F$501,A25,TRAITEMENTS!$G$2:$G$501,B25,TRAITEMENTS!$H$2:$H$501,C25) | F25: =SUMIFS(TRAITEMENTS!$P$2:$P$501,TRAITEMENTS!$Q$2:$Q$501,$K$3,TRAITEMENTS!$F$2:$F$501,A25,TRAITEMENTS!$G$2:$G$501,B25,TRAITEMENTS!$H$2:$H$501,C25) | G25: =SUMIFS(VENTILATION!$K$2:$K$501,VENTILATION!$A$2:$A$501,$K$3,VENTILATION!$C$2:$C$501,A25,VENTILATION!$D$2:$D$501,B25,VENTILATION!$E$2:$E$501,C25) | H25: =D25-G25
A26: Bouygues Telecom | D26: =SUMIFS(TRAITEMENTS!$O$2:$O$501,TRAITEMENTS!$Q$2:$Q$501,$K$3,TRAITEMENTS!$F$2:$F$501,A26,TRAITEMENTS!$G$2:$G$501,B26,TRAITEMENTS!$H$2:$H$501,C26) | E26: =SUMIFS(TRAITEMENTS!$R$2:$R$501,TRAITEMENTS!$Q$2:$Q$501,$K$3,TRAITEMENTS!$F$2:$F$501,A26,TRAITEMENTS!$G$2:$G$501,B26,TRAITEMENTS!$H$2:$H$501,C26) | F26: =SUMIFS(TRAITEMENTS!$P$2:$P$501,TRAITEMENTS!$Q$2:$Q$501,$K$3,TRAITEMENTS!$F$2:$F$501,A26,TRAITEMENTS!$G$2:$G$501,B26,TRAITEMENTS!$H$2:$H$501,C26) | G26: =SUMIFS(VENTILATION!$K$2:$K$501,VENTILATION!$A$2:$A$501,$K$3,VENTILATION!$C$2:$C$501,A26,VENTILATION!$D$2:$D$501,B26,VENTILATION!$E$2:$E$501,C26) | H26: =D26-G26
A27: DIRCOM | C27: CIC | D27: =SUMIFS(TRAITEMENTS!$O$2:$O$501,TRAITEMENTS!$Q$2:$Q$501,$K$3,TRAITEMENTS!$F$2:$F$501,A27,TRAITEMENTS!$G$2:$G$501,B27,TRAITEMENTS!$H$2:$H$501,C27) | E27: =SUMIFS(TRAITEMENTS!$R$2:$R$501,TRAITEMENTS!$Q$2:$Q$501,$K$3,TRAITEMENTS!$F$2:$F$501,A27,TRAITEMENTS!$G$2:$G$501,B27,TRAITEMENTS!$H$2:$H$501,C27) | F27: =SUMIFS(TRAITEMENTS!$P$2:$P$501,TRAITEMENTS!$Q$2:$Q$501,$K$3,TRAITEMENTS!$F$2:$F$501,A27,TRAITEMENTS!$G$2:$G$501,B27,TRAITEMENTS!$H$2:$H$501,C27) | G27: =SUMIFS(VENTILATION!$K$2:$K$501,VENTILATION!$A$2:$A$501,$K$3,VENTILATION!$C$2:$C$501,A27,VENTILATION!$D$2:$D$501,B27,VENTILATION!$E$2:$E$501,C27) | H27: =D27-G27
A28: DIRCOM | C28: CM | D28: =SUMIFS(TRAITEMENTS!$O$2:$O$501,TRAITEMENTS!$Q$2:$Q$501,$K$3,TRAITEMENTS!$F$2:$F$501,A28,TRAITEMENTS!$G$2:$G$501,B28,TRAITEMENTS!$H$2:$H$501,C28) | E28: =SUMIFS(TRAITEMENTS!$R$2:$R$501,TRAITEMENTS!$Q$2:$Q$501,$K$3,TRAITEMENTS!$F$2:$F$501,A28,TRAITEMENTS!$G$2:$G$501,B28,TRAITEMENTS!$H$2:$H$501,C28) | F28: =SUMIFS(TRAITEMENTS!$P$2:$P$501,TRAITEMENTS!$Q$2:$Q$501,$K$3,TRAITEMENTS!$F$2:$F$501,A28,TRAITEMENTS!$G$2:$G$501,B28,TRAITEMENTS!$H$2:$H$501,C28) | G28: =SUMIFS(VENTILATION!$K$2:$K$501,VENTILATION!$A$2:$A$501,$K$3,VENTILATION!$C$2:$C$501,A28,VENTILATION!$D$2:$D$501,B28,VENTILATION!$E$2:$E$501,C28) | H28: =D28-G28
A29: DIRCO | C29: CIC | D29: =SUMIFS(TRAITEMENTS!$O$2:$O$501,TRAITEMENTS!$Q$2:$Q$501,$K$3,TRAITEMENTS!$F$2:$F$501,A29,TRAITEMENTS!$G$2:$G$501,B29,TRAITEMENTS!$H$2:$H$501,C29) | E29: =SUMIFS(TRAITEMENTS!$R$2:$R$501,TRAITEMENTS!$Q$2:$Q$501,$K$3,TRAITEMENTS!$F$2:$F$501,A29,TRAITEMENTS!$G$2:$G$501,B29,TRAITEMENTS!$H$2:$H$501,C29) | F29: =SUMIFS(TRAITEMENTS!$P$2:$P$501,TRAITEMENTS!$Q$2:$Q$501,$K$3,TRAITEMENTS!$F$2:$F$501,A29,TRAITEMENTS!$G$2:$G$501,B29,TRAITEMENTS!$H$2:$H$501,C29) | G29: =SUMIFS(VENTILATION!$K$2:$K$501,VENTILATION!$A$2:$A$501,$K$3,VENTILATION!$C$2:$C$501,A29,VENTILATION!$D$2:$D$501,B29,VENTILATION!$E$2:$E$501,C29) | H29: =D29-G29
A30: DIRCO | C30: CM | D30: =SUMIFS(TRAITEMENTS!$O$2:$O$501,TRAITEMENTS!$Q$2:$Q$501,$K$3,TRAITEMENTS!$F$2:$F$501,A30,TRAITEMENTS!$G$2:$G$501,B30,TRAITEMENTS!$H$2:$H$501,C30) | E30: =SUMIFS(TRAITEMENTS!$R$2:$R$501,TRAITEMENTS!$Q$2:$Q$501,$K$3,TRAITEMENTS!$F$2:$F$501,A30,TRAITEMENTS!$G$2:$G$501,B30,TRAITEMENTS!$H$2:$H$501,C30) | F30: =SUMIFS(TRAITEMENTS!$P$2:$P$501,TRAITEMENTS!$Q$2:$Q$501,$K$3,TRAITEMENTS!$F$2:$F$501,A30,TRAITEMENTS!$G$2:$G$501,B30,TRAITEMENTS!$H$2:$H$501,C30) | G30: =SUMIFS(VENTILATION!$K$2:$K$501,VENTILATION!$A$2:$A$501,$K$3,VENTILATION!$C$2:$C$501,A30,VENTILATION!$D$2:$D$501,B30,VENTILATION!$E$2:$E$501,C30) | H30: =D30-G30
A31: CIC CIB Asset Servicing | C31: Agence Clientèle Déposée | D31: =SUMIFS(TRAITEMENTS!$O$2:$O$501,TRAITEMENTS!$Q$2:$Q$501,$K$3,TRAITEMENTS!$F$2:$F$501,A31,TRAITEMENTS!$G$2:$G$501,B31,TRAITEMENTS!$H$2:$H$501,C31) | E31: =SUMIFS(TRAITEMENTS!$R$2:$R$501,TRAITEMENTS!$Q$2:$Q$501,$K$3,TRAITEMENTS!$F$2:$F$501,A31,TRAITEMENTS!$G$2:$G$501,B31,TRAITEMENTS!$H$2:$H$501,C31) | F31: =SUMIFS(TRAITEMENTS!$P$2:$P$501,TRAITEMENTS!$Q$2:$Q$501,$K$3,TRAITEMENTS!$F$2:$F$501,A31,TRAITEMENTS!$G$2:$G$501,B31,TRAITEMENTS!$H$2:$H$501,C31) | G31: =SUMIFS(VENTILATION!$K$2:$K$501,VENTILATION!$A$2:$A$501,$K$3,VENTILATION!$C$2:$C$501,A31,VENTILATION!$D$2:$D$501,B31,VENTILATION!$E$2:$E$501,C31) | H31: =D31-G31
A32: CMO | C32: BAD | D32: =SUMIFS(TRAITEMENTS!$O$2:$O$501,TRAITEMENTS!$Q$2:$Q$501,$K$3,TRAITEMENTS!$F$2:$F$501,A32,TRAITEMENTS!$G$2:$G$501,B32,TRAITEMENTS!$H$2:$H$501,C32) | E32: =SUMIFS(TRAITEMENTS!$R$2:$R$501,TRAITEMENTS!$Q$2:$Q$501,$K$3,TRAITEMENTS!$F$2:$F$501,A32,TRAITEMENTS!$G$2:$G$501,B32,TRAITEMENTS!$H$2:$H$501,C32) | F32: =SUMIFS(TRAITEMENTS!$P$2:$P$501,TRAITEMENTS!$Q$2:$Q$501,$K$3,TRAITEMENTS!$F$2:$F$501,A32,TRAITEMENTS!$G$2:$G$501,B32,TRAITEMENTS!$H$2:$H$501,C32) | G32: =SUMIFS(VENTILATION!$K$2:$K$501,VENTILATION!$A$2:$A$501,$K$3,VENTILATION!$C$2:$C$501,A32,VENTILATION!$D$2:$D$501,B32,VENTILATION!$E$2:$E$501,C32) | H32: =D32-G32
A33: CMO | C33: Cartes bancaires | D33: =SUMIFS(TRAITEMENTS!$O$2:$O$501,TRAITEMENTS!$Q$2:$Q$501,$K$3,TRAITEMENTS!$F$2:$F$501,A33,TRAITEMENTS!$G$2:$G$501,B33,TRAITEMENTS!$H$2:$H$501,C33) | E33: =SUMIFS(TRAITEMENTS!$R$2:$R$501,TRAITEMENTS!$Q$2:$Q$501,$K$3,TRAITEMENTS!$F$2:$F$501,A33,TRAITEMENTS!$G$2:$G$501,B33,TRAITEMENTS!$H$2:$H$501,C33) | F33: =SUMIFS(TRAITEMENTS!$P$2:$P$501,TRAITEMENTS!$Q$2:$Q$501,$K$3,TRAITEMENTS!$F$2:$F$501,A33,TRAITEMENTS!$G$2:$G$501,B33,TRAITEMENTS!$H$2:$H$501,C33) | G33: =SUMIFS(VENTILATION!$K$2:$K$501,VENTILATION!$A$2:$A$501,$K$3,VENTILATION!$C$2:$C$501,A33,VENTILATION!$D$2:$D$501,B33,VENTILATION!$E$2:$E$501,C33) | H33: =D33-G33
A34: CMO | C34: Compte courant | D34: =SUMIFS(TRAITEMENTS!$O$2:$O$501,TRAITEMENTS!$Q$2:$Q$501,$K$3,TRAITEMENTS!$F$2:$F$501,A34,TRAITEMENTS!$G$2:$G$501,B34,TRAITEMENTS!$H$2:$H$501,C34) | E34: =SUMIFS(TRAITEMENTS!$R$2:$R$501,TRAITEMENTS!$Q$2:$Q$501,$K$3,TRAITEMENTS!$F$2:$F$501,A34,TRAITEMENTS!$G$2:$G$501,B34,TRAITEMENTS!$H$2:$H$501,C34) | F34: =SUMIFS(TRAITEMENTS!$P$2:$P$501,TRAITEMENTS!$Q$2:$Q$501,$K$3,TRAITEMENTS!$F$2:$F$501,A34,TRAITEMENTS!$G$2:$G$501,B34,TRAITEMENTS!$H$2:$H$501,C34) | G34: =SUMIFS(VENTILATION!$K$2:$K$501,VENTILATION!$A$2:$A$501,$K$3,VENTILATION!$C$2:$C$501,A34,VENTILATION!$D$2:$D$501,B34,VENTILATION!$E$2:$E$501,C34) | H34: =D34-G34
A35: CMO | C35: Épargne bancaire | D35: =SUMIFS(TRAITEMENTS!$O$2:$O$501,TRAITEMENTS!$Q$2:$Q$501,$K$3,TRAITEMENTS!$F$2:$F$501,A35,TRAITEMENTS!$G$2:$G$501,B35,TRAITEMENTS!$H$2:$H$501,C35) | E35: =SUMIFS(TRAITEMENTS!$R$2:$R$501,TRAITEMENTS!$Q$2:$Q$501,$K$3,TRAITEMENTS!$F$2:$F$501,A35,TRAITEMENTS!$G$2:$G$501,B35,TRAITEMENTS!$H$2:$H$501,C35) | F35: =SUMIFS(TRAITEMENTS!$P$2:$P$501,TRAITEMENTS!$Q$2:$Q$501,$K$3,TRAITEMENTS!$F$2:$F$501,A35,TRAITEMENTS!$G$2:$G$501,B35,TRAITEMENTS!$H$2:$H$501,C35) | G35: =SUMIFS(VENTILATION!$K$2:$K$501,VENTILATION!$A$2:$A$501,$K$3,VENTILATION!$C$2:$C$501,A35,VENTILATION!$D$2:$D$501,B35,VENTILATION!$E$2:$E$501,C35) | H35: =D35-G35
A36: CMO | C36: Épargne financière | D36: =SUMIFS(TRAITEMENTS!$O$2:$O$501,TRAITEMENTS!$Q$2:$Q$501,$K$3,TRAITEMENTS!$F$2:$F$501,A36,TRAITEMENTS!$G$2:$G$501,B36,TRAITEMENTS!$H$2:$H$501,C36) | E36: =SUMIFS(TRAITEMENTS!$R$2:$R$501,TRAITEMENTS!$Q$2:$Q$501,$K$3,TRAITEMENTS!$F$2:$F$501,A36,TRAITEMENTS!$G$2:$G$501,B36,TRAITEMENTS!$H$2:$H$501,C36) | F36: =SUMIFS(TRAITEMENTS!$P$2:$P$501,TRAITEMENTS!$Q$2:$Q$501,$K$3,TRAITEMENTS!$F$2:$F$501,A36,TRAITEMENTS!$G$2:$G$501,B36,TRAITEMENTS!$H$2:$H$501,C36) | G36: =SUMIFS(VENTILATION!$K$2:$K$501,VENTILATION!$A$2:$A$501,$K$3,VENTILATION!$C$2:$C$501,A36,VENTILATION!$D$2:$D$501,B36,VENTILATION!$E$2:$E$501,C36) | H36: =D36-G36
A37: CMO | C37: Packages | D37: =SUMIFS(TRAITEMENTS!$O$2:$O$501,TRAITEMENTS!$Q$2:$Q$501,$K$3,TRAITEMENTS!$F$2:$F$501,A37,TRAITEMENTS!$G$2:$G$501,B37,TRAITEMENTS!$H$2:$H$501,C37) | E37: =SUMIFS(TRAITEMENTS!$R$2:$R$501,TRAITEMENTS!$Q$2:$Q$501,$K$3,TRAITEMENTS!$F$2:$F$501,A37,TRAITEMENTS!$G$2:$G$501,B37,TRAITEMENTS!$H$2:$H$501,C37) | F37: =SUMIFS(TRAITEMENTS!$P$2:$P$501,TRAITEMENTS!$Q$2:$Q$501,$K$3,TRAITEMENTS!$F$2:$F$501,A37,TRAITEMENTS!$G$2:$G$501,B37,TRAITEMENTS!$H$2:$H$501,C37) | G37: =SUMIFS(VENTILATION!$K$2:$K$501,VENTILATION!$A$2:$A$501,$K$3,VENTILATION!$C$2:$C$501,A37,VENTILATION!$D$2:$D$501,B37,VENTILATION!$E$2:$E$501,C37) | H37: =D37-G37
A38: CMO | C38: Tarif | D38: =SUMIFS(TRAITEMENTS!$O$2:$O$501,TRAITEMENTS!$Q$2:$Q$501,$K$3,TRAITEMENTS!$F$2:$F$501,A38,TRAITEMENTS!$G$2:$G$501,B38,TRAITEMENTS!$H$2:$H$501,C38) | E38: =SUMIFS(TRAITEMENTS!$R$2:$R$501,TRAITEMENTS!$Q$2:$Q$501,$K$3,TRAITEMENTS!$F$2:$F$501,A38,TRAITEMENTS!$G$2:$G$501,B38,TRAITEMENTS!$H$2:$H$501,C38) | F38: =SUMIFS(TRAITEMENTS!$P$2:$P$501,TRAITEMENTS!$Q$2:$Q$501,$K$3,TRAITEMENTS!$F$2:$F$501,A38,TRAITEMENTS!$G$2:$G$501,B38,TRAITEMENTS!$H$2:$H$501,C38) | G38: =SUMIFS(VENTILATION!$K$2:$K$501,VENTILATION!$A$2:$A$501,$K$3,VENTILATION!$C$2:$C$501,A38,VENTILATION!$D$2:$D$501,B38,VENTILATION!$E$2:$E$501,C38) | H38: =D38-G38

Sheet 2026_11
A1: Entité | B1: Domaine | C1: Sous-domaine | D1: Facturables (h) | E1: Actes | F1: Non facturables (h) | G1: Connectées ventilées (h) | H1: Écart (h) | J1: Année | K1: 2026
A2: ACM | C2: ASS-BIENS | D2: =SUMIFS(TRAITEMENTS!$O$2:$O$501,TRAITEMENTS!$Q$2:$Q$501,$K$3,TRAITEMENTS!$F$2:$F$501,A2,TRAITEMENTS!$G$2:$G$501,B2,TRAITEMENTS!$H$2:$H$501,C2) | E2: =SUMIFS(TRAITEMENTS!$R$2:$R$501,TRAITEMENTS!$Q$2:$Q$501,$K$3,TRAITEMENTS!$F$2:$F$501,A2,TRAITEMENTS!$G$2:$G$501,B2,TRAITEMENTS!$H$2:$H$501,C2) | F2: =SUMIFS(TRAITEMENTS!$P$2:$P$501,TRAITEMENTS!$Q$2:$Q$501,$K$3,TRAITEMENTS!$F$2:$F$501,A2,TRAITEMENTS!$G$2:$G$501,B2,TRAITEMENTS!$H$2:$H$501,C2) | G2: =SUMIFS(VENTILATION!$K$2:$K$501,VENTILATION!$A$2:$A$501,$K$3,VENTILATION!$C$2:$C$501,A2,VENTILATION!$D$2:$D$501,B2,VENTILATION!$E$2:$E$501,C2) | H2: =D2-G2 | J2: Mois | K2: 11
A3: ACM | C3: ASS-COMPTA-CONTENTIEUX | D3: =SUMIFS(TRAITEMENTS!$O$2:$O$501,TRAITEMENTS!$Q$2:$Q$501,$K$3,TRAITEMENTS!$F$2:$F$501,A3,TRAITEMENTS!$G$2:$G$501,B3,TRAITEMENTS!$H$2:$H$501,C3) | E3: =SUMIFS(TRAITEMENTS!$R$2:$R$501,TRAITEMENTS!$Q$2:$Q$501,$K$3,TRAITEMENTS!$F$2:$F$501,A3,TRAITEMENTS!$G$2:$G$501,B3,TRAITEMENTS!$H$2:$H$501,C3) | F3: =SUMIFS(TRAITEMENTS!$P$2:$P$501,TRAITEMENTS!$Q$2:$Q$501,$K$3,TRAITEMENTS!$F$2:$F$501,A3,TRAITEMENTS!$G$2:$G$501,B3,TRAITEMENTS!$H$2:$H$501,C3) | G3: =SUMIFS(VENTILATION!$K$2:$K$501,VENTILATION!$A$2:$A$501,$K$3,VENTILATION!$C$2:$C$501,A3,VENTILATION!$D$2:$D$501,B3,VENTILATION!$E$2:$E$501,C3) | H3: =D3-G3 | J3: Clé | K3: 202611
A4: ACM | C4: ASS-EMPRUNTEURS | D4: =SUMIFS(TRAITEMENTS!$O$2:$O$501,TRAITEMENTS!$Q$2:$Q$501,$K$3,TRAITEMENTS!$F$2:$F$501,A4,TRAITEMENTS!$G$2:$G$501,B4,TRAITEMENTS!$H$2:$H$501,C4) | E4: =SUMIFS(TRAITEMENTS!$R$2:$R$501,TRAITEMENTS!$Q$2:$Q$501,$K$3,TRAITEMENTS!$F$2:$F$501,A4,TRAITEMENTS!$G$2:$G$501,B4,TRAITEMENTS!$H$2:$H$501,C4) | F4: =SUMIFS(TRAITEMENTS!$P$2:$P$501,TRAITEMENTS!$Q$2:$Q$501,$K$3,TRAITEMENTS!$F$2:$F$501,A4,TRAITEMENTS!$G$2:$G$501,B4,TRAITEMENTS!$H$2:$H$501,C4) | G4: =SUMIFS(VENTILATION!$K$2:$K$501,VENTILATION!$A$2:$A$501,$K$3,VENTILATION!$C$2:$C$501,A4,VENTILATION!$D$2:$D$501,B4,VENTILATION!$E$2:$E$501,C4) | H4: =D4-G4
A5: ACM | C5: ASS-ERE | D5: =SUMIFS(TRAITEMENTS!$O$2:$O$501,TRAITEMENTS!$Q$2:$Q$501,$K$3,TRAITEMENTS!$F$2:$F$501,A5,TRAITEMENTS!$G$2:$G$501,B5,TRAITEMENTS!$H$2:$H$501,C5) | E5: =SUMIFS(TRAITEMENTS!$R$2:$R$501,TRAITEMENTS!$Q$2:$Q$501,$K$3,TRAITEMENTS!$F$2:$F$501,A5,TRAITEMENTS!$G$2:$G$501,B5,TRAITEMENTS!$H$2:$H$501,C5) | F5: =SUMIFS(TRAITEMENTS!$P$2:$P$501,TRAITEMENTS!$Q$2:$Q$501,$K$3,TRAITEMENTS!$F$2:$F$501,A5,TRAITEMENTS!$G$2:$G$501,B5,TRAITEMENTS!$H$2:$H$501,C5) | G5: =SUMIFS(VENTILATION!$K$2:$K$501,VENTILATION!$A$2:$A$501,$K$3,VENTILATION!$C$2:$C$501,A5,VENTILATION!$D$2:$D$501,B5,VENTILATION!$E$2:$E$501,C5) | H5: =D5-G5 | J5: Connectées | K5: =SUMIFS(CONNEXIONS!C2:C501,CONNEXIONS!D2:D501,K3)
A6: ACM | C6: ASS-INDEMN-BIENS-PERS | D6: =SUMIFS(TRAITEMENTS!$O$2:$O$501,TRAITEMENTS!$Q$2:$Q$501,$K$3,TRAITEMENTS!$F$2:$F$501,A6,TRAITEMENTS!$G$2:$G$501,B6,TRAITEMENTS!$H$2:$H$501,C6) | E6: =SUMIFS(TRAITEMENTS!$R$2:$R$501,TRAITEMENTS!$Q$2:$Q$501,$K$3,TRAITEMENTS!$F$2:$F$501,A6,TRAITEMENTS!$G$2:$G$501,B6,TRAITEMENTS!$H$2:$H$501,C6) | F6: =SUMIFS(TRAITEMENTS!$P$2:$P$501,TRAITEMENTS!$Q$2:$Q$501,$K$3,TRAITEMENTS!$F$2:$F$501,A6,TRAITEMENTS!$G$2:$G$501,B6,TRAITEMENTS!$H$2:$H$501,C6) | G6: =SUMIFS(VENTILATION!$K$2:$K$501,VENTILATION!$A$2:$A$501,$K$3,VENTILATION!$C$2:$C$501,A6,VENTILATION!$D$2:$D$501,B6,VENTILATION!$E$2:$E$501,C6) | H6: =D6-G6 | J6: Facturables | K6: =SUM(D2:D38)
A7: ACM | C7: ASS-PERS-COLL | D7: =SUMIFS(TRAITEMENTS!$O$2:$O$501,TRAITEMENTS!$Q$2:$Q$501,$K$3,TRAITEMENTS!$F$2:$F$501,A7,TRAITEMENTS!$G$2:$G$501,B7,TRAITEMENTS!$H$2:$H$501,C7) | E7: =SUMIFS(TRAITEMENTS!$R$2:$R$501,TRAITEMENTS!$Q$2:$Q$501,$K$3,TRAITEMENTS!$F$2:$F$501,A7,TRAITEMENTS!$G$2:$G$501,B7,TRAITEMENTS!$H$2:$H$501,C7) | F7: =SUMIFS(TRAITEMENTS!$P$2:$P$501,TRAITEMENTS!$Q$2:$Q$501,$K$3,TRAITEMENTS!$F$2:$F$501,A7,TRAITEMENTS!$G$2:$G$501,B7,TRAITEMENTS!$H$2:$H$501,C7) | G7: =SUMIFS(VENTILATION!$K$2:$K$501,VENTILATION!$A$2:$A$501,$K$3,VENTILATION!$C$2:$C$501,A7,VENTILATION!$D$2:$D$501,B7,VENTILATION!$E$2:$E$501,C7) | H7: =D7-G7 | J7: Actes | K7: =SUM(E2:E38)
A8: ACM | C8: ASS-PERS-IND | D8: =SUMIFS(TRAITEMENTS!$O$2:$O$501,TRAITEMENTS!$Q$2:$Q$501,$K$3,TRAITEMENTS!$F$2:$F$501,A8,TRAITEMENTS!$G$2:$G$501,B8,TRAITEMENTS!$H$2:$H$501,C8) | E8: =SUMIFS(TRAITEMENTS!$R$2:$R$501,TRAITEMENTS!$Q$2:$Q$501,$K$3,TRAITEMENTS!$F$2:$F$501,A8,TRAITEMENTS!$G$2:$G$501,B8,TRAITEMENTS!$H$2:$H$501,C8) | F8: =SUMIFS(TRAITEMENTS!$P$2:$P$501,TRAITEMENTS!$Q$2:$Q$501,$K$3,TRAITEMENTS!$F$2:$F$501,A8,TRAITEMENTS!$G$2:$G$501,B8,TRAITEMENTS!$H$2:$H$501,C8) | G8: =SUMIFS(VENTILATION!$K$2:$K$501,VENTILATION!$A$2:$A$501,$K$3,VENTILATION!$C$2:$C$501,A8,VENTILATION!$D$2:$D$501,B8,VENTILATION!$E$2:$E$501,C8) | H8: =D8-G8 | J8: Non facturables | K8: =SUM(F2:F38)
A9: ACM | C9: ASS-PROTECTION-JUR | D9: =SUMIFS(TRAITEMENTS!$O$2:$O$501,TRAITEMENTS!$Q$2:$Q$501,$K$3,TRAITEMENTS!$F$2:$F$501,A9,TRAITEMENTS!$G$2:$G$501,B9,TRAITEMENTS!$H$2:$H$501,C9) | E9: =SUMIFS(TRAITEMENTS!$R$2:$R$501,TRAITEMENTS!$Q$2:$Q$501,$K$3,TRAITEMENTS!$F$2:$F$501,A9,TRAITEMENTS!$G$2:$G$501,B9,TRAITEMENTS!$H$2:$H$501,C9) | F9: =SUMIFS(TRAITEMENTS!$P$2:$P$501,TRAITEMENTS!$Q$2:$Q$501,$K$3,TRAITEMENTS!$F$2:$F$501,A9,TRAITEMENTS!$G$2:$G$501,B9,TRAITEMENTS!$H$2:$H$501,C9) | G9: =SUMIFS(VENTILATION!$K$2:$K$501,VENTILATION!$A$2:$A$501,$K$3,VENTILATION!$C$2:$C$501,A9,VENTILATION!$D$2:$D$501,B9,VENTILATION!$E$2:$E$501,C9) | H9: =D9-G9 | J9: Écart | K9: =K6-K5
A10: ACM | C10: ASS-VIE-EPARGNE-RET | D10: =SUMIFS(TRAITEMENTS!$O$2:$O$501,TRAITEMENTS!$Q$2:$Q$501,$K$3,TRAITEMENTS!$F$2:$F$501,A10,TRAITEMENTS!$G$2:$G$501,B10,TRAITEMENTS!$H$2:$H$501,C10) | E10: =SUMIFS(TRAITEMENTS!$R$2:$R$501,TRAITEMENTS!$Q$2:$Q$501,$K$3,TRAITEMENTS!$F$2:$F$501,A10,TRAITEMENTS!$G$2:$G$501,B10,TRAITEMENTS!$H$2:$H$501,C10) | F10: =SUMIFS(TRAITEMENTS!$P$2:$P$501,TRAITEMENTS!$Q$2:$Q$501,$K$3,TRAITEMENTS!$F$2:$F$501,A10,TRAITEMENTS!$G$2:$G$501,B10,TRAITEMENTS!$H$2:$H$501,C10) | G10: =SUMIFS(VENTILATION!$K$2:$K$501,VENTILATION!$A$2:$A$501,$K$3,VENTILATION!$C$2:$C$501,A10,VENTILATION!$D$2:$D$501,B10,VENTILATION!$E$2:$E$501,C10) | H10: =D10-G10 | J10: Non ventilées | K10: =K5-SUM(G2:G38)
A11: COFIDIS France | B11: DMA | C11: DMA – Agence WEB | D11: =SUMIFS(TRAITEMENTS!$O$2:$O$501,TRAITEMENTS!$Q$2:$Q$501,$K$3,TRAITEMENTS!$F$2:$F$501,A11,TRAITEMENTS!$G$2:$G$501,B11,TRAITEMENTS!$H$2:$H$501,C11) | E11: =SUMIFS(TRAITEMENTS!$R$2:$R$501,TRAITEMENTS!$Q$2:$Q$501,$K$3,TRAITEMENTS!$F$2:$F$501,A11,TRAITEMENTS!$G$2:$G$501,B11,TRAITEMENTS!$H$2:$H$501,C11) | F11: =SUMIFS(TRAITEMENTS!$P$2:$P$501,TRAITEMENTS!$Q$2:$Q$501,$K$3,TRAITEMENTS!$F$2:$F$501,A11,TRAITEMENTS!$G$2:$G$501,B11,TRAITEMENTS!$H$2:$H$501,C11) | G11: =SUMIFS(VENTILATION!$K$2:$K$501,VENTILATION!$A$2:$A$501,$K$3,VENTILATION!$C$2:$C$501,A11,VENTILATION!$D$2:$D$501,B11,VENTILATION!$E$2:$E$501,C11) | H11: =D11-G11
A12: COFIDIS France | B12: DMA | C12: DMA – Marque et Stratégie | D12: =SUMIFS(TRAITEMENTS!$O$2:$O$501,TRAITEMENTS!$Q$2:$Q$501,$K$3,TRAITEMENTS!$F$2:$F$501,A12,TRAITEMENTS!$G$2:$G$501,B12,TRAITEMENTS!$H$2:$H$501,C12) | E12: =SUMIFS(TRAITEMENTS!$R$2:$R$501,TRAITEMENTS!$Q$2:$Q$501,$K$3,TRAITEMENTS!$F$2:$F$501,A12,TRAITEMENTS!$G$2:$G$501,B12,TRAITEMENTS!$H$2:$H$501,C12) | F12: =SUMIFS(TRAITEMENTS!$P$2:$P$501,TRAITEMENTS!$Q$2:$Q$501,$K$3,TRAITEMENTS!$F$2:$F$501,A12,TRAITEMENTS!$G$2:$G$501,B12,TRAITEMENTS!$H$2:$H$501,C12) | G12: =SUMIFS(VENTILATION!$K$2:$K$501,VENTILATION!$A$2:$A$501,$K$3,VENTILATION!$C$2:$C$501,A12,VENTILATION!$D$2:$D$501,B12,VENTILATION!$E$2:$E$501,C12) | H12: =D12-G12
A13: COFIDIS France | B13: DMA | C13: DMA – Performance Digitale | D13: =SUMIFS(TRAITEMENTS!$O$2:$O$501,TRAITEMENTS!$Q$2:$Q$501,$K$3,TRAITEMENTS!$F$2:$F$501,A13,TRAITEMENTS!$G$2:$G$501,B13,TRAITEMENTS!$H$2:$H$501,C13) | E13: =SUMIFS(TRAITEMENTS!$R$2:$R$501,TRAITEMENTS!$Q$2:$Q$501,$K$3,TRAITEMENTS!$F$2:$F$501,A13,TRAITEMENTS!$G$2:$G$501,B13,TRAITEMENTS!$H$2:$H$501,C13) | F13: =SUMIFS(TRAITEMENTS!$P$2:$P$501,TRAITEMENTS!$Q$2:$Q$501,$K$3,TRAITEMENTS!$F$2:$F$501,A13,TRAITEMENTS!$G$2:$G$501,B13,TRAITEMENTS!$H$2:$H$501,C13) | G13: =SUMIFS(VENTILATION!$K$2:$K$501,VENTILATION!$A$2:$A$501,$K$3,VENTILATION!$C$2:$C$501,A13,VENTILATION!$D$2:$D$501,B13,VENTILATION!$E$2:$E$501,C13) | H13: =D13-G13
A14: COFIDIS France | B14: DPA | C14: DPA – Domaine Marketing | D14: =SUMIFS(TRAITEMENTS!$O$2:$O$501,TRAITEMENTS!$Q$2:$Q$501,$K$3,TRAITEMENTS!$F$2:$F$501,A14,TRAITEMENTS!$G$2:$G$501,B14,TRAITEMENTS!$H$2:$H$501,C14) | E14: =SUMIFS(TRAITEMENTS!$R$2:$R$501,TRAITEMENTS!$Q$2:$Q$501,$K$3,TRAITEMENTS!$F$2:$F$501,A14,TRAITEMENTS!$G$2:$G$501,B14,TRAITEMENTS!$H$2:$H$501,C14) | F14: =SUMIFS(TRAITEMENTS!$P$2:$P$501,TRAITEMENTS!$Q$2:$Q$501,$K$3,TRAITEMENTS!$F$2:$F$501,A14,TRAITEMENTS!$G$2:$G$501,B14,TRAITEMENTS!$H$2:$H$501,C14) | G14: =SUMIFS(VENTILATION!$K$2:$K$501,VENTILATION!$A$2:$A$501,$K$3,VENTILATION!$C$2:$C$501,A14,VENTILATION!$D$2:$D$501,B14,VENTILATION!$E$2:$E$501,C14) | H14: =D14-G14
A15: COFIDIS France | B15: DPA | C15: DPA – Service Marketing | D15: =SUMIFS(TRAITEMENTS!$O$2:$O$501,TRAITEMENTS!$Q$2:$Q$501,$K$3,TRAITEMENTS!$F$2:$F$501,A15,TRAITEMENTS!$G$2:$G$501,B15,TRAITEMENTS!$H$2:$H$501,C15) | E15: =SUMIFS(TRAITEMENTS!$R$2:$R$501,TRAITEMENTS!$Q$2:$Q$501,$K$3,TRAITEMENTS!$F$2:$F$501,A15,TRAITEMENTS!$G$2:$G$501,B15,TRAITEMENTS!$H$2:$H$501,C15) | F15: =SUMIFS(TRAITEMENTS!$P$2:$P$501,TRAITEMENTS!$Q$2:$Q$501,$K$3,TRAITEMENTS!$F$2:$F$501,A15,TRAITEMENTS!$G$2:$G$501,B15,TRAITEMENTS!$H$2:$H$501,C15) | G15: =SUMIFS(VENTILATION!$K$2:$K$501,VENTILATION!$A$2:$A$501,$K$3,VENTILATION!$C$2:$C$501,A15,VENTILATION!$D$2:$D$501,B15,VENTILATION!$E$2:$E$501,C15) | H15: =D15-G15
A16: COFIDIS France | B16: DPA | C16: DPA – Service Relation | D16: =SUMIFS(TRAITEMENTS!$O$2:$O$501,TRAITEMENTS!$Q$2:$Q$501,$K$3,TRAITEMENTS!$F$2:$F$501,A16,TRAITEMENTS!$G$2:$G$501,B16,TRAITEMENTS!$H$2:$H$501,C16) | E16: =SUMIFS(TRAITEMENTS!$R$2:$R$501,TRAITEMENTS!$Q$2:$Q$501,$K$3,TRAITEMENTS!$F$2:$F$501,A16,TRAITEMENTS!$G$2:$G$501,B16,TRAITEMENTS!$H$2:$H$501,C16) | F16: =SUMIFS(TRAITEMENTS!$P$2:$P$501,TRAITEMENTS!$Q$2:$Q$501,$K$3,TRAITEMENTS!$F$2:$F$501,A16,TRAITEMENTS!$G$2:$G$501,B16,TRAITEMENTS!$H$2:$H$501,C16) | G16: =SUMIFS(VENTILATION!$K$2:$K$501,VENTILATION!$A$2:$A$501,$K$3,VENTILATION!$C$2:$C$501,A16,VENTILATION!$D$2:$D$501,B16,VENTILATION!$E$2:$E$501,C16) | H16: =D16-G16
A17: CONTRATHEQUE | B17: CONDITIONS GENERALES | C17: CIC | D17: =SUMIFS(TRAITEMENTS!$O$2:$O$501,TRAITEMENTS!$Q$2:$Q$501,$K$3,TRAITEMENTS!$F$2:$F$501,A17,TRAITEMENTS!$G$2:$G$501,B17,TRAITEMENTS!$H$2:$H$501,C17) | E17: =SUMIFS(TRAITEMENTS!$R$2:$R$501,TRAITEMENTS!$Q$2:$Q$501,$K$3,TRAITEMENTS!$F$2:$F$501,A17,TRAITEMENTS!$G$2:$G$501,B17,TRAITEMENTS!$H$2:$H$501,C17) | F17: =SUMIFS(TRAITEMENTS!$P$2:$P$501,TRAITEMENTS!$Q$2:$Q$501,$K$3,TRAITEMENTS!$F$2:$F$501,A17,TRAITEMENTS!$G$2:$G$501,B17,TRAITEMENTS!$H$2:$H$501,C17) | G17: =SUMIFS(VENTILATION!$K$2:$K$501,VENTILATION!$A$2:$A$501,$K$3,VENTILATION!$C$2:$C$501,A17,VENTILATION!$D$2:$D$501,B17,VENTILATION!$E$2:$E$501,C17) | H17: =D17-G17
A18: CONTRATHEQUE | B18: CONDITIONS GENERALES | C18: CM | D18: =SUMIFS(TRAITEMENTS!$O$2:$O$501,TRAITEMENTS!$Q$2:$Q$501,$K$3,TRAITEMENTS!$F$2:$F$501,A18,TRAITEMENTS!$G$2:$G$501,B18,TRAITEMENTS!$H$2:$H$501,C18) | E18: =SUMIFS(TRAITEMENTS!$R$2:$R$501,TRAITEMENTS!$Q$2:$Q$501,$K$3,TRAITEMENTS!$F$2:$F$501,A18,TRAITEMENTS!$G$2:$G$501,B18,TRAITEMENTS!$H$2:$H$501,C18) | F18: =SUMIFS(TRAITEMENTS!$P$2:$P$501,TRAITEMENTS!$Q$2:$Q$501,$K$3,TRAITEMENTS!$F$2:$F$501,A18,TRAITEMENTS!$G$2:$G$501,B18,TRAITEMENTS!$H$2:$H$501,C18) | G18: =SUMIFS(VENTILATION!$K$2:$K$501,VENTILATION!$A$2:$A$501,$K$3,VENTILATION!$C$2:$C$501,A18,VENTILATION!$D$2:$D$501,B18,VENTILATION!$E$2:$E$501,C18) | H18: =D18-G18
A19: CONTRATHEQUE | B19: CONDITIONS GENERALES | C19: Mixte | D19: =SUMIFS(TRAITEMENTS!$O$2:$O$501,TRAITEMENTS!$Q$2:$Q$501,$K$3,TRAITEMENTS!$F$2:$F$501,A19,TRAITEMENTS!$G$2:$G$501,B19,TRAITEMENTS!$H$2:$H$501,C19) | E19: =SUMIFS(TRAITEMENTS!$R$2:$R$501,TRAITEMENTS!$Q$2:$Q$501,$K$3,TRAITEMENTS!$F$2:$F$501,A19,TRAITEMENTS!$G$2:$G$501,B19,TRAITEMENTS!$H$2:$H$501,C19) | F19: =SUMIFS(TRAITEMENTS!$P$2:$P$501,TRAITEMENTS!$Q$2:$Q$501,$K$3,TRAITEMENTS!$F$2:$F$501,A19,TRAITEMENTS!$G$2:$G$501,B19,TRAITEMENTS!$H$2:$H$501,C19) | G19: =SUMIFS(VENTILATION!$K$2:$K$501,VENTILATION!$A$2:$A$501,$K$3,VENTILATION!$C$2:$C$501,A19,VENTILATION!$D$2:$D$501,B19,VENTILATION!$E$2:$E$501,C19) | H19: =D19-G19
A20: CONTRATHEQUE | B20: DOCUMENT D'INFORMATION TARIFAIRE | D20: =SUMIFS(TRAITEMENTS!$O$2:$O$501,TRAITEMENTS!$Q$2:$Q$501,$K$3,TRAITEMENTS!$F$2:$F$501,A20,TRAITEMENTS!$G$2:$G$501,B20,TRAITEMENTS!$H$2:$H$501,C20) | E20: =SUMIFS(TRAITEMENTS!$R$2:$R$501,TRAITEMENTS!$Q$2:$Q$501,$K$3,TRAITEMENTS!$F$2:$F$501,A20,TRAITEMENTS!$G$2:$G$501,B20,TRAITEMENTS!$H$2:$H$501,C20) | F20: =SUMIFS(TRAITEMENTS!$P$2:$P$501,TRAITEMENTS!$Q$2:$Q$501,$K$3,TRAITEMENTS!$F$2:$F$501,A20,TRAITEMENTS!$G$2:$G$501,B20,TRAITEMENTS!$H$2:$H$501,C20) | G20: =SUMIFS(VENTILATION!$K$2:$K$501,VENTILATION!$A$2:$A$501,$K$3,VENTILATION!$C$2:$C$501,A20,VENTILATION!$D$2:$D$501,B20,VENTILATION!$E$2:$E$501,C20) | H20: =D20-G20
A21: CONTRATHEQUE | B21: GARANTIES | D21: =SUMIFS(TRAITEMENTS!$O$2:$O$501,TRAITEMENTS!$Q$2:$Q$501,$K$3,TRAITEMENTS!$F$2:$F$501,A21,TRAITEMENTS!$G$2:$G$501,B21,TRAITEMENTS!$H$2:$H$501,C21) | E21: =SUMIFS(TRAITEMENTS!$R$2:$R$501,TRAITEMENTS!$Q$2:$Q$501,$K$3,TRAITEMENTS!$F$2:$F$501,A21,TRAITEMENTS!$G$2:$G$501,B21,TRAITEMENTS!$H$2:$H$501,C21) | F21: =SUMIFS(TRAITEMENTS!$P$2:$P$501,TRAITEMENTS!$Q$2:$Q$501,$K$3,TRAITEMENTS!$F$2:$F$501,A21,TRAITEMENTS!$G$2:$G$501,B21,TRAITEMENTS!$H$2:$H$501,C21) | G21: =SUMIFS(VENTILATION!$K$2:$K$501,VENTILATION!$A$2:$A$501,$K$3,VENTILATION!$C$2:$C$501,A21,VENTILATION!$D$2:$D$501,B21,VENTILATION!$E$2:$E$501,C21) | H21: =D21-G21
A22: CONTRATHEQUE | B22: POLITIQUE DE PROTECTION | D22: =SUMIFS(TRAITEMENTS!$O$2:$O$501,TRAITEMENTS!$Q$2:$Q$501,$K$3,TRAITEMENTS!$F$2:$F$501,A22,TRAITEMENTS!$G$2:$G$501,B22,TRAITEMENTS!$H$2:$H$501,C22) | E22: =SUMIFS(TRAITEMENTS!$R$2:$R$501,TRAITEMENTS!$Q$2:$Q$501,$K$3,TRAITEMENTS!$F$2:$F$501,A22,TRAITEMENTS!$G$2:$G$501,B22,TRAITEMENTS!$H$2:$H$501,C22) | F22: =SUMIFS(TRAITEMENTS!$P$2:$P$501,TRAITEMENTS!$Q$2:$Q$501,$K$3,TRAITEMENTS!$F$2:$F$501,A22,TRAITEMENTS!$G$2:$G$501,B22,TRAITEMENTS!$H$2:$H$501,C22) | G22: =SUMIFS(VENTILATION!$K$2:$K$501,VENTILATION!$A$2:$A$501,$K$3,VENTILATION!$C$2:$C$501,A22,VENTILATION!$D$2:$D$501,B22,VENTILATION!$E$2:$E$501,C22) | H22: =D22-G22
A23: CREATIS | D23: =SUMIFS(TRAITEMENTS!$O$2:$O$501,TRAITEMENTS!$Q$2:$Q$501,$K$3,TRAITEMENTS!$F$2:$F$501,A23,TRAITEMENTS!$G$2:$G$501,B23,TRAITEMENTS!$H$2:$H$501,C23) | E23: =SUMIFS(TRAITEMENTS!$R$2:$R$501,TRAITEMENTS!$Q$2:$Q$501,$K$3,TRAITEMENTS!$F$2:$F$501,A23,TRAITEMENTS!$G$2:$G$501,B23,TRAITEMENTS!$H$2:$H$501,C23) | F23: =SUMIFS(TRAITEMENTS!$P$2:$P$501,TRAITEMENTS!$Q$2:$Q$501,$K$3,TRAITEMENTS!$F$2:$F$501,A23,TRAITEMENTS!$G$2:$G$501,B23,TRAITEMENTS!$H$2:$H$501,C23) | G23: =SUMIFS(VENTILATION!$K$2:$K$501,VENTILATION!$A$2:$A$501,$K$3,VENTILATION!$C$2:$C$501,A23,VENTILATION!$D$2:$D$501,B23,VENTILATION!$E$2:$E$501,C23) | H23: =D23-G23
A24: CMMABN | D24: =SUMIFS(TRAITEMENTS!$O$2:$O$501,TRAITEMENTS!$Q$2:$Q$501,$K$3,TRAITEMENTS!$F$2:$F$501,A24,TRAITEMENTS!$G$2:$G$501,B24,TRAITEMENTS!$H$2:$H$501,C24) | E24: =SUMIFS(TRAITEMENTS!$R$2:$R$501,TRAITEMENTS!$Q$2:$Q$501,$K$3,TRAITEMENTS!$F$2:$F$501,A24,TRAITEMENTS!$G$2:$G$501,B24,TRAITEMENTS!$H$2:$H$501,C24) | F24: =SUMIFS(TRAITEMENTS!$P$2:$P$501,TRAITEMENTS!$Q$2:$Q$501,$K$3,TRAITEMENTS!$F$2:$F$501,A24,TRAITEMENTS!$G$2:$G$501,B24,TRAITEMENTS!$H$2:$H$501,C24) | G24: =SUMIFS(VENTILATION!$K$2:$K$501,VENTILATION!$A$2:$A$501,$K$3,VENTILATION!$C$2:$C$501,A24,VENTILATION!$D$2:$D$501,B24,VENTILATION!$E$2:$E$501,C24) | H24: =D24-G24
A25: MONABANQ | D25: =SUMIFS(TRAITEMENTS!$O$2:$O$501,TRAITEMENTS!$Q$2:$Q$501,$K$3,TRAITEMENTS!$F$2:$F$501,A25,TRAITEMENTS!$G$2:$G$501,B25,TRAITEMENTS!$H$2:$H$501,C25) | E25: =SUMIFS(TRAITEMENTS!$R$2:$R$501,TRAITEMENTS!$Q$2:$Q$501,$K$3,TRAITEMENTS!$F$2:$F$501,A25,TRAITEMENTS!$G$2:$G$501,B25,TRAITEMENTS!$H$2:$H$501,C25) | F25: =SUMIFS(TRAITEMENTS!$P$2:$P$501,TRAITEMENTS!$Q$2:$Q$501,$K$3,TRAITEMENTS!$F$2:$F$501,A25,TRAITEMENTS!$G$2:$G$501,B25,TRAITEMENTS!$H$2:$H$501,C25) | G25: =SUMIFS(VENTILATION!$K$2:$K$501,VENTILATION!$A$2:$A$501,$K$3,VENTILATION!$C$2:$C$501,A25,VENTILATION!$D$2:$D$501,B25,VENTILATION!$E$2:$E$501,C25) | H25: =D25-G25
A26: Bouygues Telecom | D26: =SUMIFS(TRAITEMENTS!$O$2:$O$501,TRAITEMENTS!$Q$2:$Q$501,$K$3,TRAITEMENTS!$F$2:$F$501,A26,TRAITEMENTS!$G$2:$G$501,B26,TRAITEMENTS!$H$2:$H$501,C26) | E26: =SUMIFS(TRAITEMENTS!$R$2:$R$501,TRAITEMENTS!$Q$2:$Q$501,$K$3,TRAITEMENTS!$F$2:$F$501,A26,TRAITEMENTS!$G$2:$G$501,B26,TRAITEMENTS!$H$2:$H$501,C26) | F26: =SUMIFS(TRAITEMENTS!$P$2:$P$501,TRAITEMENTS!$Q$2:$Q$501,$K$3,TRAITEMENTS!$F$2:$F$501,A26,TRAITEMENTS!$G$2:$G$501,B26,TRAITEMENTS!$H$2:$H$501,C26) | G26: =SUMIFS(VENTILATION!$K$2:$K$501,VENTILATION!$A$2:$A$501,$K$3,VENTILATION!$C$2:$C$501,A26,VENTILATION!$D$2:$D$501,B26,VENTILATION!$E$2:$E$501,C26) | H26: =D26-G26
A27: DIRCOM | C27: CIC | D27: =SUMIFS(TRAITEMENTS!$O$2:$O$501,TRAITEMENTS!$Q$2:$Q$501,$K$3,TRAITEMENTS!$F$2:$F$501,A27,TRAITEMENTS!$G$2:$G$501,B27,TRAITEMENTS!$H$2:$H$501,C27) | E27: =SUMIFS(TRAITEMENTS!$R$2:$R$501,TRAITEMENTS!$Q$2:$Q$501,$K$3,TRAITEMENTS!$F$2:$F$501,A27,TRAITEMENTS!$G$2:$G$501,B27,TRAITEMENTS!$H$2:$H$501,C27) | F27: =SUMIFS(TRAITEMENTS!$P$2:$P$501,TRAITEMENTS!$Q$2:$Q$501,$K$3,TRAITEMENTS!$F$2:$F$501,A27,TRAITEMENTS!$G$2:$G$501,B27,TRAITEMENTS!$H$2:$H$501,C27) | G27: =SUMIFS(VENTILATION!$K$2:$K$501,VENTILATION!$A$2:$A$501,$K$3,VENTILATION!$C$2:$C$501,A27,VENTILATION!$D$2:$D$501,B27,VENTILATION!$E$2:$E$501,C27) | H27: =D27-G27
