Workbook
Name Business: " "
Name Data: OFFSET('[1]CM-CIC'!$A$1,,,COUNTA('[1]CM-CIC'!$B:$B),COUNTA('[1]CM-CIC'!$1:$1))
Name Data: OFFSET('CM-CIC'!$A$1,,,COUNTA('CM-CIC'!$B:$B),COUNTA('CM-CIC'!$1:$1))
Name Matricules: " "
Name Nom_complet: " "
Name Pause_déjeuner: Annuaire_roster!#REF!
Name Pause_déjeuner: #REF!
Name Pausette: Annuaire_roster!#REF!
Name Pausette: #REF!
Name PL_Date: #REF!
Name PL_Date: #REF!
Name PL_Entrée: #REF!
Name PL_Entrée: #REF!
Name PL_Nom: #REF!
Name PL_Nom: #REF!
Name PL_Sortie: #REF!
Name PL_Sortie: #REF!
Name Segment: " "
Name Segment_Business12: #N/A
Name Segment_Business141: #N/A
Name Segment_Date: #N/A
Name Segment_Mois12: #N/A
Name Segment_Mois141: #N/A
Name Segment_Segment12: #N/A
Name Segment_Segment141: #N/A
Name Segment_Semaine12: #N/A
Name Segment_Semaine141: #N/A
Name Team: " "

Sheet CM-CIC
A1: Matricule | B1: Nom De l'agent | C1: Hr début shift Réalisée | D1: Hr début shift Planifiée | E1: Hr fin shift Réalisée | F1: Hr Fin shift Planifiée | G1: Durée de la Pause Dej | H1: Dépsement des pauses | I1: Retard Debut de shift | J1: Retard Dej | K1: Somme des retards | L1: Départs Anticipés | M1: Absences | N1: Hr Adherée | O1: Hr Planifiée | P1: Segment | Q1: Date | R1: Hr Abs Pure | S1: Hr Abs Totales | T1: Semaine | U1: Mois | V1: Année | W1: VTO | X1: Heures SUP | Y1: Team | Z1: Business | AA1: Statut | AB1: Congé payé | AC1: Congé sans solde | AD1: Congé spécial | AE1: Jour férié | AF1: Commentaire | AG1: Plannif spécial
A2: =+VLOOKUP(B2,Annuaire_roster!B:G,5,0) -> 1278 | B2: LISSAOUI HIBA | C2: 0.33333333 | D2: 0.33333333 | E2: 0.75 | F2: 0.75 | I2: =IF(IF(OR(C2="",D2="Congé",D2="OFF",D2="Congé spécial"),"",IF(D2>F2,D2-C2,IF(C2-D2<0,0,C2-D2)))<0.00068287037037037,"",IF(OR(D2="Congé",D2="OFF",C2="",D2="Congé spécial"),"",IF(D2>F2,D2-C2,IF(C2-D2<0,0,C2-D2)))) | K2: =IF(SUM(H2:J2)<0.00068287037037037,0,SUM(H2:J2)) -> 0 | L2: =IF(OR(F2="Congé",F2="OFF",M2="Abs",F2="Congé sans solde",F2="Férié",F2="Congé spécial",D2="Congé spécial"),0,IF(F2-E2<0,0,IF(F2-E2<=0.00068287037037037,0,F2-E2))) -> 0 | M2: =IF(AND(O2<>0,C2=""),"Abs",0) -> 0 | N2: =IFERROR(IF(OR(D2="OFF",D2="Congé",M2="Abs",D2="Congé sans solde",D2="Férié"),"",IF(O2-K2-L2>O2,O2,IF(O2-K2-L2<0,"",O2-K2-L2))),"") -> 0.375 | O2: =IF(AG2="2H Pause déjeuner",IF(F2-D2-0.0833333333333333<0,F2-D2-0.0833333333333333+1,F2-D2-0.0833333333333333),IF(OR(AND(F2="OFF",D2="OFF"),AND(F2="Congé",D2="Congé"),AND(F2="Congé sans solde",D2="Congé sans solde"),AND(F2="Congé spécial",D2="Congé spécial"),AND(F2="Férié",D2="Férié"),AND(F2="OFF",D2="Congé"),AND(F2="OFF",D2="Congé sans solde"),AND(F2="OFF",D2="Congé spécial"),AND(F2="OFF",D2="Férié"),AND(F2="Congé",D2="OFF"),AND(F2="Congé",D2="Congé sans solde"),AND(F2="Congé",D2="Congé spécial"),AND(F2="Congé",D2="Férié"),AND(F2="Congé sans solde",D2="OFF"),AND(F2="Congé sans solde",D2="Congé"),AND(F2="Congé sans solde",D2="Congé spécial"),AND(F2="Congé sans solde",D2="Férié"),AND(F2="Congé spécial",D2="OFF"),AND(F2="Congé spécial",D2="Congé"),AND(F2="Congé spécial",D2="Congé sans solde"),AND(F2="Congé spécial",D2="Férié"),AND(F2="Férié",D2="OFF"),AND(F2="Férié",D2="Congé"),AND(F2="Férié",D2="Congé sans solde"),AND(F2="Férié",D2="Congé spécial")),0,IF(OR(F2="OFF",F2="Congé",F2="Congé spécial",F2="Congé sans solde",D2="OFF",D2="Congé",D2="Congé spécial",D2="Congé sans solde"),0.208333333333334,IF(AND(AG2="",F2-D2<0),("24:00:00"-D2)+("00:00:00"+F2)-0.0416666666666667,IF(AND(OR(AG2="Allaitement",AG2="Sans déjeuner"),F2-D2<0),("24:00:00"-D2)+("00:00:00"+F2),IF(AND(AG2="",F2-D2>0.166666666666667),F2-D2-0.0416666666666667,IF(AND(OR(AG2="Allaitement",AG2="Sans déjeuner"),F2-D2>0.166666666666667),F2-D2,F2-D2))))))) -> 0.375 | P2: Accesibilité | Q2: 44804 | R2: =IF(M2="Abs",O2,0) -> 0 | S2: =SUM(R2,L2,I2,J2,W2,H2) -> 0 | T2: ="Sem - "&WEEKNUM(Q2,21) -> Sem - 36 | U2: =PROPER(TEXT(Q2,"mmmm")) -> Septembre | V2: =+TEXT(Q2,"aaa") -> 2026 | X2: =IFERROR(IF(M2="Abs",0,IF((D2-C2+E2-F2)<0.000694444444444444,0,(D2-C2+E2-F2))),0) -> 0 | Y2: =VLOOKUP('CM-CIC'!B2,Annuaire_roster!B:F,4,0) -> OUBRAHIM Mohammed | Z2: =IFERROR(VLOOKUP(B2,[2]Annuaire_roster!B:F,3,0),"-") -> Credit Mutuel | AA2: =IFERROR(VLOOKUP(B2,[2]Annuaire_roster!B:I,6,0),"-") -> - | AB2: =IF(AND(D2="Congé",F2="Congé"),0.333333333333333,IF(OR(AND(D2="Congé",F2<>"Congé"),(AND(F2="Congé",D2<>"Congé"))),0.166666666666667,"")) | AC2: =IF(AND(D2="Congé sans solde",F2="Congé sans solde"),0.333333333333333,IF(OR(AND(D2="Congé sans solde",F2<>"Congé sans solde"),(AND(F2="Congé sans solde",D2<>"Congé sans solde"))),0.166666666666667,"")) | AD2: =IF(AND(D2="Congé spécial",F2="Congé spécial"),0.333333333333333,IF(OR(AND(D2="Congé spécial",F2<>"Congé décès"),(AND(F2="Congé spécial",D2<>"Congé spécial"))),0.166666666666667,"")) | AE2: =IF(AND(D2="Férié",F2="Férié"),0.333333333333333,IF(OR(AND(D2="Férié",F2<>"Férié"),(AND(F2="Férié",D2<>"Férié"))),0.166666666666667,""))
A3: =+VLOOKUP(B3,Annuaire_roster!B:G,5,0) -> 1265 | B3: RMAIDI IMAD | D3: Congé | F3: Congé | K3: 0 | L3: 0 | M3: 0 | O3: 0 | P3: Accesibilité | Q3: 44804 | R3: 0 | S3: 0 | T3: ="Sem - "&WEEKNUM(Q3,21) -> Sem - 36 | U3: =PROPER(TEXT(Q3,"mmmm")) -> Septembre | V3: 2026 | X3: =IFERROR(IF(M3="Abs",0,IF((D3-C3+E3-F3)<0.000694444444444444,0,(D3-C3+E3-F3))),0) -> 0 | Y3: =VLOOKUP('CM-CIC'!B3,Annuaire_roster!B:F,4,0) -> OUBRAHIM Mohammed | Z3: Credit Mutuel | AA3: 0 | AB3: 0.33333333
A4: =+VLOOKUP(B4,Annuaire_roster!B:G,5,0) -> 1317 | B4: HAMDANI MOHAMED | C4: 0.33333333 | D4: 0.33333333 | E4: 0.75 | F4: 0.75 | K4: 0 | L4: 0 | M4: 0 | N4: 0.375 | O4: 0.375 | P4: Accesibilité | Q4: 44804 | R4: 0 | S4: 0 | T4: ="Sem - "&WEEKNUM(Q4,21) -> Sem - 36 | U4: =PROPER(TEXT(Q4,"mmmm")) -> Septembre | V4: 2026 | X4: =IFERROR(IF(M4="Abs",0,IF((D4-C4+E4-F4)<0.000694444444444444,0,(D4-C4+E4-F4))),0) -> 0 | Y4: =VLOOKUP('CM-CIC'!B4,Annuaire_roster!B:F,4,0) -> OUBRAHIM Mohammed | Z4: Credit Mutuel | AA4: 0
A5: =+VLOOKUP(B5,Annuaire_roster!B:G,5,0) -> 1278 | B5: LISSAOUI HIBA | C5: 0.33333333 | D5: 0.33333333 | E5: 0.75 | F5: 0.75 | K5: 0 | L5: 0 | M5: 0 | N5: 0.375 | O5: 0.375 | P5: Accesibilité | Q5: 44805 | R5: 0 | S5: 0 | T5: ="Sem - "&WEEKNUM(Q5,21) -> Sem - 36 | U5: =PROPER(TEXT(Q5,"mmmm")) -> Septembre | V5: 2026 | X5: =IFERROR(IF(M5="Abs",0,IF((D5-C5+E5-F5)<0.000694444444444444,0,(D5-C5+E5-F5))),0) -> 0 | Y5: =VLOOKUP('CM-CIC'!B5,Annuaire_roster!B:F,4,0) -> OUBRAHIM Mohammed | Z5: Credit Mutuel | AA5: 0
A6: =+VLOOKUP(B6,Annuaire_roster!B:G,5,0) -> 1265 | B6: RMAIDI IMAD | D6: Congé | F6: Congé | K6: 0 | L6: 0 | M6: 0 | O6: 0 | P6: Accesibilité | Q6: 44805 | R6: 0 | S6: 0 | T6: ="Sem - "&WEEKNUM(Q6,21) -> Sem - 36 | U6: =PROPER(TEXT(Q6,"mmmm")) -> Septembre | V6: 2026 | X6: =IFERROR(IF(M6="Abs",0,IF((D6-C6+E6-F6)<0.000694444444444444,0,(D6-C6+E6-F6))),0) -> 0 | Y6: =VLOOKUP('CM-CIC'!B6,Annuaire_roster!B:F,4,0) -> OUBRAHIM Mohammed | Z6: Credit Mutuel | AA6: 0 | AB6: 0.33333333
A7: =+VLOOKUP(B7,Annuaire_roster!B:G,5,0) -> 1317 | B7: HAMDANI MOHAMED | C7: 0.33333333 | D7: 0.33333333 | E7: 0.75 | F7: 0.75 | K7: 0 | L7: 0 | M7: 0 | N7: 0.375 | O7: 0.375 | P7: Accesibilité | Q7: 44805 | R7: 0 | S7: 0 | T7: ="Sem - "&WEEKNUM(Q7,21) -> Sem - 36 | U7: =PROPER(TEXT(Q7,"mmmm")) -> Septembre | V7: 2026 | X7: =IFERROR(IF(M7="Abs",0,IF((D7-C7+E7-F7)<0.000694444444444444,0,(D7-C7+E7-F7))),0) -> 0 | Y7: =VLOOKUP('CM-CIC'!B7,Annuaire_roster!B:F,4,0) -> OUBRAHIM Mohammed | Z7: Credit Mutuel | AA7: 0
A8: =+VLOOKUP(B8,Annuaire_roster!B:G,5,0) -> 1278 | B8: LISSAOUI HIBA | C8: 0.33333333 | D8: 0.33333333 | E8: 0.75 | F8: 0.75 | K8: 0 | L8: 0 | M8: 0 | N8: 0.375 | O8: 0.375 | P8: Accesibilité | Q8: 44806 | R8: 0 | S8: 0 | T8: ="Sem - "&WEEKNUM(Q8,21) -> Sem - 36 | U8: =PROPER(TEXT(Q8,"mmmm")) -> Septembre | V8: 2026 | X8: =IFERROR(IF(M8="Abs",0,IF((D8-C8+E8-F8)<0.000694444444444444,0,(D8-C8+E8-F8))),0) -> 0 | Y8: =VLOOKUP('CM-CIC'!B8,Annuaire_roster!B:F,4,0) -> OUBRAHIM Mohammed | Z8: Credit Mutuel | AA8: 0
A9: =+VLOOKUP(B9,Annuaire_roster!B:G,5,0) -> 1265 | B9: RMAIDI IMAD | D9: Congé | F9: Congé | K9: 0 | L9: 0 | M9: 0 | O9: 0 | P9: Accesibilité | Q9: 44806 | R9: 0 | S9: 0 | T9: ="Sem - "&WEEKNUM(Q9,21) -> Sem - 36 | U9: =PROPER(TEXT(Q9,"mmmm")) -> Septembre | V9: 2026 | X9: =IFERROR(IF(M9="Abs",0,IF((D9-C9+E9-F9)<0.000694444444444444,0,(D9-C9+E9-F9))),0) -> 0 | Y9: =VLOOKUP('CM-CIC'!B9,Annuaire_roster!B:F,4,0) -> OUBRAHIM Mohammed | Z9: Credit Mutuel | AA9: 0 | AB9: 0.33333333
A10: =+VLOOKUP(B10,Annuaire_roster!B:G,5,0) -> 1317 | B10: HAMDANI MOHAMED | C10: 0.33333333 | D10: 0.33333333 | E10: 0.75 | F10: 0.75 | K10: 0 | L10: 0 | M10: 0 | N10: 0.375 | O10: 0.375 | P10: Accesibilité | Q10: 44806 | R10: 0 | S10: 0 | T10: ="Sem - "&WEEKNUM(Q10,21) -> Sem - 36 | U10: =PROPER(TEXT(Q10,"mmmm")) -> Septembre | V10: 2026 | X10: =IFERROR(IF(M10="Abs",0,IF((D10-C10+E10-F10)<0.000694444444444444,0,(D10-C10+E10-F10))),0) -> 0 | Y10: =VLOOKUP('CM-CIC'!B10,Annuaire_roster!B:F,4,0) -> OUBRAHIM Mohammed | Z10: Credit Mutuel | AA10: 0
A11: =+VLOOKUP(B11,Annuaire_roster!B:G,5,0) -> 1278 | B11: LISSAOUI HIBA | C11: 0.33333333 | D11: 0.33333333 | E11: 0.70833333 | F11: 0.70833333 | K11: 0 | L11: 0 | M11: 0 | N11: 0.33333333 | O11: 0.33333333 | P11: Accesibilité | Q11: 44807 | R11: 0 | S11: 0 | T11: ="Sem - "&WEEKNUM(Q11,21) -> Sem - 36 | U11: =PROPER(TEXT(Q11,"mmmm")) -> Septembre | V11: 2026 | X11: =IFERROR(IF(M11="Abs",0,IF((D11-C11+E11-F11)<0.000694444444444444,0,(D11-C11+E11-F11))),0) -> 0 | Y11: =VLOOKUP('CM-CIC'!B11,Annuaire_roster!B:F,4,0) -> OUBRAHIM Mohammed | Z11: Credit Mutuel | AA11: 0
A12: =+VLOOKUP(B12,Annuaire_roster!B:G,5,0) -> 1265 | B12: RMAIDI IMAD | D12: Congé | F12: Congé | K12: 0 | L12: 0 | M12: 0 | O12: 0 | P12: Accesibilité | Q12: 44807 | R12: 0 | S12: 0 | T12: ="Sem - "&WEEKNUM(Q12,21) -> Sem - 36 | U12: =PROPER(TEXT(Q12,"mmmm")) -> Septembre | V12: 2026 | X12: =IFERROR(IF(M12="Abs",0,IF((D12-C12+E12-F12)<0.000694444444444444,0,(D12-C12+E12-F12))),0) -> 0 | Y12: =VLOOKUP('CM-CIC'!B12,Annuaire_roster!B:F,4,0) -> OUBRAHIM Mohammed | Z12: Credit Mutuel | AA12: 0 | AB12: 0.33333333
A13: =+VLOOKUP(B13,Annuaire_roster!B:G,5,0) -> 1317 | B13: HAMDANI MOHAMED | C13: 0.33333333 | D13: 0.33333333 | E13: 0.70833333 | F13: 0.70833333 | K13: 0 | L13: 0 | M13: 0 | N13: 0.33333333 | O13: 0.33333333 | P13: Accesibilité | Q13: 44807 | R13: 0 | S13: 0 | T13: ="Sem - "&WEEKNUM(Q13,21) -> Sem - 36 | U13: =PROPER(TEXT(Q13,"mmmm")) -> Septembre | V13: 2026 | X13: =IFERROR(IF(M13="Abs",0,IF((D13-C13+E13-F13)<0.000694444444444444,0,(D13-C13+E13-F13))),0) -> 0 | Y13: =VLOOKUP('CM-CIC'!B13,Annuaire_roster!B:F,4,0) -> OUBRAHIM Mohammed | Z13: Credit Mutuel | AA13: 0
A14: =+VLOOKUP(B14,Annuaire_roster!B:G,5,0) -> 1278 | B14: LISSAOUI HIBA | D14: OFF | F14: OFF | K14: 0 | L14: 0 | M14: 0 | O14: 0 | P14: Accesibilité | Q14: 44808 | R14: 0 | S14: 0 | T14: ="Sem - "&WEEKNUM(Q14,21) -> Sem - 36 | U14: =PROPER(TEXT(Q14,"mmmm")) -> Septembre | V14: 2026 | X14: =IFERROR(IF(M14="Abs",0,IF((D14-C14+E14-F14)<0.000694444444444444,0,(D14-C14+E14-F14))),0) -> 0 | Y14: =VLOOKUP('CM-CIC'!B14,Annuaire_roster!B:F,4,0) -> OUBRAHIM Mohammed | Z14: Credit Mutuel | AA14: 0
A15: =+VLOOKUP(B15,Annuaire_roster!B:G,5,0) -> 1265 | B15: RMAIDI IMAD | D15: OFF | F15: OFF | K15: 0 | L15: 0 | M15: 0 | O15: 0 | P15: Accesibilité | Q15: 44808 | R15: 0 | S15: 0 | T15: ="Sem - "&WEEKNUM(Q15,21) -> Sem - 36 | U15: =PROPER(TEXT(Q15,"mmmm")) -> Septembre | V15: 2026 | X15: =IFERROR(IF(M15="Abs",0,IF((D15-C15+E15-F15)<0.000694444444444444,0,(D15-C15+E15-F15))),0) -> 0 | Y15: =VLOOKUP('CM-CIC'!B15,Annuaire_roster!B:F,4,0) -> OUBRAHIM Mohammed | Z15: Credit Mutuel | AA15: 0
A16: =+VLOOKUP(B16,Annuaire_roster!B:G,5,0) -> 1317 | B16: HAMDANI MOHAMED | D16: OFF | F16: OFF | K16: 0 | L16: 0 | M16: 0 | O16: 0 | P16: Accesibilité | Q16: 44808 | R16: 0 | S16: 0 | T16: ="Sem - "&WEEKNUM(Q16,21) -> Sem - 36 | U16: =PROPER(TEXT(Q16,"mmmm")) -> Septembre | V16: 2026 | X16: =IFERROR(IF(M16="Abs",0,IF((D16-C16+E16-F16)<0.000694444444444444,0,(D16-C16+E16-F16))),0) -> 0 | Y16: =VLOOKUP('CM-CIC'!B16,Annuaire_roster!B:F,4,0) -> OUBRAHIM Mohammed | Z16: Credit Mutuel | AA16: 0
A17: =+VLOOKUP(B17,Annuaire_roster!B:G,5,0) -> 1278 | B17: LISSAOUI HIBA | D17: OFF | F17: OFF | K17: 0 | L17: 0 | M17: 0 | O17: 0 | P17: Accesibilité | Q17: 44809 | R17: 0 | S17: 0 | T17: ="Sem - "&WEEKNUM(Q17,21) -> Sem - 36 | U17: =PROPER(TEXT(Q17,"mmmm")) -> Septembre | V17: 2026 | X17: =IFERROR(IF(M17="Abs",0,IF((D17-C17+E17-F17)<0.000694444444444444,0,(D17-C17+E17-F17))),0) -> 0 | Y17: =VLOOKUP('CM-CIC'!B17,Annuaire_roster!B:F,4,0) -> OUBRAHIM Mohammed | Z17: Credit Mutuel | AA17: 0
A18: =+VLOOKUP(B18,Annuaire_roster!B:G,5,0) -> 1265 | B18: RMAIDI IMAD | D18: OFF | F18: OFF | K18: 0 | L18: 0 | M18: 0 | O18: 0 | P18: Accesibilité | Q18: 44809 | R18: 0 | S18: 0 | T18: ="Sem - "&WEEKNUM(Q18,21) -> Sem - 36 | U18: =PROPER(TEXT(Q18,"mmmm")) -> Septembre | V18: 2026 | X18: =IFERROR(IF(M18="Abs",0,IF((D18-C18+E18-F18)<0.000694444444444444,0,(D18-C18+E18-F18))),0) -> 0 | Y18: =VLOOKUP('CM-CIC'!B18,Annuaire_roster!B:F,4,0) -> OUBRAHIM Mohammed | Z18: Credit Mutuel | AA18: 0
A19: =+VLOOKUP(B19,Annuaire_roster!B:G,5,0) -> 1317 | B19: HAMDANI MOHAMED | D19: OFF | F19: OFF | K19: 0 | L19: 0 | M19: 0 | O19: 0 | P19: Accesibilité | Q19: 44809 | R19: 0 | S19: 0 | T19: ="Sem - "&WEEKNUM(Q19,21) -> Sem - 36 | U19: =PROPER(TEXT(Q19,"mmmm")) -> Septembre | V19: 2026 | X19: =IFERROR(IF(M19="Abs",0,IF((D19-C19+E19-F19)<0.000694444444444444,0,(D19-C19+E19-F19))),0) -> 0 | Y19: =VLOOKUP('CM-CIC'!B19,Annuaire_roster!B:F,4,0) -> OUBRAHIM Mohammed | Z19: Credit Mutuel | AA19: 0
A20: =+VLOOKUP(B20,Annuaire_roster!B:G,5,0) -> 1278 | B20: LISSAOUI HIBA | C20: 0.33333333 | D20: 0.33333333 | E20: 0.75 | F20: 0.75 | K20: 0 | L20: 0 | M20: 0 | N20: =IFERROR(IF(OR(D20="OFF",D20="Congé",M20="Abs",D20="Congé sans solde",D20="Férié"),"",IF(O20-K20-L20>O20,O20,IF(O20-K20-L20<0,"",O20-K20-L20))),"") -> 0.375 | O20: =IF(AG20="2H Pause déjeuner",IF(F20-D20-0.0833333333333333<0,F20-D20-0.0833333333333333+1,F20-D20-0.0833333333333333),IF(OR(AND(F20="OFF",D20="OFF"),AND(F20="Congé",D20="Congé"),AND(F20="Congé sans solde",D20="Congé sans solde"),AND(F20="Congé spécial",D20="Congé spécial"),AND(F20="Férié",D20="Férié"),AND(F20="OFF",D20="Congé"),AND(F20="OFF",D20="Congé sans solde"),AND(F20="OFF",D20="Congé spécial"),AND(F20="OFF",D20="Férié"),AND(F20="Congé",D20="OFF"),AND(F20="Congé",D20="Congé sans solde"),AND(F20="Congé",D20="Congé spécial"),AND(F20="Congé",D20="Férié"),AND(F20="Congé sans solde",D20="OFF"),AND(F20="Congé sans solde",D20="Congé"),AND(F20="Congé sans solde",D20="Congé spécial"),AND(F20="Congé sans solde",D20="Férié"),AND(F20="Congé spécial",D20="OFF"),AND(F20="Congé spécial",D20="Congé"),AND(F20="Congé spécial",D20="Congé sans solde"),AND(F20="Congé spécial",D20="Férié"),AND(F20="Férié",D20="OFF"),AND(F20="Férié",D20="Congé"),AND(F20="Férié",D20="Congé sans solde"),AND(F20="Férié",D20="Congé spécial")),0,IF(OR(F20="OFF",F20="Congé",F20="Congé spécial",F20="Congé sans solde",D20="OFF",D20="Congé",D20="Congé spécial",D20="Congé sans solde"),0.208333333333334,IF(AND(AG20="",F20-D20<0),("24:00:00"-D20)+("00:00:00"+F20)-0.0416666666666667,IF(AND(OR(AG20="Allaitement",AG20="Sans déjeuner"),F20-D20<0),("24:00:00"-D20)+("00:00:00"+F20),IF(AND(AG20="",F20-D20>0.166666666666667),F20-D20-0.0416666666666667,IF(AND(OR(AG20="Allaitement",AG20="Sans déjeuner"),F20-D20>0.166666666666667),F20-D20,F20-D20))))))) -> 0.375 | P20: Accesibilité | Q20: 44810 | R20: 0 | S20: 0 | T20: ="Sem - "&WEEKNUM(Q20,21) -> Sem - 37 | U20: =PROPER(TEXT(Q20,"mmmm")) -> Septembre | V20: 3061 | X20: =IFERROR(IF(M20="Abs",0,IF((D20-C20+E20-F20)<0.000694444444444444,0,(D20-C20+E20-F20))),0) -> 0 | Y20: =VLOOKUP('CM-CIC'!B20,Annuaire_roster!B:F,4,0) -> OUBRAHIM Mohammed | Z20: Credit Mutuel | AA20: FT
A21: =+VLOOKUP(B21,Annuaire_roster!B:G,5,0) -> 1265 | B21: RMAIDI IMAD | C21: 0.33333333 | D21: 0.33333333 | E21: 0.75 | F21: 0.75 | K21: 0 | L21: 0 | M21: 0 | N21: =IFERROR(IF(OR(D21="OFF",D21="Congé",M21="Abs",D21="Congé sans solde",D21="Férié"),"",IF(O21-K21-L21>O21,O21,IF(O21-K21-L21<0,"",O21-K21-L21))),"") -> 0.375 | O21: =IF(AG21="2H Pause déjeuner",IF(F21-D21-0.0833333333333333<0,F21-D21-0.0833333333333333+1,F21-D21-0.0833333333333333),IF(OR(AND(F21="OFF",D21="OFF"),AND(F21="Congé",D21="Congé"),AND(F21="Congé sans solde",D21="Congé sans solde"),AND(F21="Congé spécial",D21="Congé spécial"),AND(F21="Férié",D21="Férié"),AND(F21="OFF",D21="Congé"),AND(F21="OFF",D21="Congé sans solde"),AND(F21="OFF",D21="Congé spécial"),AND(F21="OFF",D21="Férié"),AND(F21="Congé",D21="OFF"),AND(F21="Congé",D21="Congé sans solde"),AND(F21="Congé",D21="Congé spécial"),AND(F21="Congé",D21="Férié"),AND(F21="Congé sans solde",D21="OFF"),AND(F21="Congé sans solde",D21="Congé"),AND(F21="Congé sans solde",D21="Congé spécial"),AND(F21="Congé sans solde",D21="Férié"),AND(F21="Congé spécial",D21="OFF"),AND(F21="Congé spécial",D21="Congé"),AND(F21="Congé spécial",D21="Congé sans solde"),AND(F21="Congé spécial",D21="Férié"),AND(F21="Férié",D21="OFF"),AND(F21="Férié",D21="Congé"),AND(F21="Férié",D21="Congé sans solde"),AND(F21="Férié",D21="Congé spécial")),0,IF(OR(F21="OFF",F21="Congé",F21="Congé spécial",F21="Congé sans solde",D21="OFF",D21="Congé",D21="Congé spécial",D21="Congé sans solde"),0.208333333333334,IF(AND(AG21="",F21-D21<0),("24:00:00"-D21)+("00:00:00"+F21)-0.0416666666666667,IF(AND(OR(AG21="Allaitement",AG21="Sans déjeuner"),F21-D21<0),("24:00:00"-D21)+("00:00:00"+F21),IF(AND(AG21="",F21-D21>0.166666666666667),F21-D21-0.0416666666666667,IF(AND(OR(AG21="Allaitement",AG21="Sans déjeuner"),F21-D21>0.166666666666667),F21-D21,F21-D21))))))) -> 0.375 | P21: Accesibilité | Q21: 44810 | R21: 0 | S21: 0 | T21: ="Sem - "&WEEKNUM(Q21,21) -> Sem - 37 | U21: =PROPER(TEXT(Q21,"mmmm")) -> Septembre | V21: 3062 | X21: =IFERROR(IF(M21="Abs",0,IF((D21-C21+E21-F21)<0.000694444444444444,0,(D21-C21+E21-F21))),0) -> 0 | Y21: =VLOOKUP('CM-CIC'!B21,Annuaire_roster!B:F,4,0) -> OUBRAHIM Mohammed | Z21: Credit Mutuel | AA21: FT
A22: =+VLOOKUP(B22,Annuaire_roster!B:G,5,0) -> 1317 | B22: HAMDANI MOHAMED | C22: 0.33333333 | D22: 0.33333333 | E22: 0.75 | F22: 0.75 | K22: 0 | L22: 0 | M22: 0 | N22: =IFERROR(IF(OR(D22="OFF",D22="Congé",M22="Abs",D22="Congé sans solde",D22="Férié"),"",IF(O22-K22-L22>O22,O22,IF(O22-K22-L22<0,"",O22-K22-L22))),"") -> 0.375 | O22: =IF(AG22="2H Pause déjeuner",IF(F22-D22-0.0833333333333333<0,F22-D22-0.0833333333333333+1,F22-D22-0.0833333333333333),IF(OR(AND(F22="OFF",D22="OFF"),AND(F22="Congé",D22="Congé"),AND(F22="Congé sans solde",D22="Congé sans solde"),AND(F22="Congé spécial",D22="Congé spécial"),AND(F22="Férié",D22="Férié"),AND(F22="OFF",D22="Congé"),AND(F22="OFF",D22="Congé sans solde"),AND(F22="OFF",D22="Congé spécial"),AND(F22="OFF",D22="Férié"),AND(F22="Congé",D22="OFF"),AND(F22="Congé",D22="Congé sans solde"),AND(F22="Congé",D22="Congé spécial"),AND(F22="Congé",D22="Férié"),AND(F22="Congé sans solde",D22="OFF"),AND(F22="Congé sans solde",D22="Congé"),AND(F22="Congé sans solde",D22="Congé spécial"),AND(F22="Congé sans solde",D22="Férié"),AND(F22="Congé spécial",D22="OFF"),AND(F22="Congé spécial",D22="Congé"),AND(F22="Congé spécial",D22="Congé sans solde"),AND(F22="Congé spécial",D22="Férié"),AND(F22="Férié",D22="OFF"),AND(F22="Férié",D22="Congé"),AND(F22="Férié",D22="Congé sans solde"),AND(F22="Férié",D22="Congé spécial")),0,IF(OR(F22="OFF",F22="Congé",F22="Congé spécial",F22="Congé sans solde",D22="OFF",D22="Congé",D22="Congé spécial",D22="Congé sans solde"),0.208333333333334,IF(AND(AG22="",F22-D22<0),("24:00:00"-D22)+("00:00:00"+F22)-0.0416666666666667,IF(AND(OR(AG22="Allaitement",AG22="Sans déjeuner"),F22-D22<0),("24:00:00"-D22)+("00:00:00"+F22),IF(AND(AG22="",F22-D22>0.166666666666667),F22-D22-0.0416666666666667,IF(AND(OR(AG22="Allaitement",AG22="Sans déjeuner"),F22-D22>0.166666666666667),F22-D22,F22-D22))))))) -> 0.375 | P22: Accesibilité | Q22: 44810 | R22: 0 | S22: 0 | T22: ="Sem - "&WEEKNUM(Q22,21) -> Sem - 37 | U22: =PROPER(TEXT(Q22,"mmmm")) -> Septembre | V22: 3063 | X22: =IFERROR(IF(M22="Abs",0,IF((D22-C22+E22-F22)<0.000694444444444444,0,(D22-C22+E22-F22))),0) -> 0 | Y22: =VLOOKUP('CM-CIC'!B22,Annuaire_roster!B:F,4,0) -> OUBRAHIM Mohammed | Z22: Credit Mutuel | AA22: FT
A23: =+VLOOKUP(B23,Annuaire_roster!B:G,5,0) -> 1278 | B23: LISSAOUI HIBA | C23: 0.33333333 | D23: 0.33333333 | E23: 0.75 | F23: 0.75 | K23: 0 | L23: 0 | M23: 0 | N23: =IFERROR(IF(OR(D23="OFF",D23="Congé",M23="Abs",D23="Congé sans solde",D23="Férié"),"",IF(O23-K23-L23>O23,O23,IF(O23-K23-L23<0,"",O23-K23-L23))),"") -> 0.375 | O23: =IF(AG23="2H Pause déjeuner",IF(F23-D23-0.0833333333333333<0,F23-D23-0.0833333333333333+1,F23-D23-0.0833333333333333),IF(OR(AND(F23="OFF",D23="OFF"),AND(F23="Congé",D23="Congé"),AND(F23="Congé sans solde",D23="Congé sans solde"),AND(F23="Congé spécial",D23="Congé spécial"),AND(F23="Férié",D23="Férié"),AND(F23="OFF",D23="Congé"),AND(F23="OFF",D23="Congé sans solde"),AND(F23="OFF",D23="Congé spécial"),AND(F23="OFF",D23="Férié"),AND(F23="Congé",D23="OFF"),AND(F23="Congé",D23="Congé sans solde"),AND(F23="Congé",D23="Congé spécial"),AND(F23="Congé",D23="Férié"),AND(F23="Congé sans solde",D23="OFF"),AND(F23="Congé sans solde",D23="Congé"),AND(F23="Congé sans solde",D23="Congé spécial"),AND(F23="Congé sans solde",D23="Férié"),AND(F23="Congé spécial",D23="OFF"),AND(F23="Congé spécial",D23="Congé"),AND(F23="Congé spécial",D23="Congé sans solde"),AND(F23="Congé spécial",D23="Férié"),AND(F23="Férié",D23="OFF"),AND(F23="Férié",D23="Congé"),AND(F23="Férié",D23="Congé sans solde"),AND(F23="Férié",D23="Congé spécial")),0,IF(OR(F23="OFF",F23="Congé",F23="Congé spécial",F23="Congé sans solde",D23="OFF",D23="Congé",D23="Congé spécial",D23="Congé sans solde"),0.208333333333334,IF(AND(AG23="",F23-D23<0),("24:00:00"-D23)+("00:00:00"+F23)-0.0416666666666667,IF(AND(OR(AG23="Allaitement",AG23="Sans déjeuner"),F23-D23<0),("24:00:00"-D23)+("00:00:00"+F23),IF(AND(AG23="",F23-D23>0.166666666666667),F23-D23-0.0416666666666667,IF(AND(OR(AG23="Allaitement",AG23="Sans déjeuner"),F23-D23>0.166666666666667),F23-D23,F23-D23))))))) -> 0.375 | P23: Accesibilité | Q23: 44811 | R23: 0 | S23: 0 | T23: ="Sem - "&WEEKNUM(Q23,21) -> Sem - 37 | U23: =PROPER(TEXT(Q23,"mmmm")) -> Septembre | V23: 3064 | X23: =IFERROR(IF(M23="Abs",0,IF((D23-C23+E23-F23)<0.000694444444444444,0,(D23-C23+E23-F23))),0) -> 0 | Y23: =VLOOKUP('CM-CIC'!B23,Annuaire_roster!B:F,4,0) -> OUBRAHIM Mohammed | Z23: Credit Mutuel | AA23: FT
A24: =+VLOOKUP(B24,Annuaire_roster!B:G,5,0) -> 1265 | B24: RMAIDI IMAD | C24: 0.33333333 | D24: 0.33333333 | E24: 0.75 | F24: 0.75 | K24: 0 | L24: 0 | M24: 0 | N24: =IFERROR(IF(OR(D24="OFF",D24="Congé",M24="Abs",D24="Congé sans solde",D24="Férié"),"",IF(O24-K24-L24>O24,O24,IF(O24-K24-L24<0,"",O24-K24-L24))),"") -> 0.375 | O24: =IF(AG24="2H Pause déjeuner",IF(F24-D24-0.0833333333333333<0,F24-D24-0.0833333333333333+1,F24-D24-0.0833333333333333),IF(OR(AND(F24="OFF",D24="OFF"),AND(F24="Congé",D24="Congé"),AND(F24="Congé sans solde",D24="Congé sans solde"),AND(F24="Congé spécial",D24="Congé spécial"),AND(F24="Férié",D24="Férié"),AND(F24="OFF",D24="Congé"),AND(F24="OFF",D24="Congé sans solde"),AND(F24="OFF",D24="Congé spécial"),AND(F24="OFF",D24="Férié"),AND(F24="Congé",D24="OFF"),AND(F24="Congé",D24="Congé sans solde"),AND(F24="Congé",D24="Congé spécial"),AND(F24="Congé",D24="Férié"),AND(F24="Congé sans solde",D24="OFF"),AND(F24="Congé sans solde",D24="Congé"),AND(F24="Congé sans solde",D24="Congé spécial"),AND(F24="Congé sans solde",D24="Férié"),AND(F24="Congé spécial",D24="OFF"),AND(F24="Congé spécial",D24="Congé"),AND(F24="Congé spécial",D24="Congé sans solde"),AND(F24="Congé spécial",D24="Férié"),AND(F24="Férié",D24="OFF"),AND(F24="Férié",D24="Congé"),AND(F24="Férié",D24="Congé sans solde"),AND(F24="Férié",D24="Congé spécial")),0,IF(OR(F24="OFF",F24="Congé",F24="Congé spécial",F24="Congé sans solde",D24="OFF",D24="Congé",D24="Congé spécial",D24="Congé sans solde"),0.208333333333334,IF(AND(AG24="",F24-D24<0),("24:00:00"-D24)+("00:00:00"+F24)-0.0416666666666667,IF(AND(OR(AG24="Allaitement",AG24="Sans déjeuner"),F24-D24<0),("24:00:00"-D24)+("00:00:00"+F24),IF(AND(AG24="",F24-D24>0.166666666666667),F24-D24-0.0416666666666667,IF(AND(OR(AG24="Allaitement",AG24="Sans déjeuner"),F24-D24>0.166666666666667),F24-D24,F24-D24))))))) -> 0.375 | P24: Accesibilité | Q24: 44811 | R24: 0 | S24: 0 | T24: ="Sem - "&WEEKNUM(Q24,21) -> Sem - 37 | U24: =PROPER(TEXT(Q24,"mmmm")) -> Septembre | V24: 3065 | X24: =IFERROR(IF(M24="Abs",0,IF((D24-C24+E24-F24)<0.000694444444444444,0,(D24-C24+E24-F24))),0) -> 0 | Y24: =VLOOKUP('CM-CIC'!B24,Annuaire_roster!B:F,4,0) -> OUBRAHIM Mohammed | Z24: Credit Mutuel | AA24: FT
A25: =+VLOOKUP(B25,Annuaire_roster!B:G,5,0) -> 1317 | B25: HAMDANI MOHAMED | C25: 0.33333333 | D25: 0.33333333 | E25: 0.75 | F25: 0.75 | K25: 0 | L25: 0 | M25: 0 | N25: =IFERROR(IF(OR(D25="OFF",D25="Congé",M25="Abs",D25="Congé sans solde",D25="Férié"),"",IF(O25-K25-L25>O25,O25,IF(O25-K25-L25<0,"",O25-K25-L25))),"") -> 0.375 | O25: =IF(AG25="2H Pause déjeuner",IF(F25-D25-0.0833333333333333<0,F25-D25-0.0833333333333333+1,F25-D25-0.0833333333333333),IF(OR(AND(F25="OFF",D25="OFF"),AND(F25="Congé",D25="Congé"),AND(F25="Congé sans solde",D25="Congé sans solde"),AND(F25="Congé spécial",D25="Congé spécial"),AND(F25="Férié",D25="Férié"),AND(F25="OFF",D25="Congé"),AND(F25="OFF",D25="Congé sans solde"),AND(F25="OFF",D25="Congé spécial"),AND(F25="OFF",D25="Férié"),AND(F25="Congé",D25="OFF"),AND(F25="Congé",D25="Congé sans solde"),AND(F25="Congé",D25="Congé spécial"),AND(F25="Congé",D25="Férié"),AND(F25="Congé sans solde",D25="OFF"),AND(F25="Congé sans solde",D25="Congé"),AND(F25="Congé sans solde",D25="Congé spécial"),AND(F25="Congé sans solde",D25="Férié"),AND(F25="Congé spécial",D25="OFF"),AND(F25="Congé spécial",D25="Congé"),AND(F25="Congé spécial",D25="Congé sans solde"),AND(F25="Congé spécial",D25="Férié"),AND(F25="Férié",D25="OFF"),AND(F25="Férié",D25="Congé"),AND(F25="Férié",D25="Congé sans solde"),AND(F25="Férié",D25="Congé spécial")),0,IF(OR(F25="OFF",F25="Congé",F25="Congé spécial",F25="Congé sans solde",D25="OFF",D25="Congé",D25="Congé spécial",D25="Congé sans solde"),0.208333333333334,IF(AND(AG25="",F25-D25<0),("24:00:00"-D25)+("00:00:00"+F25)-0.0416666666666667,IF(AND(OR(AG25="Allaitement",AG25="Sans déjeuner"),F25-D25<0),("24:00:00"-D25)+("00:00:00"+F25),IF(AND(AG25="",F25-D25>0.166666666666667),F25-D25-0.0416666666666667,IF(AND(OR(AG25="Allaitement",AG25="Sans déjeuner"),F25-D25>0.166666666666667),F25-D25,F25-D25))))))) -> 0.375 | P25: Accesibilité | Q25: 44811 | R25: 0 | S25: 0 | T25: ="Sem - "&WEEKNUM(Q25,21) -> Sem - 37 | U25: =PROPER(TEXT(Q25,"mmmm")) -> Septembre | V25: 3066 | X25: =IFERROR(IF(M25="Abs",0,IF((D25-C25+E25-F25)<0.000694444444444444,0,(D25-C25+E25-F25))),0) -> 0 | Y25: =VLOOKUP('CM-CIC'!B25,Annuaire_roster!B:F,4,0) -> OUBRAHIM Mohammed | Z25: Credit Mutuel | AA25: FT
A26: =+VLOOKUP(B26,Annuaire_roster!B:G,5,0) -> 1278 | B26: LISSAOUI HIBA | C26: 0.33333333 | D26: 0.33333333 | E26: 0.75 | F26: 0.75 | K26: 0 | L26: 0 | M26: 0 | N26: =IFERROR(IF(OR(D26="OFF",D26="Congé",M26="Abs",D26="Congé sans solde",D26="Férié"),"",IF(O26-K26-L26>O26,O26,IF(O26-K26-L26<0,"",O26-K26-L26))),"") -> 0.375 | O26: =IF(AG26="2H Pause déjeuner",IF(F26-D26-0.0833333333333333<0,F26-D26-0.0833333333333333+1,F26-D26-0.0833333333333333),IF(OR(AND(F26="OFF",D26="OFF"),AND(F26="Congé",D26="Congé"),AND(F26="Congé sans solde",D26="Congé sans solde"),AND(F26="Congé spécial",D26="Congé spécial"),AND(F26="Férié",D26="Férié"),AND(F26="OFF",D26="Congé"),AND(F26="OFF",D26="Congé sans solde"),AND(F26="OFF",D26="Congé spécial"),AND(F26="OFF",D26="Férié"),AND(F26="Congé",D26="OFF"),AND(F26="Congé",D26="Congé sans solde"),AND(F26="Congé",D26="Congé spécial"),AND(F26="Congé",D26="Férié"),AND(F26="Congé sans solde",D26="OFF"),AND(F26="Congé sans solde",D26="Congé"),AND(F26="Congé sans solde",D26="Congé spécial"),AND(F26="Congé sans solde",D26="Férié"),AND(F26="Congé spécial",D26="OFF"),AND(F26="Congé spécial",D26="Congé"),AND(F26="Congé spécial",D26="Congé sans solde"),AND(F26="Congé spécial",D26="Férié"),AND(F26="Férié",D26="OFF"),AND(F26="Férié",D26="Congé"),AND(F26="Férié",D26="Congé sans solde"),AND(F26="Férié",D26="Congé spécial")),0,IF(OR(F26="OFF",F26="Congé",F26="Congé spécial",F26="Congé sans solde",D26="OFF",D26="Congé",D26="Congé spécial",D26="Congé sans solde"),0.208333333333334,IF(AND(AG26="",F26-D26<0),("24:00:00"-D26)+("00:00:00"+F26)-0.0416666666666667,IF(AND(OR(AG26="Allaitement",AG26="Sans déjeuner"),F26-D26<0),("24:00:00"-D26)+("00:00:00"+F26),IF(AND(AG26="",F26-D26>0.166666666666667),F26-D26-0.0416666666666667,IF(AND(OR(AG26="Allaitement",AG26="Sans déjeuner"),F26-D26>0.166666666666667),F26-D26,F26-D26))))))) -> 0.375 | P26: Accesibilité | Q26: 44812 | R26: 0 | S26: 0 | T26: ="Sem - "&WEEKNUM(Q26,21) -> Sem - 37 | U26: =PROPER(TEXT(Q26,"mmmm")) -> Septembre | V26: 3067 | X26: =IFERROR(IF(M26="Abs",0,IF((D26-C26+E26-F26)<0.000694444444444444,0,(D26-C26+E26-F26))),0) -> 0 | Y26: =VLOOKUP('CM-CIC'!B26,Annuaire_roster!B:F,4,0) -> OUBRAHIM Mohammed | Z26: Credit Mutuel | AA26: FT
A27: =+VLOOKUP(B27,Annuaire_roster!B:G,5,0) -> 1265 | B27: RMAIDI IMAD | C27: 0.33333333 | D27: 0.33333333 | E27: 0.75 | F27: 0.75 | K27: 0 | L27: 0 | M27: 0 | N27: =IFERROR(IF(OR(D27="OFF",D27="Congé",M27="Abs",D27="Congé sans solde",D27="Férié"),"",IF(O27-K27-L27>O27,O27,IF(O27-K27-L27<0,"",O27-K27-L27))),"") -> 0.375 | O27: =IF(AG27="2H Pause déjeuner",IF(F27-D27-0.0833333333333333<0,F27-D27-0.0833333333333333+1,F27-D27-0.0833333333333333),IF(OR(AND(F27="OFF",D27="OFF"),AND(F27="Congé",D27="Congé"),AND(F27="Congé sans solde",D27="Congé sans solde"),AND(F27="Congé spécial",D27="Congé spécial"),AND(F27="Férié",D27="Férié"),AND(F27="OFF",D27="Congé"),AND(F27="OFF",D27="Congé sans solde"),AND(F27="OFF",D27="Congé spécial"),AND(F27="OFF",D27="Férié"),AND(F27="Congé",D27="OFF"),AND(F27="Congé",D27="Congé sans solde"),AND(F27="Congé",D27="Congé spécial"),AND(F27="Congé",D27="Férié"),AND(F27="Congé sans solde",D27="OFF"),AND(F27="Congé sans solde",D27="Congé"),AND(F27="Congé sans solde",D27="Congé spécial"),AND(F27="Congé sans solde",D27="Férié"),AND(F27="Congé spécial",D27="OFF"),AND(F27="Congé spécial",D27="Congé"),AND(F27="Congé spécial",D27="Congé sans solde"),AND(F27="Congé spécial",D27="Férié"),AND(F27="Férié",D27="OFF"),AND(F27="Férié",D27="Congé"),AND(F27="Férié",D27="Congé sans solde"),AND(F27="Férié",D27="Congé spécial")),0,IF(OR(F27="OFF",F27="Congé",F27="Congé spécial",F27="Congé sans solde",D27="OFF",D27="Congé",D27="Congé spécial",D27="Congé sans solde"),0.208333333333334,IF(AND(AG27="",F27-D27<0),("24:00:00"-D27)+("00:00:00"+F27)-0.0416666666666667,IF(AND(OR(AG27="Allaitement",AG27="Sans déjeuner"),F27-D27<0),("24:00:00"-D27)+("00:00:00"+F27),IF(AND(AG27="",F27-D27>0.166666666666667),F27-D27-0.0416666666666667,IF(AND(OR(AG27="Allaitement",AG27="Sans déjeuner"),F27-D27>0.166666666666667),F27-D27,F27-D27))))))) -> 0.375 | P27: Accesibilité | Q27: 44812 | R27: 0 | S27: 0 | T27: ="Sem - "&WEEKNUM(Q27,21) -> Sem - 37 | U27: =PROPER(TEXT(Q27,"mmmm")) -> Septembre | V27: 3068 | X27: =IFERROR(IF(M27="Abs",0,IF((D27-C27+E27-F27)<0.000694444444444444,0,(D27-C27+E27-F27))),0) -> 0 | Y27: =VLOOKUP('CM-CIC'!B27,Annuaire_roster!B:F,4,0) -> OUBRAHIM Mohammed | Z27: Credit Mutuel | AA27: FT
A28: =+VLOOKUP(B28,Annuaire_roster!B:G,5,0) -> 1317 | B28: HAMDANI MOHAMED | C28: 0.33333333 | D28: 0.33333333 | E28: 0.75 | F28: 0.75 | K28: 0 | L28: 0 | M28: 0 | N28: =IFERROR(IF(OR(D28="OFF",D28="Congé",M28="Abs",D28="Congé sans solde",D28="Férié"),"",IF(O28-K28-L28>O28,O28,IF(O28-K28-L28<0,"",O28-K28-L28))),"") -> 0.375 | O28: =IF(AG28="2H Pause déjeuner",IF(F28-D28-0.0833333333333333<0,F28-D28-0.0833333333333333+1,F28-D28-0.0833333333333333),IF(OR(AND(F28="OFF",D28="OFF"),AND(F28="Congé",D28="Congé"),AND(F28="Congé sans solde",D28="Congé sans solde"),AND(F28="Congé spécial",D28="Congé spécial"),AND(F28="Férié",D28="Férié"),AND(F28="OFF",D28="Congé"),AND(F28="OFF",D28="Congé sans solde"),AND(F28="OFF",D28="Congé spécial"),AND(F28="OFF",D28="Férié"),AND(F28="Congé",D28="OFF"),AND(F28="Congé",D28="Congé sans solde"),AND(F28="Congé",D28="Congé spécial"),AND(F28="Congé",D28="Férié"),AND(F28="Congé sans solde",D28="OFF"),AND(F28="Congé sans solde",D28="Congé"),AND(F28="Congé sans solde",D28="Congé spécial"),AND(F28="Congé sans solde",D28="Férié"),AND(F28="Congé spécial",D28="OFF"),AND(F28="Congé spécial",D28="Congé"),AND(F28="Congé spécial",D28="Congé sans solde"),AND(F28="Congé spécial",D28="Férié"),AND(F28="Férié",D28="OFF"),AND(F28="Férié",D28="Congé"),AND(F28="Férié",D28="Congé sans solde"),AND(F28="Férié",D28="Congé spécial")),0,IF(OR(F28="OFF",F28="Congé",F28="Congé spécial",F28="Congé sans solde",D28="OFF",D28="Congé",D28="Congé spécial",D28="Congé sans solde"),0.208333333333334,IF(AND(AG28="",F28-D28<0),("24:00:00"-D28)+("00:00:00"+F28)-0.0416666666666667,IF(AND(OR(AG28="Allaitement",AG28="Sans déjeuner"),F28-D28<0),("24:00:00"-D28)+("00:00:00"+F28),IF(AND(AG28="",F28-D28>0.166666666666667),F28-D28-0.0416666666666667,IF(AND(OR(AG28="Allaitement",AG28="Sans déjeuner"),F28-D28>0.166666666666667),F28-D28,F28-D28))))))) -> 0.375 | P28: Accesibilité | Q28: 44812 | R28: 0 | S28: 0 | T28: ="Sem - "&WEEKNUM(Q28,21) -> Sem - 37 | U28: =PROPER(TEXT(Q28,"mmmm")) -> Septembre | V28: 3069 | X28: =IFERROR(IF(M28="Abs",0,IF((D28-C28+E28-F28)<0.000694444444444444,0,(D28-C28+E28-F28))),0) -> 0 | Y28: =VLOOKUP('CM-CIC'!B28,Annuaire_roster!B:F,4,0) -> OUBRAHIM Mohammed | Z28: Credit Mutuel | AA28: FT
A29: =+VLOOKUP(B29,Annuaire_roster!B:G,5,0) -> 1278 | B29: LISSAOUI HIBA | C29: 0.33333333 | D29: 0.33333333 | E29: 0.75 | F29: 0.75 | K29: 0 | L29: 0 | M29: 0 | N29: =IFERROR(IF(OR(D29="OFF",D29="Congé",M29="Abs",D29="Congé sans solde",D29="Férié"),"",IF(O29-K29-L29>O29,O29,IF(O29-K29-L29<0,"",O29-K29-L29))),"") -> 0.375 | O29: =IF(AG29="2H Pause déjeuner",IF(F29-D29-0.0833333333333333<0,F29-D29-0.0833333333333333+1,F29-D29-0.0833333333333333),IF(OR(AND(F29="OFF",D29="OFF"),AND(F29="Congé",D29="Congé"),AND(F29="Congé sans solde",D29="Congé sans solde"),AND(F29="Congé spécial",D29="Congé spécial"),AND(F29="Férié",D29="Férié"),AND(F29="OFF",D29="Congé"),AND(F29="OFF",D29="Congé sans solde"),AND(F29="OFF",D29="Congé spécial"),AND(F29="OFF",D29="Férié"),AND(F29="Congé",D29="OFF"),AND(F29="Congé",D29="Congé sans solde"),AND(F29="Congé",D29="Congé spécial"),AND(F29="Congé",D29="Férié"),AND(F29="Congé sans solde",D29="OFF"),AND(F29="Congé sans solde",D29="Congé"),AND(F29="Congé sans solde",D29="Congé spécial"),AND(F29="Congé sans solde",D29="Férié"),AND(F29="Congé spécial",D29="OFF"),AND(F29="Congé spécial",D29="Congé"),AND(F29="Congé spécial",D29="Congé sans solde"),AND(F29="Congé spécial",D29="Férié"),AND(F29="Férié",D29="OFF"),AND(F29="Férié",D29="Congé"),AND(F29="Férié",D29="Congé sans solde"),AND(F29="Férié",D29="Congé spécial")),0,IF(OR(F29="OFF",F29="Congé",F29="Congé spécial",F29="Congé sans solde",D29="OFF",D29="Congé",D29="Congé spécial",D29="Congé sans solde"),0.208333333333334,IF(AND(AG29="",F29-D29<0),("24:00:00"-D29)+("00:00:00"+F29)-0.0416666666666667,IF(AND(OR(AG29="Allaitement",AG29="Sans déjeuner"),F29-D29<0),("24:00:00"-D29)+("00:00:00"+F29),IF(AND(AG29="",F29-D29>0.166666666666667),F29-D29-0.0416666666666667,IF(AND(OR(AG29="Allaitement",AG29="Sans déjeuner"),F29-D29>0.166666666666667),F29-D29,F29-D29))))))) -> 0.375 | P29: Accesibilité | Q29: 44813 | R29: 0 | S29: 0 | T29: ="Sem - "&WEEKNUM(Q29,21) -> Sem - 37 | U29: =PROPER(TEXT(Q29,"mmmm")) -> Septembre | V29: 3070 | X29: =IFERROR(IF(M29="Abs",0,IF((D29-C29+E29-F29)<0.000694444444444444,0,(D29-C29+E29-F29))),0) -> 0 | Y29: =VLOOKUP('CM-CIC'!B29,Annuaire_roster!B:F,4,0) -> OUBRAHIM Mohammed | Z29: Credit Mutuel | AA29: FT
A30: =+VLOOKUP(B30,Annuaire_roster!B:G,5,0) -> 1265 | B30: RMAIDI IMAD | C30: 0.33333333 | D30: 0.33333333 | E30: 0.75 | F30: 0.75 | K30: 0 | L30: 0 | M30: 0 | N30: =IFERROR(IF(OR(D30="OFF",D30="Congé",M30="Abs",D30="Congé sans solde",D30="Férié"),"",IF(O30-K30-L30>O30,O30,IF(O30-K30-L30<0,"",O30-K30-L30))),"") -> 0.375 | O30: =IF(AG30="2H Pause déjeuner",IF(F30-D30-0.0833333333333333<0,F30-D30-0.0833333333333333+1,F30-D30-0.0833333333333333),IF(OR(AND(F30="OFF",D30="OFF"),AND(F30="Congé",D30="Congé"),AND(F30="Congé sans solde",D30="Congé sans solde"),AND(F30="Congé spécial",D30="Congé spécial"),AND(F30="Férié",D30="Férié"),AND(F30="OFF",D30="Congé"),AND(F30="OFF",D30="Congé sans solde"),AND(F30="OFF",D30="Congé spécial"),AND(F30="OFF",D30="Férié"),AND(F30="Congé",D30="OFF"),AND(F30="Congé",D30="Congé sans solde"),AND(F30="Congé",D30="Congé spécial"),AND(F30="Congé",D30="Férié"),AND(F30="Congé sans solde",D30="OFF"),AND(F30="Congé sans solde",D30="Congé"),AND(F30="Congé sans solde",D30="Congé spécial"),AND(F30="Congé sans solde",D30="Férié"),AND(F30="Congé spécial",D30="OFF"),AND(F30="Congé spécial",D30="Congé"),AND(F30="Congé spécial",D30="Congé sans solde"),AND(F30="Congé spécial",D30="Férié"),AND(F30="Férié",D30="OFF"),AND(F30="Férié",D30="Congé"),AND(F30="Férié",D30="Congé sans solde"),AND(F30="Férié",D30="Congé spécial")),0,IF(OR(F30="OFF",F30="Congé",F30="Congé spécial",F30="Congé sans solde",D30="OFF",D30="Congé",D30="Congé spécial",D30="Congé sans solde"),0.208333333333334,IF(AND(AG30="",F30-D30<0),("24:00:00"-D30)+("00:00:00"+F30)-0.0416666666666667,IF(AND(OR(AG30="Allaitement",AG30="Sans déjeuner"),F30-D30<0),("24:00:00"-D30)+("00:00:00"+F30),IF(AND(AG30="",F30-D30>0.166666666666667),F30-D30-0.0416666666666667,IF(AND(OR(AG30="Allaitement",AG30="Sans déjeuner"),F30-D30>0.166666666666667),F30-D30,F30-D30))))))) -> 0.375 | P30: Accesibilité | Q30: 44813 | R30: 0 | S30: 0 | T30: ="Sem - "&WEEKNUM(Q30,21) -> Sem - 37 | U30: =PROPER(TEXT(Q30,"mmmm")) -> Septembre | V30: 3071 | X30: =IFERROR(IF(M30="Abs",0,IF((D30-C30+E30-F30)<0.000694444444444444,0,(D30-C30+E30-F30))),0) -> 0 | Y30: =VLOOKUP('CM-CIC'!B30,Annuaire_roster!B:F,4,0) -> OUBRAHIM Mohammed | Z30: Credit Mutuel | AA30: FT
A31: =+VLOOKUP(B31,Annuaire_roster!B:G,5,0) -> 1317 | B31: HAMDANI MOHAMED | C31: 0.33333333 | D31: 0.33333333 | E31: 0.75 | F31: 0.75 | K31: 0 | L31: 0 | M31: 0 | N31: =IFERROR(IF(OR(D31="OFF",D31="Congé",M31="Abs",D31="Congé sans solde",D31="Férié"),"",IF(O31-K31-L31>O31,O31,IF(O31-K31-L31<0,"",O31-K31-L31))),"") -> 0.375 | O31: =IF(AG31="2H Pause déjeuner",IF(F31-D31-0.0833333333333333<0,F31-D31-0.0833333333333333+1,F31-D31-0.0833333333333333),IF(OR(AND(F31="OFF",D31="OFF"),AND(F31="Congé",D31="Congé"),AND(F31="Congé sans solde",D31="Congé sans solde"),AND(F31="Congé spécial",D31="Congé spécial"),AND(F31="Férié",D31="Férié"),AND(F31="OFF",D31="Congé"),AND(F31="OFF",D31="Congé sans solde"),AND(F31="OFF",D31="Congé spécial"),AND(F31="OFF",D31="Férié"),AND(F31="Congé",D31="OFF"),AND(F31="Congé",D31="Congé sans solde"),AND(F31="Congé",D31="Congé spécial"),AND(F31="Congé",D31="Férié"),AND(F31="Congé sans solde",D31="OFF"),AND(F31="Congé sans solde",D31="Congé"),AND(F31="Congé sans solde",D31="Congé spécial"),AND(F31="Congé sans solde",D31="Férié"),AND(F31="Congé spécial",D31="OFF"),AND(F31="Congé spécial",D31="Congé"),AND(F31="Congé spécial",D31="Congé sans solde"),AND(F31="Congé spécial",D31="Férié"),AND(F31="Férié",D31="OFF"),AND(F31="Férié",D31="Congé"),AND(F31="Férié",D31="Congé sans solde"),AND(F31="Férié",D31="Congé spécial")),0,IF(OR(F31="OFF",F31="Congé",F31="Congé spécial",F31="Congé sans solde",D31="OFF",D31="Congé",D31="Congé spécial",D31="Congé sans solde"),0.208333333333334,IF(AND(AG31="",F31-D31<0),("24:00:00"-D31)+("00:00:00"+F31)-0.0416666666666667,IF(AND(OR(AG31="Allaitement",AG31="Sans déjeuner"),F31-D31<0),("24:00:00"-D31)+("00:00:00"+F31),IF(AND(AG31="",F31-D31>0.166666666666667),F31-D31-0.0416666666666667,IF(AND(OR(AG31="Allaitement",AG31="Sans déjeuner"),F31-D31>0.166666666666667),F31-D31,F31-D31))))))) -> 0.375 | P31: Accesibilité | Q31: 44813 | R31: 0 | S31: 0 | T31: ="Sem - "&WEEKNUM(Q31,21) -> Sem - 37 | U31: =PROPER(TEXT(Q31,"mmmm")) -> Septembre | V31: 3072 | X31: =IFERROR(IF(M31="Abs",0,IF((D31-C31+E31-F31)<0.000694444444444444,0,(D31-C31+E31-F31))),0) -> 0 | Y31: =VLOOKUP('CM-CIC'!B31,Annuaire_roster!B:F,4,0) -> OUBRAHIM Mohammed | Z31: Credit Mutuel | AA31: FT
... A34: =+VLOOKUP(B34,Annuaire_roster!B:G,5,0) -> 1317 | B34: HAMDANI MOHAMED | C34: 0.33333333 | D34: 0.33333333 | E34: 0.70833333 | F34: 0.70833333 | K34: 0 | L34: 0 | M34: 0 | N34: =IFERROR(IF(OR(D34="OFF",D34="Congé",M34="Abs",D34="Congé sans solde",D34="Férié"),"",IF(O34-K34-L34>O34,O34,IF(O34-K34-L34<0,"",O34-K34-L34))),"") -> 0.33333333 | O34: =IF(AG34="2H Pause déjeuner",IF(F34-D34-0.0833333333333333<0,F34-D34-0.0833333333333333+1,F34-D34-0.0833333333333333),IF(OR(AND(F34="OFF",D34="OFF"),AND(F34="Congé",D34="Congé"),AND(F34="Congé sans solde",D34="Congé sans solde"),AND(F34="Congé spécial",D34="Congé spécial"),AND(F34="Férié",D34="Férié"),AND(F34="OFF",D34="Congé"),AND(F34="OFF",D34="Congé sans solde"),AND(F34="OFF",D34="Congé spécial"),AND(F34="OFF",D34="Férié"),AND(F34="Congé",D34="OFF"),AND(F34="Congé",D34="Congé sans solde"),AND(F34="Congé",D34="Congé spécial"),AND(F34="Congé",D34="Férié"),AND(F34="Congé sans solde",D34="OFF"),AND(F34="Congé sans solde",D34="Congé"),AND(F34="Congé sans solde",D34="Congé spécial"),AND(F34="Congé sans solde",D34="Férié"),AND(F34="Congé spécial",D34="OFF"),AND(F34="Congé spécial",D34="Congé"),AND(F34="Congé spécial",D34="Congé sans solde"),AND(F34="Congé spécial",D34="Férié"),AND(F34="Férié",D34="OFF"),AND(F34="Férié",D34="Congé"),AND(F34="Férié",D34="Congé sans solde"),AND(F34="Férié",D34="Congé spécial")),0,IF(OR(F34="OFF",F34="Congé",F34="Congé spécial",F34="Congé sans solde",D34="OFF",D34="Congé",D34="Congé spécial",D34="Congé sans solde"),0.208333333333334,IF(AND(AG34="",F34-D34<0),("24:00:00"-D34)+("00:00:00"+F34)-0.0416666666666667,IF(AND(OR(AG34="Allaitement",AG34="Sans déjeuner"),F34-D34<0),("24:00:00"-D34)+("00:00:00"+F34),IF(AND(AG34="",F34-D34>0.166666666666667),F34-D34-0.0416666666666667,IF(AND(OR(AG34="Allaitement",AG34="Sans déjeuner"),F34-D34>0.166666666666667),F34-D34,F34-D34))))))) -> 0.33333333 | P34: Accesibilité | Q34: 44814 | R34: 0 | S34: 0 | T34: ="Sem - "&WEEKNUM(Q34,21) -> Sem - 37 | U34: =PROPER(TEXT(Q34,"mmmm")) -> Septembre | V34: 3075 | X34: =IFERROR(IF(M34="Abs",0,IF((D34-C34+E34-F34)<0.000694444444444444,0,(D34-C34+E34-F34))),0) -> 0 | Y34: =VLOOKUP('CM-CIC'!B34,Annuaire_roster!B:F,4,0) -> OUBRAHIM Mohammed | Z34: Credit Mutuel | AA34: FT
A35: =+VLOOKUP(B35,Annuaire_roster!B:G,5,0) -> 1278 | B35: LISSAOUI HIBA | D35: OFF | F35: OFF | K35: 0 | L35: 0 | M35: 0 | N35: =IFERROR(IF(OR(D35="OFF",D35="Congé",M35="Abs",D35="Congé sans solde",D35="Férié"),"",IF(O35-K35-L35>O35,O35,IF(O35-K35-L35<0,"",O35-K35-L35))),"") | O35: =IF(AG35="2H Pause déjeuner",IF(F35-D35-0.0833333333333333<0,F35-D35-0.0833333333333333+1,F35-D35-0.0833333333333333),IF(OR(AND(F35="OFF",D35="OFF"),AND(F35="Congé",D35="Congé"),AND(F35="Congé sans solde",D35="Congé sans solde"),AND(F35="Congé spécial",D35="Congé spécial"),AND(F35="Férié",D35="Férié"),AND(F35="OFF",D35="Congé"),AND(F35="OFF",D35="Congé sans solde"),AND(F35="OFF",D35="Congé spécial"),AND(F35="OFF",D35="Férié"),AND(F35="Congé",D35="OFF"),AND(F35="Congé",D35="Congé sans solde"),AND(F35="Congé",D35="Congé spécial"),AND(F35="Congé",D35="Férié"),AND(F35="Congé sans solde",D35="OFF"),AND(F35="Congé sans solde",D35="Congé"),AND(F35="Congé sans solde",D35="Congé spécial"),AND(F35="Congé sans solde",D35="Férié"),AND(F35="Congé spécial",D35="OFF"),AND(F35="Congé spécial",D35="Congé"),AND(F35="Congé spécial",D35="Congé sans solde"),AND(F35="Congé spécial",D35="Férié"),AND(F35="Férié",D35="OFF"),AND(F35="Férié",D35="Congé"),AND(F35="Férié",D35="Congé sans solde"),AND(F35="Férié",D35="Congé spécial")),0,IF(OR(F35="OFF",F35="Congé",F35="Congé spécial",F35="Congé sans solde",D35="OFF",D35="Congé",D35="Congé spécial",D35="Congé sans solde"),0.208333333333334,IF(AND(AG35="",F35-D35<0),("24:00:00"-D35)+("00:00:00"+F35)-0.0416666666666667,IF(AND(OR(AG35="Allaitement",AG35="Sans déjeuner"),F35-D35<0),("24:00:00"-D35)+("00:00:00"+F35),IF(AND(AG35="",F35-D35>0.166666666666667),F35-D35-0.0416666666666667,IF(AND(OR(AG35="Allaitement",AG35="Sans déjeuner"),F35-D35>0.166666666666667),F35-D35,F35-D35))))))) -> 0 | P35: Accesibilité | Q35: 44815 | R35: 0 | S35: 0 | T35: ="Sem - "&WEEKNUM(Q35,21) -> Sem - 37 | U35: =PROPER(TEXT(Q35,"mmmm")) -> Septembre | V35: 3076 | X35: =IFERROR(IF(M35="Abs",0,IF((D35-C35+E35-F35)<0.000694444444444444,0,(D35-C35+E35-F35))),0) -> 0 | Y35: =VLOOKUP('CM-CIC'!B35,Annuaire_roster!B:F,4,0) -> OUBRAHIM Mohammed | Z35: Credit Mutuel | AA35: FT
A36: =+VLOOKUP(B36,Annuaire_roster!B:G,5,0) -> 1265 | B36: RMAIDI IMAD | D36: OFF | F36: OFF | K36: 0 | L36: 0 | M36: 0 | N36: =IFERROR(IF(OR(D36="OFF",D36="Congé",M36="Abs",D36="Congé sans solde",D36="Férié"),"",IF(O36-K36-L36>O36,O36,IF(O36-K36-L36<0,"",O36-K36-L36))),"") | O36: =IF(AG36="2H Pause déjeuner",IF(F36-D36-0.0833333333333333<0,F36-D36-0.0833333333333333+1,F36-D36-0.0833333333333333),IF(OR(AND(F36="OFF",D36="OFF"),AND(F36="Congé",D36="Congé"),AND(F36="Congé sans solde",D36="Congé sans solde"),AND(F36="Congé spécial",D36="Congé spécial"),AND(F36="Férié",D36="Férié"),AND(F36="OFF",D36="Congé"),AND(F36="OFF",D36="Congé sans solde"),AND(F36="OFF",D36="Congé spécial"),AND(F36="OFF",D36="Férié"),AND(F36="Congé",D36="OFF"),AND(F36="Congé",D36="Congé sans solde"),AND(F36="Congé",D36="Congé spécial"),AND(F36="Congé",D36="Férié"),AND(F36="Congé sans solde",D36="OFF"),AND(F36="Congé sans solde",D36="Congé"),AND(F36="Congé sans solde",D36="Congé spécial"),AND(F36="Congé sans solde",D36="Férié"),AND(F36="Congé spécial",D36="OFF"),AND(F36="Congé spécial",D36="Congé"),AND(F36="Congé spécial",D36="Congé sans solde"),AND(F36="Congé spécial",D36="Férié"),AND(F36="Férié",D36="OFF"),AND(F36="Férié",D36="Congé"),AND(F36="Férié",D36="Congé sans solde"),AND(F36="Férié",D36="Congé spécial")),0,IF(OR(F36="OFF",F36="Congé",F36="Congé spécial",F36="Congé sans solde",D36="OFF",D36="Congé",D36="Congé spécial",D36="Congé sans solde"),0.208333333333334,IF(AND(AG36="",F36-D36<0),("24:00:00"-D36)+("00:00:00"+F36)-0.0416666666666667,IF(AND(OR(AG36="Allaitement",AG36="Sans déjeuner"),F36-D36<0),("24:00:00"-D36)+("00:00:00"+F36),IF(AND(AG36="",F36-D36>0.166666666666667),F36-D36-0.0416666666666667,IF(AND(OR(AG36="Allaitement",AG36="Sans déjeuner"),F36-D36>0.166666666666667),F36-D36,F36-D36))))))) -> 0 | P36: Accesibilité | Q36: 44815 | R36: 0 | S36: 0 | T36: ="Sem - "&WEEKNUM(Q36,21) -> Sem - 37 | U36: =PROPER(TEXT(Q36,"mmmm")) -> Septembre | V36: 3077 | X36: =IFERROR(IF(M36="Abs",0,IF((D36-C36+E36-F36)<0.000694444444444444,0,(D36-C36+E36-F36))),0) -> 0 | Y36: =VLOOKUP('CM-CIC'!B36,Annuaire_roster!B:F,4,0) -> OUBRAHIM Mohammed | Z36: Credit Mutuel | AA36: FT
A37: =+VLOOKUP(B37,Annuaire_roster!B:G,5,0) -> 1317 | B37: HAMDANI MOHAMED | D37: OFF | F37: OFF | K37: 0 | L37: 0 | M37: 0 | N37: =IFERROR(IF(OR(D37="OFF",D37="Congé",M37="Abs",D37="Congé sans solde",D37="Férié"),"",IF(O37-K37-L37>O37,O37,IF(O37-K37-L37<0,"",O37-K37-L37))),"") | O37: =IF(AG37="2H Pause déjeuner",IF(F37-D37-0.0833333333333333<0,F37-D37-0.0833333333333333+1,F37-D37-0.0833333333333333),IF(OR(AND(F37="OFF",D37="OFF"),AND(F37="Congé",D37="Congé"),AND(F37="Congé sans solde",D37="Congé sans solde"),AND(F37="Congé spécial",D37="Congé spécial"),AND(F37="Férié",D37="Férié"),AND(F37="OFF",D37="Congé"),AND(F37="OFF",D37="Congé sans solde"),AND(F37="OFF",D37="Congé spécial"),AND(F37="OFF",D37="Férié"),AND(F37="Congé",D37="OFF"),AND(F37="Congé",D37="Congé sans solde"),AND(F37="Congé",D37="Congé spécial"),AND(F37="Congé",D37="Férié"),AND(F37="Congé sans solde",D37="OFF"),AND(F37="Congé sans solde",D37="Congé"),AND(F37="Congé sans solde",D37="Congé spécial"),AND(F37="Congé sans solde",D37="Férié"),AND(F37="Congé spécial",D37="OFF"),AND(F37="Congé spécial",D37="Congé"),AND(F37="Congé spécial",D37="Congé sans solde"),AND(F37="Congé spécial",D37="Férié"),AND(F37="Férié",D37="OFF"),AND(F37="Férié",D37="Congé"),AND(F37="Férié",D37="Congé sans solde"),AND(F37="Férié",D37="Congé spécial")),0,IF(OR(F37="OFF",F37="Congé",F37="Congé spécial",F37="Congé sans solde",D37="OFF",D37="Congé",D37="Congé spécial",D37="Congé sans solde"),0.208333333333334,IF(AND(AG37="",F37-D37<0),("24:00:00"-D37)+("00:00:00"+F37)-0.0416666666666667,IF(AND(OR(AG37="Allaitement",AG37="Sans déjeuner"),F37-D37<0),("24:00:00"-D37)+("00:00:00"+F37),IF(AND(AG37="",F37-D37>0.166666666666667),F37-D37-0.0416666666666667,IF(AND(OR(AG37="Allaitement",AG37="Sans déjeuner"),F37-D37>0.166666666666667),F37-D37,F37-D37))))))) -> 0 | P37: Accesibilité | Q37: 44815 | R37: 0 | S37: 0 | T37: ="Sem - "&WEEKNUM(Q37,21) -> Sem - 37 | U37: =PROPER(TEXT(Q37,"mmmm")) -> Septembre | V37: 3078 | X37: =IFERROR(IF(M37="Abs",0,IF((D37-C37+E37-F37)<0.000694444444444444,0,(D37-C37+E37-F37))),0) -> 0 | Y37: =VLOOKUP('CM-CIC'!B37,Annuaire_roster!B:F,4,0) -> OUBRAHIM Mohammed | Z37: Credit Mutuel | AA37: FT
A38: =+VLOOKUP(B38,Annuaire_roster!B:G,5,0) -> 1278 | B38: LISSAOUI HIBA | D38: OFF | F38: OFF | K38: 0 | L38: 0 | M38: 0 | N38: =IFERROR(IF(OR(D38="OFF",D38="Congé",M38="Abs",D38="Congé sans solde",D38="Férié"),"",IF(O38-K38-L38>O38,O38,IF(O38-K38-L38<0,"",O38-K38-L38))),"") | O38: =IF(AG38="2H Pause déjeuner",IF(F38-D38-0.0833333333333333<0,F38-D38-0.0833333333333333+1,F38-D38-0.0833333333333333),IF(OR(AND(F38="OFF",D38="OFF"),AND(F38="Congé",D38="Congé"),AND(F38="Congé sans solde",D38="Congé sans solde"),AND(F38="Congé spécial",D38="Congé spécial"),AND(F38="Férié",D38="Férié"),AND(F38="OFF",D38="Congé"),AND(F38="OFF",D38="Congé sans solde"),AND(F38="OFF",D38="Congé spécial"),AND(F38="OFF",D38="Férié"),AND(F38="Congé",D38="OFF"),AND(F38="Congé",D38="Congé sans solde"),AND(F38="Congé",D38="Congé spécial"),AND(F38="Congé",D38="Férié"),AND(F38="Congé sans solde",D38="OFF"),AND(F38="Congé sans solde",D38="Congé"),AND(F38="Congé sans solde",D38="Congé spécial"),AND(F38="Congé sans solde",D38="Férié"),AND(F38="Congé spécial",D38="OFF"),AND(F38="Congé spécial",D38="Congé"),AND(F38="Congé spécial",D38="Congé sans solde"),AND(F38="Congé spécial",D38="Férié"),AND(F38="Férié",D38="OFF"),AND(F38="Férié",D38="Congé"),AND(F38="Férié",D38="Congé sans solde"),AND(F38="Férié",D38="Congé spécial")),0,IF(OR(F38="OFF",F38="Congé",F38="Congé spécial",F38="Congé sans solde",D38="OFF",D38="Congé",D38="Congé spécial",D38="Congé sans solde"),0.208333333333334,IF(AND(AG38="",F38-D38<0),("24:00:00"-D38)+("00:00:00"+F38)-0.0416666666666667,IF(AND(OR(AG38="Allaitement",AG38="Sans déjeuner"),F38-D38<0),("24:00:00"-D38)+("00:00:00"+F38),IF(AND(AG38="",F38-D38>0.166666666666667),F38-D38-0.0416666666666667,IF(AND(OR(AG38="Allaitement",AG38="Sans déjeuner"),F38-D38>0.166666666666667),F38-D38,F38-D38))))))) -> 0 | P38: Accesibilité | Q38: 44816 | R38: 0 | S38: 0 | T38: ="Sem - "&WEEKNUM(Q38,21) -> Sem - 37 | U38: =PROPER(TEXT(Q38,"mmmm")) -> Septembre | V38: 3079 | X38: =IFERROR(IF(M38="Abs",0,IF((D38-C38+E38-F38)<0.000694444444444444,0,(D38-C38+E38-F38))),0) -> 0 | Y38: =VLOOKUP('CM-CIC'!B38,Annuaire_roster!B:F,4,0) -> OUBRAHIM Mohammed | Z38: Credit Mutuel | AA38: FT
A39: =+VLOOKUP(B39,Annuaire_roster!B:G,5,0) -> 1265 | B39: RMAIDI IMAD | D39: OFF | F39: OFF | K39: 0 | L39: 0 | M39: 0 | N39: =IFERROR(IF(OR(D39="OFF",D39="Congé",M39="Abs",D39="Congé sans solde",D39="Férié"),"",IF(O39-K39-L39>O39,O39,IF(O39-K39-L39<0,"",O39-K39-L39))),"") | O39: =IF(AG39="2H Pause déjeuner",IF(F39-D39-0.0833333333333333<0,F39-D39-0.0833333333333333+1,F39-D39-0.0833333333333333),IF(OR(AND(F39="OFF",D39="OFF"),AND(F39="Congé",D39="Congé"),AND(F39="Congé sans solde",D39="Congé sans solde"),AND(F39="Congé spécial",D39="Congé spécial"),AND(F39="Férié",D39="Férié"),AND(F39="OFF",D39="Congé"),AND(F39="OFF",D39="Congé sans solde"),AND(F39="OFF",D39="Congé spécial"),AND(F39="OFF",D39="Férié"),AND(F39="Congé",D39="OFF"),AND(F39="Congé",D39="Congé sans solde"),AND(F39="Congé",D39="Congé spécial"),AND(F39="Congé",D39="Férié"),AND(F39="Congé sans solde",D39="OFF"),AND(F39="Congé sans solde",D39="Congé"),AND(F39="Congé sans solde",D39="Congé spécial"),AND(F39="Congé sans solde",D39="Férié"),AND(F39="Congé spécial",D39="OFF"),AND(F39="Congé spécial",D39="Congé"),AND(F39="Congé spécial",D39="Congé sans solde"),AND(F39="Congé spécial",D39="Férié"),AND(F39="Férié",D39="OFF"),AND(F39="Férié",D39="Congé"),AND(F39="Férié",D39="Congé sans solde"),AND(F39="Férié",D39="Congé spécial")),0,IF(OR(F39="OFF",F39="Congé",F39="Congé spécial",F39="Congé sans solde",D39="OFF",D39="Congé",D39="Congé spécial",D39="Congé sans solde"),0.208333333333334,IF(AND(AG39="",F39-D39<0),("24:00:00"-D39)+("00:00:00"+F39)-0.0416666666666667,IF(AND(OR(AG39="Allaitement",AG39="Sans déjeuner"),F39-D39<0),("24:00:00"-D39)+("00:00:00"+F39),IF(AND(AG39="",F39-D39>0.166666666666667),F39-D39-0.0416666666666667,IF(AND(OR(AG39="Allaitement",AG39="Sans déjeuner"),F39-D39>0.166666666666667),F39-D39,F39-D39))))))) -> 0 | P39: Accesibilité | Q39: 44816 | R39: 0 | S39: 0 | T39: ="Sem - "&WEEKNUM(Q39,21) -> Sem - 37 | U39: =PROPER(TEXT(Q39,"mmmm")) -> Septembre | V39: 3080 | X39: =IFERROR(IF(M39="Abs",0,IF((D39-C39+E39-F39)<0.000694444444444444,0,(D39-C39+E39-F39))),0) -> 0 | Y39: =VLOOKUP('CM-CIC'!B39,Annuaire_roster!B:F,4,0) -> OUBRAHIM Mohammed | Z39: Credit Mutuel | AA39: FT
A40: =+VLOOKUP(B40,Annuaire_roster!B:G,5,0) -> 1317 | B40: HAMDANI MOHAMED | D40: OFF | F40: OFF | K40: 0 | L40: 0 | M40: 0 | N40: =IFERROR(IF(OR(D40="OFF",D40="Congé",M40="Abs",D40="Congé sans solde",D40="Férié"),"",IF(O40-K40-L40>O40,O40,IF(O40-K40-L40<0,"",O40-K40-L40))),"") | O40: =IF(AG40="2H Pause déjeuner",IF(F40-D40-0.0833333333333333<0,F40-D40-0.0833333333333333+1,F40-D40-0.0833333333333333),IF(OR(AND(F40="OFF",D40="OFF"),AND(F40="Congé",D40="Congé"),AND(F40="Congé sans solde",D40="Congé sans solde"),AND(F40="Congé spécial",D40="Congé spécial"),AND(F40="Férié",D40="Férié"),AND(F40="OFF",D40="Congé"),AND(F40="OFF",D40="Congé sans solde"),AND(F40="OFF",D40="Congé spécial"),AND(F40="OFF",D40="Férié"),AND(F40="Congé",D40="OFF"),AND(F40="Congé",D40="Congé sans solde"),AND(F40="Congé",D40="Congé spécial"),AND(F40="Congé",D40="Férié"),AND(F40="Congé sans solde",D40="OFF"),AND(F40="Congé sans solde",D40="Congé"),AND(F40="Congé sans solde",D40="Congé spécial"),AND(F40="Congé sans solde",D40="Férié"),AND(F40="Congé spécial",D40="OFF"),AND(F40="Congé spécial",D40="Congé"),AND(F40="Congé spécial",D40="Congé sans solde"),AND(F40="Congé spécial",D40="Férié"),AND(F40="Férié",D40="OFF"),AND(F40="Férié",D40="Congé"),AND(F40="Férié",D40="Congé sans solde"),AND(F40="Férié",D40="Congé spécial")),0,IF(OR(F40="OFF",F40="Congé",F40="Congé spécial",F40="Congé sans solde",D40="OFF",D40="Congé",D40="Congé spécial",D40="Congé sans solde"),0.208333333333334,IF(AND(AG40="",F40-D40<0),("24:00:00"-D40)+("00:00:00"+F40)-0.0416666666666667,IF(AND(OR(AG40="Allaitement",AG40="Sans déjeuner"),F40-D40<0),("24:00:00"-D40)+("00:00:00"+F40),IF(AND(AG40="",F40-D40>0.166666666666667),F40-D40-0.0416666666666667,IF(AND(OR(AG40="Allaitement",AG40="Sans déjeuner"),F40-D40>0.166666666666667),F40-D40,F40-D40))))))) -> 0 | P40: Accesibilité | Q40: 44816 | R40: 0 | S40: 0 | T40: ="Sem - "&WEEKNUM(Q40,21) -> Sem - 37 | U40: =PROPER(TEXT(Q40,"mmmm")) -> Septembre | V40: 3081 | X40: =IFERROR(IF(M40="Abs",0,IF((D40-C40+E40-F40)<0.000694444444444444,0,(D40-C40+E40-F40))),0) -> 0 | Y40: =VLOOKUP('CM-CIC'!B40,Annuaire_roster!B:F,4,0) -> OUBRAHIM Mohammed | Z40: Credit Mutuel | AA40: FT
A41: =+VLOOKUP(B41,Annuaire_roster!B:G,5,0) -> 1317 | B41: HAMDANI MOHAMED | C41: 0.34513889 | D41: 0.33333333 | E41: 0.75 | F41: 0.75 | L41: 0 | M41: 0 | N41: =IFERROR(IF(OR(D41="OFF",D41="Congé",M41="Abs",D41="Congé sans solde",D41="Férié"),"",IF(O41-K41-L41>O41,O41,IF(O41-K41-L41<0,"",O41-K41-L41))),"") -> 0.375 | O41: =IF(AG41="2H Pause déjeuner",IF(F41-D41-0.0833333333333333<0,F41-D41-0.0833333333333333+1,F41-D41-0.0833333333333333),IF(OR(AND(F41="OFF",D41="OFF"),AND(F41="Congé",D41="Congé"),AND(F41="Congé sans solde",D41="Congé sans solde"),AND(F41="Congé spécial",D41="Congé spécial"),AND(F41="Férié",D41="Férié"),AND(F41="OFF",D41="Congé"),AND(F41="OFF",D41="Congé sans solde"),AND(F41="OFF",D41="Congé spécial"),AND(F41="OFF",D41="Férié"),AND(F41="Congé",D41="OFF"),AND(F41="Congé",D41="Congé sans solde"),AND(F41="Congé",D41="Congé spécial"),AND(F41="Congé",D41="Férié"),AND(F41="Congé sans solde",D41="OFF"),AND(F41="Congé sans solde",D41="Congé"),AND(F41="Congé sans solde",D41="Congé spécial"),AND(F41="Congé sans solde",D41="Férié"),AND(F41="Congé spécial",D41="OFF"),AND(F41="Congé spécial",D41="Congé"),AND(F41="Congé spécial",D41="Congé sans solde"),AND(F41="Congé spécial",D41="Férié"),AND(F41="Férié",D41="OFF"),AND(F41="Férié",D41="Congé"),AND(F41="Férié",D41="Congé sans solde"),AND(F41="Férié",D41="Congé spécial")),0,IF(OR(F41="OFF",F41="Congé",F41="Congé spécial",F41="Congé sans solde",D41="OFF",D41="Congé",D41="Congé spécial",D41="Congé sans solde"),0.208333333333334,IF(AND(AG41="",F41-D41<0),("24:00:00"-D41)+("00:00:00"+F41)-0.0416666666666667,IF(AND(OR(AG41="Allaitement",AG41="Sans déjeuner"),F41-D41<0),("24:00:00"-D41)+("00:00:00"+F41),IF(AND(AG41="",F41-D41>0.166666666666667),F41-D41-0.0416666666666667,IF(AND(OR(AG41="Allaitement",AG41="Sans déjeuner"),F41-D41>0.166666666666667),F41-D41,F41-D41))))))) -> 0.375 | P41: Accesibilité | Q41: 44817 | R41: =IF(M41="Abs",O41,0) -> 0 | S41: =SUM(R41,L41,I41,J41,W41,H41) -> 0 | T41: ="Sem - "&WEEKNUM(Q41,21) -> Sem - 38 | U41: =PROPER(TEXT(Q41,"mmmm")) -> Septembre | V41: =+TEXT(Q41,"aaa") -> 2026 | X41: =IFERROR(IF(M41="Abs",0,IF((D41-C41+E41-F41)<0.000694444444444444,0,(D41-C41+E41-F41))),0) -> 0 | Y41: =VLOOKUP('CM-CIC'!B41,Annuaire_roster!B:F,4,0) -> OUBRAHIM Mohammed | Z41: Credit Mutuel | AA41: Forfaitaire | AB41: =IF(AND(D41="Congé",F41="Congé"),0.333333333333333,IF(OR(AND(D41="Congé",F41<>"Congé"),(AND(F41="Congé",D41<>"Congé"))),0.166666666666667,"")) | AC41: =IF(AND(D41="Congé sans solde",F41="Congé sans solde"),0.333333333333333,IF(OR(AND(D41="Congé sans solde",F41<>"Congé sans solde"),(AND(F41="Congé sans solde",D41<>"Congé sans solde"))),0.166666666666667,"")) | AD41: =IF(AND(D41="Congé spécial",F41="Congé spécial"),0.333333333333333,IF(OR(AND(D41="Congé spécial",F41<>"Congé décès"),(AND(F41="Congé spécial",D41<>"Congé spécial"))),0.166666666666667,"")) | AE41: =IF(AND(D41="Férié",F41="Férié"),0.333333333333333,IF(OR(AND(D41="Férié",F41<>"Férié"),(AND(F41="Férié",D41<>"Férié"))),0.166666666666667,""))
