Workbook

Sheet Bilan agents
A1: Suivi d’assiduité — activité Accessibilité
A2: Source : « consolider du pointage CMAF 2026 » — lignes du segment Accesibilité uniquement. Tout est calculé depuis l’onglet Pointage.
A4: Tolérance retard (min) | C4: 0 | D4: ← à modifier (hypothèse : 0 = tout retard compté)
A5: Objectif d’assiduité | C5: 0.95 | D5: ← à modifier (hypothèse de ma part, non issue du fichier)
A7: Agent | B7: Matricule | C7: Premier pointage | D7: Dernier pointage | E7: Jours planifiés | F7: Jours présents | G7: Jours absents | H7: Non renseignés | I7: Congés | J7: Fériés | K7: Repos (OFF) | L7: Taux d’assiduité | M7: Nb retards | N7: Total retards (min) | O7: Heures planifiées | P7: Heures adhérées | Q7: Adhérence heures | R7: Heures sup. (min)
A8: BENCHRIF HAFSSA | B8: 1262 | C8: =_xlfn.MINIFS(Pointage!$C$2:$C$967,Pointage!$A$2:$A$967,$A8) -> 46012 | D8: =_xlfn.MAXIFS(Pointage!$C$2:$C$967,Pointage!$A$2:$A$967,$A8) -> 46133 | E8: =F8+G8+H8 -> 69 | F8: =COUNTIFS(Pointage!$A$2:$A$967,$A8,Pointage!$Q$2:$Q$967,"P") -> 68 | G8: =COUNTIFS(Pointage!$A$2:$A$967,$A8,Pointage!$Q$2:$Q$967,"A") -> 1 | H8: =COUNTIFS(Pointage!$A$2:$A$967,$A8,Pointage!$Q$2:$Q$967,"NR") -> 0 | I8: =COUNTIFS(Pointage!$A$2:$A$967,$A8,Pointage!$Q$2:$Q$967,"CP") -> 3 | J8: =COUNTIFS(Pointage!$A$2:$A$967,$A8,Pointage!$Q$2:$Q$967,"F") -> 1 | K8: =COUNTIFS(Pointage!$A$2:$A$967,$A8,Pointage!$Q$2:$Q$967,"R") -> 37 | L8: =IFERROR(F8/(F8+G8),"") -> 0.98550725 | M8: =COUNTIFS(Pointage!$A$2:$A$967,$A8,Pointage!$P$2:$P$967,">0") -> 2 | N8: =SUMIFS(Pointage!$P$2:$P$967,Pointage!$A$2:$A$967,$A8) -> 28 | O8: =SUMIFS(Pointage!$L$2:$L$967,Pointage!$A$2:$A$967,$A8) -> 25.291667 | P8: =SUMIFS(Pointage!$M$2:$M$967,Pointage!$A$2:$A$967,$A8) -> 24.916667 | Q8: =IFERROR(P8/O8,"") -> 0.98517298 | R8: =ROUND(SUMIFS(Pointage!$O$2:$O$967,Pointage!$A$2:$A$967,$A8)*1440,0) -> 11
A9: LISSAOUI HIBA | B9: 1278 | C9: =_xlfn.MINIFS(Pointage!$C$2:$C$967,Pointage!$A$2:$A$967,$A9) -> 46012 | D9: =_xlfn.MAXIFS(Pointage!$C$2:$C$967,Pointage!$A$2:$A$967,$A9) -> 46306 | E9: =F9+G9+H9 -> 181 | F9: =COUNTIFS(Pointage!$A$2:$A$967,$A9,Pointage!$Q$2:$Q$967,"P") -> 181 | G9: =COUNTIFS(Pointage!$A$2:$A$967,$A9,Pointage!$Q$2:$Q$967,"A") -> 0 | H9: =COUNTIFS(Pointage!$A$2:$A$967,$A9,Pointage!$Q$2:$Q$967,"NR") -> 0 | I9: =COUNTIFS(Pointage!$A$2:$A$967,$A9,Pointage!$Q$2:$Q$967,"CP") -> 8 | J9: =COUNTIFS(Pointage!$A$2:$A$967,$A9,Pointage!$Q$2:$Q$967,"F") -> 3 | K9: =COUNTIFS(Pointage!$A$2:$A$967,$A9,Pointage!$Q$2:$Q$967,"R") -> 91 | L9: =IFERROR(F9/(F9+G9),"") -> 1 | M9: =COUNTIFS(Pointage!$A$2:$A$967,$A9,Pointage!$P$2:$P$967,">0") -> 1 | N9: =SUMIFS(Pointage!$P$2:$P$967,Pointage!$A$2:$A$967,$A9) -> 83 | O9: =SUMIFS(Pointage!$L$2:$L$967,Pointage!$A$2:$A$967,$A9) -> 66.375 | P9: =SUMIFS(Pointage!$M$2:$M$967,Pointage!$A$2:$A$967,$A9) -> 66.375 | Q9: =IFERROR(P9/O9,"") -> 1 | R9: =ROUND(SUMIFS(Pointage!$O$2:$O$967,Pointage!$A$2:$A$967,$A9)*1440,0) -> 221
A10: RMAIDI IMAD | B10: 1265 | C10: =_xlfn.MINIFS(Pointage!$C$2:$C$967,Pointage!$A$2:$A$967,$A10) -> 46012 | D10: =_xlfn.MAXIFS(Pointage!$C$2:$C$967,Pointage!$A$2:$A$967,$A10) -> 46306 | E10: =F10+G10+H10 -> 180 | F10: =COUNTIFS(Pointage!$A$2:$A$967,$A10,Pointage!$Q$2:$Q$967,"P") -> 175 | G10: =COUNTIFS(Pointage!$A$2:$A$967,$A10,Pointage!$Q$2:$Q$967,"A") -> 5 | H10: =COUNTIFS(Pointage!$A$2:$A$967,$A10,Pointage!$Q$2:$Q$967,"NR") -> 0 | I10: =COUNTIFS(Pointage!$A$2:$A$967,$A10,Pointage!$Q$2:$Q$967,"CP") -> 10 | J10: =COUNTIFS(Pointage!$A$2:$A$967,$A10,Pointage!$Q$2:$Q$967,"F") -> 2 | K10: =COUNTIFS(Pointage!$A$2:$A$967,$A10,Pointage!$Q$2:$Q$967,"R") -> 91 | L10: =IFERROR(F10/(F10+G10),"") -> 0.97222222 | M10: =COUNTIFS(Pointage!$A$2:$A$967,$A10,Pointage!$P$2:$P$967,">0") -> 3 | N10: =SUMIFS(Pointage!$P$2:$P$967,Pointage!$A$2:$A$967,$A10) -> 31 | O10: =SUMIFS(Pointage!$L$2:$L$967,Pointage!$A$2:$A$967,$A10) -> 66.041667 | P10: =SUMIFS(Pointage!$M$2:$M$967,Pointage!$A$2:$A$967,$A10) -> 64.208333 | Q10: =IFERROR(P10/O10,"") -> 0.97223975 | R10: =ROUND(SUMIFS(Pointage!$O$2:$O$967,Pointage!$A$2:$A$967,$A10)*1440,0) -> 209
A11: HAMDANI MOHAMED | B11: 1317 | C11: =_xlfn.MINIFS(Pointage!$C$2:$C$967,Pointage!$A$2:$A$967,$A11) -> 46012 | D11: =_xlfn.MAXIFS(Pointage!$C$2:$C$967,Pointage!$A$2:$A$967,$A11) -> 46306 | E11: =F11+G11+H11 -> 186 | F11: =COUNTIFS(Pointage!$A$2:$A$967,$A11,Pointage!$Q$2:$Q$967,"P") -> 186 | G11: =COUNTIFS(Pointage!$A$2:$A$967,$A11,Pointage!$Q$2:$Q$967,"A") -> 0 | H11: =COUNTIFS(Pointage!$A$2:$A$967,$A11,Pointage!$Q$2:$Q$967,"NR") -> 0 | I11: =COUNTIFS(Pointage!$A$2:$A$967,$A11,Pointage!$Q$2:$Q$967,"CP") -> 4 | J11: =COUNTIFS(Pointage!$A$2:$A$967,$A11,Pointage!$Q$2:$Q$967,"F") -> 2 | K11: =COUNTIFS(Pointage!$A$2:$A$967,$A11,Pointage!$Q$2:$Q$967,"R") -> 91 | L11: =IFERROR(F11/(F11+G11),"") -> 1 | M11: =COUNTIFS(Pointage!$A$2:$A$967,$A11,Pointage!$P$2:$P$967,">0") -> 8 | N11: =SUMIFS(Pointage!$P$2:$P$967,Pointage!$A$2:$A$967,$A11) -> 152 | O11: =SUMIFS(Pointage!$L$2:$L$967,Pointage!$A$2:$A$967,$A11) -> 68.25 | P11: =SUMIFS(Pointage!$M$2:$M$967,Pointage!$A$2:$A$967,$A11) -> 68.25 | Q11: =IFERROR(P11/O11,"") -> 1 | R11: =ROUND(SUMIFS(Pointage!$O$2:$O$967,Pointage!$A$2:$A$967,$A11)*1440,0) -> 177
A12: JEBBALI YOUSSEF | B12: 01631 | C12: =_xlfn.MINIFS(Pointage!$C$2:$C$967,Pointage!$A$2:$A$967,$A12) -> 46300 | D12: =_xlfn.MAXIFS(Pointage!$C$2:$C$967,Pointage!$A$2:$A$967,$A12) -> 46306 | E12: =F12+G12+H12 -> 5 | F12: =COUNTIFS(Pointage!$A$2:$A$967,$A12,Pointage!$Q$2:$Q$967,"P") -> 5 | G12: =COUNTIFS(Pointage!$A$2:$A$967,$A12,Pointage!$Q$2:$Q$967,"A") -> 0 | H12: =COUNTIFS(Pointage!$A$2:$A$967,$A12,Pointage!$Q$2:$Q$967,"NR") -> 0 | I12: =COUNTIFS(Pointage!$A$2:$A$967,$A12,Pointage!$Q$2:$Q$967,"CP") -> 0 | J12: =COUNTIFS(Pointage!$A$2:$A$967,$A12,Pointage!$Q$2:$Q$967,"F") -> 0 | K12: =COUNTIFS(Pointage!$A$2:$A$967,$A12,Pointage!$Q$2:$Q$967,"R") -> 2 | L12: =IFERROR(F12/(F12+G12),"") -> 1 | M12: =COUNTIFS(Pointage!$A$2:$A$967,$A12,Pointage!$P$2:$P$967,">0") -> 0 | N12: =SUMIFS(Pointage!$P$2:$P$967,Pointage!$A$2:$A$967,$A12) -> 0 | O12: =SUMIFS(Pointage!$L$2:$L$967,Pointage!$A$2:$A$967,$A12) -> 0 | P12: =SUMIFS(Pointage!$M$2:$M$967,Pointage!$A$2:$A$967,$A12) -> 0 | Q12: =IFERROR(P12/O12,"") | R12: =ROUND(SUMIFS(Pointage!$O$2:$O$967,Pointage!$A$2:$A$967,$A12)*1440,0) -> 0
A13: Équipe | E13: =SUM(E8:E12) -> 621 | F13: =SUM(F8:F12) -> 615 | G13: =SUM(G8:G12) -> 6 | H13: =SUM(H8:H12) -> 0 | I13: =SUM(I8:I12) -> 25 | J13: =SUM(J8:J12) -> 8 | K13: =SUM(K8:K12) -> 312 | L13: =IFERROR(F13/(F13+G13),"") -> 0.99033816 | M13: =SUM(M8:M12) -> 14 | N13: =SUM(N8:N12) -> 294 | O13: =SUM(O8:O12) -> 225.95833 | P13: =SUM(P8:P12) -> 223.75 | Q13: =IFERROR(P13/O13,"") -> 0.99022681 | R13: =SUM(R8:R12) -> 618
A15: Légende des statuts (onglet Pointage)
A16: P | B16: Présent (début réalisé renseigné)
A17: A | B17: Absent (heures d’absence > 0)
A18: NR | B18: Jour planifié sans réalisé ni absence (non renseigné)
A19: CP | B19: Congé
A20: F | B20: Férié
A21: R | B21: Repos / OFF
A23: Taux d’assiduité = jours présents / (présents + absents). Retard = début réalisé − début planifié, au-delà de la tolérance.

Sheet Suivi hebdo
A1: Suivi hebdomadaire par agent
A3: Agent | B3: Année ISO | C3: Semaine | D3: Période (lun.–dim.) | E3: Jours planifiés | F3: Présents | G3: Absents | H3: Non renseignés | I3: Congés | J3: Fériés | K3: Nb retards | L3: Retards (min) | M3: Heures planifiées | N3: Heures adhérées | O3: Taux d’assiduité | P3: Adhérence heures
A4: BENCHRIF HAFSSA | B4: 2025 | C4: 51 | D4: 15/12/2025 – 21/12/2025 | E4: =F4+G4+H4 -> 0 | F4: =COUNTIFS(Pointage!$A$2:$A$967,$A4,Pointage!$D$2:$D$967,$B4,Pointage!$E$2:$E$967,$C4,Pointage!$Q$2:$Q$967,"P") -> 0 | G4: =COUNTIFS(Pointage!$A$2:$A$967,$A4,Pointage!$D$2:$D$967,$B4,Pointage!$E$2:$E$967,$C4,Pointage!$Q$2:$Q$967,"A") -> 0 | H4: =COUNTIFS(Pointage!$A$2:$A$967,$A4,Pointage!$D$2:$D$967,$B4,Pointage!$E$2:$E$967,$C4,Pointage!$Q$2:$Q$967,"NR") -> 0 | I4: =COUNTIFS(Pointage!$A$2:$A$967,$A4,Pointage!$D$2:$D$967,$B4,Pointage!$E$2:$E$967,$C4,Pointage!$Q$2:$Q$967,"CP") -> 0 | J4: =COUNTIFS(Pointage!$A$2:$A$967,$A4,Pointage!$D$2:$D$967,$B4,Pointage!$E$2:$E$967,$C4,Pointage!$Q$2:$Q$967,"F") -> 0 | K4: =COUNTIFS(Pointage!$A$2:$A$967,$A4,Pointage!$D$2:$D$967,$B4,Pointage!$E$2:$E$967,$C4,Pointage!$P$2:$P$967,">0") -> 0 | L4: =SUMIFS(Pointage!$P$2:$P$967,Pointage!$A$2:$A$967,$A4,Pointage!$D$2:$D$967,$B4,Pointage!$E$2:$E$967,$C4) -> 0 | M4: =SUMIFS(Pointage!$L$2:$L$967,Pointage!$A$2:$A$967,$A4,Pointage!$D$2:$D$967,$B4,Pointage!$E$2:$E$967,$C4) -> 0 | N4: =SUMIFS(Pointage!$M$2:$M$967,Pointage!$A$2:$A$967,$A4,Pointage!$D$2:$D$967,$B4,Pointage!$E$2:$E$967,$C4) -> 0 | O4: =IFERROR(F4/(F4+G4),"") | P4: =IFERROR(N4/M4,"")
A5: BENCHRIF HAFSSA | B5: 2025 | C5: 52 | D5: 22/12/2025 – 28/12/2025 | E5: =F5+G5+H5 -> 4 | F5: =COUNTIFS(Pointage!$A$2:$A$967,$A5,Pointage!$D$2:$D$967,$B5,Pointage!$E$2:$E$967,$C5,Pointage!$Q$2:$Q$967,"P") -> 4 | G5: =COUNTIFS(Pointage!$A$2:$A$967,$A5,Pointage!$D$2:$D$967,$B5,Pointage!$E$2:$E$967,$C5,Pointage!$Q$2:$Q$967,"A") -> 0 | H5: =COUNTIFS(Pointage!$A$2:$A$967,$A5,Pointage!$D$2:$D$967,$B5,Pointage!$E$2:$E$967,$C5,Pointage!$Q$2:$Q$967,"NR") -> 0 | I5: =COUNTIFS(Pointage!$A$2:$A$967,$A5,Pointage!$D$2:$D$967,$B5,Pointage!$E$2:$E$967,$C5,Pointage!$Q$2:$Q$967,"CP") -> 0 | J5: =COUNTIFS(Pointage!$A$2:$A$967,$A5,Pointage!$D$2:$D$967,$B5,Pointage!$E$2:$E$967,$C5,Pointage!$Q$2:$Q$967,"F") -> 0 | K5: =COUNTIFS(Pointage!$A$2:$A$967,$A5,Pointage!$D$2:$D$967,$B5,Pointage!$E$2:$E$967,$C5,Pointage!$P$2:$P$967,">0") -> 0 | L5: =SUMIFS(Pointage!$P$2:$P$967,Pointage!$A$2:$A$967,$A5,Pointage!$D$2:$D$967,$B5,Pointage!$E$2:$E$967,$C5) -> 0 | M5: =SUMIFS(Pointage!$L$2:$L$967,Pointage!$A$2:$A$967,$A5,Pointage!$D$2:$D$967,$B5,Pointage!$E$2:$E$967,$C5) -> 1.4583333 | N5: =SUMIFS(Pointage!$M$2:$M$967,Pointage!$A$2:$A$967,$A5,Pointage!$D$2:$D$967,$B5,Pointage!$E$2:$E$967,$C5) -> 1.4583333 | O5: =IFERROR(F5/(F5+G5),"") -> 1 | P5: =IFERROR(N5/M5,"") -> 1
A6: BENCHRIF HAFSSA | B6: 2026 | C6: 1 | D6: 29/12/2025 – 04/01/2026 | E6: =F6+G6+H6 -> 4 | F6: =COUNTIFS(Pointage!$A$2:$A$967,$A6,Pointage!$D$2:$D$967,$B6,Pointage!$E$2:$E$967,$C6,Pointage!$Q$2:$Q$967,"P") -> 4 | G6: =COUNTIFS(Pointage!$A$2:$A$967,$A6,Pointage!$D$2:$D$967,$B6,Pointage!$E$2:$E$967,$C6,Pointage!$Q$2:$Q$967,"A") -> 0 | H6: =COUNTIFS(Pointage!$A$2:$A$967,$A6,Pointage!$D$2:$D$967,$B6,Pointage!$E$2:$E$967,$C6,Pointage!$Q$2:$Q$967,"NR") -> 0 | I6: =COUNTIFS(Pointage!$A$2:$A$967,$A6,Pointage!$D$2:$D$967,$B6,Pointage!$E$2:$E$967,$C6,Pointage!$Q$2:$Q$967,"CP") -> 0 | J6: =COUNTIFS(Pointage!$A$2:$A$967,$A6,Pointage!$D$2:$D$967,$B6,Pointage!$E$2:$E$967,$C6,Pointage!$Q$2:$Q$967,"F") -> 1 | K6: =COUNTIFS(Pointage!$A$2:$A$967,$A6,Pointage!$D$2:$D$967,$B6,Pointage!$E$2:$E$967,$C6,Pointage!$P$2:$P$967,">0") -> 0 | L6: =SUMIFS(Pointage!$P$2:$P$967,Pointage!$A$2:$A$967,$A6,Pointage!$D$2:$D$967,$B6,Pointage!$E$2:$E$967,$C6) -> 0 | M6: =SUMIFS(Pointage!$L$2:$L$967,Pointage!$A$2:$A$967,$A6,Pointage!$D$2:$D$967,$B6,Pointage!$E$2:$E$967,$C6) -> 1.4583333 | N6: =SUMIFS(Pointage!$M$2:$M$967,Pointage!$A$2:$A$967,$A6,Pointage!$D$2:$D$967,$B6,Pointage!$E$2:$E$967,$C6) -> 1.4583333 | O6: =IFERROR(F6/(F6+G6),"") -> 1 | P6: =IFERROR(N6/M6,"") -> 1
A7: BENCHRIF HAFSSA | B7: 2026 | C7: 2 | D7: 05/01/2026 – 11/01/2026 | E7: =F7+G7+H7 -> 4 | F7: =COUNTIFS(Pointage!$A$2:$A$967,$A7,Pointage!$D$2:$D$967,$B7,Pointage!$E$2:$E$967,$C7,Pointage!$Q$2:$Q$967,"P") -> 4 | G7: =COUNTIFS(Pointage!$A$2:$A$967,$A7,Pointage!$D$2:$D$967,$B7,Pointage!$E$2:$E$967,$C7,Pointage!$Q$2:$Q$967,"A") -> 0 | H7: =COUNTIFS(Pointage!$A$2:$A$967,$A7,Pointage!$D$2:$D$967,$B7,Pointage!$E$2:$E$967,$C7,Pointage!$Q$2:$Q$967,"NR") -> 0 | I7: =COUNTIFS(Pointage!$A$2:$A$967,$A7,Pointage!$D$2:$D$967,$B7,Pointage!$E$2:$E$967,$C7,Pointage!$Q$2:$Q$967,"CP") -> 1 | J7: =COUNTIFS(Pointage!$A$2:$A$967,$A7,Pointage!$D$2:$D$967,$B7,Pointage!$E$2:$E$967,$C7,Pointage!$Q$2:$Q$967,"F") -> 0 | K7: =COUNTIFS(Pointage!$A$2:$A$967,$A7,Pointage!$D$2:$D$967,$B7,Pointage!$E$2:$E$967,$C7,Pointage!$P$2:$P$967,">0") -> 1 | L7: =SUMIFS(Pointage!$P$2:$P$967,Pointage!$A$2:$A$967,$A7,Pointage!$D$2:$D$967,$B7,Pointage!$E$2:$E$967,$C7) -> 5 | M7: =SUMIFS(Pointage!$L$2:$L$967,Pointage!$A$2:$A$967,$A7,Pointage!$D$2:$D$967,$B7,Pointage!$E$2:$E$967,$C7) -> 1.5 | N7: =SUMIFS(Pointage!$M$2:$M$967,Pointage!$A$2:$A$967,$A7,Pointage!$D$2:$D$967,$B7,Pointage!$E$2:$E$967,$C7) -> 1.5 | O7: =IFERROR(F7/(F7+G7),"") -> 1 | P7: =IFERROR(N7/M7,"") -> 1
A8: BENCHRIF HAFSSA | B8: 2026 | C8: 3 | D8: 12/01/2026 – 18/01/2026 | E8: =F8+G8+H8 -> 5 | F8: =COUNTIFS(Pointage!$A$2:$A$967,$A8,Pointage!$D$2:$D$967,$B8,Pointage!$E$2:$E$967,$C8,Pointage!$Q$2:$Q$967,"P") -> 5 | G8: =COUNTIFS(Pointage!$A$2:$A$967,$A8,Pointage!$D$2:$D$967,$B8,Pointage!$E$2:$E$967,$C8,Pointage!$Q$2:$Q$967,"A") -> 0 | H8: =COUNTIFS(Pointage!$A$2:$A$967,$A8,Pointage!$D$2:$D$967,$B8,Pointage!$E$2:$E$967,$C8,Pointage!$Q$2:$Q$967,"NR") -> 0 | I8: =COUNTIFS(Pointage!$A$2:$A$967,$A8,Pointage!$D$2:$D$967,$B8,Pointage!$E$2:$E$967,$C8,Pointage!$Q$2:$Q$967,"CP") -> 0 | J8: =COUNTIFS(Pointage!$A$2:$A$967,$A8,Pointage!$D$2:$D$967,$B8,Pointage!$E$2:$E$967,$C8,Pointage!$Q$2:$Q$967,"F") -> 0 | K8: =COUNTIFS(Pointage!$A$2:$A$967,$A8,Pointage!$D$2:$D$967,$B8,Pointage!$E$2:$E$967,$C8,Pointage!$P$2:$P$967,">0") -> 0 | L8: =SUMIFS(Pointage!$P$2:$P$967,Pointage!$A$2:$A$967,$A8,Pointage!$D$2:$D$967,$B8,Pointage!$E$2:$E$967,$C8) -> 0 | M8: =SUMIFS(Pointage!$L$2:$L$967,Pointage!$A$2:$A$967,$A8,Pointage!$D$2:$D$967,$B8,Pointage!$E$2:$E$967,$C8) -> 1.8333333 | N8: =SUMIFS(Pointage!$M$2:$M$967,Pointage!$A$2:$A$967,$A8,Pointage!$D$2:$D$967,$B8,Pointage!$E$2:$E$967,$C8) -> 1.8333333 | O8: =IFERROR(F8/(F8+G8),"") -> 1 | P8: =IFERROR(N8/M8,"") -> 1
A9: BENCHRIF HAFSSA | B9: 2026 | C9: 4 | D9: 19/01/2026 – 25/01/2026 | E9: =F9+G9+H9 -> 3 | F9: =COUNTIFS(Pointage!$A$2:$A$967,$A9,Pointage!$D$2:$D$967,$B9,Pointage!$E$2:$E$967,$C9,Pointage!$Q$2:$Q$967,"P") -> 2 | G9: =COUNTIFS(Pointage!$A$2:$A$967,$A9,Pointage!$D$2:$D$967,$B9,Pointage!$E$2:$E$967,$C9,Pointage!$Q$2:$Q$967,"A") -> 1 | H9: =COUNTIFS(Pointage!$A$2:$A$967,$A9,Pointage!$D$2:$D$967,$B9,Pointage!$E$2:$E$967,$C9,Pointage!$Q$2:$Q$967,"NR") -> 0 | I9: =COUNTIFS(Pointage!$A$2:$A$967,$A9,Pointage!$D$2:$D$967,$B9,Pointage!$E$2:$E$967,$C9,Pointage!$Q$2:$Q$967,"CP") -> 0 | J9: =COUNTIFS(Pointage!$A$2:$A$967,$A9,Pointage!$D$2:$D$967,$B9,Pointage!$E$2:$E$967,$C9,Pointage!$Q$2:$Q$967,"F") -> 0 | K9: =COUNTIFS(Pointage!$A$2:$A$967,$A9,Pointage!$D$2:$D$967,$B9,Pointage!$E$2:$E$967,$C9,Pointage!$P$2:$P$967,">0") -> 0 | L9: =SUMIFS(Pointage!$P$2:$P$967,Pointage!$A$2:$A$967,$A9,Pointage!$D$2:$D$967,$B9,Pointage!$E$2:$E$967,$C9) -> 0 | M9: =SUMIFS(Pointage!$L$2:$L$967,Pointage!$A$2:$A$967,$A9,Pointage!$D$2:$D$967,$B9,Pointage!$E$2:$E$967,$C9) -> 1.0833333 | N9: =SUMIFS(Pointage!$M$2:$M$967,Pointage!$A$2:$A$967,$A9,Pointage!$D$2:$D$967,$B9,Pointage!$E$2:$E$967,$C9) -> 0.70833333 | O9: =IFERROR(F9/(F9+G9),"") -> 0.66666667 | P9: =IFERROR(N9/M9,"") -> 0.65384615
A10: BENCHRIF HAFSSA | B10: 2026 | C10: 5 | D10: 26/01/2026 – 01/02/2026 | E10: =F10+G10+H10 -> 5 | F10: =COUNTIFS(Pointage!$A$2:$A$967,$A10,Pointage!$D$2:$D$967,$B10,Pointage!$E$2:$E$967,$C10,Pointage!$Q$2:$Q$967,"P") -> 5 | G10: =COUNTIFS(Pointage!$A$2:$A$967,$A10,Pointage!$D$2:$D$967,$B10,Pointage!$E$2:$E$967,$C10,Pointage!$Q$2:$Q$967,"A") -> 0 | H10: =COUNTIFS(Pointage!$A$2:$A$967,$A10,Pointage!$D$2:$D$967,$B10,Pointage!$E$2:$E$967,$C10,Pointage!$Q$2:$Q$967,"NR") -> 0 | I10: =COUNTIFS(Pointage!$A$2:$A$967,$A10,Pointage!$D$2:$D$967,$B10,Pointage!$E$2:$E$967,$C10,Pointage!$Q$2:$Q$967,"CP") -> 0 | J10: =COUNTIFS(Pointage!$A$2:$A$967,$A10,Pointage!$D$2:$D$967,$B10,Pointage!$E$2:$E$967,$C10,Pointage!$Q$2:$Q$967,"F") -> 0 | K10: =COUNTIFS(Pointage!$A$2:$A$967,$A10,Pointage!$D$2:$D$967,$B10,Pointage!$E$2:$E$967,$C10,Pointage!$P$2:$P$967,">0") -> 0 | L10: =SUMIFS(Pointage!$P$2:$P$967,Pointage!$A$2:$A$967,$A10,Pointage!$D$2:$D$967,$B10,Pointage!$E$2:$E$967,$C10) -> 0 | M10: =SUMIFS(Pointage!$L$2:$L$967,Pointage!$A$2:$A$967,$A10,Pointage!$D$2:$D$967,$B10,Pointage!$E$2:$E$967,$C10) -> 1.8333333 | N10: =SUMIFS(Pointage!$M$2:$M$967,Pointage!$A$2:$A$967,$A10,Pointage!$D$2:$D$967,$B10,Pointage!$E$2:$E$967,$C10) -> 1.8333333 | O10: =IFERROR(F10/(F10+G10),"") -> 1 | P10: =IFERROR(N10/M10,"") -> 1
A11: BENCHRIF HAFSSA | B11: 2026 | C11: 6 | D11: 02/02/2026 – 08/02/2026 | E11: =F11+G11+H11 -> 5 | F11: =COUNTIFS(Pointage!$A$2:$A$967,$A11,Pointage!$D$2:$D$967,$B11,Pointage!$E$2:$E$967,$C11,Pointage!$Q$2:$Q$967,"P") -> 5 | G11: =COUNTIFS(Pointage!$A$2:$A$967,$A11,Pointage!$D$2:$D$967,$B11,Pointage!$E$2:$E$967,$C11,Pointage!$Q$2:$Q$967,"A") -> 0 | H11: =COUNTIFS(Pointage!$A$2:$A$967,$A11,Pointage!$D$2:$D$967,$B11,Pointage!$E$2:$E$967,$C11,Pointage!$Q$2:$Q$967,"NR") -> 0 | I11: =COUNTIFS(Pointage!$A$2:$A$967,$A11,Pointage!$D$2:$D$967,$B11,Pointage!$E$2:$E$967,$C11,Pointage!$Q$2:$Q$967,"CP") -> 0 | J11: =COUNTIFS(Pointage!$A$2:$A$967,$A11,Pointage!$D$2:$D$967,$B11,Pointage!$E$2:$E$967,$C11,Pointage!$Q$2:$Q$967,"F") -> 0 | K11: =COUNTIFS(Pointage!$A$2:$A$967,$A11,Pointage!$D$2:$D$967,$B11,Pointage!$E$2:$E$967,$C11,Pointage!$P$2:$P$967,">0") -> 1 | L11: =SUMIFS(Pointage!$P$2:$P$967,Pointage!$A$2:$A$967,$A11,Pointage!$D$2:$D$967,$B11,Pointage!$E$2:$E$967,$C11) -> 23 | M11: =SUMIFS(Pointage!$L$2:$L$967,Pointage!$A$2:$A$967,$A11,Pointage!$D$2:$D$967,$B11,Pointage!$E$2:$E$967,$C11) -> 1.8333333 | N11: =SUMIFS(Pointage!$M$2:$M$967,Pointage!$A$2:$A$967,$A11,Pointage!$D$2:$D$967,$B11,Pointage!$E$2:$E$967,$C11) -> 1.8333333 | O11: =IFERROR(F11/(F11+G11),"") -> 1 | P11: =IFERROR(N11/M11,"") -> 1
A12: BENCHRIF HAFSSA | B12: 2026 | C12: 7 | D12: 09/02/2026 – 15/02/2026 | E12: =F12+G12+H12 -> 5 | F12: =COUNTIFS(Pointage!$A$2:$A$967,$A12,Pointage!$D$2:$D$967,$B12,Pointage!$E$2:$E$967,$C12,Pointage!$Q$2:$Q$967,"P") -> 5 | G12: =COUNTIFS(Pointage!$A$2:$A$967,$A12,Pointage!$D$2:$D$967,$B12,Pointage!$E$2:$E$967,$C12,Pointage!$Q$2:$Q$967,"A") -> 0 | H12: =COUNTIFS(Pointage!$A$2:$A$967,$A12,Pointage!$D$2:$D$967,$B12,Pointage!$E$2:$E$967,$C12,Pointage!$Q$2:$Q$967,"NR") -> 0 | I12: =COUNTIFS(Pointage!$A$2:$A$967,$A12,Pointage!$D$2:$D$967,$B12,Pointage!$E$2:$E$967,$C12,Pointage!$Q$2:$Q$967,"CP") -> 0 | J12: =COUNTIFS(Pointage!$A$2:$A$967,$A12,Pointage!$D$2:$D$967,$B12,Pointage!$E$2:$E$967,$C12,Pointage!$Q$2:$Q$967,"F") -> 0 | K12: =COUNTIFS(Pointage!$A$2:$A$967,$A12,Pointage!$D$2:$D$967,$B12,Pointage!$E$2:$E$967,$C12,Pointage!$P$2:$P$967,">0") -> 0 | L12: =SUMIFS(Pointage!$P$2:$P$967,Pointage!$A$2:$A$967,$A12,Pointage!$D$2:$D$967,$B12,Pointage!$E$2:$E$967,$C12) -> 0 | M12: =SUMIFS(Pointage!$L$2:$L$967,Pointage!$A$2:$A$967,$A12,Pointage!$D$2:$D$967,$B12,Pointage!$E$2:$E$967,$C12) -> 1.8333333 | N12: =SUMIFS(Pointage!$M$2:$M$967,Pointage!$A$2:$A$967,$A12,Pointage!$D$2:$D$967,$B12,Pointage!$E$2:$E$967,$C12) -> 1.8333333 | O12: =IFERROR(F12/(F12+G12),"") -> 1 | P12: =IFERROR(N12/M12,"") -> 1
A13: BENCHRIF HAFSSA | B13: 2026 | C13: 8 | D13: 16/02/2026 – 22/02/2026 | E13: =F13+G13+H13 -> 0 | F13: =COUNTIFS(Pointage!$A$2:$A$967,$A13,Pointage!$D$2:$D$967,$B13,Pointage!$E$2:$E$967,$C13,Pointage!$Q$2:$Q$967,"P") -> 0 | G13: =COUNTIFS(Pointage!$A$2:$A$967,$A13,Pointage!$D$2:$D$967,$B13,Pointage!$E$2:$E$967,$C13,Pointage!$Q$2:$Q$967,"A") -> 0 | H13: =COUNTIFS(Pointage!$A$2:$A$967,$A13,Pointage!$D$2:$D$967,$B13,Pointage!$E$2:$E$967,$C13,Pointage!$Q$2:$Q$967,"NR") -> 0 | I13: =COUNTIFS(Pointage!$A$2:$A$967,$A13,Pointage!$D$2:$D$967,$B13,Pointage!$E$2:$E$967,$C13,Pointage!$Q$2:$Q$967,"CP") -> 0 | J13: =COUNTIFS(Pointage!$A$2:$A$967,$A13,Pointage!$D$2:$D$967,$B13,Pointage!$E$2:$E$967,$C13,Pointage!$Q$2:$Q$967,"F") -> 0 | K13: =COUNTIFS(Pointage!$A$2:$A$967,$A13,Pointage!$D$2:$D$967,$B13,Pointage!$E$2:$E$967,$C13,Pointage!$P$2:$P$967,">0") -> 0 | L13: =SUMIFS(Pointage!$P$2:$P$967,Pointage!$A$2:$A$967,$A13,Pointage!$D$2:$D$967,$B13,Pointage!$E$2:$E$967,$C13) -> 0 | M13: =SUMIFS(Pointage!$L$2:$L$967,Pointage!$A$2:$A$967,$A13,Pointage!$D$2:$D$967,$B13,Pointage!$E$2:$E$967,$C13) -> 0 | N13: =SUMIFS(Pointage!$M$2:$M$967,Pointage!$A$2:$A$967,$A13,Pointage!$D$2:$D$967,$B13,Pointage!$E$2:$E$967,$C13) -> 0 | O13: =IFERROR(F13/(F13+G13),"") | P13: =IFERROR(N13/M13,"")
A14: BENCHRIF HAFSSA | B14: 2026 | C14: 9 | D14: 23/02/2026 – 01/03/2026 | E14: =F14+G14+H14 -> 5 | F14: =COUNTIFS(Pointage!$A$2:$A$967,$A14,Pointage!$D$2:$D$967,$B14,Pointage!$E$2:$E$967,$C14,Pointage!$Q$2:$Q$967,"P") -> 5 | G14: =COUNTIFS(Pointage!$A$2:$A$967,$A14,Pointage!$D$2:$D$967,$B14,Pointage!$E$2:$E$967,$C14,Pointage!$Q$2:$Q$967,"A") -> 0 | H14: =COUNTIFS(Pointage!$A$2:$A$967,$A14,Pointage!$D$2:$D$967,$B14,Pointage!$E$2:$E$967,$C14,Pointage!$Q$2:$Q$967,"NR") -> 0 | I14: =COUNTIFS(Pointage!$A$2:$A$967,$A14,Pointage!$D$2:$D$967,$B14,Pointage!$E$2:$E$967,$C14,Pointage!$Q$2:$Q$967,"CP") -> 0 | J14: =COUNTIFS(Pointage!$A$2:$A$967,$A14,Pointage!$D$2:$D$967,$B14,Pointage!$E$2:$E$967,$C14,Pointage!$Q$2:$Q$967,"F") -> 0 | K14: =COUNTIFS(Pointage!$A$2:$A$967,$A14,Pointage!$D$2:$D$967,$B14,Pointage!$E$2:$E$967,$C14,Pointage!$P$2:$P$967,">0") -> 0 | L14: =SUMIFS(Pointage!$P$2:$P$967,Pointage!$A$2:$A$967,$A14,Pointage!$D$2:$D$967,$B14,Pointage!$E$2:$E$967,$C14) -> 0 | M14: =SUMIFS(Pointage!$L$2:$L$967,Pointage!$A$2:$A$967,$A14,Pointage!$D$2:$D$967,$B14,Pointage!$E$2:$E$967,$C14) -> 1.8333333 | N14: =SUMIFS(Pointage!$M$2:$M$967,Pointage!$A$2:$A$967,$A14,Pointage!$D$2:$D$967,$B14,Pointage!$E$2:$E$967,$C14) -> 1.8333333 | O14: =IFERROR(F14/(F14+G14),"") -> 1 | P14: =IFERROR(N14/M14,"") -> 1
A15: BENCHRIF HAFSSA | B15: 2026 | C15: 10 | D15: 02/03/2026 – 08/03/2026 | E15: =F15+G15+H15 -> 5 | F15: =COUNTIFS(Pointage!$A$2:$A$967,$A15,Pointage!$D$2:$D$967,$B15,Pointage!$E$2:$E$967,$C15,Pointage!$Q$2:$Q$967,"P") -> 5 | G15: =COUNTIFS(Pointage!$A$2:$A$967,$A15,Pointage!$D$2:$D$967,$B15,Pointage!$E$2:$E$967,$C15,Pointage!$Q$2:$Q$967,"A") -> 0 | H15: =COUNTIFS(Pointage!$A$2:$A$967,$A15,Pointage!$D$2:$D$967,$B15,Pointage!$E$2:$E$967,$C15,Pointage!$Q$2:$Q$967,"NR") -> 0 | I15: =COUNTIFS(Pointage!$A$2:$A$967,$A15,Pointage!$D$2:$D$967,$B15,Pointage!$E$2:$E$967,$C15,Pointage!$Q$2:$Q$967,"CP") -> 0 | J15: =COUNTIFS(Pointage!$A$2:$A$967,$A15,Pointage!$D$2:$D$967,$B15,Pointage!$E$2:$E$967,$C15,Pointage!$Q$2:$Q$967,"F") -> 0 | K15: =COUNTIFS(Pointage!$A$2:$A$967,$A15,Pointage!$D$2:$D$967,$B15,Pointage!$E$2:$E$967,$C15,Pointage!$P$2:$P$967,">0") -> 0 | L15: =SUMIFS(Pointage!$P$2:$P$967,Pointage!$A$2:$A$967,$A15,Pointage!$D$2:$D$967,$B15,Pointage!$E$2:$E$967,$C15) -> 0 | M15: =SUMIFS(Pointage!$L$2:$L$967,Pointage!$A$2:$A$967,$A15,Pointage!$D$2:$D$967,$B15,Pointage!$E$2:$E$967,$C15) -> 1.8333333 | N15: =SUMIFS(Pointage!$M$2:$M$967,Pointage!$A$2:$A$967,$A15,Pointage!$D$2:$D$967,$B15,Pointage!$E$2:$E$967,$C15) -> 1.8333333 | O15: =IFERROR(F15/(F15+G15),"") -> 1 | P15: =IFERROR(N15/M15,"") -> 1
... A152: JEBBALI YOUSSEF | B152: 2026 | C152: 41 | D152: 05/10/2026 – 11/10/2026 | E152: =F152+G152+H152 -> 5 | F152: =COUNTIFS(Pointage!$A$2:$A$967,$A152,Pointage!$D$2:$D$967,$B152,Pointage!$E$2:$E$967,$C152,Pointage!$Q$2:$Q$967,"P") -> 5 | G152: =COUNTIFS(Pointage!$A$2:$A$967,$A152,Pointage!$D$2:$D$967,$B152,Pointage!$E$2:$E$967,$C152,Pointage!$Q$2:$Q$967,"A") -> 0 | H152: =COUNTIFS(Pointage!$A$2:$A$967,$A152,Pointage!$D$2:$D$967,$B152,Pointage!$E$2:$E$967,$C152,Pointage!$Q$2:$Q$967,"NR") -> 0 | I152: =COUNTIFS(Pointage!$A$2:$A$967,$A152,Pointage!$D$2:$D$967,$B152,Pointage!$E$2:$E$967,$C152,Pointage!$Q$2:$Q$967,"CP") -> 0 | J152: =COUNTIFS(Pointage!$A$2:$A$967,$A152,Pointage!$D$2:$D$967,$B152,Pointage!$E$2:$E$967,$C152,Pointage!$Q$2:$Q$967,"F") -> 0 | K152: =COUNTIFS(Pointage!$A$2:$A$967,$A152,Pointage!$D$2:$D$967,$B152,Pointage!$E$2:$E$967,$C152,Pointage!$P$2:$P$967,">0") -> 0 | L152: =SUMIFS(Pointage!$P$2:$P$967,Pointage!$A$2:$A$967,$A152,Pointage!$D$2:$D$967,$B152,Pointage!$E$2:$E$967,$C152) -> 0 | M152: =SUMIFS(Pointage!$L$2:$L$967,Pointage!$A$2:$A$967,$A152,Pointage!$D$2:$D$967,$B152,Pointage!$E$2:$E$967,$C152) -> 0 | N152: =SUMIFS(Pointage!$M$2:$M$967,Pointage!$A$2:$A$967,$A152,Pointage!$D$2:$D$967,$B152,Pointage!$E$2:$E$967,$C152) -> 0 | O152: =IFERROR(F152/(F152+G152),"") -> 1 | P152: =IFERROR(N152/M152,"")

Sheet Pointage
A1: Agent | B1: Matricule | C1: Date | D1: Année ISO | E1: Semaine | F1: Mois | G1: Jour | H1: Début planifié | I1: Début réalisé | J1: Fin planifiée | K1: Fin réalisée | L1: Hr planifiées | M1: Hr adhérées | N1: Hr absence | O1: Heures sup. | P1: Retard (min) | Q1: Statut | R1: Commentaire
A2: BENCHRIF HAFSSA | B2: 1262 | C2: 46012 | D2: 2025 | E2: 51 | F2: Décembre | G2: dim. | H2: OFF | L2: 0 | N2: 0 | O2: 0 | P2: =IF(AND(ISNUMBER(H2),ISNUMBER(I2)),MAX(0,ROUND((I2-H2)*1440,0)-'Bilan agents'!$C$4),0) -> 0 | Q2: =IF(H2="Congé","CP",IF(H2="Férié","F",IF(H2="OFF","R",IF(N2>0,"A",IF(ISNUMBER(I2),"P","NR"))))) -> R
A3: BENCHRIF HAFSSA | B3: 1262 | C3: 46013 | D3: 2025 | E3: 52 | F3: Décembre | G3: lun. | H3: 0.33333333 | I3: 0.33263889 | J3: 0.75 | K3: 0.75 | L3: 0.375 | M3: 0.375 | N3: 0 | O3: 0 | P3: =IF(AND(ISNUMBER(H3),ISNUMBER(I3)),MAX(0,ROUND((I3-H3)*1440,0)-'Bilan agents'!$C$4),0) -> 0 | Q3: =IF(H3="Congé","CP",IF(H3="Férié","F",IF(H3="OFF","R",IF(N3>0,"A",IF(ISNUMBER(I3),"P","NR"))))) -> P
A4: BENCHRIF HAFSSA | B4: 1262 | C4: 46014 | D4: 2025 | E4: 52 | F4: Décembre | G4: mar. | H4: 0.33333333 | I4: 0.33263889 | J4: 0.75 | K4: 0.75 | L4: 0.375 | M4: 0.375 | N4: 0 | O4: 0 | P4: =IF(AND(ISNUMBER(H4),ISNUMBER(I4)),MAX(0,ROUND((I4-H4)*1440,0)-'Bilan agents'!$C$4),0) -> 0 | Q4: =IF(H4="Congé","CP",IF(H4="Férié","F",IF(H4="OFF","R",IF(N4>0,"A",IF(ISNUMBER(I4),"P","NR"))))) -> P
A5: BENCHRIF HAFSSA | B5: 1262 | C5: 46015 | D5: 2025 | E5: 52 | F5: Décembre | G5: mer. | H5: 0.33333333 | I5: 0.33263889 | J5: 0.75 | K5: 0.75 | L5: 0.375 | M5: 0.375 | N5: 0 | O5: 0 | P5: =IF(AND(ISNUMBER(H5),ISNUMBER(I5)),MAX(0,ROUND((I5-H5)*1440,0)-'Bilan agents'!$C$4),0) -> 0 | Q5: =IF(H5="Congé","CP",IF(H5="Férié","F",IF(H5="OFF","R",IF(N5>0,"A",IF(ISNUMBER(I5),"P","NR"))))) -> P
A6: BENCHRIF HAFSSA | B6: 1262 | C6: 46016 | D6: 2025 | E6: 52 | F6: Décembre | G6: jeu. | H6: OFF | L6: 0 | N6: 0 | O6: 0 | P6: =IF(AND(ISNUMBER(H6),ISNUMBER(I6)),MAX(0,ROUND((I6-H6)*1440,0)-'Bilan agents'!$C$4),0) -> 0 | Q6: =IF(H6="Congé","CP",IF(H6="Férié","F",IF(H6="OFF","R",IF(N6>0,"A",IF(ISNUMBER(I6),"P","NR"))))) -> R
A7: BENCHRIF HAFSSA | B7: 1262 | C7: 46017 | D7: 2025 | E7: 52 | F7: Décembre | G7: ven. | H7: 0.33333333 | I7: 0.33333333 | J7: 0.70833333 | K7: 0.70833333 | L7: 0.33333333 | M7: 0.33333333 | N7: 0 | O7: 0 | P7: =IF(AND(ISNUMBER(H7),ISNUMBER(I7)),MAX(0,ROUND((I7-H7)*1440,0)-'Bilan agents'!$C$4),0) -> 0 | Q7: =IF(H7="Congé","CP",IF(H7="Férié","F",IF(H7="OFF","R",IF(N7>0,"A",IF(ISNUMBER(I7),"P","NR"))))) -> P
A8: BENCHRIF HAFSSA | B8: 1262 | C8: 46018 | D8: 2025 | E8: 52 | F8: Décembre | G8: sam. | H8: OFF | L8: 0 | N8: 0 | O8: 0 | P8: =IF(AND(ISNUMBER(H8),ISNUMBER(I8)),MAX(0,ROUND((I8-H8)*1440,0)-'Bilan agents'!$C$4),0) -> 0 | Q8: =IF(H8="Congé","CP",IF(H8="Férié","F",IF(H8="OFF","R",IF(N8>0,"A",IF(ISNUMBER(I8),"P","NR"))))) -> R
A9: BENCHRIF HAFSSA | B9: 1262 | C9: 46019 | D9: 2025 | E9: 52 | F9: Décembre | G9: dim. | H9: OFF | L9: 0 | N9: 0 | O9: 0 | P9: =IF(AND(ISNUMBER(H9),ISNUMBER(I9)),MAX(0,ROUND((I9-H9)*1440,0)-'Bilan agents'!$C$4),0) -> 0 | Q9: =IF(H9="Congé","CP",IF(H9="Férié","F",IF(H9="OFF","R",IF(N9>0,"A",IF(ISNUMBER(I9),"P","NR"))))) -> R
A10: BENCHRIF HAFSSA | B10: 1262 | C10: 46020 | D10: 2026 | E10: 1 | F10: Décembre | G10: lun. | H10: 0.33333333 | I10: 0.33263889 | J10: 0.75 | K10: 0.75 | L10: 0.375 | M10: 0.375 | N10: 0 | O10: 0 | P10: =IF(AND(ISNUMBER(H10),ISNUMBER(I10)),MAX(0,ROUND((I10-H10)*1440,0)-'Bilan agents'!$C$4),0) -> 0 | Q10: =IF(H10="Congé","CP",IF(H10="Férié","F",IF(H10="OFF","R",IF(N10>0,"A",IF(ISNUMBER(I10),"P","NR"))))) -> P
A11: BENCHRIF HAFSSA | B11: 1262 | C11: 46021 | D11: 2026 | E11: 1 | F11: Décembre | G11: mar. | H11: 0.33333333 | I11: 0.33263889 | J11: 0.75 | K11: 0.75 | L11: 0.375 | M11: 0.375 | N11: 0 | O11: 0 | P11: =IF(AND(ISNUMBER(H11),ISNUMBER(I11)),MAX(0,ROUND((I11-H11)*1440,0)-'Bilan agents'!$C$4),0) -> 0 | Q11: =IF(H11="Congé","CP",IF(H11="Férié","F",IF(H11="OFF","R",IF(N11>0,"A",IF(ISNUMBER(I11),"P","NR"))))) -> P
A12: BENCHRIF HAFSSA | B12: 1262 | C12: 46022 | D12: 2026 | E12: 1 | F12: Décembre | G12: mer. | H12: 0.33333333 | I12: 0.33263889 | J12: 0.75 | K12: 0.75 | L12: 0.375 | M12: 0.375 | N12: 0 | O12: 0 | P12: =IF(AND(ISNUMBER(H12),ISNUMBER(I12)),MAX(0,ROUND((I12-H12)*1440,0)-'Bilan agents'!$C$4),0) -> 0 | Q12: =IF(H12="Congé","CP",IF(H12="Férié","F",IF(H12="OFF","R",IF(N12>0,"A",IF(ISNUMBER(I12),"P","NR"))))) -> P
A13: BENCHRIF HAFSSA | B13: 1262 | C13: 46023 | D13: 2026 | E13: 1 | F13: Janvier | G13: jeu. | H13: Férié | L13: 0 | N13: 0 | O13: 0 | P13: =IF(AND(ISNUMBER(H13),ISNUMBER(I13)),MAX(0,ROUND((I13-H13)*1440,0)-'Bilan agents'!$C$4),0) -> 0 | Q13: =IF(H13="Congé","CP",IF(H13="Férié","F",IF(H13="OFF","R",IF(N13>0,"A",IF(ISNUMBER(I13),"P","NR"))))) -> F
A14: BENCHRIF HAFSSA | B14: 1262 | C14: 46024 | D14: 2026 | E14: 1 | F14: Janvier | G14: ven. | H14: 0.33333333 | I14: 0.33333333 | J14: 0.70833333 | K14: 0.70833333 | L14: 0.33333333 | M14: 0.33333333 | N14: 0 | O14: 0 | P14: =IF(AND(ISNUMBER(H14),ISNUMBER(I14)),MAX(0,ROUND((I14-H14)*1440,0)-'Bilan agents'!$C$4),0) -> 0 | Q14: =IF(H14="Congé","CP",IF(H14="Férié","F",IF(H14="OFF","R",IF(N14>0,"A",IF(ISNUMBER(I14),"P","NR"))))) -> P
A15: BENCHRIF HAFSSA | B15: 1262 | C15: 46025 | D15: 2026 | E15: 1 | F15: Janvier | G15: sam. | H15: OFF | L15: 0 | N15: 0 | O15: 0 | P15: =IF(AND(ISNUMBER(H15),ISNUMBER(I15)),MAX(0,ROUND((I15-H15)*1440,0)-'Bilan agents'!$C$4),0) -> 0 | Q15: =IF(H15="Congé","CP",IF(H15="Férié","F",IF(H15="OFF","R",IF(N15>0,"A",IF(ISNUMBER(I15),"P","NR"))))) -> R
A16: BENCHRIF HAFSSA | B16: 1262 | C16: 46026 | D16: 2026 | E16: 1 | F16: Janvier | G16: dim. | H16: OFF | L16: 0 | N16: 0 | O16: 0 | P16: =IF(AND(ISNUMBER(H16),ISNUMBER(I16)),MAX(0,ROUND((I16-H16)*1440,0)-'Bilan agents'!$C$4),0) -> 0 | Q16: =IF(H16="Congé","CP",IF(H16="Férié","F",IF(H16="OFF","R",IF(N16>0,"A",IF(ISNUMBER(I16),"P","NR"))))) -> R
A17: BENCHRIF HAFSSA | B17: 1262 | C17: 46027 | D17: 2026 | E17: 2 | F17: Janvier | G17: lun. | H17: 0.33333333 | I17: 0.33263889 | J17: 0.75 | K17: 0.75 | L17: 0.375 | M17: 0.375 | N17: 0 | O17: 0 | P17: =IF(AND(ISNUMBER(H17),ISNUMBER(I17)),MAX(0,ROUND((I17-H17)*1440,0)-'Bilan agents'!$C$4),0) -> 0 | Q17: =IF(H17="Congé","CP",IF(H17="Férié","F",IF(H17="OFF","R",IF(N17>0,"A",IF(ISNUMBER(I17),"P","NR"))))) -> P
A18: BENCHRIF HAFSSA | B18: 1262 | C18: 46028 | D18: 2026 | E18: 2 | F18: Janvier | G18: mar. | H18: 0.33333333 | I18: 0.33263889 | J18: 0.75 | K18: 0.75 | L18: 0.375 | M18: 0.375 | N18: 0 | O18: 0 | P18: =IF(AND(ISNUMBER(H18),ISNUMBER(I18)),MAX(0,ROUND((I18-H18)*1440,0)-'Bilan agents'!$C$4),0) -> 0 | Q18: =IF(H18="Congé","CP",IF(H18="Férié","F",IF(H18="OFF","R",IF(N18>0,"A",IF(ISNUMBER(I18),"P","NR"))))) -> P
A19: BENCHRIF HAFSSA | B19: 1262 | C19: 46029 | D19: 2026 | E19: 2 | F19: Janvier | G19: mer. | H19: 0.33333333 | I19: 0.33263889 | J19: 0.75 | K19: 0.75 | L19: 0.375 | M19: 0.375 | N19: 0 | O19: 0 | P19: =IF(AND(ISNUMBER(H19),ISNUMBER(I19)),MAX(0,ROUND((I19-H19)*1440,0)-'Bilan agents'!$C$4),0) -> 0 | Q19: =IF(H19="Congé","CP",IF(H19="Férié","F",IF(H19="OFF","R",IF(N19>0,"A",IF(ISNUMBER(I19),"P","NR"))))) -> P
A20: BENCHRIF HAFSSA | B20: 1262 | C20: 46030 | D20: 2026 | E20: 2 | F20: Janvier | G20: jeu. | H20: 0.33333333 | I20: 0.33680556 | J20: 0.75 | K20: 0.75 | L20: 0.375 | M20: 0.375 | N20: 0 | O20: 0 | P20: =IF(AND(ISNUMBER(H20),ISNUMBER(I20)),MAX(0,ROUND((I20-H20)*1440,0)-'Bilan agents'!$C$4),0) -> 5 | Q20: =IF(H20="Congé","CP",IF(H20="Férié","F",IF(H20="OFF","R",IF(N20>0,"A",IF(ISNUMBER(I20),"P","NR"))))) -> P
A21: BENCHRIF HAFSSA | B21: 1262 | C21: 46031 | D21: 2026 | E21: 2 | F21: Janvier | G21: ven. | H21: Congé | L21: 0 | N21: 0 | O21: 0 | P21: =IF(AND(ISNUMBER(H21),ISNUMBER(I21)),MAX(0,ROUND((I21-H21)*1440,0)-'Bilan agents'!$C$4),0) -> 0 | Q21: =IF(H21="Congé","CP",IF(H21="Férié","F",IF(H21="OFF","R",IF(N21>0,"A",IF(ISNUMBER(I21),"P","NR"))))) -> CP
A22: BENCHRIF HAFSSA | B22: 1262 | C22: 46032 | D22: 2026 | E22: 2 | F22: Janvier | G22: sam. | H22: OFF | L22: 0 | N22: 0 | O22: 0 | P22: =IF(AND(ISNUMBER(H22),ISNUMBER(I22)),MAX(0,ROUND((I22-H22)*1440,0)-'Bilan agents'!$C$4),0) -> 0 | Q22: =IF(H22="Congé","CP",IF(H22="Férié","F",IF(H22="OFF","R",IF(N22>0,"A",IF(ISNUMBER(I22),"P","NR"))))) -> R
A23: BENCHRIF HAFSSA | B23: 1262 | C23: 46033 | D23: 2026 | E23: 2 | F23: Janvier | G23: dim. | H23: OFF | L23: 0 | N23: 0 | O23: 0 | P23: =IF(AND(ISNUMBER(H23),ISNUMBER(I23)),MAX(0,ROUND((I23-H23)*1440,0)-'Bilan agents'!$C$4),0) -> 0 | Q23: =IF(H23="Congé","CP",IF(H23="Férié","F",IF(H23="OFF","R",IF(N23>0,"A",IF(ISNUMBER(I23),"P","NR"))))) -> R
A24: BENCHRIF HAFSSA | B24: 1262 | C24: 46034 | D24: 2026 | E24: 3 | F24: Janvier | G24: lun. | H24: 0.33333333 | I24: 0.33194444 | J24: 0.75 | K24: 0.75 | L24: 0.375 | M24: 0.375 | N24: 0 | O24: 0.0013888889 | P24: =IF(AND(ISNUMBER(H24),ISNUMBER(I24)),MAX(0,ROUND((I24-H24)*1440,0)-'Bilan agents'!$C$4),0) -> 0 | Q24: =IF(H24="Congé","CP",IF(H24="Férié","F",IF(H24="OFF","R",IF(N24>0,"A",IF(ISNUMBER(I24),"P","NR"))))) -> P
A25: BENCHRIF HAFSSA | B25: 1262 | C25: 46035 | D25: 2026 | E25: 3 | F25: Janvier | G25: mar. | H25: 0.33333333 | I25: 0.33194444 | J25: 0.75 | K25: 0.75 | L25: 0.375 | M25: 0.375 | N25: 0 | O25: 0.0013888889 | P25: =IF(AND(ISNUMBER(H25),ISNUMBER(I25)),MAX(0,ROUND((I25-H25)*1440,0)-'Bilan agents'!$C$4),0) -> 0 | Q25: =IF(H25="Congé","CP",IF(H25="Férié","F",IF(H25="OFF","R",IF(N25>0,"A",IF(ISNUMBER(I25),"P","NR"))))) -> P
A26: BENCHRIF HAFSSA | B26: 1262 | C26: 46036 | D26: 2026 | E26: 3 | F26: Janvier | G26: mer. | H26: 0.33333333 | I26: 0.33333333 | J26: 0.75 | K26: 0.75 | L26: 0.375 | M26: 0.375 | N26: 0 | O26: 0 | P26: =IF(AND(ISNUMBER(H26),ISNUMBER(I26)),MAX(0,ROUND((I26-H26)*1440,0)-'Bilan agents'!$C$4),0) -> 0 | Q26: =IF(H26="Congé","CP",IF(H26="Férié","F",IF(H26="OFF","R",IF(N26>0,"A",IF(ISNUMBER(I26),"P","NR"))))) -> P
A27: BENCHRIF HAFSSA | B27: 1262 | C27: 46037 | D27: 2026 | E27: 3 | F27: Janvier | G27: jeu. | H27: 0.33333333 | I27: 0.33263889 | J27: 0.75 | K27: 0.75 | L27: 0.375 | M27: 0.375 | N27: 0 | O27: 0 | P27: =IF(AND(ISNUMBER(H27),ISNUMBER(I27)),MAX(0,ROUND((I27-H27)*1440,0)-'Bilan agents'!$C$4),0) -> 0 | Q27: =IF(H27="Congé","CP",IF(H27="Férié","F",IF(H27="OFF","R",IF(N27>0,"A",IF(ISNUMBER(I27),"P","NR"))))) -> P
A28: BENCHRIF HAFSSA | B28: 1262 | C28: 46038 | D28: 2026 | E28: 3 | F28: Janvier | G28: ven. | H28: 0.33333333 | I28: 0.33263889 | J28: 0.70833333 | K28: 0.70833333 | L28: 0.33333333 | M28: 0.33333333 | N28: 0 | O28: 0 | P28: =IF(AND(ISNUMBER(H28),ISNUMBER(I28)),MAX(0,ROUND((I28-H28)*1440,0)-'Bilan agents'!$C$4),0) -> 0 | Q28: =IF(H28="Congé","CP",IF(H28="Férié","F",IF(H28="OFF","R",IF(N28>0,"A",IF(ISNUMBER(I28),"P","NR"))))) -> P
A29: BENCHRIF HAFSSA | B29: 1262 | C29: 46039 | D29: 2026 | E29: 3 | F29: Janvier | G29: sam. | H29: OFF | L29: 0 | N29: 0 | O29: 0 | P29: =IF(AND(ISNUMBER(H29),ISNUMBER(I29)),MAX(0,ROUND((I29-H29)*1440,0)-'Bilan agents'!$C$4),0) -> 0 | Q29: =IF(H29="Congé","CP",IF(H29="Férié","F",IF(H29="OFF","R",IF(N29>0,"A",IF(ISNUMBER(I29),"P","NR"))))) -> R
A30: BENCHRIF HAFSSA | B30: 1262 | C30: 46040 | D30: 2026 | E30: 3 | F30: Janvier | G30: dim. | H30: OFF | L30: 0 | N30: 0 | O30: 0 | P30: =IF(AND(ISNUMBER(H30),ISNUMBER(I30)),MAX(0,ROUND((I30-H30)*1440,0)-'Bilan agents'!$C$4),0) -> 0 | Q30: =IF(H30="Congé","CP",IF(H30="Férié","F",IF(H30="OFF","R",IF(N30>0,"A",IF(ISNUMBER(I30),"P","NR"))))) -> R
A31: BENCHRIF HAFSSA | B31: 1262 | C31: 46043 | D31: 2026 | E31: 4 | F31: Janvier | G31: mer. | H31: 0.33333333 | I31: 0.33263889 | J31: 0.75 | K31: 0.75 | L31: 0.375 | M31: 0.375 | N31: 0 | O31: 0 | P31: =IF(AND(ISNUMBER(H31),ISNUMBER(I31)),MAX(0,ROUND((I31-H31)*1440,0)-'Bilan agents'!$C$4),0) -> 0 | Q31: =IF(H31="Congé","CP",IF(H31="Férié","F",IF(H31="OFF","R",IF(N31>0,"A",IF(ISNUMBER(I31),"P","NR"))))) -> P
A32: BENCHRIF HAFSSA | B32: 1262 | C32: 46044 | D32: 2026 | E32: 4 | F32: Janvier | G32: jeu. | H32: 0.33333333 | J32: 0.75 | L32: 0.375 | N32: 0.375 | O32: 0 | P32: =IF(AND(ISNUMBER(H32),ISNUMBER(I32)),MAX(0,ROUND((I32-H32)*1440,0)-'Bilan agents'!$C$4),0) -> 0 | Q32: =IF(H32="Congé","CP",IF(H32="Férié","F",IF(H32="OFF","R",IF(N32>0,"A",IF(ISNUMBER(I32),"P","NR"))))) -> A
A33: BENCHRIF HAFSSA | B33: 1262 | C33: 46045 | D33: 2026 | E33: 4 | F33: Janvier | G33: ven. | H33: 0.33333333 | I33: 0.33263889 | J33: 0.70833333 | K33: 0.70833333 | L33: 0.33333333 | M33: 0.33333333 | N33: 0 | O33: 0 | P33: =IF(AND(ISNUMBER(H33),ISNUMBER(I33)),MAX(0,ROUND((I33-H33)*1440,0)-'Bilan agents'!$C$4),0) -> 0 | Q33: =IF(H33="Congé","CP",IF(H33="Férié","F",IF(H33="OFF","R",IF(N33>0,"A",IF(ISNUMBER(I33),"P","NR"))))) -> P
A34: BENCHRIF HAFSSA | B34: 1262 | C34: 46046 | D34: 2026 | E34: 4 | F34: Janvier | G34: sam. | H34: OFF | L34: 0 | N34: 0 | O34: 0 | P34: =IF(AND(ISNUMBER(H34),ISNUMBER(I34)),MAX(0,ROUND((I34-H34)*1440,0)-'Bilan agents'!$C$4),0) -> 0 | Q34: =IF(H34="Congé","CP",IF(H34="Férié","F",IF(H34="OFF","R",IF(N34>0,"A",IF(ISNUMBER(I34),"P","NR"))))) -> R
A35: BENCHRIF HAFSSA | B35: 1262 | C35: 46047 | D35: 2026 | E35: 4 | F35: Janvier | G35: dim. | H35: OFF | L35: 0 | N35: 0 | O35: 0 | P35: =IF(AND(ISNUMBER(H35),ISNUMBER(I35)),MAX(0,ROUND((I35-H35)*1440,0)-'Bilan agents'!$C$4),0) -> 0 | Q35: =IF(H35="Congé","CP",IF(H35="Férié","F",IF(H35="OFF","R",IF(N35>0,"A",IF(ISNUMBER(I35),"P","NR"))))) -> R
A36: BENCHRIF HAFSSA | B36: 1262 | C36: 46048 | D36: 2026 | E36: 5 | F36: Janvier | G36: lun. | H36: 0.33333333 | I36: 0.33333333 | J36: 0.75 | K36: 0.75 | L36: 0.375 | M36: 0.375 | N36: 0 | O36: 0 | P36: =IF(AND(ISNUMBER(H36),ISNUMBER(I36)),MAX(0,ROUND((I36-H36)*1440,0)-'Bilan agents'!$C$4),0) -> 0 | Q36: =IF(H36="Congé","CP",IF(H36="Férié","F",IF(H36="OFF","R",IF(N36>0,"A",IF(ISNUMBER(I36),"P","NR"))))) -> P
A37: BENCHRIF HAFSSA | B37: 1262 | C37: 46049 | D37: 2026 | E37: 5 | F37: Janvier | G37: mar. | H37: 0.33333333 | I37: 0.33263889 | J37: 0.75 | K37: 0.75 | L37: 0.375 | M37: 0.375 | N37: 0 | O37: 0 | P37: =IF(AND(ISNUMBER(H37),ISNUMBER(I37)),MAX(0,ROUND((I37-H37)*1440,0)-'Bilan agents'!$C$4),0) -> 0 | Q37: =IF(H37="Congé","CP",IF(H37="Férié","F",IF(H37="OFF","R",IF(N37>0,"A",IF(ISNUMBER(I37),"P","NR"))))) -> P
A38: BENCHRIF HAFSSA | B38: 1262 | C38: 46050 | D38: 2026 | E38: 5 | F38: Janvier | G38: mer. | H38: 0.33333333 | I38: 0.33263889 | J38: 0.75 | K38: 0.75 | L38: 0.375 | M38: 0.375 | N38: 0 | O38: 0 | P38: =IF(AND(ISNUMBER(H38),ISNUMBER(I38)),MAX(0,ROUND((I38-H38)*1440,0)-'Bilan agents'!$C$4),0) -> 0 | Q38: =IF(H38="Congé","CP",IF(H38="Férié","F",IF(H38="OFF","R",IF(N38>0,"A",IF(ISNUMBER(I38),"P","NR"))))) -> P
A39: BENCHRIF HAFSSA | B39: 1262 | C39: 46051 | D39: 2026 | E39: 5 | F39: Janvier | G39: jeu. | H39: 0.33333333 | I39: 0.33263889 | J39: 0.75 | K39: 0.75 | L39: 0.375 | M39: 0.375 | N39: 0 | O39: 0 | P39: =IF(AND(ISNUMBER(H39),ISNUMBER(I39)),MAX(0,ROUND((I39-H39)*1440,0)-'Bilan agents'!$C$4),0) -> 0 | Q39: =IF(H39="Congé","CP",IF(H39="Férié","F",IF(H39="OFF","R",IF(N39>0,"A",IF(ISNUMBER(I39),"P","NR"))))) -> P
A40: BENCHRIF HAFSSA | B40: 1262 | C40: 46052 | D40: 2026 | E40: 5 | F40: Janvier | G40: ven. | H40: 0.33333333 | I40: 0.33333333 | J40: 0.70833333 | K40: 0.70833333 | L40: 0.33333333 | M40: 0.33333333 | N40: 0 | O40: 0 | P40: =IF(AND(ISNUMBER(H40),ISNUMBER(I40)),MAX(0,ROUND((I40-H40)*1440,0)-'Bilan agents'!$C$4),0) -> 0 | Q40: =IF(H40="Congé","CP",IF(H40="Férié","F",IF(H40="OFF","R",IF(N40>0,"A",IF(ISNUMBER(I40),"P","NR"))))) -> P
...

Sheet Notes
A1: Sujet | B1: Précision
A2: Périmètre | B2: Lignes dont le segment est « Accesibilité » (orthographe du fichier) : 966 lignes sur 1 006 161. Les 28 lignes « Sortant » de JEBBALI YOUSSEF sont exclues.
A3: Période | B3: Du 21/12/2025 au 11/10/2026 (semaines ISO 2025-S51 à 2026-S41). Aucune donnée au-delà du 11/10 dans le fichier.
A4: Jours sans donnée | B4: Aucune ligne pour les 4 agents les 19–20/01, 16–20/02 et 16–20/03/2026 : ces jours ne sont ni comptés présents ni absents.
A5: BENCHRIF HAFSSA | B5: Dernier pointage le 21/04/2026 (110 jours).
A6: JEBBALI YOUSSEF | B6: Seule la semaine 41 existe (5 jours planifiés, tous pointés présents) ; les colonnes d’heures (planifiées / adhérées) ne sont pas renseignées dans le fichier, d’où des heures à 0 et pas d’adhérence calculée.
A7: Retards | B7: Les colonnes « Retard » / « Somme des retards » du fichier sont à 0 partout, alors que 14 jours ont un début réalisé postérieur au planifié (de 2 à 83 min). Les retards sont donc recalculés (début réalisé − début planifié), avec la tolérance de « Bilan agents » C4.
A8: Données corrompues | B8: 21 lignes du 07 au 13/09/2026 (Hiba, Imad, Mohamed) ont des colonnes Semaine/Mois/Année/Heures sup. invalides (ex. « Sem - 1071 », année 3061). Semaine et mois sont recalculés depuis la date, heures sup. mises à 0 ; les horaires restent ceux du fichier.
A9: Colonnes ignorées | B9: Statut (Forfaitaire / FT / 0 / -), Team (valeurs mixtes) et Congé/Férié détaillés : non utilisés ; les congés et fériés sont pris dans l’horaire planifié (Congé / Férié).
A10: Semaines | B10: Semaine = semaine ISO calculée depuis la date (lundi–dimanche).
A11: Hypothèses | B11: Objectif d’assiduité 95 % et tolérance de retard 0 min sont des paramètres modifiables (cellules jaunes de « Bilan agents »), non issus du fichier.
