Workbook

Sheet Synthèse hebdo
A1: Synthèse des évaluations par collaborateur et par semaine
A2: Nb docs = documents traités dans la semaine ; Note moy. = moyenne des notes /100 des documents évalués (cellule vide = aucun document). Calculé par formules à partir de l'onglet « Détail ».
A4: Année | B4: Semaine | C4: Période (lun.–dim.) | D4: Hafssa BENCHRIF | F4: Hiba LISSAOUI | H4: Imad RMAIDI | J4: Mohamed HAMDANI | L4: Youssef | N4: Équipe
D5: Nb docs | E5: Note moy. | F5: Nb docs | G5: Note moy. | H5: Nb docs | I5: Note moy. | J5: Nb docs | K5: Note moy. | L5: Nb docs | M5: Note moy. | N5: Nb docs | O5: Note moy.
A6: 2025 | B6: 51 | C6: 15/12/2025 – 21/12/2025 | D6: =COUNTIFS(Détail!$A:$A,"Hafssa BENCHRIF",Détail!$B:$B,$A6,Détail!$C:$C,$B6,Détail!$E:$E,"<>(à saisir)") | E6: =IFERROR(AVERAGEIFS(Détail!$I:$I,Détail!$A:$A,"Hafssa BENCHRIF",Détail!$B:$B,$A6,Détail!$C:$C,$B6),"") | F6: =COUNTIFS(Détail!$A:$A,"Hiba LISSAOUI",Détail!$B:$B,$A6,Détail!$C:$C,$B6,Détail!$E:$E,"<>(à saisir)") | G6: =IFERROR(AVERAGEIFS(Détail!$I:$I,Détail!$A:$A,"Hiba LISSAOUI",Détail!$B:$B,$A6,Détail!$C:$C,$B6),"") | H6: =COUNTIFS(Détail!$A:$A,"Imad RMAIDI",Détail!$B:$B,$A6,Détail!$C:$C,$B6,Détail!$E:$E,"<>(à saisir)") | I6: =IFERROR(AVERAGEIFS(Détail!$I:$I,Détail!$A:$A,"Imad RMAIDI",Détail!$B:$B,$A6,Détail!$C:$C,$B6),"") | J6: =COUNTIFS(Détail!$A:$A,"Mohamed HAMDANI",Détail!$B:$B,$A6,Détail!$C:$C,$B6,Détail!$E:$E,"<>(à saisir)") | K6: =IFERROR(AVERAGEIFS(Détail!$I:$I,Détail!$A:$A,"Mohamed HAMDANI",Détail!$B:$B,$A6,Détail!$C:$C,$B6),"") | L6: =COUNTIFS(Détail!$A:$A,"Youssef",Détail!$B:$B,$A6,Détail!$C:$C,$B6,Détail!$E:$E,"<>(à saisir)") | M6: =IFERROR(AVERAGEIFS(Détail!$I:$I,Détail!$A:$A,"Youssef",Détail!$B:$B,$A6,Détail!$C:$C,$B6),"") | N6: =COUNTIFS(Détail!$B:$B,$A6,Détail!$C:$C,$B6,Détail!$E:$E,"<>(à saisir)") | O6: =IFERROR(AVERAGEIFS(Détail!$I:$I,Détail!$B:$B,$A6,Détail!$C:$C,$B6),"")
A7: 2025 | B7: 52 | C7: 22/12/2025 – 28/12/2025 | D7: =COUNTIFS(Détail!$A:$A,"Hafssa BENCHRIF",Détail!$B:$B,$A7,Détail!$C:$C,$B7,Détail!$E:$E,"<>(à saisir)") | E7: =IFERROR(AVERAGEIFS(Détail!$I:$I,Détail!$A:$A,"Hafssa BENCHRIF",Détail!$B:$B,$A7,Détail!$C:$C,$B7),"") | F7: =COUNTIFS(Détail!$A:$A,"Hiba LISSAOUI",Détail!$B:$B,$A7,Détail!$C:$C,$B7,Détail!$E:$E,"<>(à saisir)") | G7: =IFERROR(AVERAGEIFS(Détail!$I:$I,Détail!$A:$A,"Hiba LISSAOUI",Détail!$B:$B,$A7,Détail!$C:$C,$B7),"") | H7: =COUNTIFS(Détail!$A:$A,"Imad RMAIDI",Détail!$B:$B,$A7,Détail!$C:$C,$B7,Détail!$E:$E,"<>(à saisir)") | I7: =IFERROR(AVERAGEIFS(Détail!$I:$I,Détail!$A:$A,"Imad RMAIDI",Détail!$B:$B,$A7,Détail!$C:$C,$B7),"") | J7: =COUNTIFS(Détail!$A:$A,"Mohamed HAMDANI",Détail!$B:$B,$A7,Détail!$C:$C,$B7,Détail!$E:$E,"<>(à saisir)") | K7: =IFERROR(AVERAGEIFS(Détail!$I:$I,Détail!$A:$A,"Mohamed HAMDANI",Détail!$B:$B,$A7,Détail!$C:$C,$B7),"") | L7: =COUNTIFS(Détail!$A:$A,"Youssef",Détail!$B:$B,$A7,Détail!$C:$C,$B7,Détail!$E:$E,"<>(à saisir)") | M7: =IFERROR(AVERAGEIFS(Détail!$I:$I,Détail!$A:$A,"Youssef",Détail!$B:$B,$A7,Détail!$C:$C,$B7),"") | N7: =COUNTIFS(Détail!$B:$B,$A7,Détail!$C:$C,$B7,Détail!$E:$E,"<>(à saisir)") | O7: =IFERROR(AVERAGEIFS(Détail!$I:$I,Détail!$B:$B,$A7,Détail!$C:$C,$B7),"")
A8: 2026 | B8: 1 | C8: 29/12/2025 – 04/01/2026 | D8: =COUNTIFS(Détail!$A:$A,"Hafssa BENCHRIF",Détail!$B:$B,$A8,Détail!$C:$C,$B8,Détail!$E:$E,"<>(à saisir)") | E8: =IFERROR(AVERAGEIFS(Détail!$I:$I,Détail!$A:$A,"Hafssa BENCHRIF",Détail!$B:$B,$A8,Détail!$C:$C,$B8),"") | F8: =COUNTIFS(Détail!$A:$A,"Hiba LISSAOUI",Détail!$B:$B,$A8,Détail!$C:$C,$B8,Détail!$E:$E,"<>(à saisir)") | G8: =IFERROR(AVERAGEIFS(Détail!$I:$I,Détail!$A:$A,"Hiba LISSAOUI",Détail!$B:$B,$A8,Détail!$C:$C,$B8),"") | H8: =COUNTIFS(Détail!$A:$A,"Imad RMAIDI",Détail!$B:$B,$A8,Détail!$C:$C,$B8,Détail!$E:$E,"<>(à saisir)") | I8: =IFERROR(AVERAGEIFS(Détail!$I:$I,Détail!$A:$A,"Imad RMAIDI",Détail!$B:$B,$A8,Détail!$C:$C,$B8),"") | J8: =COUNTIFS(Détail!$A:$A,"Mohamed HAMDANI",Détail!$B:$B,$A8,Détail!$C:$C,$B8,Détail!$E:$E,"<>(à saisir)") | K8: =IFERROR(AVERAGEIFS(Détail!$I:$I,Détail!$A:$A,"Mohamed HAMDANI",Détail!$B:$B,$A8,Détail!$C:$C,$B8),"") | L8: =COUNTIFS(Détail!$A:$A,"Youssef",Détail!$B:$B,$A8,Détail!$C:$C,$B8,Détail!$E:$E,"<>(à saisir)") | M8: =IFERROR(AVERAGEIFS(Détail!$I:$I,Détail!$A:$A,"Youssef",Détail!$B:$B,$A8,Détail!$C:$C,$B8),"") | N8: =COUNTIFS(Détail!$B:$B,$A8,Détail!$C:$C,$B8,Détail!$E:$E,"<>(à saisir)") | O8: =IFERROR(AVERAGEIFS(Détail!$I:$I,Détail!$B:$B,$A8,Détail!$C:$C,$B8),"")
A9: 2026 | B9: 2 | C9: 05/01/2026 – 11/01/2026 | D9: =COUNTIFS(Détail!$A:$A,"Hafssa BENCHRIF",Détail!$B:$B,$A9,Détail!$C:$C,$B9,Détail!$E:$E,"<>(à saisir)") | E9: =IFERROR(AVERAGEIFS(Détail!$I:$I,Détail!$A:$A,"Hafssa BENCHRIF",Détail!$B:$B,$A9,Détail!$C:$C,$B9),"") | F9: =COUNTIFS(Détail!$A:$A,"Hiba LISSAOUI",Détail!$B:$B,$A9,Détail!$C:$C,$B9,Détail!$E:$E,"<>(à saisir)") | G9: =IFERROR(AVERAGEIFS(Détail!$I:$I,Détail!$A:$A,"Hiba LISSAOUI",Détail!$B:$B,$A9,Détail!$C:$C,$B9),"") | H9: =COUNTIFS(Détail!$A:$A,"Imad RMAIDI",Détail!$B:$B,$A9,Détail!$C:$C,$B9,Détail!$E:$E,"<>(à saisir)") | I9: =IFERROR(AVERAGEIFS(Détail!$I:$I,Détail!$A:$A,"Imad RMAIDI",Détail!$B:$B,$A9,Détail!$C:$C,$B9),"") | J9: =COUNTIFS(Détail!$A:$A,"Mohamed HAMDANI",Détail!$B:$B,$A9,Détail!$C:$C,$B9,Détail!$E:$E,"<>(à saisir)") | K9: =IFERROR(AVERAGEIFS(Détail!$I:$I,Détail!$A:$A,"Mohamed HAMDANI",Détail!$B:$B,$A9,Détail!$C:$C,$B9),"") | L9: =COUNTIFS(Détail!$A:$A,"Youssef",Détail!$B:$B,$A9,Détail!$C:$C,$B9,Détail!$E:$E,"<>(à saisir)") | M9: =IFERROR(AVERAGEIFS(Détail!$I:$I,Détail!$A:$A,"Youssef",Détail!$B:$B,$A9,Détail!$C:$C,$B9),"") | N9: =COUNTIFS(Détail!$B:$B,$A9,Détail!$C:$C,$B9,Détail!$E:$E,"<>(à saisir)") | O9: =IFERROR(AVERAGEIFS(Détail!$I:$I,Détail!$B:$B,$A9,Détail!$C:$C,$B9),"")
A10: 2026 | B10: 3 | C10: 12/01/2026 – 18/01/2026 | D10: =COUNTIFS(Détail!$A:$A,"Hafssa BENCHRIF",Détail!$B:$B,$A10,Détail!$C:$C,$B10,Détail!$E:$E,"<>(à saisir)") | E10: =IFERROR(AVERAGEIFS(Détail!$I:$I,Détail!$A:$A,"Hafssa BENCHRIF",Détail!$B:$B,$A10,Détail!$C:$C,$B10),"") | F10: =COUNTIFS(Détail!$A:$A,"Hiba LISSAOUI",Détail!$B:$B,$A10,Détail!$C:$C,$B10,Détail!$E:$E,"<>(à saisir)") | G10: =IFERROR(AVERAGEIFS(Détail!$I:$I,Détail!$A:$A,"Hiba LISSAOUI",Détail!$B:$B,$A10,Détail!$C:$C,$B10),"") | H10: =COUNTIFS(Détail!$A:$A,"Imad RMAIDI",Détail!$B:$B,$A10,Détail!$C:$C,$B10,Détail!$E:$E,"<>(à saisir)") | I10: =IFERROR(AVERAGEIFS(Détail!$I:$I,Détail!$A:$A,"Imad RMAIDI",Détail!$B:$B,$A10,Détail!$C:$C,$B10),"") | J10: =COUNTIFS(Détail!$A:$A,"Mohamed HAMDANI",Détail!$B:$B,$A10,Détail!$C:$C,$B10,Détail!$E:$E,"<>(à saisir)") | K10: =IFERROR(AVERAGEIFS(Détail!$I:$I,Détail!$A:$A,"Mohamed HAMDANI",Détail!$B:$B,$A10,Détail!$C:$C,$B10),"") | L10: =COUNTIFS(Détail!$A:$A,"Youssef",Détail!$B:$B,$A10,Détail!$C:$C,$B10,Détail!$E:$E,"<>(à saisir)") | M10: =IFERROR(AVERAGEIFS(Détail!$I:$I,Détail!$A:$A,"Youssef",Détail!$B:$B,$A10,Détail!$C:$C,$B10),"") | N10: =COUNTIFS(Détail!$B:$B,$A10,Détail!$C:$C,$B10,Détail!$E:$E,"<>(à saisir)") | O10: =IFERROR(AVERAGEIFS(Détail!$I:$I,Détail!$B:$B,$A10,Détail!$C:$C,$B10),"")
A11: 2026 | B11: 4 | C11: 19/01/2026 – 25/01/2026 | D11: =COUNTIFS(Détail!$A:$A,"Hafssa BENCHRIF",Détail!$B:$B,$A11,Détail!$C:$C,$B11,Détail!$E:$E,"<>(à saisir)") | E11: =IFERROR(AVERAGEIFS(Détail!$I:$I,Détail!$A:$A,"Hafssa BENCHRIF",Détail!$B:$B,$A11,Détail!$C:$C,$B11),"") | F11: =COUNTIFS(Détail!$A:$A,"Hiba LISSAOUI",Détail!$B:$B,$A11,Détail!$C:$C,$B11,Détail!$E:$E,"<>(à saisir)") | G11: =IFERROR(AVERAGEIFS(Détail!$I:$I,Détail!$A:$A,"Hiba LISSAOUI",Détail!$B:$B,$A11,Détail!$C:$C,$B11),"") | H11: =COUNTIFS(Détail!$A:$A,"Imad RMAIDI",Détail!$B:$B,$A11,Détail!$C:$C,$B11,Détail!$E:$E,"<>(à saisir)") | I11: =IFERROR(AVERAGEIFS(Détail!$I:$I,Détail!$A:$A,"Imad RMAIDI",Détail!$B:$B,$A11,Détail!$C:$C,$B11),"") | J11: =COUNTIFS(Détail!$A:$A,"Mohamed HAMDANI",Détail!$B:$B,$A11,Détail!$C:$C,$B11,Détail!$E:$E,"<>(à saisir)") | K11: =IFERROR(AVERAGEIFS(Détail!$I:$I,Détail!$A:$A,"Mohamed HAMDANI",Détail!$B:$B,$A11,Détail!$C:$C,$B11),"") | L11: =COUNTIFS(Détail!$A:$A,"Youssef",Détail!$B:$B,$A11,Détail!$C:$C,$B11,Détail!$E:$E,"<>(à saisir)") | M11: =IFERROR(AVERAGEIFS(Détail!$I:$I,Détail!$A:$A,"Youssef",Détail!$B:$B,$A11,Détail!$C:$C,$B11),"") | N11: =COUNTIFS(Détail!$B:$B,$A11,Détail!$C:$C,$B11,Détail!$E:$E,"<>(à saisir)") | O11: =IFERROR(AVERAGEIFS(Détail!$I:$I,Détail!$B:$B,$A11,Détail!$C:$C,$B11),"")
A12: 2026 | B12: 5 | C12: 26/01/2026 – 01/02/2026 | D12: =COUNTIFS(Détail!$A:$A,"Hafssa BENCHRIF",Détail!$B:$B,$A12,Détail!$C:$C,$B12,Détail!$E:$E,"<>(à saisir)") | E12: =IFERROR(AVERAGEIFS(Détail!$I:$I,Détail!$A:$A,"Hafssa BENCHRIF",Détail!$B:$B,$A12,Détail!$C:$C,$B12),"") | F12: =COUNTIFS(Détail!$A:$A,"Hiba LISSAOUI",Détail!$B:$B,$A12,Détail!$C:$C,$B12,Détail!$E:$E,"<>(à saisir)") | G12: =IFERROR(AVERAGEIFS(Détail!$I:$I,Détail!$A:$A,"Hiba LISSAOUI",Détail!$B:$B,$A12,Détail!$C:$C,$B12),"") | H12: =COUNTIFS(Détail!$A:$A,"Imad RMAIDI",Détail!$B:$B,$A12,Détail!$C:$C,$B12,Détail!$E:$E,"<>(à saisir)") | I12: =IFERROR(AVERAGEIFS(Détail!$I:$I,Détail!$A:$A,"Imad RMAIDI",Détail!$B:$B,$A12,Détail!$C:$C,$B12),"") | J12: =COUNTIFS(Détail!$A:$A,"Mohamed HAMDANI",Détail!$B:$B,$A12,Détail!$C:$C,$B12,Détail!$E:$E,"<>(à saisir)") | K12: =IFERROR(AVERAGEIFS(Détail!$I:$I,Détail!$A:$A,"Mohamed HAMDANI",Détail!$B:$B,$A12,Détail!$C:$C,$B12),"") | L12: =COUNTIFS(Détail!$A:$A,"Youssef",Détail!$B:$B,$A12,Détail!$C:$C,$B12,Détail!$E:$E,"<>(à saisir)") | M12: =IFERROR(AVERAGEIFS(Détail!$I:$I,Détail!$A:$A,"Youssef",Détail!$B:$B,$A12,Détail!$C:$C,$B12),"") | N12: =COUNTIFS(Détail!$B:$B,$A12,Détail!$C:$C,$B12,Détail!$E:$E,"<>(à saisir)") | O12: =IFERROR(AVERAGEIFS(Détail!$I:$I,Détail!$B:$B,$A12,Détail!$C:$C,$B12),"")
A13: 2026 | B13: 6 | C13: 02/02/2026 – 08/02/2026 | D13: =COUNTIFS(Détail!$A:$A,"Hafssa BENCHRIF",Détail!$B:$B,$A13,Détail!$C:$C,$B13,Détail!$E:$E,"<>(à saisir)") | E13: =IFERROR(AVERAGEIFS(Détail!$I:$I,Détail!$A:$A,"Hafssa BENCHRIF",Détail!$B:$B,$A13,Détail!$C:$C,$B13),"") | F13: =COUNTIFS(Détail!$A:$A,"Hiba LISSAOUI",Détail!$B:$B,$A13,Détail!$C:$C,$B13,Détail!$E:$E,"<>(à saisir)") | G13: =IFERROR(AVERAGEIFS(Détail!$I:$I,Détail!$A:$A,"Hiba LISSAOUI",Détail!$B:$B,$A13,Détail!$C:$C,$B13),"") | H13: =COUNTIFS(Détail!$A:$A,"Imad RMAIDI",Détail!$B:$B,$A13,Détail!$C:$C,$B13,Détail!$E:$E,"<>(à saisir)") | I13: =IFERROR(AVERAGEIFS(Détail!$I:$I,Détail!$A:$A,"Imad RMAIDI",Détail!$B:$B,$A13,Détail!$C:$C,$B13),"") | J13: =COUNTIFS(Détail!$A:$A,"Mohamed HAMDANI",Détail!$B:$B,$A13,Détail!$C:$C,$B13,Détail!$E:$E,"<>(à saisir)") | K13: =IFERROR(AVERAGEIFS(Détail!$I:$I,Détail!$A:$A,"Mohamed HAMDANI",Détail!$B:$B,$A13,Détail!$C:$C,$B13),"") | L13: =COUNTIFS(Détail!$A:$A,"Youssef",Détail!$B:$B,$A13,Détail!$C:$C,$B13,Détail!$E:$E,"<>(à saisir)") | M13: =IFERROR(AVERAGEIFS(Détail!$I:$I,Détail!$A:$A,"Youssef",Détail!$B:$B,$A13,Détail!$C:$C,$B13),"") | N13: =COUNTIFS(Détail!$B:$B,$A13,Détail!$C:$C,$B13,Détail!$E:$E,"<>(à saisir)") | O13: =IFERROR(AVERAGEIFS(Détail!$I:$I,Détail!$B:$B,$A13,Détail!$C:$C,$B13),"")
A14: 2026 | B14: 7 | C14: 09/02/2026 – 15/02/2026 | D14: =COUNTIFS(Détail!$A:$A,"Hafssa BENCHRIF",Détail!$B:$B,$A14,Détail!$C:$C,$B14,Détail!$E:$E,"<>(à saisir)") | E14: =IFERROR(AVERAGEIFS(Détail!$I:$I,Détail!$A:$A,"Hafssa BENCHRIF",Détail!$B:$B,$A14,Détail!$C:$C,$B14),"") | F14: =COUNTIFS(Détail!$A:$A,"Hiba LISSAOUI",Détail!$B:$B,$A14,Détail!$C:$C,$B14,Détail!$E:$E,"<>(à saisir)") | G14: =IFERROR(AVERAGEIFS(Détail!$I:$I,Détail!$A:$A,"Hiba LISSAOUI",Détail!$B:$B,$A14,Détail!$C:$C,$B14),"") | H14: =COUNTIFS(Détail!$A:$A,"Imad RMAIDI",Détail!$B:$B,$A14,Détail!$C:$C,$B14,Détail!$E:$E,"<>(à saisir)") | I14: =IFERROR(AVERAGEIFS(Détail!$I:$I,Détail!$A:$A,"Imad RMAIDI",Détail!$B:$B,$A14,Détail!$C:$C,$B14),"") | J14: =COUNTIFS(Détail!$A:$A,"Mohamed HAMDANI",Détail!$B:$B,$A14,Détail!$C:$C,$B14,Détail!$E:$E,"<>(à saisir)") | K14: =IFERROR(AVERAGEIFS(Détail!$I:$I,Détail!$A:$A,"Mohamed HAMDANI",Détail!$B:$B,$A14,Détail!$C:$C,$B14),"") | L14: =COUNTIFS(Détail!$A:$A,"Youssef",Détail!$B:$B,$A14,Détail!$C:$C,$B14,Détail!$E:$E,"<>(à saisir)") | M14: =IFERROR(AVERAGEIFS(Détail!$I:$I,Détail!$A:$A,"Youssef",Détail!$B:$B,$A14,Détail!$C:$C,$B14),"") | N14: =COUNTIFS(Détail!$B:$B,$A14,Détail!$C:$C,$B14,Détail!$E:$E,"<>(à saisir)") | O14: =IFERROR(AVERAGEIFS(Détail!$I:$I,Détail!$B:$B,$A14,Détail!$C:$C,$B14),"")
A15: 2026 | B15: 8 | C15: 16/02/2026 – 22/02/2026 | D15: =COUNTIFS(Détail!$A:$A,"Hafssa BENCHRIF",Détail!$B:$B,$A15,Détail!$C:$C,$B15,Détail!$E:$E,"<>(à saisir)") | E15: =IFERROR(AVERAGEIFS(Détail!$I:$I,Détail!$A:$A,"Hafssa BENCHRIF",Détail!$B:$B,$A15,Détail!$C:$C,$B15),"") | F15: =COUNTIFS(Détail!$A:$A,"Hiba LISSAOUI",Détail!$B:$B,$A15,Détail!$C:$C,$B15,Détail!$E:$E,"<>(à saisir)") | G15: =IFERROR(AVERAGEIFS(Détail!$I:$I,Détail!$A:$A,"Hiba LISSAOUI",Détail!$B:$B,$A15,Détail!$C:$C,$B15),"") | H15: =COUNTIFS(Détail!$A:$A,"Imad RMAIDI",Détail!$B:$B,$A15,Détail!$C:$C,$B15,Détail!$E:$E,"<>(à saisir)") | I15: =IFERROR(AVERAGEIFS(Détail!$I:$I,Détail!$A:$A,"Imad RMAIDI",Détail!$B:$B,$A15,Détail!$C:$C,$B15),"") | J15: =COUNTIFS(Détail!$A:$A,"Mohamed HAMDANI",Détail!$B:$B,$A15,Détail!$C:$C,$B15,Détail!$E:$E,"<>(à saisir)") | K15: =IFERROR(AVERAGEIFS(Détail!$I:$I,Détail!$A:$A,"Mohamed HAMDANI",Détail!$B:$B,$A15,Détail!$C:$C,$B15),"") | L15: =COUNTIFS(Détail!$A:$A,"Youssef",Détail!$B:$B,$A15,Détail!$C:$C,$B15,Détail!$E:$E,"<>(à saisir)") | M15: =IFERROR(AVERAGEIFS(Détail!$I:$I,Détail!$A:$A,"Youssef",Détail!$B:$B,$A15,Détail!$C:$C,$B15),"") | N15: =COUNTIFS(Détail!$B:$B,$A15,Détail!$C:$C,$B15,Détail!$E:$E,"<>(à saisir)") | O15: =IFERROR(AVERAGEIFS(Détail!$I:$I,Détail!$B:$B,$A15,Détail!$C:$C,$B15),"")
A16: 2026 | B16: 9 | C16: 23/02/2026 – 01/03/2026 | D16: =COUNTIFS(Détail!$A:$A,"Hafssa BENCHRIF",Détail!$B:$B,$A16,Détail!$C:$C,$B16,Détail!$E:$E,"<>(à saisir)") | E16: =IFERROR(AVERAGEIFS(Détail!$I:$I,Détail!$A:$A,"Hafssa BENCHRIF",Détail!$B:$B,$A16,Détail!$C:$C,$B16),"") | F16: =COUNTIFS(Détail!$A:$A,"Hiba LISSAOUI",Détail!$B:$B,$A16,Détail!$C:$C,$B16,Détail!$E:$E,"<>(à saisir)") | G16: =IFERROR(AVERAGEIFS(Détail!$I:$I,Détail!$A:$A,"Hiba LISSAOUI",Détail!$B:$B,$A16,Détail!$C:$C,$B16),"") | H16: =COUNTIFS(Détail!$A:$A,"Imad RMAIDI",Détail!$B:$B,$A16,Détail!$C:$C,$B16,Détail!$E:$E,"<>(à saisir)") | I16: =IFERROR(AVERAGEIFS(Détail!$I:$I,Détail!$A:$A,"Imad RMAIDI",Détail!$B:$B,$A16,Détail!$C:$C,$B16),"") | J16: =COUNTIFS(Détail!$A:$A,"Mohamed HAMDANI",Détail!$B:$B,$A16,Détail!$C:$C,$B16,Détail!$E:$E,"<>(à saisir)") | K16: =IFERROR(AVERAGEIFS(Détail!$I:$I,Détail!$A:$A,"Mohamed HAMDANI",Détail!$B:$B,$A16,Détail!$C:$C,$B16),"") | L16: =COUNTIFS(Détail!$A:$A,"Youssef",Détail!$B:$B,$A16,Détail!$C:$C,$B16,Détail!$E:$E,"<>(à saisir)") | M16: =IFERROR(AVERAGEIFS(Détail!$I:$I,Détail!$A:$A,"Youssef",Détail!$B:$B,$A16,Détail!$C:$C,$B16),"") | N16: =COUNTIFS(Détail!$B:$B,$A16,Détail!$C:$C,$B16,Détail!$E:$E,"<>(à saisir)") | O16: =IFERROR(AVERAGEIFS(Détail!$I:$I,Détail!$B:$B,$A16,Détail!$C:$C,$B16),"")
A17: 2026 | B17: 10 | C17: 02/03/2026 – 08/03/2026 | D17: =COUNTIFS(Détail!$A:$A,"Hafssa BENCHRIF",Détail!$B:$B,$A17,Détail!$C:$C,$B17,Détail!$E:$E,"<>(à saisir)") | E17: =IFERROR(AVERAGEIFS(Détail!$I:$I,Détail!$A:$A,"Hafssa BENCHRIF",Détail!$B:$B,$A17,Détail!$C:$C,$B17),"") | F17: =COUNTIFS(Détail!$A:$A,"Hiba LISSAOUI",Détail!$B:$B,$A17,Détail!$C:$C,$B17,Détail!$E:$E,"<>(à saisir)") | G17: =IFERROR(AVERAGEIFS(Détail!$I:$I,Détail!$A:$A,"Hiba LISSAOUI",Détail!$B:$B,$A17,Détail!$C:$C,$B17),"") | H17: =COUNTIFS(Détail!$A:$A,"Imad RMAIDI",Détail!$B:$B,$A17,Détail!$C:$C,$B17,Détail!$E:$E,"<>(à saisir)") | I17: =IFERROR(AVERAGEIFS(Détail!$I:$I,Détail!$A:$A,"Imad RMAIDI",Détail!$B:$B,$A17,Détail!$C:$C,$B17),"") | J17: =COUNTIFS(Détail!$A:$A,"Mohamed HAMDANI",Détail!$B:$B,$A17,Détail!$C:$C,$B17,Détail!$E:$E,"<>(à saisir)") | K17: =IFERROR(AVERAGEIFS(Détail!$I:$I,Détail!$A:$A,"Mohamed HAMDANI",Détail!$B:$B,$A17,Détail!$C:$C,$B17),"") | L17: =COUNTIFS(Détail!$A:$A,"Youssef",Détail!$B:$B,$A17,Détail!$C:$C,$B17,Détail!$E:$E,"<>(à saisir)") | M17: =IFERROR(AVERAGEIFS(Détail!$I:$I,Détail!$A:$A,"Youssef",Détail!$B:$B,$A17,Détail!$C:$C,$B17),"") | N17: =COUNTIFS(Détail!$B:$B,$A17,Détail!$C:$C,$B17,Détail!$E:$E,"<>(à saisir)") | O17: =IFERROR(AVERAGEIFS(Détail!$I:$I,Détail!$B:$B,$A17,Détail!$C:$C,$B17),"")
... A51: 2026 | B51: 44 | C51: 26/10/2026 – 01/11/2026 | D51: =COUNTIFS(Détail!$A:$A,"Hafssa BENCHRIF",Détail!$B:$B,$A51,Détail!$C:$C,$B51,Détail!$E:$E,"<>(à saisir)") | E51: =IFERROR(AVERAGEIFS(Détail!$I:$I,Détail!$A:$A,"Hafssa BENCHRIF",Détail!$B:$B,$A51,Détail!$C:$C,$B51),"") | F51: =COUNTIFS(Détail!$A:$A,"Hiba LISSAOUI",Détail!$B:$B,$A51,Détail!$C:$C,$B51,Détail!$E:$E,"<>(à saisir)") | G51: =IFERROR(AVERAGEIFS(Détail!$I:$I,Détail!$A:$A,"Hiba LISSAOUI",Détail!$B:$B,$A51,Détail!$C:$C,$B51),"") | H51: =COUNTIFS(Détail!$A:$A,"Imad RMAIDI",Détail!$B:$B,$A51,Détail!$C:$C,$B51,Détail!$E:$E,"<>(à saisir)") | I51: =IFERROR(AVERAGEIFS(Détail!$I:$I,Détail!$A:$A,"Imad RMAIDI",Détail!$B:$B,$A51,Détail!$C:$C,$B51),"") | J51: =COUNTIFS(Détail!$A:$A,"Mohamed HAMDANI",Détail!$B:$B,$A51,Détail!$C:$C,$B51,Détail!$E:$E,"<>(à saisir)") | K51: =IFERROR(AVERAGEIFS(Détail!$I:$I,Détail!$A:$A,"Mohamed HAMDANI",Détail!$B:$B,$A51,Détail!$C:$C,$B51),"") | L51: =COUNTIFS(Détail!$A:$A,"Youssef",Détail!$B:$B,$A51,Détail!$C:$C,$B51,Détail!$E:$E,"<>(à saisir)") | M51: =IFERROR(AVERAGEIFS(Détail!$I:$I,Détail!$A:$A,"Youssef",Détail!$B:$B,$A51,Détail!$C:$C,$B51),"") | N51: =COUNTIFS(Détail!$B:$B,$A51,Détail!$C:$C,$B51,Détail!$E:$E,"<>(à saisir)") | O51: =IFERROR(AVERAGEIFS(Détail!$I:$I,Détail!$B:$B,$A51,Détail!$C:$C,$B51),"")
A52: Total / moyenne | D52: =SUM(D6:D51) | E52: =IFERROR(AVERAGEIFS(Détail!$I:$I,Détail!$A:$A,"Hafssa BENCHRIF"),"") | F52: =SUM(F6:F51) | G52: =IFERROR(AVERAGEIFS(Détail!$I:$I,Détail!$A:$A,"Hiba LISSAOUI"),"") | H52: =SUM(H6:H51) | I52: =IFERROR(AVERAGEIFS(Détail!$I:$I,Détail!$A:$A,"Imad RMAIDI"),"") | J52: =SUM(J6:J51) | K52: =IFERROR(AVERAGEIFS(Détail!$I:$I,Détail!$A:$A,"Mohamed HAMDANI"),"") | L52: =SUM(L6:L51) | M52: =IFERROR(AVERAGEIFS(Détail!$I:$I,Détail!$A:$A,"Youssef"),"") | N52: =SUM(N6:N51) | O52: =IFERROR(AVERAGE(Détail!$I:$I),"")

Sheet Par collaborateur
A1: Bilan par collaborateur
A3: Collaborateur | B3: Documents traités | C3: Documents évalués | D3: Semaines actives | E3: Note moyenne /100 | F3: Note min. | G3: Documents à 100 % | H3: Documents < 100 % | I3: Documents < 85 % | J3: Rapports manquants | K3: Critères non conformes | L3: Notes à saisir (jaune)
A4: Hafssa BENCHRIF | B4: =COUNTIFS(Détail!$A:$A,"Hafssa BENCHRIF",Détail!$E:$E,"<>(à saisir)") | C4: =COUNTIFS(Détail!$A:$A,"Hafssa BENCHRIF",Détail!$I:$I,">=0") | D4: =SUMPRODUCT((Détail!$A$2:$A$142="Hafssa BENCHRIF")*(Détail!$E$2:$E$142<>"(à saisir)")/COUNTIFS(Détail!$A$2:$A$142,Détail!$A$2:$A$142,Détail!$D$2:$D$142,Détail!$D$2:$D$142)) | E4: =IFERROR(AVERAGEIFS(Détail!$I:$I,Détail!$A:$A,"Hafssa BENCHRIF"),"") | F4: =_xlfn.MINIFS(Détail!$I$2:$I$142,Détail!$A$2:$A$142,"Hafssa BENCHRIF") | G4: =COUNTIFS(Détail!$A:$A,"Hafssa BENCHRIF",Détail!$I:$I,">=99.95") | H4: =COUNTIFS(Détail!$A:$A,"Hafssa BENCHRIF",Détail!$I:$I,"<99.95") | I4: =COUNTIFS(Détail!$A:$A,"Hafssa BENCHRIF",Détail!$I:$I,"<85") | J4: =B4-C4 | K4: =SUMIFS(Détail!$L:$L,Détail!$A:$A,"Hafssa BENCHRIF") | L4: =COUNTIFS(Détail!$A:$A,"Hafssa BENCHRIF",Détail!$J:$J,"À saisir")
A5: Hiba LISSAOUI | B5: =COUNTIFS(Détail!$A:$A,"Hiba LISSAOUI",Détail!$E:$E,"<>(à saisir)") | C5: =COUNTIFS(Détail!$A:$A,"Hiba LISSAOUI",Détail!$I:$I,">=0") | D5: =SUMPRODUCT((Détail!$A$2:$A$142="Hiba LISSAOUI")*(Détail!$E$2:$E$142<>"(à saisir)")/COUNTIFS(Détail!$A$2:$A$142,Détail!$A$2:$A$142,Détail!$D$2:$D$142,Détail!$D$2:$D$142)) | E5: =IFERROR(AVERAGEIFS(Détail!$I:$I,Détail!$A:$A,"Hiba LISSAOUI"),"") | F5: =_xlfn.MINIFS(Détail!$I$2:$I$142,Détail!$A$2:$A$142,"Hiba LISSAOUI") | G5: =COUNTIFS(Détail!$A:$A,"Hiba LISSAOUI",Détail!$I:$I,">=99.95") | H5: =COUNTIFS(Détail!$A:$A,"Hiba LISSAOUI",Détail!$I:$I,"<99.95") | I5: =COUNTIFS(Détail!$A:$A,"Hiba LISSAOUI",Détail!$I:$I,"<85") | J5: =B5-C5 | K5: =SUMIFS(Détail!$L:$L,Détail!$A:$A,"Hiba LISSAOUI") | L5: =COUNTIFS(Détail!$A:$A,"Hiba LISSAOUI",Détail!$J:$J,"À saisir")
A6: Imad RMAIDI | B6: =COUNTIFS(Détail!$A:$A,"Imad RMAIDI",Détail!$E:$E,"<>(à saisir)") | C6: =COUNTIFS(Détail!$A:$A,"Imad RMAIDI",Détail!$I:$I,">=0") | D6: =SUMPRODUCT((Détail!$A$2:$A$142="Imad RMAIDI")*(Détail!$E$2:$E$142<>"(à saisir)")/COUNTIFS(Détail!$A$2:$A$142,Détail!$A$2:$A$142,Détail!$D$2:$D$142,Détail!$D$2:$D$142)) | E6: =IFERROR(AVERAGEIFS(Détail!$I:$I,Détail!$A:$A,"Imad RMAIDI"),"") | F6: =_xlfn.MINIFS(Détail!$I$2:$I$142,Détail!$A$2:$A$142,"Imad RMAIDI") | G6: =COUNTIFS(Détail!$A:$A,"Imad RMAIDI",Détail!$I:$I,">=99.95") | H6: =COUNTIFS(Détail!$A:$A,"Imad RMAIDI",Détail!$I:$I,"<99.95") | I6: =COUNTIFS(Détail!$A:$A,"Imad RMAIDI",Détail!$I:$I,"<85") | J6: =B6-C6 | K6: =SUMIFS(Détail!$L:$L,Détail!$A:$A,"Imad RMAIDI") | L6: =COUNTIFS(Détail!$A:$A,"Imad RMAIDI",Détail!$J:$J,"À saisir")
A7: Mohamed HAMDANI | B7: =COUNTIFS(Détail!$A:$A,"Mohamed HAMDANI",Détail!$E:$E,"<>(à saisir)") | C7: =COUNTIFS(Détail!$A:$A,"Mohamed HAMDANI",Détail!$I:$I,">=0") | D7: =SUMPRODUCT((Détail!$A$2:$A$142="Mohamed HAMDANI")*(Détail!$E$2:$E$142<>"(à saisir)")/COUNTIFS(Détail!$A$2:$A$142,Détail!$A$2:$A$142,Détail!$D$2:$D$142,Détail!$D$2:$D$142)) | E7: =IFERROR(AVERAGEIFS(Détail!$I:$I,Détail!$A:$A,"Mohamed HAMDANI"),"") | F7: =_xlfn.MINIFS(Détail!$I$2:$I$142,Détail!$A$2:$A$142,"Mohamed HAMDANI") | G7: =COUNTIFS(Détail!$A:$A,"Mohamed HAMDANI",Détail!$I:$I,">=99.95") | H7: =COUNTIFS(Détail!$A:$A,"Mohamed HAMDANI",Détail!$I:$I,"<99.95") | I7: =COUNTIFS(Détail!$A:$A,"Mohamed HAMDANI",Détail!$I:$I,"<85") | J7: =B7-C7 | K7: =SUMIFS(Détail!$L:$L,Détail!$A:$A,"Mohamed HAMDANI") | L7: =COUNTIFS(Détail!$A:$A,"Mohamed HAMDANI",Détail!$J:$J,"À saisir")
A8: Youssef | B8: =COUNTIFS(Détail!$A:$A,"Youssef",Détail!$E:$E,"<>(à saisir)") | C8: =COUNTIFS(Détail!$A:$A,"Youssef",Détail!$I:$I,">=0") | D8: =SUMPRODUCT((Détail!$A$2:$A$142="Youssef")*(Détail!$E$2:$E$142<>"(à saisir)")/COUNTIFS(Détail!$A$2:$A$142,Détail!$A$2:$A$142,Détail!$D$2:$D$142,Détail!$D$2:$D$142)) | E8: =IFERROR(AVERAGEIFS(Détail!$I:$I,Détail!$A:$A,"Youssef"),"") | F8: =_xlfn.MINIFS(Détail!$I$2:$I$142,Détail!$A$2:$A$142,"Youssef") | G8: =COUNTIFS(Détail!$A:$A,"Youssef",Détail!$I:$I,">=99.95") | H8: =COUNTIFS(Détail!$A:$A,"Youssef",Détail!$I:$I,"<99.95") | I8: =COUNTIFS(Détail!$A:$A,"Youssef",Détail!$I:$I,"<85") | J8: =B8-C8 | K8: =SUMIFS(Détail!$L:$L,Détail!$A:$A,"Youssef") | L8: =COUNTIFS(Détail!$A:$A,"Youssef",Détail!$J:$J,"À saisir")
A9: Équipe | B9: =SUM(B4:B8) | C9: =SUM(C4:C8) | D9: =SUM(D4:D8) | E9: =IFERROR(AVERAGE(Détail!$I:$I),"") | F9: =MIN(F4:F8) | G9: =SUM(G4:G8) | H9: =SUM(H4:H8) | I9: =SUM(I4:I8) | J9: =SUM(J4:J8) | K9: =SUM(K4:K8) | L9: =SUM(L4:L8)
A11: Seuil de conformité retenu : 85 % (identique aux rapports RAPDF). « Semaines actives » = semaines avec au moins un document.

Sheet Détail
A1: Collaborateur | B1: Année | C1: Semaine | D1: Clé semaine | E1: Document | F1: Type | G1: Date d'évaluation | H1: Source | I1: Note /100 | J1: Statut | K1: Critères conformes | L1: Critères non conformes | M1: Critères non applicables | N1: Détail des critères non conformes | O1: Action corrective | P1: Jours planifiés | Q1: Présents | R1: Absents | S1: Non renseignés | T1: Congés | U1: Jours fériés | V1: Nb retards | W1: Retards (min) | X1: Heures planifiées | Y1: Heures adhérées | Z1: Taux d’assiduité | AA1: Adhérence heures
A2: Hafssa BENCHRIF | B2: 2025 | C2: 51 | D2: =B2&"-S"&TEXT(C2,"00") | E2: CG0570v02 0525 | F2: word | H2: Grille | I2: 100 | J2: =IF(I2="","Rapport manquant",IF(I2>=85,"CONFORME (≥85%)","NON CONFORME (<85%)")) | K2: 10 | L2: 0 | M2: 36 | P2: 0 | Q2: 0 | R2: 0 | S2: 0 | T2: 0 | U2: 0 | V2: 0 | W2: 0 | X2: 0 | Y2: 0
A3: Hafssa BENCHRIF | B3: 2025 | C3: 51 | D3: =B3&"-S"&TEXT(C3,"00") | E3: CM0409v04 1214 LIVRET PUNCH | F3: word | H3: Grille | I3: 100 | J3: =IF(I3="","Rapport manquant",IF(I3>=85,"CONFORME (≥85%)","NON CONFORME (<85%)")) | K3: 8 | L3: 0 | M3: 38 | P3: 0 | Q3: 0 | R3: 0 | S3: 0 | T3: 0 | U3: 0 | V3: 0 | W3: 0 | X3: 0 | Y3: 0
A4: Hiba LISSAOUI | B4: 2025 | C4: 51 | D4: =B4&"-S"&TEXT(C4,"00") | E4: CG.05.78v02 1024 CG BAD EI CM CIC | F4: word | H4: Grille | I4: 96.7 | J4: =IF(I4="","À saisir",IF(I4>=85,"CONFORME (≥85%)","NON CONFORME (<85%)")) | K4: 9 | L4: 1 | M4: 36 | N4: 5.2 – Chaque contenu présenté sous forme de liste utilise-t-il un style de liste ? | O4: Debrief de l’agent pour le sensibiliser à l’importance d’être vigilant sur le traitement, puis exercice pratique avec l’ensemble de l’équipe. | P4: 0 | Q4: 0 | R4: 0 | S4: 0 | T4: 0 | U4: 0 | V4: 0 | W4: 0 | X4: 0 | Y4: 0
A5: Hiba LISSAOUI | B5: 2025 | C5: 51 | D5: =B5&"-S"&TEXT(C5,"00") | E5: CG0566 0725 CM | F5: word | H5: Grille | I5: 100 | J5: =IF(I5="","À saisir",IF(I5>=85,"CONFORME (≥85%)","NON CONFORME (<85%)")) | K5: 10 | L5: 0 | M5: 36 | P5: 0 | Q5: 0 | R5: 0 | S5: 0 | T5: 0 | U5: 0 | V5: 0 | W5: 0 | X5: 0 | Y5: 0
A6: Imad RMAIDI | B6: 2025 | C6: 51 | D6: =B6&"-S"&TEXT(C6,"00") | E6: CG0443v02 1214 LIVRET BIENVENUE + | F6: word | H6: Grille | I6: 100 | J6: =IF(I6="","À saisir",IF(I6>=85,"CONFORME (≥85%)","NON CONFORME (<85%)")) | K6: 9 | L6: 0 | M6: 37 | P6: 0 | Q6: 0 | R6: 0 | S6: 0 | T6: 0 | U6: 0 | V6: 0 | W6: 0 | X6: 0 | Y6: 0
A7: Imad RMAIDI | B7: 2025 | C7: 51 | D7: =B7&"-S"&TEXT(C7,"00") | E7: CM0310v03 1122 livret bleu Prem's | F7: word | H7: Grille | I7: 100 | J7: =IF(I7="","À saisir",IF(I7>=85,"CONFORME (≥85%)","NON CONFORME (<85%)")) | K7: 12 | L7: 0 | M7: 34 | P7: 0 | Q7: 0 | R7: 0 | S7: 0 | T7: 0 | U7: 0 | V7: 0 | W7: 0 | X7: 0 | Y7: 0
A8: Mohamed HAMDANI | B8: 2025 | C8: 51 | D8: =B8&"-S"&TEXT(C8,"00") | E8: CI0396v03 1018 CG carte de retrait DE | F8: word | H8: Grille | I8: 100 | J8: =IF(I8="","À saisir",IF(I8>=85,"CONFORME (≥85%)","NON CONFORME (<85%)")) | K8: 11 | L8: 0 | M8: 35 | P8: 0 | Q8: 0 | R8: 0 | S8: 0 | T8: 0 | U8: 0 | V8: 0 | W8: 0 | X8: 0 | Y8: 0
A9: Mohamed HAMDANI | B9: 2025 | C9: 51 | D9: =B9&"-S"&TEXT(C9,"00") | E9: CM0575v01 0324 Carte achat public | F9: word | H9: Grille | I9: 93.3 | J9: =IF(I9="","À saisir",IF(I9>=85,"CONFORME (≥85%)","NON CONFORME (<85%)")) | K9: 12 | L9: 2 | M9: 32 | N9: 5.1 – L’information est-elle structurée par l’utilisation appropriée de titres ? 5.2 – Chaque contenu présenté sous forme de liste utilise-t-il un style de liste ? | O9: Debrief de l’agent pour le sensibiliser à l’importance d’être vigilant sur le traitement, puis exercice pratique avec l’ensemble de l’équipe. | P9: 0 | Q9: 0 | R9: 0 | S9: 0 | T9: 0 | U9: 0 | V9: 0 | W9: 0 | X9: 0 | Y9: 0
A10: Hafssa BENCHRIF | B10: 2025 | C10: 52 | D10: =B10&"-S"&TEXT(C10,"00") | E10: CG0563v01 0123 CG Services de Dépôt | F10: word | H10: Grille | I10: 100 | J10: =IF(I10="","Rapport manquant",IF(I10>=85,"CONFORME (≥85%)","NON CONFORME (<85%)")) | K10: 9 | L10: 0 | M10: 37 | P10: 4 | Q10: 4 | R10: 0 | S10: 0 | T10: 0 | U10: 0 | V10: 0 | W10: 0 | X10: 1.4583333 | Y10: 1.4583333 | Z10: 1 | AA10: 1
A11: Hafssa BENCHRIF | B11: 2025 | C11: 52 | D11: =B11&"-S"&TEXT(C11,"00") | E11: CG0706 1219 | F11: word | H11: Grille | I11: 100 | J11: =IF(I11="","Rapport manquant",IF(I11>=85,"CONFORME (≥85%)","NON CONFORME (<85%)")) | K11: 13 | L11: 0 | M11: 33 | P11: 4 | Q11: 4 | R11: 0 | S11: 0 | T11: 0 | U11: 0 | V11: 0 | W11: 0 | X11: 1.4583333 | Y11: 1.4583333 | Z11: 1 | AA11: 1
A12: Hiba LISSAOUI | B12: 2025 | C12: 52 | D12: =B12&"-S"&TEXT(C12,"00") | E12: CG0704 1120 | F12: word | H12: Grille | I12: 96.7 | J12: =IF(I12="","À saisir",IF(I12>=85,"CONFORME (≥85%)","NON CONFORME (<85%)")) | K12: 14 | L12: 1 | M12: 31 | N12: 6.3 – Chaque lien signalé uniquement par la couleur et dont la nature n’est pas évidente est-il visible, par rapport au texte environnant ? | O12: Debrief de l’agent pour le sensibiliser à l’importance d’être vigilant sur le traitement, puis exercice pratique avec l’ensemble de l’équipe. | P12: 4 | Q12: 4 | R12: 0 | S12: 0 | T12: 0 | U12: 0 | V12: 0 | W12: 0 | X12: 1.4583333 | Y12: 1.4583333 | Z12: 1 | AA12: 1
A13: Hiba LISSAOUI | B13: 2025 | C13: 52 | D13: =B13&"-S"&TEXT(C13,"00") | E13: GR8884v11 0122 caut PP EPS | F13: word | H13: Grille | I13: 100 | J13: =IF(I13="","À saisir",IF(I13>=85,"CONFORME (≥85%)","NON CONFORME (<85%)")) | K13: 14 | L13: 0 | M13: 32 | P13: 4 | Q13: 4 | R13: 0 | S13: 0 | T13: 0 | U13: 0 | V13: 0 | W13: 0 | X13: 1.4583333 | Y13: 1.4583333 | Z13: 1 | AA13: 1
A14: Imad RMAIDI | B14: 2025 | C14: 52 | D14: =B14&"-S"&TEXT(C14,"00") | E14: CG0403v02 0314 CG Livret bienvenue DE | F14: word | H14: Grille | I14: 100 | J14: =IF(I14="","À saisir",IF(I14>=85,"CONFORME (≥85%)","NON CONFORME (<85%)")) | K14: 10 | L14: 0 | M14: 36 | P14: 4 | Q14: 4 | R14: 0 | S14: 0 | T14: 0 | U14: 0 | V14: 0 | W14: 0 | X14: 1.4583333 | Y14: 1.4583333 | Z14: 1 | AA14: 1
A15: Imad RMAIDI | B15: 2025 | C15: 52 | D15: =B15&"-S"&TEXT(C15,"00") | E15: CG0523v01 0616 Livret Crescendo UK | F15: word | H15: Grille | I15: 100 | J15: =IF(I15="","À saisir",IF(I15>=85,"CONFORME (≥85%)","NON CONFORME (<85%)")) | K15: 10 | L15: 0 | M15: 36 | P15: 4 | Q15: 4 | R15: 0 | S15: 0 | T15: 0 | U15: 0 | V15: 0 | W15: 0 | X15: 1.4583333 | Y15: 1.4583333 | Z15: 1 | AA15: 1
A16: Mohamed HAMDANI | B16: 2025 | C16: 52 | D16: =B16&"-S"&TEXT(C16,"00") | E16: CG0309v01 0710 carte authen bancaire FR | F16: word | H16: Grille | I16: 100 | J16: =IF(I16="","À saisir",IF(I16>=85,"CONFORME (≥85%)","NON CONFORME (<85%)")) | K16: 9 | L16: 0 | M16: 37 | P16: 4 | Q16: 4 | R16: 0 | S16: 0 | T16: 0 | U16: 0 | V16: 0 | W16: 0 | X16: 1.4583333 | Y16: 1.4583333 | Z16: 1 | AA16: 1
A17: Mohamed HAMDANI | B17: 2025 | C17: 52 | D17: =B17&"-S"&TEXT(C17,"00") | E17: CG0309v01 0710 carte authen bancaire UK | F17: word | H17: Grille | I17: 100 | J17: =IF(I17="","À saisir",IF(I17>=85,"CONFORME (≥85%)","NON CONFORME (<85%)")) | K17: 9 | L17: 0 | M17: 37 | P17: 4 | Q17: 4 | R17: 0 | S17: 0 | T17: 0 | U17: 0 | V17: 0 | W17: 0 | X17: 1.4583333 | Y17: 1.4583333 | Z17: 1 | AA17: 1
A18: Hafssa BENCHRIF | B18: 2026 | C18: 1 | D18: =B18&"-S"&TEXT(C18,"00") | E18: GR8860v08 0122 nant ass vie ss contre ass | F18: word | H18: Grille | I18: 100 | J18: =IF(I18="","Rapport manquant",IF(I18>=85,"CONFORME (≥85%)","NON CONFORME (<85%)")) | K18: 14 | L18: 0 | M18: 32 | P18: 4 | Q18: 4 | R18: 0 | S18: 0 | T18: 0 | U18: 1 | V18: 0 | W18: 0 | X18: 1.4583333 | Y18: 1.4583333 | Z18: 1 | AA18: 1
A19: Hiba LISSAOUI | B19: 2026 | C19: 1 | D19: =B19&"-S"&TEXT(C19,"00") | E19: CG0212v02 0214 conv information conseil | F19: word | H19: Grille | I19: 100 | J19: =IF(I19="","À saisir",IF(I19>=85,"CONFORME (≥85%)","NON CONFORME (<85%)")) | K19: 10 | L19: 0 | M19: 36 | P19: 4 | Q19: 4 | R19: 0 | S19: 0 | T19: 0 | U19: 1 | V19: 0 | W19: 0 | X19: 1.4583333 | Y19: 1.4583333 | Z19: 1 | AA19: 1
A20: Imad RMAIDI | B20: 2026 | C20: 1 | D20: =B20&"-S"&TEXT(C20,"00") | E20: CG0312 0725 | F20: word | H20: Grille | I20: 100 | J20: =IF(I20="","À saisir",IF(I20>=85,"CONFORME (≥85%)","NON CONFORME (<85%)")) | K20: 10 | L20: 0 | M20: 36 | P20: 4 | Q20: 4 | R20: 0 | S20: 0 | T20: 0 | U20: 1 | V20: 0 | W20: 0 | X20: 1.4583333 | Y20: 1.4583333 | Z20: 1 | AA20: 1
A21: Mohamed HAMDANI | B21: 2026 | C21: 1 | D21: =B21&"-S"&TEXT(C21,"00") | E21: CV0508v03 0922 TCN | F21: word | H21: Grille | I21: 100 | J21: =IF(I21="","À saisir",IF(I21>=85,"CONFORME (≥85%)","NON CONFORME (<85%)")) | K21: 9 | L21: 0 | M21: 37 | P21: 4 | Q21: 4 | R21: 0 | S21: 0 | T21: 0 | U21: 1 | V21: 0 | W21: 0 | X21: 1.4583333 | Y21: 1.4583333 | Z21: 1 | AA21: 1
A22: Hafssa BENCHRIF | B22: 2026 | C22: 2 | D22: =B22&"-S"&TEXT(C22,"00") | E22: CG0309v01 0710 carte authen bancaire DE | F22: word | H22: Grille | I22: 100 | J22: =IF(I22="","Rapport manquant",IF(I22>=85,"CONFORME (≥85%)","NON CONFORME (<85%)")) | K22: 9 | L22: 0 | M22: 37 | P22: 4 | Q22: 4 | R22: 0 | S22: 0 | T22: 1 | U22: 0 | V22: 1 | W22: 5 | X22: 1.5 | Y22: 1.5 | Z22: 1 | AA22: 1
A23: Hiba LISSAOUI | B23: 2026 | C23: 2 | D23: =B23&"-S"&TEXT(C23,"00") | E23: GR8903v04 1021 délég ttle capitalisation | F23: word | H23: Grille | I23: 100 | J23: =IF(I23="","À saisir",IF(I23>=85,"CONFORME (≥85%)","NON CONFORME (<85%)")) | K23: 16 | L23: 0 | M23: 30 | P23: 5 | Q23: 5 | R23: 0 | S23: 0 | T23: 0 | U23: 0 | V23: 0 | W23: 0 | X23: 1.8333333 | Y23: 1.8333333 | Z23: 1 | AA23: 1
A24: Imad RMAIDI | B24: 2026 | C24: 2 | D24: =B24&"-S"&TEXT(C24,"00") | E24: GR8865v11 0123 gage auto | F24: word | H24: Grille | I24: 100 | J24: =IF(I24="","À saisir",IF(I24>=85,"CONFORME (≥85%)","NON CONFORME (<85%)")) | K24: 17 | L24: 0 | M24: 29 | P24: 5 | Q24: 5 | R24: 0 | S24: 0 | T24: 0 | U24: 0 | V24: 0 | W24: 0 | X24: 1.8333333 | Y24: 1.8333333 | Z24: 1 | AA24: 1
A25: Mohamed HAMDANI | B25: 2026 | C25: 2 | D25: =B25&"-S"&TEXT(C25,"00") | E25: GR8875v09 0122 nant cpte bancaire | F25: word | H25: Grille | I25: 100 | J25: =IF(I25="","À saisir",IF(I25>=85,"CONFORME (≥85%)","NON CONFORME (<85%)")) | K25: 17 | L25: 0 | M25: 29 | P25: 5 | Q25: 5 | R25: 0 | S25: 0 | T25: 0 | U25: 0 | V25: 0 | W25: 0 | X25: 1.8333333 | Y25: 1.8333333 | Z25: 1 | AA25: 1
A26: Hafssa BENCHRIF | B26: 2026 | C26: 3 | D26: =B26&"-S"&TEXT(C26,"00") | E26: GR8830v05 0221 prom de gage ou nant | F26: word | H26: Grille | I26: 100 | J26: =IF(I26="","Rapport manquant",IF(I26>=85,"CONFORME (≥85%)","NON CONFORME (<85%)")) | K26: 14 | L26: 0 | M26: 32 | P26: 5 | Q26: 5 | R26: 0 | S26: 0 | T26: 0 | U26: 0 | V26: 0 | W26: 0 | X26: 1.8333333 | Y26: 1.8333333 | Z26: 1 | AA26: 1
A27: Hiba LISSAOUI | B27: 2026 | C27: 3 | D27: =B27&"-S"&TEXT(C27,"00") | E27: CG0103v17 0323 MCD | F27: word | H27: Grille | I27: 100 | J27: =IF(I27="","À saisir",IF(I27>=85,"CONFORME (≥85%)","NON CONFORME (<85%)")) | K27: 10 | L27: 0 | M27: 36 | P27: 5 | Q27: 5 | R27: 0 | S27: 0 | T27: 0 | U27: 0 | V27: 1 | W27: 83 | X27: 1.8333333 | Y27: 1.8333333 | Z27: 1 | AA27: 1
A28: Imad RMAIDI | B28: 2026 | C28: 3 | D28: =B28&"-S"&TEXT(C28,"00") | E28: CI0433v06 0312 Stage prévention | F28: word | H28: Grille | I28: 100 | J28: =IF(I28="","À saisir",IF(I28>=85,"CONFORME (≥85%)","NON CONFORME (<85%)")) | K28: 17 | L28: 0 | M28: 29 | P28: 5 | Q28: 5 | R28: 0 | S28: 0 | T28: 0 | U28: 0 | V28: 0 | W28: 0 | X28: 1.8333333 | Y28: 1.8333333 | Z28: 1 | AA28: 1
A29: Mohamed HAMDANI | B29: 2026 | C29: 3 | D29: =B29&"-S"&TEXT(C29,"00") | E29: GR8866v04 0123 bord gage auto | F29: word | H29: Grille | I29: 100 | J29: =IF(I29="","À saisir",IF(I29>=85,"CONFORME (≥85%)","NON CONFORME (<85%)")) | K29: 15 | L29: 0 | M29: 31 | P29: 5 | Q29: 5 | R29: 0 | S29: 0 | T29: 0 | U29: 0 | V29: 0 | W29: 0 | X29: 1.8333333 | Y29: 1.8333333 | Z29: 1 | AA29: 1
A30: Hafssa BENCHRIF | B30: 2026 | C30: 4 | D30: =B30&"-S"&TEXT(C30,"00") | E30: GR8847v03 0122 nant CTF conv | F30: word | H30: Grille | I30: 100 | J30: =IF(I30="","Rapport manquant",IF(I30>=85,"CONFORME (≥85%)","NON CONFORME (<85%)")) | K30: 15 | L30: 0 | M30: 31 | P30: 3 | Q30: 2 | R30: 1 | S30: 0 | T30: 0 | U30: 0 | V30: 0 | W30: 0 | X30: 1.0833333 | Y30: 0.70833333 | Z30: 0.66666667 | AA30: 0.65384615
A31: Hiba LISSAOUI | B31: 2026 | C31: 4 | D31: =B31&"-S"&TEXT(C31,"00") | E31: GR8845v11 0122 nant CTF | F31: word | H31: Grille | I31: 98 | J31: =IF(I31="","À saisir",IF(I31>=85,"CONFORME (≥85%)","NON CONFORME (<85%)")) | K31: 16 | L31: 1 | M31: 29 | N31: 3.4 – Pour chaque tableau de présentation, le contenu linéarisé reste-t-il compréhensible ? | O31: Debrief de l’agent pour le sensibiliser à l’importance d’être vigilant sur le traitement, puis exercice pratique avec l’ensemble de l’équipe. | P31: 3 | Q31: 3 | R31: 0 | S31: 0 | T31: 0 | U31: 0 | V31: 0 | W31: 0 | X31: 1.0833333 | Y31: 1.0833333 | Z31: 1 | AA31: 1
A32: Imad RMAIDI | B32: 2026 | C32: 4 | D32: =B32&"-S"&TEXT(C32,"00") | E32: CM0459v03 1015 CG Tonic Privilege DE | F32: word | H32: Grille | I32: 100 | J32: =IF(I32="","À saisir",IF(I32>=85,"CONFORME (≥85%)","NON CONFORME (<85%)")) | K32: 17 | L32: 0 | M32: 29 | P32: 3 | Q32: 3 | R32: 0 | S32: 0 | T32: 0 | U32: 0 | V32: 0 | W32: 0 | X32: 1.0833333 | Y32: 1.0833333 | Z32: 1 | AA32: 1
A33: Mohamed HAMDANI | B33: 2026 | C33: 4 | D33: =B33&"-S"&TEXT(C33,"00") | E33: CI0464v07 1122 CG livret A Prem_s DE | F33: word | H33: Grille | I33: 100 | J33: =IF(I33="","À saisir",IF(I33>=85,"CONFORME (≥85%)","NON CONFORME (<85%)")) | K33: 10 | L33: 0 | M33: 36 | P33: 3 | Q33: 3 | R33: 0 | S33: 0 | T33: 0 | U33: 0 | V33: 1 | W33: 12 | X33: 1.0833333 | Y33: 1.0833333 | Z33: 1 | AA33: 1
A34: Hafssa BENCHRIF | B34: 2026 | C34: 5 | D34: =B34&"-S"&TEXT(C34,"00") | E34: CG0552v01 0620 AAD | F34: word | H34: Grille | I34: 100 | J34: =IF(I34="","Rapport manquant",IF(I34>=85,"CONFORME (≥85%)","NON CONFORME (<85%)")) | K34: 10 | L34: 0 | M34: 36 | P34: 5 | Q34: 5 | R34: 0 | S34: 0 | T34: 0 | U34: 0 | V34: 0 | W34: 0 | X34: 1.8333333 | Y34: 1.8333333 | Z34: 1 | AA34: 1
A35: Hafssa BENCHRIF | B35: 2026 | C35: 8 | D35: =B35&"-S"&TEXT(C35,"00") | E35: COL_9902030098_011000733309323 | F35: pdf | G35: 46073 | H35: RAPDF | I35: 100 | J35: =IF(I35="","Rapport manquant",IF(I35>=85,"CONFORME (≥85%)","NON CONFORME (<85%)")) | K35: 15 | L35: 0 | M35: 31 | P35: 0 | Q35: 0 | R35: 0 | S35: 0 | T35: 0 | U35: 0 | V35: 0 | W35: 0 | X35: 0 | Y35: 0
A36: Hiba LISSAOUI | B36: 2026 | C36: 8 | D36: =B36&"-S"&TEXT(C36,"00") | E36: EMP_9902030152_011000758125238 | F36: pdf | G36: 46073 | H36: RAPDF | I36: 87.5 | J36: =IF(I36="","À saisir",IF(I36>=85,"CONFORME (≥85%)","NON CONFORME (<85%)")) | K36: 14 | L36: 2 | M36: 30 | N36: 3.1 – Chaque tableau de données complexe a-t-il une alternative ? (le tableau a une alternative "voir texte en bas") 3.2 – Pour chaque tableau de données complexe ayant une alternative, cette alternative est-elle pertinente ? (le texte sous le tableau) | O36: Debrief de l’agent pour le sensibiliser à l’importance d’être vigilant sur le traitement, puis exercice pratique avec l’ensemble de l’équipe. | P36: 0 | Q36: 0 | R36: 0 | S36: 0 | T36: 0 | U36: 0 | V36: 0 | W36: 0 | X36: 0 | Y36: 0
A37: Imad RMAIDI | B37: 2026 | C37: 8 | D37: =B37&"-S"&TEXT(C37,"00") | E37: SAN_9902030040_011000804912506 | F37: pdf | G37: 46073 | H37: RAPDF | I37: 100 | J37: =IF(I37="","À saisir",IF(I37>=85,"CONFORME (≥85%)","NON CONFORME (<85%)")) | K37: 12 | L37: 0 | M37: 28 | P37: 0 | Q37: 0 | R37: 0 | S37: 0 | T37: 0 | U37: 0 | V37: 0 | W37: 0 | X37: 0 | Y37: 0
A38: Mohamed HAMDANI | B38: 2026 | C38: 8 | D38: =B38&"-S"&TEXT(C38,"00") | E38: SAN_9902030040_011000804912412 | F38: pdf | G38: 46073 | H38: RAPDF | I38: 100 | J38: =IF(I38="","À saisir",IF(I38>=85,"CONFORME (≥85%)","NON CONFORME (<85%)")) | K38: 12 | L38: 0 | M38: 34 | P38: 0 | Q38: 0 | R38: 0 | S38: 0 | T38: 0 | U38: 0 | V38: 0 | W38: 0 | X38: 0 | Y38: 0
A39: Hafssa BENCHRIF | B39: 2026 | C39: 9 | D39: =B39&"-S"&TEXT(C39,"00") | E39: COL_9902030098_011000744004221 | F39: pdf | G39: 46077 | H39: RAPDF | I39: 100 | J39: =IF(I39="","Rapport manquant",IF(I39>=85,"CONFORME (≥85%)","NON CONFORME (<85%)")) | K39: 15 | L39: 0 | M39: 31 | P39: 5 | Q39: 5 | R39: 0 | S39: 0 | T39: 0 | U39: 0 | V39: 0 | W39: 0 | X39: 1.8333333 | Y39: 1.8333333 | Z39: 1 | AA39: 1
A40: Hiba LISSAOUI | B40: 2026 | C40: 9 | D40: =B40&"-S"&TEXT(C40,"00") | E40: EMP_9902030152_011000767923078 | F40: pdf | G40: 46078 | H40: RAPDF | I40: 100 | J40: =IF(I40="","À saisir",IF(I40>=85,"CONFORME (≥85%)","NON CONFORME (<85%)")) | K40: 14 | L40: 0 | M40: 30 | N40: 3.1 – Chaque tableau de données complexe a-t-il une alternative ? 3.2 – Pour chaque tableau de données complexe ayant une alternative, cette alternative est-elle pertinente ? | P40: 5 | Q40: 5 | R40: 0 | S40: 0 | T40: 0 | U40: 0 | V40: 0 | W40: 0 | X40: 1.8333333 | Y40: 1.8333333 | Z40: 1 | AA40: 1
...

Sheet Remarques
A1: Collaborateur | B1: Année | C1: Semaine | D1: Document | E1: Remarque
A2: Imad RMAIDI | B2: 2026 | C2: 11 | D2: SAN_9902020008_011000745243123 | E2: Document traité (fichiers présents) mais aucun rapport d'évaluation : note non renseignée.
A3: Mohamed HAMDANI | B3: 2026 | C3: 11 | D3: SAN_9902030053_011000789059347 | E3: Document traité (fichiers présents) mais aucun rapport d'évaluation : note non renseignée.
A4: Imad RMAIDI | B4: 2026 | C4: 12 | D4: (dossier vide) | E4: Dossier de la semaine créé mais vide : aucun document ni rapport.
A5: Hafssa BENCHRIF | B5: 2026 | C5: 16 | D5: 9800059279 Fc_E-Retrait_v062026 | E5: Document traité (fichiers présents) mais aucun rapport d'évaluation : note non renseignée.
A6: Hafssa BENCHRIF | B6: 2026 | C6: 17 | D6: (dossier vide) | E6: Dossier de la semaine créé mais vide : aucun document ni rapport.
A7: Mohamed HAMDANI | B7: 2026 | C7: 23 | D7: PEA _0140020765-Vadsf2026 | E7: Type de document « Non spécifié » dans le rapport : déduit du dossier (pdf).
A8: Hiba LISSAOUI | B8: 2026 | C8: 24 | D8: P1_Notice_Monabanq_10-2026 | E8: Dossier classé en S24 mais le rapport indique « Semaine 31 » (évalué le 2026-07-28) : semaine du dossier retenue.
A9: Hiba LISSAOUI | B9: 2026 | C9: 24 | D9: P1_Notice_Monabanq_10-2026 | E9: Type de document « Non spécifié » dans le rapport : déduit du dossier (pdf).
A10: Hiba LISSAOUI | B10: 2026 | C10: 25 | D10: 0130015514_FC Tonic Privilège à préavis_072026 | E10: Dossier classé en S25 mais le rapport indique « Semaine 31 » (évalué le 2026-07-28) : semaine du dossier retenue.
A11: Hiba LISSAOUI | B11: 2026 | C11: 25 | D11: 0130015514_FC Tonic Privilège à préavis_072026 | E11: Type de document « Non spécifié » dans le rapport : déduit du dossier (pdf).
A12: Mohamed HAMDANI | B12: 2026 | C12: 25 | D12: 0130018095_FC CM ADD_072026 | E12: Type de document « Non spécifié » dans le rapport : déduit du dossier (pdf).
A13: Mohamed HAMDANI | B13: 2026 | C13: 26 | D13: 0130009109 CM - Eurocompte jeune 072026 | E13: Type de document « Non spécifié » dans le rapport : déduit du dossier (pdf).
... A24: Hiba LISSAOUI | B24: 2026 | C24: 44 | D24: VIE_9902030044_011000541137492 | E24: Date d'évaluation (2026-10-29) postérieure à aujourd'hui : à vérifier.
