Workbook

Sheet Synthèse hebdo
A1: Synthèse des évaluations par collaborateur et par semaine
A2: Nb docs = documents traités dans la semaine ; Note moy. = moyenne des notes /100 des documents évalués (cellule vide = aucun document). Calculé par formules à partir de l'onglet « Détail ».
A4: Année | B4: Semaine | C4: Période (lun.–dim.) | D4: Hafssa BENCHRIF | F4: Hiba LISSAOUI | H4: Imad RMAIDI | J4: Mohamed HAMDANI | L4: Youssef | N4: Équipe
D5: Nb docs | E5: Note moy. | F5: Nb docs | G5: Note moy. | H5: Nb docs | I5: Note moy. | J5: Nb docs | K5: Note moy. | L5: Nb docs | M5: Note moy. | N5: Nb docs | O5: Note moy.
A6: 2025 | B6: 51 | C6: 15/12/2025 – 21/12/2025 | D6: =COUNTIFS(Détail!$A:$A,"Hafssa BENCHRIF",Détail!$B:$B,$A6,Détail!$C:$C,$B6) -> 2 | E6: =IFERROR(AVERAGEIFS(Détail!$I:$I,Détail!$A:$A,"Hafssa BENCHRIF",Détail!$B:$B,$A6,Détail!$C:$C,$B6),"") -> 100 | F6: =COUNTIFS(Détail!$A:$A,"Hiba LISSAOUI",Détail!$B:$B,$A6,Détail!$C:$C,$B6) -> 2 | G6: =IFERROR(AVERAGEIFS(Détail!$I:$I,Détail!$A:$A,"Hiba LISSAOUI",Détail!$B:$B,$A6,Détail!$C:$C,$B6),"") -> 98.35 | H6: =COUNTIFS(Détail!$A:$A,"Imad RMAIDI",Détail!$B:$B,$A6,Détail!$C:$C,$B6) -> 2 | I6: =IFERROR(AVERAGEIFS(Détail!$I:$I,Détail!$A:$A,"Imad RMAIDI",Détail!$B:$B,$A6,Détail!$C:$C,$B6),"") -> 100 | J6: =COUNTIFS(Détail!$A:$A,"Mohamed HAMDANI",Détail!$B:$B,$A6,Détail!$C:$C,$B6) -> 2 | K6: =IFERROR(AVERAGEIFS(Détail!$I:$I,Détail!$A:$A,"Mohamed HAMDANI",Détail!$B:$B,$A6,Détail!$C:$C,$B6),"") -> 96.65 | L6: =COUNTIFS(Détail!$A:$A,"Youssef",Détail!$B:$B,$A6,Détail!$C:$C,$B6) -> 0 | M6: =IFERROR(AVERAGEIFS(Détail!$I:$I,Détail!$A:$A,"Youssef",Détail!$B:$B,$A6,Détail!$C:$C,$B6),"") | N6: =COUNTIFS(Détail!$B:$B,$A6,Détail!$C:$C,$B6) -> 8 | O6: =IFERROR(AVERAGEIFS(Détail!$I:$I,Détail!$B:$B,$A6,Détail!$C:$C,$B6),"") -> 98.75
A7: 2025 | B7: 52 | C7: 22/12/2025 – 28/12/2025 | D7: =COUNTIFS(Détail!$A:$A,"Hafssa BENCHRIF",Détail!$B:$B,$A7,Détail!$C:$C,$B7) -> 2 | E7: =IFERROR(AVERAGEIFS(Détail!$I:$I,Détail!$A:$A,"Hafssa BENCHRIF",Détail!$B:$B,$A7,Détail!$C:$C,$B7),"") -> 100 | F7: =COUNTIFS(Détail!$A:$A,"Hiba LISSAOUI",Détail!$B:$B,$A7,Détail!$C:$C,$B7) -> 2 | G7: =IFERROR(AVERAGEIFS(Détail!$I:$I,Détail!$A:$A,"Hiba LISSAOUI",Détail!$B:$B,$A7,Détail!$C:$C,$B7),"") -> 98.35 | H7: =COUNTIFS(Détail!$A:$A,"Imad RMAIDI",Détail!$B:$B,$A7,Détail!$C:$C,$B7) -> 2 | I7: =IFERROR(AVERAGEIFS(Détail!$I:$I,Détail!$A:$A,"Imad RMAIDI",Détail!$B:$B,$A7,Détail!$C:$C,$B7),"") -> 100 | J7: =COUNTIFS(Détail!$A:$A,"Mohamed HAMDANI",Détail!$B:$B,$A7,Détail!$C:$C,$B7) -> 2 | K7: =IFERROR(AVERAGEIFS(Détail!$I:$I,Détail!$A:$A,"Mohamed HAMDANI",Détail!$B:$B,$A7,Détail!$C:$C,$B7),"") -> 100 | L7: =COUNTIFS(Détail!$A:$A,"Youssef",Détail!$B:$B,$A7,Détail!$C:$C,$B7) -> 0 | M7: =IFERROR(AVERAGEIFS(Détail!$I:$I,Détail!$A:$A,"Youssef",Détail!$B:$B,$A7,Détail!$C:$C,$B7),"") | N7: =COUNTIFS(Détail!$B:$B,$A7,Détail!$C:$C,$B7) -> 8 | O7: =IFERROR(AVERAGEIFS(Détail!$I:$I,Détail!$B:$B,$A7,Détail!$C:$C,$B7),"") -> 99.5875
A8: 2026 | B8: 1 | C8: 29/12/2025 – 04/01/2026 | D8: =COUNTIFS(Détail!$A:$A,"Hafssa BENCHRIF",Détail!$B:$B,$A8,Détail!$C:$C,$B8) -> 1 | E8: =IFERROR(AVERAGEIFS(Détail!$I:$I,Détail!$A:$A,"Hafssa BENCHRIF",Détail!$B:$B,$A8,Détail!$C:$C,$B8),"") -> 100 | F8: =COUNTIFS(Détail!$A:$A,"Hiba LISSAOUI",Détail!$B:$B,$A8,Détail!$C:$C,$B8) -> 1 | G8: =IFERROR(AVERAGEIFS(Détail!$I:$I,Détail!$A:$A,"Hiba LISSAOUI",Détail!$B:$B,$A8,Détail!$C:$C,$B8),"") -> 100 | H8: =COUNTIFS(Détail!$A:$A,"Imad RMAIDI",Détail!$B:$B,$A8,Détail!$C:$C,$B8) -> 1 | I8: =IFERROR(AVERAGEIFS(Détail!$I:$I,Détail!$A:$A,"Imad RMAIDI",Détail!$B:$B,$A8,Détail!$C:$C,$B8),"") -> 100 | J8: =COUNTIFS(Détail!$A:$A,"Mohamed HAMDANI",Détail!$B:$B,$A8,Détail!$C:$C,$B8) -> 1 | K8: =IFERROR(AVERAGEIFS(Détail!$I:$I,Détail!$A:$A,"Mohamed HAMDANI",Détail!$B:$B,$A8,Détail!$C:$C,$B8),"") -> 100 | L8: =COUNTIFS(Détail!$A:$A,"Youssef",Détail!$B:$B,$A8,Détail!$C:$C,$B8) -> 0 | M8: =IFERROR(AVERAGEIFS(Détail!$I:$I,Détail!$A:$A,"Youssef",Détail!$B:$B,$A8,Détail!$C:$C,$B8),"") | N8: =COUNTIFS(Détail!$B:$B,$A8,Détail!$C:$C,$B8) -> 4 | O8: =IFERROR(AVERAGEIFS(Détail!$I:$I,Détail!$B:$B,$A8,Détail!$C:$C,$B8),"") -> 100
A9: 2026 | B9: 2 | C9: 05/01/2026 – 11/01/2026 | D9: =COUNTIFS(Détail!$A:$A,"Hafssa BENCHRIF",Détail!$B:$B,$A9,Détail!$C:$C,$B9) -> 1 | E9: =IFERROR(AVERAGEIFS(Détail!$I:$I,Détail!$A:$A,"Hafssa BENCHRIF",Détail!$B:$B,$A9,Détail!$C:$C,$B9),"") -> 100 | F9: =COUNTIFS(Détail!$A:$A,"Hiba LISSAOUI",Détail!$B:$B,$A9,Détail!$C:$C,$B9) -> 1 | G9: =IFERROR(AVERAGEIFS(Détail!$I:$I,Détail!$A:$A,"Hiba LISSAOUI",Détail!$B:$B,$A9,Détail!$C:$C,$B9),"") -> 100 | H9: =COUNTIFS(Détail!$A:$A,"Imad RMAIDI",Détail!$B:$B,$A9,Détail!$C:$C,$B9) -> 1 | I9: =IFERROR(AVERAGEIFS(Détail!$I:$I,Détail!$A:$A,"Imad RMAIDI",Détail!$B:$B,$A9,Détail!$C:$C,$B9),"") -> 100 | J9: =COUNTIFS(Détail!$A:$A,"Mohamed HAMDANI",Détail!$B:$B,$A9,Détail!$C:$C,$B9) -> 1 | K9: =IFERROR(AVERAGEIFS(Détail!$I:$I,Détail!$A:$A,"Mohamed HAMDANI",Détail!$B:$B,$A9,Détail!$C:$C,$B9),"") -> 100 | L9: =COUNTIFS(Détail!$A:$A,"Youssef",Détail!$B:$B,$A9,Détail!$C:$C,$B9) -> 0 | M9: =IFERROR(AVERAGEIFS(Détail!$I:$I,Détail!$A:$A,"Youssef",Détail!$B:$B,$A9,Détail!$C:$C,$B9),"") | N9: =COUNTIFS(Détail!$B:$B,$A9,Détail!$C:$C,$B9) -> 4 | O9: =IFERROR(AVERAGEIFS(Détail!$I:$I,Détail!$B:$B,$A9,Détail!$C:$C,$B9),"") -> 100
A10: 2026 | B10: 3 | C10: 12/01/2026 – 18/01/2026 | D10: =COUNTIFS(Détail!$A:$A,"Hafssa BENCHRIF",Détail!$B:$B,$A10,Détail!$C:$C,$B10) -> 1 | E10: =IFERROR(AVERAGEIFS(Détail!$I:$I,Détail!$A:$A,"Hafssa BENCHRIF",Détail!$B:$B,$A10,Détail!$C:$C,$B10),"") -> 100 | F10: =COUNTIFS(Détail!$A:$A,"Hiba LISSAOUI",Détail!$B:$B,$A10,Détail!$C:$C,$B10) -> 1 | G10: =IFERROR(AVERAGEIFS(Détail!$I:$I,Détail!$A:$A,"Hiba LISSAOUI",Détail!$B:$B,$A10,Détail!$C:$C,$B10),"") -> 100 | H10: =COUNTIFS(Détail!$A:$A,"Imad RMAIDI",Détail!$B:$B,$A10,Détail!$C:$C,$B10) -> 1 | I10: =IFERROR(AVERAGEIFS(Détail!$I:$I,Détail!$A:$A,"Imad RMAIDI",Détail!$B:$B,$A10,Détail!$C:$C,$B10),"") -> 100 | J10: =COUNTIFS(Détail!$A:$A,"Mohamed HAMDANI",Détail!$B:$B,$A10,Détail!$C:$C,$B10) -> 1 | K10: =IFERROR(AVERAGEIFS(Détail!$I:$I,Détail!$A:$A,"Mohamed HAMDANI",Détail!$B:$B,$A10,Détail!$C:$C,$B10),"") -> 100 | L10: =COUNTIFS(Détail!$A:$A,"Youssef",Détail!$B:$B,$A10,Détail!$C:$C,$B10) -> 0 | M10: =IFERROR(AVERAGEIFS(Détail!$I:$I,Détail!$A:$A,"Youssef",Détail!$B:$B,$A10,Détail!$C:$C,$B10),"") | N10: =COUNTIFS(Détail!$B:$B,$A10,Détail!$C:$C,$B10) -> 4 | O10: =IFERROR(AVERAGEIFS(Détail!$I:$I,Détail!$B:$B,$A10,Détail!$C:$C,$B10),"") -> 100
A11: 2026 | B11: 4 | C11: 19/01/2026 – 25/01/2026 | D11: =COUNTIFS(Détail!$A:$A,"Hafssa BENCHRIF",Détail!$B:$B,$A11,Détail!$C:$C,$B11) -> 1 | E11: =IFERROR(AVERAGEIFS(Détail!$I:$I,Détail!$A:$A,"Hafssa BENCHRIF",Détail!$B:$B,$A11,Détail!$C:$C,$B11),"") -> 100 | F11: =COUNTIFS(Détail!$A:$A,"Hiba LISSAOUI",Détail!$B:$B,$A11,Détail!$C:$C,$B11) -> 1 | G11: =IFERROR(AVERAGEIFS(Détail!$I:$I,Détail!$A:$A,"Hiba LISSAOUI",Détail!$B:$B,$A11,Détail!$C:$C,$B11),"") -> 98 | H11: =COUNTIFS(Détail!$A:$A,"Imad RMAIDI",Détail!$B:$B,$A11,Détail!$C:$C,$B11) -> 1 | I11: =IFERROR(AVERAGEIFS(Détail!$I:$I,Détail!$A:$A,"Imad RMAIDI",Détail!$B:$B,$A11,Détail!$C:$C,$B11),"") -> 100 | J11: =COUNTIFS(Détail!$A:$A,"Mohamed HAMDANI",Détail!$B:$B,$A11,Détail!$C:$C,$B11) -> 1 | K11: =IFERROR(AVERAGEIFS(Détail!$I:$I,Détail!$A:$A,"Mohamed HAMDANI",Détail!$B:$B,$A11,Détail!$C:$C,$B11),"") -> 100 | L11: =COUNTIFS(Détail!$A:$A,"Youssef",Détail!$B:$B,$A11,Détail!$C:$C,$B11) -> 0 | M11: =IFERROR(AVERAGEIFS(Détail!$I:$I,Détail!$A:$A,"Youssef",Détail!$B:$B,$A11,Détail!$C:$C,$B11),"") | N11: =COUNTIFS(Détail!$B:$B,$A11,Détail!$C:$C,$B11) -> 4 | O11: =IFERROR(AVERAGEIFS(Détail!$I:$I,Détail!$B:$B,$A11,Détail!$C:$C,$B11),"") -> 99.5
A12: 2026 | B12: 5 | C12: 26/01/2026 – 01/02/2026 | D12: =COUNTIFS(Détail!$A:$A,"Hafssa BENCHRIF",Détail!$B:$B,$A12,Détail!$C:$C,$B12) -> 1 | E12: =IFERROR(AVERAGEIFS(Détail!$I:$I,Détail!$A:$A,"Hafssa BENCHRIF",Détail!$B:$B,$A12,Détail!$C:$C,$B12),"") -> 100 | F12: =COUNTIFS(Détail!$A:$A,"Hiba LISSAOUI",Détail!$B:$B,$A12,Détail!$C:$C,$B12) -> 0 | G12: =IFERROR(AVERAGEIFS(Détail!$I:$I,Détail!$A:$A,"Hiba LISSAOUI",Détail!$B:$B,$A12,Détail!$C:$C,$B12),"") | H12: =COUNTIFS(Détail!$A:$A,"Imad RMAIDI",Détail!$B:$B,$A12,Détail!$C:$C,$B12) -> 0 | I12: =IFERROR(AVERAGEIFS(Détail!$I:$I,Détail!$A:$A,"Imad RMAIDI",Détail!$B:$B,$A12,Détail!$C:$C,$B12),"") | J12: =COUNTIFS(Détail!$A:$A,"Mohamed HAMDANI",Détail!$B:$B,$A12,Détail!$C:$C,$B12) -> 0 | K12: =IFERROR(AVERAGEIFS(Détail!$I:$I,Détail!$A:$A,"Mohamed HAMDANI",Détail!$B:$B,$A12,Détail!$C:$C,$B12),"") | L12: =COUNTIFS(Détail!$A:$A,"Youssef",Détail!$B:$B,$A12,Détail!$C:$C,$B12) -> 0 | M12: =IFERROR(AVERAGEIFS(Détail!$I:$I,Détail!$A:$A,"Youssef",Détail!$B:$B,$A12,Détail!$C:$C,$B12),"") | N12: =COUNTIFS(Détail!$B:$B,$A12,Détail!$C:$C,$B12) -> 1 | O12: =IFERROR(AVERAGEIFS(Détail!$I:$I,Détail!$B:$B,$A12,Détail!$C:$C,$B12),"") -> 100
A13: 2026 | B13: 6 | C13: 02/02/2026 – 08/02/2026 | D13: =COUNTIFS(Détail!$A:$A,"Hafssa BENCHRIF",Détail!$B:$B,$A13,Détail!$C:$C,$B13) -> 0 | E13: =IFERROR(AVERAGEIFS(Détail!$I:$I,Détail!$A:$A,"Hafssa BENCHRIF",Détail!$B:$B,$A13,Détail!$C:$C,$B13),"") | F13: =COUNTIFS(Détail!$A:$A,"Hiba LISSAOUI",Détail!$B:$B,$A13,Détail!$C:$C,$B13) -> 0 | G13: =IFERROR(AVERAGEIFS(Détail!$I:$I,Détail!$A:$A,"Hiba LISSAOUI",Détail!$B:$B,$A13,Détail!$C:$C,$B13),"") | H13: =COUNTIFS(Détail!$A:$A,"Imad RMAIDI",Détail!$B:$B,$A13,Détail!$C:$C,$B13) -> 0 | I13: =IFERROR(AVERAGEIFS(Détail!$I:$I,Détail!$A:$A,"Imad RMAIDI",Détail!$B:$B,$A13,Détail!$C:$C,$B13),"") | J13: =COUNTIFS(Détail!$A:$A,"Mohamed HAMDANI",Détail!$B:$B,$A13,Détail!$C:$C,$B13) -> 0 | K13: =IFERROR(AVERAGEIFS(Détail!$I:$I,Détail!$A:$A,"Mohamed HAMDANI",Détail!$B:$B,$A13,Détail!$C:$C,$B13),"") | L13: =COUNTIFS(Détail!$A:$A,"Youssef",Détail!$B:$B,$A13,Détail!$C:$C,$B13) -> 0 | M13: =IFERROR(AVERAGEIFS(Détail!$I:$I,Détail!$A:$A,"Youssef",Détail!$B:$B,$A13,Détail!$C:$C,$B13),"") | N13: =COUNTIFS(Détail!$B:$B,$A13,Détail!$C:$C,$B13) -> 0 | O13: =IFERROR(AVERAGEIFS(Détail!$I:$I,Détail!$B:$B,$A13,Détail!$C:$C,$B13),"")
A14: 2026 | B14: 7 | C14: 09/02/2026 – 15/02/2026 | D14: =COUNTIFS(Détail!$A:$A,"Hafssa BENCHRIF",Détail!$B:$B,$A14,Détail!$C:$C,$B14) -> 0 | E14: =IFERROR(AVERAGEIFS(Détail!$I:$I,Détail!$A:$A,"Hafssa BENCHRIF",Détail!$B:$B,$A14,Détail!$C:$C,$B14),"") | F14: =COUNTIFS(Détail!$A:$A,"Hiba LISSAOUI",Détail!$B:$B,$A14,Détail!$C:$C,$B14) -> 0 | G14: =IFERROR(AVERAGEIFS(Détail!$I:$I,Détail!$A:$A,"Hiba LISSAOUI",Détail!$B:$B,$A14,Détail!$C:$C,$B14),"") | H14: =COUNTIFS(Détail!$A:$A,"Imad RMAIDI",Détail!$B:$B,$A14,Détail!$C:$C,$B14) -> 0 | I14: =IFERROR(AVERAGEIFS(Détail!$I:$I,Détail!$A:$A,"Imad RMAIDI",Détail!$B:$B,$A14,Détail!$C:$C,$B14),"") | J14: =COUNTIFS(Détail!$A:$A,"Mohamed HAMDANI",Détail!$B:$B,$A14,Détail!$C:$C,$B14) -> 0 | K14: =IFERROR(AVERAGEIFS(Détail!$I:$I,Détail!$A:$A,"Mohamed HAMDANI",Détail!$B:$B,$A14,Détail!$C:$C,$B14),"") | L14: =COUNTIFS(Détail!$A:$A,"Youssef",Détail!$B:$B,$A14,Détail!$C:$C,$B14) -> 0 | M14: =IFERROR(AVERAGEIFS(Détail!$I:$I,Détail!$A:$A,"Youssef",Détail!$B:$B,$A14,Détail!$C:$C,$B14),"") | N14: =COUNTIFS(Détail!$B:$B,$A14,Détail!$C:$C,$B14) -> 0 | O14: =IFERROR(AVERAGEIFS(Détail!$I:$I,Détail!$B:$B,$A14,Détail!$C:$C,$B14),"")
A15: 2026 | B15: 8 | C15: 16/02/2026 – 22/02/2026 | D15: =COUNTIFS(Détail!$A:$A,"Hafssa BENCHRIF",Détail!$B:$B,$A15,Détail!$C:$C,$B15) -> 1 | E15: =IFERROR(AVERAGEIFS(Détail!$I:$I,Détail!$A:$A,"Hafssa BENCHRIF",Détail!$B:$B,$A15,Détail!$C:$C,$B15),"") -> 100 | F15: =COUNTIFS(Détail!$A:$A,"Hiba LISSAOUI",Détail!$B:$B,$A15,Détail!$C:$C,$B15) -> 1 | G15: =IFERROR(AVERAGEIFS(Détail!$I:$I,Détail!$A:$A,"Hiba LISSAOUI",Détail!$B:$B,$A15,Détail!$C:$C,$B15),"") -> 87.5 | H15: =COUNTIFS(Détail!$A:$A,"Imad RMAIDI",Détail!$B:$B,$A15,Détail!$C:$C,$B15) -> 1 | I15: =IFERROR(AVERAGEIFS(Détail!$I:$I,Détail!$A:$A,"Imad RMAIDI",Détail!$B:$B,$A15,Détail!$C:$C,$B15),"") -> 100 | J15: =COUNTIFS(Détail!$A:$A,"Mohamed HAMDANI",Détail!$B:$B,$A15,Détail!$C:$C,$B15) -> 1 | K15: =IFERROR(AVERAGEIFS(Détail!$I:$I,Détail!$A:$A,"Mohamed HAMDANI",Détail!$B:$B,$A15,Détail!$C:$C,$B15),"") -> 100 | L15: =COUNTIFS(Détail!$A:$A,"Youssef",Détail!$B:$B,$A15,Détail!$C:$C,$B15) -> 0 | M15: =IFERROR(AVERAGEIFS(Détail!$I:$I,Détail!$A:$A,"Youssef",Détail!$B:$B,$A15,Détail!$C:$C,$B15),"") | N15: =COUNTIFS(Détail!$B:$B,$A15,Détail!$C:$C,$B15) -> 4 | O15: =IFERROR(AVERAGEIFS(Détail!$I:$I,Détail!$B:$B,$A15,Détail!$C:$C,$B15),"") -> 96.875
A16: 2026 | B16: 9 | C16: 23/02/2026 – 01/03/2026 | D16: =COUNTIFS(Détail!$A:$A,"Hafssa BENCHRIF",Détail!$B:$B,$A16,Détail!$C:$C,$B16) -> 1 | E16: =IFERROR(AVERAGEIFS(Détail!$I:$I,Détail!$A:$A,"Hafssa BENCHRIF",Détail!$B:$B,$A16,Détail!$C:$C,$B16),"") -> 100 | F16: =COUNTIFS(Détail!$A:$A,"Hiba LISSAOUI",Détail!$B:$B,$A16,Détail!$C:$C,$B16) -> 1 | G16: =IFERROR(AVERAGEIFS(Détail!$I:$I,Détail!$A:$A,"Hiba LISSAOUI",Détail!$B:$B,$A16,Détail!$C:$C,$B16),"") -> 100 | H16: =COUNTIFS(Détail!$A:$A,"Imad RMAIDI",Détail!$B:$B,$A16,Détail!$C:$C,$B16) -> 1 | I16: =IFERROR(AVERAGEIFS(Détail!$I:$I,Détail!$A:$A,"Imad RMAIDI",Détail!$B:$B,$A16,Détail!$C:$C,$B16),"") -> 100 | J16: =COUNTIFS(Détail!$A:$A,"Mohamed HAMDANI",Détail!$B:$B,$A16,Détail!$C:$C,$B16) -> 1 | K16: =IFERROR(AVERAGEIFS(Détail!$I:$I,Détail!$A:$A,"Mohamed HAMDANI",Détail!$B:$B,$A16,Détail!$C:$C,$B16),"") -> 100 | L16: =COUNTIFS(Détail!$A:$A,"Youssef",Détail!$B:$B,$A16,Détail!$C:$C,$B16) -> 0 | M16: =IFERROR(AVERAGEIFS(Détail!$I:$I,Détail!$A:$A,"Youssef",Détail!$B:$B,$A16,Détail!$C:$C,$B16),"") | N16: =COUNTIFS(Détail!$B:$B,$A16,Détail!$C:$C,$B16) -> 4 | O16: =IFERROR(AVERAGEIFS(Détail!$I:$I,Détail!$B:$B,$A16,Détail!$C:$C,$B16),"") -> 100
A17: 2026 | B17: 10 | C17: 02/03/2026 – 08/03/2026 | D17: =COUNTIFS(Détail!$A:$A,"Hafssa BENCHRIF",Détail!$B:$B,$A17,Détail!$C:$C,$B17) -> 1 | E17: =IFERROR(AVERAGEIFS(Détail!$I:$I,Détail!$A:$A,"Hafssa BENCHRIF",Détail!$B:$B,$A17,Détail!$C:$C,$B17),"") -> 93.3 | F17: =COUNTIFS(Détail!$A:$A,"Hiba LISSAOUI",Détail!$B:$B,$A17,Détail!$C:$C,$B17) -> 1 | G17: =IFERROR(AVERAGEIFS(Détail!$I:$I,Détail!$A:$A,"Hiba LISSAOUI",Détail!$B:$B,$A17,Détail!$C:$C,$B17),"") -> 100 | H17: =COUNTIFS(Détail!$A:$A,"Imad RMAIDI",Détail!$B:$B,$A17,Détail!$C:$C,$B17) -> 1 | I17: =IFERROR(AVERAGEIFS(Détail!$I:$I,Détail!$A:$A,"Imad RMAIDI",Détail!$B:$B,$A17,Détail!$C:$C,$B17),"") -> 100 | J17: =COUNTIFS(Détail!$A:$A,"Mohamed HAMDANI",Détail!$B:$B,$A17,Détail!$C:$C,$B17) -> 1 | K17: =IFERROR(AVERAGEIFS(Détail!$I:$I,Détail!$A:$A,"Mohamed HAMDANI",Détail!$B:$B,$A17,Détail!$C:$C,$B17),"") -> 100 | L17: =COUNTIFS(Détail!$A:$A,"Youssef",Détail!$B:$B,$A17,Détail!$C:$C,$B17) -> 0 | M17: =IFERROR(AVERAGEIFS(Détail!$I:$I,Détail!$A:$A,"Youssef",Détail!$B:$B,$A17,Détail!$C:$C,$B17),"") | N17: =COUNTIFS(Détail!$B:$B,$A17,Détail!$C:$C,$B17) -> 4 | O17: =IFERROR(AVERAGEIFS(Détail!$I:$I,Détail!$B:$B,$A17,Détail!$C:$C,$B17),"") -> 98.325
... A51: 2026 | B51: 44 | C51: 26/10/2026 – 01/11/2026 | D51: =COUNTIFS(Détail!$A:$A,"Hafssa BENCHRIF",Détail!$B:$B,$A51,Détail!$C:$C,$B51) -> 0 | E51: =IFERROR(AVERAGEIFS(Détail!$I:$I,Détail!$A:$A,"Hafssa BENCHRIF",Détail!$B:$B,$A51,Détail!$C:$C,$B51),"") | F51: =COUNTIFS(Détail!$A:$A,"Hiba LISSAOUI",Détail!$B:$B,$A51,Détail!$C:$C,$B51) -> 1 | G51: =IFERROR(AVERAGEIFS(Détail!$I:$I,Détail!$A:$A,"Hiba LISSAOUI",Détail!$B:$B,$A51,Détail!$C:$C,$B51),"") -> 100 | H51: =COUNTIFS(Détail!$A:$A,"Imad RMAIDI",Détail!$B:$B,$A51,Détail!$C:$C,$B51) -> 0 | I51: =IFERROR(AVERAGEIFS(Détail!$I:$I,Détail!$A:$A,"Imad RMAIDI",Détail!$B:$B,$A51,Détail!$C:$C,$B51),"") | J51: =COUNTIFS(Détail!$A:$A,"Mohamed HAMDANI",Détail!$B:$B,$A51,Détail!$C:$C,$B51) -> 0 | K51: =IFERROR(AVERAGEIFS(Détail!$I:$I,Détail!$A:$A,"Mohamed HAMDANI",Détail!$B:$B,$A51,Détail!$C:$C,$B51),"") | L51: =COUNTIFS(Détail!$A:$A,"Youssef",Détail!$B:$B,$A51,Détail!$C:$C,$B51) -> 0 | M51: =IFERROR(AVERAGEIFS(Détail!$I:$I,Détail!$A:$A,"Youssef",Détail!$B:$B,$A51,Détail!$C:$C,$B51),"") | N51: =COUNTIFS(Détail!$B:$B,$A51,Détail!$C:$C,$B51) -> 1 | O51: =IFERROR(AVERAGEIFS(Détail!$I:$I,Détail!$B:$B,$A51,Détail!$C:$C,$B51),"") -> 100
A52: Total / moyenne | D52: =SUM(D6:D51) -> 15 | E52: =IFERROR(AVERAGEIFS(Détail!$I:$I,Détail!$A:$A,"Hafssa BENCHRIF"),"") -> 99.521429 | F52: =SUM(F6:F51) -> 41 | G52: =IFERROR(AVERAGEIFS(Détail!$I:$I,Détail!$A:$A,"Hiba LISSAOUI"),"") -> 99.297561 | H52: =SUM(H6:H51) -> 39 | I52: =IFERROR(AVERAGEIFS(Détail!$I:$I,Détail!$A:$A,"Imad RMAIDI"),"") -> 100 | J52: =SUM(J6:J51) -> 34 | K52: =IFERROR(AVERAGEIFS(Détail!$I:$I,Détail!$A:$A,"Mohamed HAMDANI"),"") -> 99.348485 | L52: =SUM(L6:L51) -> 4 | M52: =IFERROR(AVERAGEIFS(Détail!$I:$I,Détail!$A:$A,"Youssef"),"") -> 100 | N52: =SUM(N6:N51) -> 133 | O52: =IFERROR(AVERAGE(Détail!$I:$I),"") -> 99.561538

Sheet Par collaborateur
A1: Bilan par collaborateur
A3: Collaborateur | B3: Documents traités | C3: Documents évalués | D3: Semaines actives | E3: Note moyenne /100 | F3: Note min. | G3: Documents à 100 % | H3: Documents < 100 % | I3: Documents < 85 % | J3: Rapports manquants | K3: Critères non conformes
A4: Hafssa BENCHRIF | B4: =COUNTIFS(Détail!$A:$A,"Hafssa BENCHRIF") -> 15 | C4: =COUNTIFS(Détail!$A:$A,"Hafssa BENCHRIF",Détail!$I:$I,">=0") -> 14 | D4: =SUMPRODUCT((Détail!$A$2:$A$134="Hafssa BENCHRIF")/COUNTIFS(Détail!$A$2:$A$134,Détail!$A$2:$A$134,Détail!$D$2:$D$134,Détail!$D$2:$D$134)) -> 13 | E4: =IFERROR(AVERAGEIFS(Détail!$I:$I,Détail!$A:$A,"Hafssa BENCHRIF"),"") -> 99.521429 | F4: =_xlfn.MINIFS(Détail!$I$2:$I$134,Détail!$A$2:$A$134,"Hafssa BENCHRIF") -> 93.3 | G4: =COUNTIFS(Détail!$A:$A,"Hafssa BENCHRIF",Détail!$I:$I,">=99.95") -> 13 | H4: =COUNTIFS(Détail!$A:$A,"Hafssa BENCHRIF",Détail!$I:$I,"<99.95") -> 1 | I4: =COUNTIFS(Détail!$A:$A,"Hafssa BENCHRIF",Détail!$I:$I,"<85") -> 0 | J4: =B4-C4 -> 1 | K4: =SUMIFS(Détail!$L:$L,Détail!$A:$A,"Hafssa BENCHRIF") -> 1
A5: Hiba LISSAOUI | B5: =COUNTIFS(Détail!$A:$A,"Hiba LISSAOUI") -> 41 | C5: =COUNTIFS(Détail!$A:$A,"Hiba LISSAOUI",Détail!$I:$I,">=0") -> 41 | D5: =SUMPRODUCT((Détail!$A$2:$A$134="Hiba LISSAOUI")/COUNTIFS(Détail!$A$2:$A$134,Détail!$A$2:$A$134,Détail!$D$2:$D$134,Détail!$D$2:$D$134)) -> 39 | E5: =IFERROR(AVERAGEIFS(Détail!$I:$I,Détail!$A:$A,"Hiba LISSAOUI"),"") -> 99.297561 | F5: =_xlfn.MINIFS(Détail!$I$2:$I$134,Détail!$A$2:$A$134,"Hiba LISSAOUI") -> 87.5 | G5: =COUNTIFS(Détail!$A:$A,"Hiba LISSAOUI",Détail!$I:$I,">=99.95") -> 36 | H5: =COUNTIFS(Détail!$A:$A,"Hiba LISSAOUI",Détail!$I:$I,"<99.95") -> 5 | I5: =COUNTIFS(Détail!$A:$A,"Hiba LISSAOUI",Détail!$I:$I,"<85") -> 0 | J5: =B5-C5 -> 0 | K5: =SUMIFS(Détail!$L:$L,Détail!$A:$A,"Hiba LISSAOUI") -> 6
A6: Imad RMAIDI | B6: =COUNTIFS(Détail!$A:$A,"Imad RMAIDI") -> 39 | C6: =COUNTIFS(Détail!$A:$A,"Imad RMAIDI",Détail!$I:$I,">=0") -> 38 | D6: =SUMPRODUCT((Détail!$A$2:$A$134="Imad RMAIDI")/COUNTIFS(Détail!$A$2:$A$134,Détail!$A$2:$A$134,Détail!$D$2:$D$134,Détail!$D$2:$D$134)) -> 37 | E6: =IFERROR(AVERAGEIFS(Détail!$I:$I,Détail!$A:$A,"Imad RMAIDI"),"") -> 100 | F6: =_xlfn.MINIFS(Détail!$I$2:$I$134,Détail!$A$2:$A$134,"Imad RMAIDI") -> 100 | G6: =COUNTIFS(Détail!$A:$A,"Imad RMAIDI",Détail!$I:$I,">=99.95") -> 38 | H6: =COUNTIFS(Détail!$A:$A,"Imad RMAIDI",Détail!$I:$I,"<99.95") -> 0 | I6: =COUNTIFS(Détail!$A:$A,"Imad RMAIDI",Détail!$I:$I,"<85") -> 0 | J6: =B6-C6 -> 1 | K6: =SUMIFS(Détail!$L:$L,Détail!$A:$A,"Imad RMAIDI") -> 0
A7: Mohamed HAMDANI | B7: =COUNTIFS(Détail!$A:$A,"Mohamed HAMDANI") -> 34 | C7: =COUNTIFS(Détail!$A:$A,"Mohamed HAMDANI",Détail!$I:$I,">=0") -> 33 | D7: =SUMPRODUCT((Détail!$A$2:$A$134="Mohamed HAMDANI")/COUNTIFS(Détail!$A$2:$A$134,Détail!$A$2:$A$134,Détail!$D$2:$D$134,Détail!$D$2:$D$134)) -> 32 | E7: =IFERROR(AVERAGEIFS(Détail!$I:$I,Détail!$A:$A,"Mohamed HAMDANI"),"") -> 99.348485 | F7: =_xlfn.MINIFS(Détail!$I$2:$I$134,Détail!$A$2:$A$134,"Mohamed HAMDANI") -> 92.3 | G7: =COUNTIFS(Détail!$A:$A,"Mohamed HAMDANI",Détail!$I:$I,">=99.95") -> 30 | H7: =COUNTIFS(Détail!$A:$A,"Mohamed HAMDANI",Détail!$I:$I,"<99.95") -> 3 | I7: =COUNTIFS(Détail!$A:$A,"Mohamed HAMDANI",Détail!$I:$I,"<85") -> 0 | J7: =B7-C7 -> 1 | K7: =SUMIFS(Détail!$L:$L,Détail!$A:$A,"Mohamed HAMDANI") -> 4
A8: Youssef | B8: =COUNTIFS(Détail!$A:$A,"Youssef") -> 4 | C8: =COUNTIFS(Détail!$A:$A,"Youssef",Détail!$I:$I,">=0") -> 4 | D8: =SUMPRODUCT((Détail!$A$2:$A$134="Youssef")/COUNTIFS(Détail!$A$2:$A$134,Détail!$A$2:$A$134,Détail!$D$2:$D$134,Détail!$D$2:$D$134)) -> 4 | E8: =IFERROR(AVERAGEIFS(Détail!$I:$I,Détail!$A:$A,"Youssef"),"") -> 100 | F8: =_xlfn.MINIFS(Détail!$I$2:$I$134,Détail!$A$2:$A$134,"Youssef") -> 100 | G8: =COUNTIFS(Détail!$A:$A,"Youssef",Détail!$I:$I,">=99.95") -> 4 | H8: =COUNTIFS(Détail!$A:$A,"Youssef",Détail!$I:$I,"<99.95") -> 0 | I8: =COUNTIFS(Détail!$A:$A,"Youssef",Détail!$I:$I,"<85") -> 0 | J8: =B8-C8 -> 0 | K8: =SUMIFS(Détail!$L:$L,Détail!$A:$A,"Youssef") -> 0
A9: Équipe | B9: =SUM(B4:B8) -> 133 | C9: =SUM(C4:C8) -> 130 | D9: =SUM(D4:D8) -> 125 | E9: =IFERROR(AVERAGE(Détail!$I:$I),"") -> 99.561538 | F9: =MIN(F4:F8) -> 87.5 | G9: =SUM(G4:G8) -> 121 | H9: =SUM(H4:H8) -> 9 | I9: =SUM(I4:I8) -> 0 | J9: =SUM(J4:J8) -> 3 | K9: =SUM(K4:K8) -> 11
A11: Seuil de conformité retenu : 85 % (identique aux rapports RAPDF). « Semaines actives » = semaines avec au moins un document.

Sheet Détail
A1: Collaborateur | B1: Année | C1: Semaine | D1: Clé semaine | E1: Document | F1: Type | G1: Date d'évaluation | H1: Source | I1: Note /100 | J1: Statut | K1: Critères conformes | L1: Critères non conformes | M1: Critères non applicables
A2: Hafssa BENCHRIF | B2: 2025 | C2: 51 | D2: =B2&"-S"&TEXT(C2,"00") -> 2025-S51 | E2: CG0570v02 0525 | F2: word | H2: Grille | I2: 100 | J2: =IF(I2="","Rapport manquant",IF(I2>=85,"CONFORME (≥85%)","NON CONFORME (<85%)")) -> CONFORME (≥85%) | K2: 10 | L2: 0 | M2: 36
A3: Hafssa BENCHRIF | B3: 2025 | C3: 51 | D3: =B3&"-S"&TEXT(C3,"00") -> 2025-S51 | E3: CM0409v04 1214 LIVRET PUNCH | F3: word | H3: Grille | I3: 100 | J3: =IF(I3="","Rapport manquant",IF(I3>=85,"CONFORME (≥85%)","NON CONFORME (<85%)")) -> CONFORME (≥85%) | K3: 8 | L3: 0 | M3: 38
A4: Hiba LISSAOUI | B4: 2025 | C4: 51 | D4: =B4&"-S"&TEXT(C4,"00") -> 2025-S51 | E4: CG.05.78v02 1024 CG BAD EI CM CIC | F4: word | H4: Grille | I4: 96.7 | J4: =IF(I4="","Rapport manquant",IF(I4>=85,"CONFORME (≥85%)","NON CONFORME (<85%)")) -> CONFORME (≥85%) | K4: 9 | L4: 1 | M4: 36
A5: Hiba LISSAOUI | B5: 2025 | C5: 51 | D5: =B5&"-S"&TEXT(C5,"00") -> 2025-S51 | E5: CG0566 0725 CM | F5: word | H5: Grille | I5: 100 | J5: =IF(I5="","Rapport manquant",IF(I5>=85,"CONFORME (≥85%)","NON CONFORME (<85%)")) -> CONFORME (≥85%) | K5: 10 | L5: 0 | M5: 36
A6: Imad RMAIDI | B6: 2025 | C6: 51 | D6: =B6&"-S"&TEXT(C6,"00") -> 2025-S51 | E6: CG0443v02 1214 LIVRET BIENVENUE + | F6: word | H6: Grille | I6: 100 | J6: =IF(I6="","Rapport manquant",IF(I6>=85,"CONFORME (≥85%)","NON CONFORME (<85%)")) -> CONFORME (≥85%) | K6: 9 | L6: 0 | M6: 37
A7: Imad RMAIDI | B7: 2025 | C7: 51 | D7: =B7&"-S"&TEXT(C7,"00") -> 2025-S51 | E7: CM0310v03 1122 livret bleu Prem's | F7: word | H7: Grille | I7: 100 | J7: =IF(I7="","Rapport manquant",IF(I7>=85,"CONFORME (≥85%)","NON CONFORME (<85%)")) -> CONFORME (≥85%) | K7: 12 | L7: 0 | M7: 34
A8: Mohamed HAMDANI | B8: 2025 | C8: 51 | D8: =B8&"-S"&TEXT(C8,"00") -> 2025-S51 | E8: CI0396v03 1018 CG carte de retrait DE | F8: word | H8: Grille | I8: 100 | J8: =IF(I8="","Rapport manquant",IF(I8>=85,"CONFORME (≥85%)","NON CONFORME (<85%)")) -> CONFORME (≥85%) | K8: 11 | L8: 0 | M8: 35
A9: Mohamed HAMDANI | B9: 2025 | C9: 51 | D9: =B9&"-S"&TEXT(C9,"00") -> 2025-S51 | E9: CM0575v01 0324 Carte achat public | F9: word | H9: Grille | I9: 93.3 | J9: =IF(I9="","Rapport manquant",IF(I9>=85,"CONFORME (≥85%)","NON CONFORME (<85%)")) -> CONFORME (≥85%) | K9: 12 | L9: 2 | M9: 32
A10: Hafssa BENCHRIF | B10: 2025 | C10: 52 | D10: =B10&"-S"&TEXT(C10,"00") -> 2025-S52 | E10: CG0563v01 0123 CG Services de Dépôt | F10: word | H10: Grille | I10: 100 | J10: =IF(I10="","Rapport manquant",IF(I10>=85,"CONFORME (≥85%)","NON CONFORME (<85%)")) -> CONFORME (≥85%) | K10: 9 | L10: 0 | M10: 37
A11: Hafssa BENCHRIF | B11: 2025 | C11: 52 | D11: =B11&"-S"&TEXT(C11,"00") -> 2025-S52 | E11: CG0706 1219 | F11: word | H11: Grille | I11: 100 | J11: =IF(I11="","Rapport manquant",IF(I11>=85,"CONFORME (≥85%)","NON CONFORME (<85%)")) -> CONFORME (≥85%) | K11: 13 | L11: 0 | M11: 33
A12: Hiba LISSAOUI | B12: 2025 | C12: 52 | D12: =B12&"-S"&TEXT(C12,"00") -> 2025-S52 | E12: CG0704 1120 | F12: word | H12: Grille | I12: 96.7 | J12: =IF(I12="","Rapport manquant",IF(I12>=85,"CONFORME (≥85%)","NON CONFORME (<85%)")) -> CONFORME (≥85%) | K12: 14 | L12: 1 | M12: 31
A13: Hiba LISSAOUI | B13: 2025 | C13: 52 | D13: =B13&"-S"&TEXT(C13,"00") -> 2025-S52 | E13: GR8884v11 0122 caut PP EPS | F13: word | H13: Grille | I13: 100 | J13: =IF(I13="","Rapport manquant",IF(I13>=85,"CONFORME (≥85%)","NON CONFORME (<85%)")) -> CONFORME (≥85%) | K13: 14 | L13: 0 | M13: 32
... A34: Hafssa BENCHRIF | B34: 2026 | C34: 5 | D34: =B34&"-S"&TEXT(C34,"00") -> 2026-S05 | E34: CG0552v01 0620 AAD | F34: word | H34: Grille | I34: 100 | J34: =IF(I34="","Rapport manquant",IF(I34>=85,"CONFORME (≥85%)","NON CONFORME (<85%)")) -> CONFORME (≥85%) | K34: 10 | L34: 0 | M34: 36
A35: Hafssa BENCHRIF | B35: 2026 | C35: 8 | D35: =B35&"-S"&TEXT(C35,"00") -> 2026-S08 | E35: COL_9902030098_011000733309323 | F35: pdf | G35: 46073 | H35: RAPDF | I35: 100 | J35: =IF(I35="","Rapport manquant",IF(I35>=85,"CONFORME (≥85%)","NON CONFORME (<85%)")) -> CONFORME (≥85%) | K35: 15 | L35: 0 | M35: 31
A36: Hiba LISSAOUI | B36: 2026 | C36: 8 | D36: =B36&"-S"&TEXT(C36,"00") -> 2026-S08 | E36: EMP_9902030152_011000758125238 | F36: pdf | G36: 46073 | H36: RAPDF | I36: 87.5 | J36: =IF(I36="","Rapport manquant",IF(I36>=85,"CONFORME (≥85%)","NON CONFORME (<85%)")) -> CONFORME (≥85%) | K36: 14 | L36: 2 | M36: 30
A37: Imad RMAIDI | B37: 2026 | C37: 8 | D37: =B37&"-S"&TEXT(C37,"00") -> 2026-S08 | E37: SAN_9902030040_011000804912506 | F37: pdf | G37: 46073 | H37: RAPDF | I37: 100 | J37: =IF(I37="","Rapport manquant",IF(I37>=85,"CONFORME (≥85%)","NON CONFORME (<85%)")) -> CONFORME (≥85%) | K37: 12 | L37: 0 | M37: 28
A38: Mohamed HAMDANI | B38: 2026 | C38: 8 | D38: =B38&"-S"&TEXT(C38,"00") -> 2026-S08 | E38: SAN_9902030040_011000804912412 | F38: pdf | G38: 46073 | H38: RAPDF | I38: 100 | J38: =IF(I38="","Rapport manquant",IF(I38>=85,"CONFORME (≥85%)","NON CONFORME (<85%)")) -> CONFORME (≥85%) | K38: 12 | L38: 0 | M38: 34
A39: Hafssa BENCHRIF | B39: 2026 | C39: 9 | D39: =B39&"-S"&TEXT(C39,"00") -> 2026-S09 | E39: COL_9902030098_011000744004221 | F39: pdf | G39: 46077 | H39: RAPDF | I39: 100 | J39: =IF(I39="","Rapport manquant",IF(I39>=85,"CONFORME (≥85%)","NON CONFORME (<85%)")) -> CONFORME (≥85%) | K39: 15 | L39: 0 | M39: 31
A40: Hiba LISSAOUI | B40: 2026 | C40: 9 | D40: =B40&"-S"&TEXT(C40,"00") -> 2026-S09 | E40: EMP_9902030152_011000767923078 | F40: pdf | G40: 46078 | H40: RAPDF | I40: 100 | J40: =IF(I40="","Rapport manquant",IF(I40>=85,"CONFORME (≥85%)","NON CONFORME (<85%)")) -> CONFORME (≥85%) | K40: 14 | L40: 0 | M40: 30
A41: Imad RMAIDI | B41: 2026 | C41: 9 | D41: =B41&"-S"&TEXT(C41,"00") -> 2026-S09 | E41: SAN_9902030040_011000804912294 | F41: pdf | G41: 46076 | H41: RAPDF | I41: 100 | J41: =IF(I41="","Rapport manquant",IF(I41>=85,"CONFORME (≥85%)","NON CONFORME (<85%)")) -> CONFORME (≥85%) | K41: 12 | L41: 0 | M41: 28
A42: Mohamed HAMDANI | B42: 2026 | C42: 9 | D42: =B42&"-S"&TEXT(C42,"00") -> 2026-S09 | E42: SAN_9902030030_011000710963677 | F42: pdf | G42: 46078 | H42: RAPDF | I42: 100 | J42: =IF(I42="","Rapport manquant",IF(I42>=85,"CONFORME (≥85%)","NON CONFORME (<85%)")) -> CONFORME (≥85%) | K42: 13 | L42: 0 | M42: 33
A43: Hafssa BENCHRIF | B43: 2026 | C43: 10 | D43: =B43&"-S"&TEXT(C43,"00") -> 2026-S10 | E43: COL_9902030098_011000764636583 | F43: pdf | G43: 46084 | H43: RAPDF | I43: 93.3 | J43: =IF(I43="","Rapport manquant",IF(I43>=85,"CONFORME (≥85%)","NON CONFORME (<85%)")) -> CONFORME (≥85%) | K43: 14 | L43: 1 | M43: 31
A44: Hiba LISSAOUI | B44: 2026 | C44: 10 | D44: =B44&"-S"&TEXT(C44,"00") -> 2026-S10 | E44: EMP_9902030152_011000767923080 | F44: pdf | G44: 46085 | H44: RAPDF | I44: 100 | J44: =IF(I44="","Rapport manquant",IF(I44>=85,"CONFORME (≥85%)","NON CONFORME (<85%)")) -> CONFORME (≥85%) | K44: 16 | L44: 0 | M44: 30
A45: Imad RMAIDI | B45: 2026 | C45: 10 | D45: =B45&"-S"&TEXT(C45,"00") -> 2026-S10 | E45: SAN_9902030030_011000710963708 | F45: pdf | G45: 46084 | H45: RAPDF | I45: 100 | J45: =IF(I45="","Rapport manquant",IF(I45>=85,"CONFORME (≥85%)","NON CONFORME (<85%)")) -> CONFORME (≥85%) | K45: 15 | L45: 0 | M45: 31
A46: Mohamed HAMDANI | B46: 2026 | C46: 10 | D46: =B46&"-S"&TEXT(C46,"00") -> 2026-S10 | E46: SAN_9902030030_011000710963634 | F46: pdf | G46: 46086 | H46: RAPDF | I46: 100 | J46: =IF(I46="","Rapport manquant",IF(I46>=85,"CONFORME (≥85%)","NON CONFORME (<85%)")) -> CONFORME (≥85%) | K46: 13 | L46: 0 | M46: 33
... A48: Hiba LISSAOUI | B48: 2026 | C48: 11 | D48: =B48&"-S"&TEXT(C48,"00") -> 2026-S11 | E48: CM.05.32 | F48: pdf | G48: 46093 | H48: RAPDF | I48: 100 | J48: =IF(I48="","Rapport manquant",IF(I48>=85,"CONFORME (≥85%)","NON CONFORME (<85%)")) -> CONFORME (≥85%) | K48: 10 | L48: 0 | M48: 36
A49: Imad RMAIDI | B49: 2026 | C49: 11 | D49: =B49&"-S"&TEXT(C49,"00") -> 2026-S11 | E49: SAN_9902020008_011000745243123 | F49: pdf | H49: — | J49: =IF(I49="","Rapport manquant",IF(I49>=85,"CONFORME (≥85%)","NON CONFORME (<85%)")) -> Rapport manquant
A50: Mohamed HAMDANI | B50: 2026 | C50: 11 | D50: =B50&"-S"&TEXT(C50,"00") -> 2026-S11 | E50: SAN_9902030053_011000789059347 | F50: pdf | H50: — | J50: =IF(I50="","Rapport manquant",IF(I50>=85,"CONFORME (≥85%)","NON CONFORME (<85%)")) -> Rapport manquant
A51: Hafssa BENCHRIF | B51: 2026 | C51: 12 | D51: =B51&"-S"&TEXT(C51,"00") -> 2026-S12 | E51: 81.69.55 | F51: pdf | G51: 46100 | H51: RAPDF | I51: 100 | J51: =IF(I51="","Rapport manquant",IF(I51>=85,"CONFORME (≥85%)","NON CONFORME (<85%)")) -> CONFORME (≥85%) | K51: 18 | L51: 0 | M51: 28
A52: Hiba LISSAOUI | B52: 2026 | C52: 12 | D52: =B52&"-S"&TEXT(C52,"00") -> 2026-S12 | E52: 16.61.12 notice | F52: pdf | G52: 46100 | H52: RAPDF | I52: 100 | J52: =IF(I52="","Rapport manquant",IF(I52>=85,"CONFORME (≥85%)","NON CONFORME (<85%)")) -> CONFORME (≥85%) | K52: 14 | L52: 0 | M52: 32
A53: Mohamed HAMDANI | B53: 2026 | C53: 12 | D53: =B53&"-S"&TEXT(C53,"00") -> 2026-S12 | E53: DIT10278 | F53: pdf | G53: 46100 | H53: RAPDF | I53: 100 | J53: =IF(I53="","Rapport manquant",IF(I53>=85,"CONFORME (≥85%)","NON CONFORME (<85%)")) -> CONFORME (≥85%) | K53: 13 | L53: 0 | M53: 33
A54: Hafssa BENCHRIF | B54: 2026 | C54: 16 | D54: =B54&"-S"&TEXT(C54,"00") -> 2026-S16 | E54: 9800059279 Fc_E-Retrait_v062026 | F54: word | H54: — | J54: =IF(I54="","Rapport manquant",IF(I54>=85,"CONFORME (≥85%)","NON CONFORME (<85%)")) -> Rapport manquant
A55: Hiba LISSAOUI | B55: 2026 | C55: 16 | D55: =B55&"-S"&TEXT(C55,"00") -> 2026-S16 | E55: 9800155243 Fc_CB_MC_Vie_Quotidienne_v062026 | F55: word | G55: 46129 | H55: RAPDF | I55: 100 | J55: =IF(I55="","Rapport manquant",IF(I55>=85,"CONFORME (≥85%)","NON CONFORME (<85%)")) -> CONFORME (≥85%) | K55: 20 | L55: 0 | M55: 26
A56: Imad RMAIDI | B56: 2026 | C56: 16 | D56: =B56&"-S"&TEXT(C56,"00") -> 2026-S16 | E56: 9800103268 Fz_CB_MC_Gold_Devise_v062026 | F56: word | G56: 46129 | H56: RAPDF | I56: 100 | J56: =IF(I56="","Rapport manquant",IF(I56>=85,"CONFORME (≥85%)","NON CONFORME (<85%)")) -> CONFORME (≥85%) | K56: 17 | L56: 0 | M56: 29
A57: Mohamed HAMDANI | B57: 2026 | C57: 16 | D57: =B57&"-S"&TEXT(C57,"00") -> 2026-S16 | E57: 9800166677 Fz_Apple_Pay_v062026 | F57: word | G57: 46129 | H57: RAPDF | I57: 100 | J57: =IF(I57="","Rapport manquant",IF(I57>=85,"CONFORME (≥85%)","NON CONFORME (<85%)")) -> CONFORME (≥85%) | K57: 15 | L57: 0 | M57: 31
A58: Hiba LISSAOUI | B58: 2026 | C58: 17 | D58: =B58&"-S"&TEXT(C58,"00") -> 2026-S17 | E58: 9800165798 Fc_CB_MC_Gold_Certizen_v062026 | F58: word | G58: 46135 | H58: RAPDF | I58: 100 | J58: =IF(I58="","Rapport manquant",IF(I58>=85,"CONFORME (≥85%)","NON CONFORME (<85%)")) -> CONFORME (≥85%) | K58: 18 | L58: 0 | M58: 28
A59: Imad RMAIDI | B59: 2026 | C59: 17 | D59: =B59&"-S"&TEXT(C59,"00") -> 2026-S17 | E59: 9800182914 CM FC compte courant PART | F59: word | G59: 46136 | H59: RAPDF | I59: 100 | J59: =IF(I59="","Rapport manquant",IF(I59>=85,"CONFORME (≥85%)","NON CONFORME (<85%)")) -> CONFORME (≥85%) | K59: 13 | L59: 0 | M59: 33
A60: Mohamed HAMDANI | B60: 2026 | C60: 17 | D60: =B60&"-S"&TEXT(C60,"00") -> 2026-S17 | E60: Fiche Zoom Alertes CIC revue | F60: word | G60: 46136 | H60: RAPDF | I60: 100 | J60: =IF(I60="","Rapport manquant",IF(I60>=85,"CONFORME (≥85%)","NON CONFORME (<85%)")) -> CONFORME (≥85%) | K60: 16 | L60: 0 | M60: 30
A61: Hiba LISSAOUI | B61: 2026 | C61: 18 | D61: =B61&"-S"&TEXT(C61,"00") -> 2026-S18 | E61: 0110017197 Fc_CB_Visa_Classic_v062026 | F61: word | G61: 46143 | H61: RAPDF | I61: 100 | J61: =IF(I61="","Rapport manquant",IF(I61>=85,"CONFORME (≥85%)","NON CONFORME (<85%)")) -> CONFORME (≥85%) | K61: 19 | L61: 0 | M61: 27
...

Sheet Remarques
A1: Collaborateur | B1: Année | C1: Semaine | D1: Document | E1: Remarque
A2: Hafssa BENCHRIF | B2: 2025 | C2: 51 | D2: (dossier vide) | E2: Dossier de la semaine créé mais vide : aucun document ni rapport.
A3: Hiba LISSAOUI | B3: 2025 | C3: 51 | D3: (dossier vide) | E3: Dossier de la semaine créé mais vide : aucun document ni rapport.
A4: Imad RMAIDI | B4: 2025 | C4: 51 | D4: (dossier vide) | E4: Dossier de la semaine créé mais vide : aucun document ni rapport.
A5: Mohamed HAMDANI | B5: 2025 | C5: 51 | D5: (dossier vide) | E5: Dossier de la semaine créé mais vide : aucun document ni rapport.
A6: Hafssa BENCHRIF | B6: 2025 | C6: 52 | D6: (dossier vide) | E6: Dossier de la semaine créé mais vide : aucun document ni rapport.
A7: Hiba LISSAOUI | B7: 2025 | C7: 52 | D7: (dossier vide) | E7: Dossier de la semaine créé mais vide : aucun document ni rapport.
A8: Imad RMAIDI | B8: 2025 | C8: 52 | D8: (dossier vide) | E8: Dossier de la semaine créé mais vide : aucun document ni rapport.
A9: Mohamed HAMDANI | B9: 2025 | C9: 52 | D9: (dossier vide) | E9: Dossier de la semaine créé mais vide : aucun document ni rapport.
A10: Hafssa BENCHRIF | B10: 2026 | C10: 1 | D10: (dossier vide) | E10: Dossier de la semaine créé mais vide : aucun document ni rapport.
A11: Hiba LISSAOUI | B11: 2026 | C11: 1 | D11: (dossier vide) | E11: Dossier de la semaine créé mais vide : aucun document ni rapport.
A12: Imad RMAIDI | B12: 2026 | C12: 1 | D12: (dossier vide) | E12: Dossier de la semaine créé mais vide : aucun document ni rapport.
A13: Mohamed HAMDANI | B13: 2026 | C13: 1 | D13: (dossier vide) | E13: Dossier de la semaine créé mais vide : aucun document ni rapport.
... A87: Hiba LISSAOUI | B87: 2026 | C87: 44 | D87: VIE_9902030044_011000541137492 | E87: Date d'évaluation (2026-10-29) postérieure à aujourd'hui : à vérifier.
